Workbook

Sheet Cover
A1: Broadcom Inc. — Cover
A2: $ in millions except per-share data | USD | as of 2026-09-22
A4: Broadcom Inc. (NASDAQ: AVGO) — Financial Model
A6: Company Overview
A7: Legal name | B7: Broadcom Inc. (Delaware; formerly Broadcom Limited, a Singapore public company, through the April 2018 redomiciliation)
A8: Ticker | B8: AVGO (NASDAQ)
A9: Reporting currency / units | B9: USD, $ in millions except per-share data
A10: Reporting framework | B10: US GAAP
A11: Fiscal year end | B11: Last Sunday of October or first Sunday of November (52/53-week fiscal year)
A12: Fiscal years covered | B12: FY2016 (ended 2016-10-30) through FY2025 (ended 2025-11-02), plus 3Q FY2026 (13 weeks ended 2026-08-02)
A13: As-of date | B13: 2025-11-02 (FY2025 fiscal year end); interim data through 2026-08-02
A14: Model date | B14: 2026-09-22
A15: Consolidation scope | B15: Consolidated (includes VMware, Inc. from November 22, 2023)
A17: Color Legend
A18: Hardcoded reported value | B18: Blue font — taken directly from a source filing
A19: Formula / calculation | B19: Black font — computed from other cells in this workbook
A20: Cross-sheet link | B20: Green font — pulled from another sheet
A21: Memo / commentary | B21: Grey italic — margin, growth, or annotation row
A23: Sheet Directory
A24: IS — Income Statement | B24: As-reported revenue through net income, EPS, margins, YoY growth
A25: BS — Balance Sheet | B25: As-reported assets/liabilities/equity, balance check, working-capital analytics (DSO/DIO/DPO/CCC)
A26: CF — Cash Flow Statement | B26: As-reported operating/investing/financing detail, cash walk check, FCF analytics
A27: SEG — Segments | B27: Segment revenue & operating income across three successive segment structures (4-seg / 3-seg / 2-seg), tie-out checks
A28: DM — Derived Metrics | B28: Profitability, returns, leverage, solvency, liquidity, coverage, cash conversion, earnings quality, growth, working capital
A29: Sources | B29: Filing-level source index and key comparability notes
A31: Key Comparability Caveats — read before using this model
A32: 1. VMware scale jump (FY2023 -> FY2024) | B32: VMware, Inc. acquisition closed Nov 22, 2023 (day 1 of FY2024), for $86,290M total consideration (~$54.2B in Broadcom stock, remainder cash). Goodwill $43.7B->$97.9B, intangibles $3.9B->$40.6B, total assets $72.9B->$165.6B, revenue $35.8B->$51.6B. FY2023 and prior are pre-VMware; treat FY2023->FY2024 as a structural break, not organic growth.
A33: 2. FY2025 revenue reclassification | B33: Per FY2025 10-K Note 3: 'we included upfront license revenue of $7,800 million within products revenue... we reclassified $4,601 million and $1,058 million of upfront license revenue from subscriptions and services revenue to products revenue for fiscal years 2024 and 2023, respectively.' This model uses each fiscal year's OWN as-filed Products/Subscriptions split (i.e., FY2024 and FY2023 columns are NOT reclassified/recast) — a pure historical series. Do not compare Products vs. Subscriptions growth rates across the FY2023/FY2024/FY2025 boundary without adjusting for this.
A34: 3. 10-for-1 forward stock split (July 2024) | B34: Effective July 15, 2024 (within FY2024). FY2016-FY2023 EPS/share-count columns are each year's own pre-split as-filed figures; FY2024 onward are post-split. WASO basic jumps from 415M (FY2023) to 4,624M (FY2024) — roughly 11.1x, reflecting both the 10:1 split and real new share issuance for the VMware deal. Do not compute raw EPS/share-count YoY growth across this boundary.
A35: 4. 2018 CIK change / redomiciliation | B35: Broadcom redomiciled from Singapore (Broadcom Limited, CIK 0001649338) to Delaware (Broadcom Inc., CIK 0001730168) on April 4, 2018, accounted for as a common-control transaction (historical financials carried over on the same basis, no restatement). Treated as continuous in this model. Noncontrolling interest (exchangeable LP units) existed FY2016-FY2018 and was eliminated at the redomiciliation.
A36: 5. Segment redefinition | B36: FY2016-FY2018: 4 segments (Wired Infrastructure, Wireless Communications, Enterprise Storage, Industrial & Other). FY2019 only: 3 segments (Semiconductor Solutions, Infrastructure Software, IP Licensing) following the Nov 2018 CA Technologies acquisition. FY2020-present: 2 segments (Semiconductor Solutions, Infrastructure Software). The SEG sheet presents each structure as a separate block (not stitched together) per the source-hierarchy rule against mixing segment definitions.
A37: 6. FY2020-FY2022 segment data sourced from MD&A, not a formal Note | B37: Broadcom's FY2020, FY2021 and FY2022 10-Ks do not include a numeric segment table in the Segment Information note (narrative only in some years); the segment revenue/operating income figures for those years are sourced from each year's MD&A 'Results of Operations' table instead (still Tier-2 SEC-filing sourced, just a different section of the same document).
A38: 7. FY2024 discontinued operations | B38: Broadcom sold the VMware End-User Computing (EUC) business to KKR on July 1, 2024 for $3.5B cash. FY2024's own as-filed income statement includes a 'Loss from discontinued operations, net of income taxes' line of $(273)M; FY2023 and earlier show no such line since EUC was only acquired as part of VMware at the start of FY2024 (no retroactive restatement was required or made).
A39: 8. 3Q FY2026 (10-Q) presentation basis | B39: Income Statement and Segment quarterly columns show the single 13-week quarter ended 2026-08-02. Balance Sheet quarterly column is the point-in-time balance as of 2026-08-02. Cash Flow Statement quarterly column is the cumulative 9-month year-to-date figure as filed (Broadcom's 10-Q does not present single-quarter cash flows) — this is a different grain than the IS/BS quarterly column and is explicitly noted on the CF sheet.

Sheet Income Statement
A1: Broadcom Inc. — Income Statement
A2: $ in millions except per-share data | USD | as of 2026-09-22
C3: FY2016 | D3: FY2017 | E3: FY2018 | F3: FY2019 | G3: FY2020 | H3: FY2021 | I3: FY2022 | J3: FY2023 | K3: FY2024 | L3: FY2025 | M3: · | N3: · | O3: 2Q FY2024 | P3: 3Q FY2024 | Q3: 1Q FY2025 | R3: 2Q FY2025 | S3: 3Q FY2025 | T3: 1Q FY2026 | U3: 2Q FY2026 | V3: 3Q FY2026
C4: 2016-10-30 | D4: 2017-10-29 | E4: 2018-11-04 | F4: 2019-11-03 | G4: 2020-11-01 | H4: 2021-10-31 | I4: 2022-10-30 | J4: 2023-10-29 | K4: 2024-11-03 | L4: 2025-11-02 | O4: 2024-05-05 | P4: 2024-08-04 | Q4: 2025-02-02 | R4: 2025-05-04 | S4: 2025-08-03 | T4: 2026-02-01 | U4: 2026-05-03 | V4: 2026-08-02
A6: CONTENTS
A7: =HYPERLINK("#'Income Statement'!A13","1. REVENUE") -> 1. REVENUE
A8: =HYPERLINK("#'Income Statement'!A20","2. COST OF REVENUE") -> 2. COST OF REVENUE
A9: =HYPERLINK("#'Income Statement'!A30","3. OPERATING EXPENSES") -> 3. OPERATING EXPENSES
A10: =HYPERLINK("#'Income Statement'!A41","4. NON-OPERATING ITEMS AND TAXES") -> 4. NON-OPERATING ITEMS AND TAXES
A11: =HYPERLINK("#'Income Statement'!A57","5. EPS & SHARE COUNT") -> 5. EPS & SHARE COUNT
A13: 1. REVENUE
A14: Net revenue | C14: 13240 | D14: 17636 | E14: 20848 | F14: 22597 | G14: 23888 | H14: 27450 | I14: 33203 | J14: 35819 | K14: 51574 | L14: 63887 | O14: 12487 | P14: 13072 | Q14: 14916 | R14: 15004 | S14: 15952 | T14: 19311 | U14: 22187 | V14: 29591
A15: YoY Growth | D15: =IF(N(C14)=0,"",D14/C14-1) -> 0.33202417 | E15: =IF(N(D14)=0,"",E14/D14-1) -> 0.18212747 | F15: =IF(N(E14)=0,"",F14/E14-1) -> 0.083892939 | G15: =IF(N(F14)=0,"",G14/F14-1) -> 0.057131478 | H15: =IF(N(G14)=0,"",H14/G14-1) -> 0.14911253 | I15: =IF(N(H14)=0,"",I14/H14-1) -> 0.20958106 | J15: =IF(N(I14)=0,"",J14/I14-1) -> 0.078788061 | K15: =IF(N(J14)=0,"",K14/J14-1) -> 0.43985036 | L15: =IF(N(K14)=0,"",L14/K14-1) -> 0.23874433 | S15: =IF(N(O14)=0,"",S14/O14-1) -> 0.27748859 | T15: =IF(N(P14)=0,"",T14/P14-1) -> 0.47727968 | U15: =IF(N(Q14)=0,"",U14/Q14-1) -> 0.48746313 | V15: =IF(N(R14)=0,"",V14/R14-1) -> 0.97220741
A16: Products revenue | B16: Products/Subscriptions split first disclosed in FY2019 10-K; not presented separately for FY2016-FY2018 in their own filings. SEPARATELY: starting with the FY2026 Q1 10-Q, Broadcom reclassified 'upfront license revenue' from Subscriptions/services into Products (applied retrospectively to that filing's own FY2025 Q1 comparative column only). The 1Q/2Q/3Q FY2025 quarterly columns in this model are each shown on that quarter's OWN as-originally-filed (pre-reclassification) basis, consistent with the own-quarter/no-restatement rule used throughout this workbook — they are therefore NOT directly comparable, line-for-line, to the FY2025 annual column (which uses the FY2025 10-K's post-reclassification presentation) or to the 1Q/2Q FY2026 columns (also post-reclassification). Total revenue is unaffected in all cases — only the Products/Subscriptions split shifts. | F16: 18117 | G16: 17435 | H16: 20886 | I16: 26277 | J16: 27891 | K16: 30359 | L16: 44847 | O16: 7192 | P16: 7439 | Q16: 8171 | R16: 8506 | S16: 9257 | T16: 14130 | U16: 16892 | V16: 24279
A17: Subscriptions and services revenue | F17: 4480 | G17: 6453 | H17: 6564 | I17: 6926 | J17: 7928 | K17: 21215 | L17: 19040 | O17: 5295 | P17: 5633 | Q17: 6745 | R17: 6498 | S17: 6695 | T17: 5181 | U17: 5295 | V17: 5312
A18: Split vs Total Revenue (should be ~0) | F18: =F16+F17-F14 -> 0 | G18: =G16+G17-G14 -> 0 | H18: =H16+H17-H14 -> 0 | I18: =I16+I17-I14 -> 0 | J18: =J16+J17-J14 -> 0 | K18: =K16+K17-K14 -> 0 | L18: =L16+L17-L14 -> 0 | O18: =O16+O17-O14 -> 0 | P18: =P16+P17-P14 -> 0 | Q18: =Q16+Q17-Q14 -> 0 | R18: =R16+R17-R14 -> 0 | S18: =S16+S17-S14 -> 0 | T18: =T16+T17-T14 -> 0 | U18: =U16+U17-U14 -> 0 | V18: =V16+V17-V14 -> 0
A20: 2. COST OF REVENUE
A21: Cost of products sold | C21: 5295 | D21: 6593 | E21: 7021 | F21: 6208 | G21: 5892 | H21: 6555 | I21: 7629 | J21: 8636 | K21: 9797 | L21: 12115 | O21: 2429 | P21: 2434 | Q21: 2693 | R21: 2720 | S21: 3096 | T21: 4041 | U21: 4665 | V21: 6983
A22: Cost of subscriptions and services | F22: 515 | G22: 626 | H22: 607 | I22: 627 | J22: 636 | K22: 2991 | L22: 2371 | O22: 713 | P22: 699 | Q22: 580 | R22: 576 | S22: 608 | T22: 638 | U22: 636 | V22: 641
A23: Purchase accounting effect on inventory | C23: 1185 | D23: 4 | E23: 70
A24: Amortization of acquisition-related intangible assets | C24: 763 | D24: 2511 | E24: 3004 | F24: 3314 | G24: 3819 | H24: 3427 | I24: 2847 | J24: 1853 | K24: 6023 | L24: 6031 | O24: 1516 | P24: 1525 | Q24: 1484 | R24: 1483 | S24: 1519 | T24: 1462 | U24: 1461 | V24: 1499
A25: Restructuring charges | C25: 57 | D25: 19 | E25: 20 | F25: 77 | G25: 35 | H25: 17 | I25: 5 | J25: 4 | K25: 254 | L25: 76 | O25: 53 | P25: 58 | Q25: 14 | R25: 28 | S25: 26 | T25: 13 | U25: 10 | V25: 12
A26: Total cost of revenue | C26: =C21+C22+C23+C24+C25 -> 7300 | D26: =D21+D22+D23+D24+D25 -> 9127 | E26: =E21+E22+E23+E24+E25 -> 10115 | F26: =F21+F22+F23+F24+F25 -> 10114 | G26: =G21+G22+G23+G24+G25 -> 10372 | H26: =H21+H22+H23+H24+H25 -> 10606 | I26: =I21+I22+I23+I24+I25 -> 11108 | J26: =J21+J22+J23+J24+J25 -> 11129 | ... L26: =L21+L22+L23+L24+L25 -> 20593 | O26: =O21+O22+O23+O24+O25 -> 4711 | P26: =P21+P22+P23+P24+P25 -> 4716 | Q26: =Q21+Q22+Q23+Q24+Q25 -> 4771 | R26: =R21+R22+R23+R24+R25 -> 4807 | S26: =S21+S22+S23+S24+S25 -> 5249 | T26: =T21+T22+T23+T24+T25 -> 6154 | U26: =U21+U22+U23+U24+U25 -> 6772 | V26: =V21+V22+V23+V24+V25 -> 9135
A27: Gross margin | C27: =C14-C26 -> 5940 | D27: =D14-D26 -> 8509 | E27: =E14-E26 -> 10733 | F27: =F14-F26 -> 12483 | G27: =G14-G26 -> 13516 | H27: =H14-H26 -> 16844 | I27: =I14-I26 -> 22095 | J27: =J14-J26 -> 24690 | ... L27: =L14-L26 -> 43294 | O27: =O14-O26 -> 7776 | P27: =P14-P26 -> 8356 | Q27: =Q14-Q26 -> 10145 | R27: =R14-R26 -> 10197 | S27: =S14-S26 -> 10703 | T27: =T14-T26 -> 13157 | U27: =U14-U26 -> 15415 | V27: =V14-V26 -> 20456
A28: Gross Margin % | C28: =C27/C14 -> 0.44864048 | D28: =D27/D14 -> 0.48247902 | E28: =E27/E14 -> 0.51482157 | F28: =F27/F14 -> 0.55241846 | G28: =G27/G14 -> 0.5658071 | H28: =H27/H14 -> 0.61362477 | I28: =I27/I14 -> 0.66545192 | J28: =J27/J14 -> 0.68929898 | ... L28: =L27/L14 -> 0.67766525 | O28: =O27/O14 -> 0.62272764 | P28: =P27/P14 -> 0.63922889 | Q28: =Q27/Q14 -> 0.68014213 | R28: =R27/R14 -> 0.67961877 | S28: =S27/S14 -> 0.67095035 | T28: =T27/T14 -> 0.68132153 | U28: =U27/U14 -> 0.69477622 | V28: =V27/V14 -> 0.69129127
A30: 3. OPERATING EXPENSES
A31: Research and development | C31: 2674 | D31: 3292 | E31: 3768 | F31: 4696 | G31: 4968 | H31: 4854 | I31: 4919 | J31: 5253 | K31: 9310 | L31: 10977 | O31: 2415 | P31: 2353 | Q31: 2253 | R31: 2693 | S31: 3050 | T31: 2965 | U31: 2995 | V31: 2895
A32: Selling, general and administrative | C32: 806 | D32: 787 | E32: 1056 | F32: 1709 | G32: 1935 | H32: 1347 | I32: 1382 | J32: 1592 | K32: 4959 | L32: 4211 | O32: 1277 | P32: 1100 | Q32: 949 | R32: 1083 | S32: 1072 | T32: 1019 | U32: 1055 | V32: 996
A33: Amortization of acquisition-related intangible assets | C33: 1873 | D33: 1764 | E33: 541 | F33: 1898 | G33: 2401 | H33: 1976 | I33: 1512 | J33: 1394 | K33: 3244 | L33: 2031 | O33: 827 | P33: 812 | Q33: 511 | R33: 506 | S33: 507 | T33: 507 | U33: 506 | V33: 507
A34: Restructuring, impairment and other charges | C34: 996 | D34: 161 | E34: 219 | F34: 736 | G34: 198 | H34: 148 | I34: 57 | J34: 244 | K34: 1533 | L34: 591 | O34: 292 | P34: 303 | Q34: 172 | R34: 86 | S34: 187 | T34: 103 | U34: 71 | V34: 103
A35: Litigation settlements | D35: 122 | E35: 14
A36: Total operating expenses | C36: =C31+C32+C33+C34+C35 -> 6349 | D36: =D31+D32+D33+D34+D35 -> 6126 | E36: =E31+E32+E33+E34+E35 -> 5598 | F36: =F31+F32+F33+F34+F35 -> 9039 | G36: =G31+G32+G33+G34+G35 -> 9502 | H36: =H31+H32+H33+H34+H35 -> 8325 | I36: =I31+I32+I33+I34+I35 -> 7870 | J36: =J31+J32+J33+J34+J35 -> 8483 | ... L36: =L31+L32+L33+L34+L35 -> 17810 | O36: =O31+O32+O33+O34+O35 -> 4811 | P36: =P31+P32+P33+P34+P35 -> 4568 | Q36: =Q31+Q32+Q33+Q34+Q35 -> 3885 | R36: =R31+R32+R33+R34+R35 -> 4368 | S36: =S31+S32+S33+S34+S35 -> 4816 | T36: =T31+T32+T33+T34+T35 -> 4594 | U36: =U31+U32+U33+U34+U35 -> 4627 | V36: =V31+V32+V33+V34+V35 -> 4501
A37: Operating income (loss) | C37: =C27-C36 -> -409 | D37: =D27-D36 -> 2383 | E37: =E27-E36 -> 5135 | F37: =F27-F36 -> 3444 | G37: =G27-G36 -> 4014 | H37: =H27-H36 -> 8519 | I37: =I27-I36 -> 14225 | J37: =J27-J36 -> 16207 | ... L37: =L27-L36 -> 25484 | O37: =O27-O36 -> 2965 | P37: =P27-P36 -> 3788 | Q37: =Q27-Q36 -> 6260 | R37: =R27-R36 -> 5829 | S37: =S27-S36 -> 5887 | T37: =T27-T36 -> 8563 | U37: =U27-U36 -> 10788 | V37: =V27-V36 -> 15955
A38: Operating Margin % | C38: =C37/C14 -> -0.030891239 | D38: =D37/D14 -> 0.13512134 | E38: =E37/E14 -> 0.2463066 | F38: =F37/F14 -> 0.15240961 | G38: =G37/G14 -> 0.16803416 | H38: =H37/H14 -> 0.31034608 | I38: =I37/I14 -> 0.42842514 | J38: =J37/J14 -> 0.45246936 | ... L38: =L37/L14 -> 0.39889179 | O38: =O37/O14 -> 0.23744694 | P38: =P37/P14 -> 0.28977968 | Q38: =Q37/Q14 -> 0.41968356 | R38: =R37/R14 -> 0.3884964 | S38: =S37/S14 -> 0.36904463 | T38: =T37/T14 -> 0.44342603 | U38: =U37/U14 -> 0.48623068 | V38: =V37/V14 -> 0.53918421
A39: YoY Growth | D39: =IF(N(C37)=0,"",D37/C37-1) -> -6.8264059 | E39: =IF(N(D37)=0,"",E37/D37-1) -> 1.1548468 | F39: =IF(N(E37)=0,"",F37/E37-1) -> -0.32930867 | G39: =IF(N(F37)=0,"",G37/F37-1) -> 0.16550523 | H39: =IF(N(G37)=0,"",H37/G37-1) -> 1.1223219 | I39: =IF(N(H37)=0,"",I37/H37-1) -> 0.66979692 | J39: =IF(N(I37)=0,"",J37/I37-1) -> 0.13933216 | K39: =IF(N(J37)=0,"",K37/J37-1) -> -0.16930956 | L39: =IF(N(K37)=0,"",L37/K37-1) -> 0.89289163 | S39: =IF(N(O37)=0,"",S37/O37-1) -> 0.98549747 | T39: =IF(N(P37)=0,"",T37/P37-1) -> 1.2605597 | U39: =IF(N(Q37)=0,"",U37/Q37-1) -> 0.72332268 | V39: =IF(N(R37)=0,"",V37/R37-1) -> 1.7371762
A41: 4. NON-OPERATING ITEMS AND TAXES
A42: Interest expense | C42: -585 | D42: -454 | E42: -628 | F42: -1444 | G42: -1777 | H42: -1885 | I42: -1737 | J42: -1622 | K42: -3953 | L42: -3210 | O42: -1047 | P42: -1064 | Q42: -873 | R42: -769 | S42: -807 | T42: -801 | U42: -776 | V42: -778
A43: Loss on extinguishment of debt | B43: Not broken out separately on the IS face after FY2017; folded into Other income (expense), net in later years (see CF addback for later years' non-cash portion). | C43: -123 | D43: -166
A44: Impairment on investment | E44: -106
A45: Other income (expense), net | C45: 10 | D45: 62 | E45: 144 | F45: 226 | G45: 206 | H45: 131 | I45: -54 | J45: 512 | K45: 406 | L45: 455 | O45: 87 | P45: 82 | Q45: 103 | R45: 25 | S45: 205 | T45: 433 | U45: 118 | V45: 98
...

Sheet Balance Sheet
A1: Broadcom Inc. — Balance Sheet
A2: $ in millions except per-share data | USD | as of 2026-09-22
C3: FY2016 | D3: FY2017 | E3: FY2018 | F3: FY2019 | G3: FY2020 | H3: FY2021 | I3: FY2022 | J3: FY2023 | K3: FY2024 | L3: FY2025 | M3: · | N3: · | O3: 2Q FY2024 | P3: 3Q FY2024 | Q3: 1Q FY2025 | R3: 2Q FY2025 | S3: 3Q FY2025 | T3: 1Q FY2026 | U3: 2Q FY2026 | V3: 3Q FY2026
C4: 2016-10-30 | D4: 2017-10-29 | E4: 2018-11-04 | F4: 2019-11-03 | G4: 2020-11-01 | H4: 2021-10-31 | I4: 2022-10-30 | J4: 2023-10-29 | K4: 2024-11-03 | L4: 2025-11-02 | O4: 2024-05-05 | P4: 2024-08-04 | Q4: 2025-02-02 | R4: 2025-05-04 | S4: 2025-08-03 | T4: 2026-02-01 | U4: 2026-05-03 | V4: 2026-08-02
A6: CONTENTS
A7: =HYPERLINK("#'Balance Sheet'!A14","1. CURRENT ASSETS") -> 1. CURRENT ASSETS
A8: =HYPERLINK("#'Balance Sheet'!A21","2. LONG-TERM ASSETS") -> 2. LONG-TERM ASSETS
A9: =HYPERLINK("#'Balance Sheet'!A28","3. CURRENT LIABILITIES") -> 3. CURRENT LIABILITIES
A10: =HYPERLINK("#'Balance Sheet'!A35","4. LONG-TERM LIABILITIES") -> 4. LONG-TERM LIABILITIES
A11: =HYPERLINK("#'Balance Sheet'!A41","5. MEZZANINE AND EQUITY") -> 5. MEZZANINE AND EQUITY
A12: =HYPERLINK("#'Balance Sheet'!A51","6. WORKING CAPITAL ANALYTICS") -> 6. WORKING CAPITAL ANALYTICS
A14: 1. CURRENT ASSETS
A15: Cash and cash equivalents | C15: 3097 | D15: 11204 | E15: 4292 | F15: 5055 | G15: 7618 | H15: 12163 | I15: 12416 | J15: 14189 | K15: 9348 | L15: 16178 | O15: 9809 | P15: 9952 | Q15: 9307 | R15: 9472 | S15: 10718 | T15: 14174 | U15: 19628 | V15: 23975
A16: Trade accounts receivable, net | C16: 2181 | D16: 2448 | E16: 3325 | F16: 3259 | G16: 2297 | H16: 2071 | I16: 2958 | J16: 3154 | K16: 4416 | L16: 7145 | O16: 5500 | P16: 4665 | Q16: 4955 | R16: 5563 | S16: 6494 | T16: 8460 | U16: 10830 | V16: 13707
A17: Inventory | C17: 1400 | D17: 1447 | E17: 1124 | F17: 874 | G17: 1003 | H17: 1297 | I17: 1925 | J17: 1898 | K17: 1760 | L17: 2270 | O17: 1842 | P17: 1894 | Q17: 1908 | R17: 2017 | S17: 2180 | T17: 2962 | U17: 4328 | V17: 4523
A18: Other current assets | C18: 447 | D18: 724 | E18: 366 | F18: 729 | G18: 977 | H18: 1055 | I18: 1205 | J18: 1606 | K18: 4071 | L18: 5980 | O18: 8151 | P18: 3436 | Q18: 4820 | R18: 5129 | S18: 5606 | T18: 6466 | U18: 7427 | V18: 9968
A19: Total current assets | C19: =C15+C16+C17+C18 -> 7125 | D19: =D15+D16+D17+D18 -> 15823 | E19: =E15+E16+E17+E18 -> 9107 | F19: =F15+F16+F17+F18 -> 9917 | G19: =G15+G16+G17+G18 -> 11895 | H19: =H15+H16+H17+H18 -> 16586 | I19: =I15+I16+I17+I18 -> 18504 | J19: =J15+J16+J17+J18 -> 20847 | ... L19: =L15+L16+L17+L18 -> 31573 | O19: =O15+O16+O17+O18 -> 25302 | P19: =P15+P16+P17+P18 -> 19947 | Q19: =Q15+Q16+Q17+Q18 -> 20990 | R19: =R15+R16+R17+R18 -> 22181 | S19: =S15+S16+S17+S18 -> 24998 | T19: =T15+T16+T17+T18 -> 32062 | U19: =U15+U16+U17+U18 -> 42213 | V19: =V15+V16+V17+V18 -> 52173
A21: 2. LONG-TERM ASSETS
A22: Property, plant and equipment, net | C22: 2509 | D22: 2599 | E22: 2635 | F22: 2565 | G22: 2509 | H22: 2348 | I22: 2223 | J22: 2154 | K22: 2521 | L22: 2530 | O22: 2668 | P22: 2602 | Q22: 2465 | R22: 2462 | S22: 2451 | T22: 2599 | U22: 2788 | V22: 3144
A23: Goodwill | C23: 24732 | D23: 24706 | E23: 26913 | F23: 36714 | G23: 43447 | H23: 43450 | I23: 43614 | J23: 43653 | K23: 97873 | L23: 97801 | O23: 97873 | P23: 97873 | Q23: 97871 | R23: 97801 | S23: 97801 | T23: 97801 | U23: 97801 | V23: 97801
A24: Intangible assets, net | C24: 15068 | D24: 10832 | E24: 10762 | F24: 17554 | G24: 16782 | H24: 11374 | I24: 7111 | J24: 3867 | K24: 40583 | L24: 32273 | O24: 45407 | P24: 43034 | Q24: 38583 | R24: 36393 | S24: 34344 | T24: 30302 | U24: 28333 | V24: 26325
A25: Other long-term assets | C25: 532 | D25: 458 | E25: 707 | F25: 743 | G25: 1300 | H25: 1812 | I25: 1797 | J25: 2340 | K25: 5073 | L25: 6915 | O25: 3961 | P25: 4510 | Q25: 5449 | R25: 5793 | S25: 6027 | T25: 7139 | U25: 8023 | V25: 8705
A26: Total assets | C26: =C19+C22+C23+C24+C25 -> 49966 | D26: =D19+D22+D23+D24+D25 -> 54418 | E26: =E19+E22+E23+E24+E25 -> 50124 | F26: =F19+F22+F23+F24+F25 -> 67493 | G26: =G19+G22+G23+G24+G25 -> 75933 | H26: =H19+H22+H23+H24+H25 -> 75570 | I26: =I19+I22+I23+I24+I25 -> 73249 | J26: =J19+J22+J23+J24+J25 -> 72861 | ... L26: =L19+L22+L23+L24+L25 -> 171092 | O26: =O19+O22+O23+O24+O25 -> 175211 | P26: =P19+P22+P23+P24+P25 -> 167966 | Q26: =Q19+Q22+Q23+Q24+Q25 -> 165358 | R26: =R19+R22+R23+R24+R25 -> 164630 | S26: =S19+S22+S23+S24+S25 -> 165621 | T26: =T19+T22+T23+T24+T25 -> 169903 | U26: =U19+U22+U23+U24+U25 -> 179158 | V26: =V19+V22+V23+V24+V25 -> 188148
A28: 3. CURRENT LIABILITIES
A29: Accounts payable | C29: 1261 | D29: 1105 | E29: 811 | F29: 855 | G29: 836 | H29: 1086 | I29: 998 | J29: 1210 | K29: 1662 | L29: 1560 | O29: 1441 | P29: 1757 | Q29: 1905 | R29: 1297 | S29: 1432 | T29: 2112 | U29: 2337 | V29: 4000
A30: Employee compensation and benefits | C30: 517 | D30: 626 | E30: 715 | F30: 641 | G30: 877 | H30: 1066 | I30: 1202 | J30: 935 | K30: 1971 | L30: 2129 | O30: 1385 | P30: 1725 | Q30: 922 | R30: 1266 | S30: 1719 | T30: 864 | U30: 1134 | V30: 1506
A31: Current portion of long-term debt / short-term debt | C31: 454 | D31: 117 | F31: 2787 | G31: 827 | H31: 290 | I31: 440 | J31: 1608 | K31: 1271 | L31: 3152 | O31: 2426 | P31: 3161 | Q31: 5653 | R31: 5531 | S31: 1399 | T31: 2252 | U31: 2252 | V31: 2252
A32: Other current liabilities | C32: 846 | D32: 681 | E32: 812 | F32: 2616 | G32: 3831 | H32: 3839 | I32: 4412 | J32: 3652 | K32: 11793 | L32: 11673 | O32: 14919 | P32: 12578 | Q32: 12430 | R32: 12503 | S32: 12154 | T32: 11631 | U32: 13139 | V32: 13080
A33: Total current liabilities | C33: =C29+C30+C31+C32 -> 3078 | D33: =D29+D30+D31+D32 -> 2529 | E33: =E29+E30+E31+E32 -> 2338 | F33: =F29+F30+F31+F32 -> 6899 | G33: =G29+G30+G31+G32 -> 6371 | H33: =H29+H30+H31+H32 -> 6281 | I33: =I29+I30+I31+I32 -> 7052 | J33: =J29+J30+J31+J32 -> 7405 | ... L33: =L29+L30+L31+L32 -> 18514 | O33: =O29+O30+O31+O32 -> 20171 | P33: =P29+P30+P31+P32 -> 19221 | Q33: =Q29+Q30+Q31+Q32 -> 20910 | R33: =R29+R30+R31+R32 -> 20597 | S33: =S29+S30+S31+S32 -> 16704 | T33: =T29+T30+T31+T32 -> 16859 | U33: =U29+U30+U31+U32 -> 18862 | V33: =V29+V30+V31+V32 -> 20838
A35: 4. LONG-TERM LIABILITIES
A36: Long-term debt | C36: 13188 | D36: 17431 | E36: 17493 | F36: 30011 | G36: 40235 | H36: 39440 | I36: 39075 | J36: 37621 | K36: 66295 | L36: 61984 | O36: 71590 | P36: 66798 | Q36: 60926 | R36: 61751 | S36: 62830 | T36: 63805 | U36: 62655 | V36: 57167
A37: Pension and postretirement obligations | B37: Separately disclosed only in FY2016-FY2017; folded into Other long-term liabilities thereafter. | C37: 531 | D37: 112
A38: Other long-term liabilities | C38: 11293 | D38: 11160 | E38: 3636 | F38: 5613 | G38: 5426 | H38: 4860 | I38: 4413 | J38: 3847 | K38: 14975 | L38: 9302 | O38: 13489 | P38: 16296 | Q38: 13733 | R38: 12696 | S38: 12810 | T38: 9367 | U38: 9950 | V38: 10453
A39: Total liabilities | C39: =C33+C36+C37+C38 -> 28090 | D39: =D33+D36+D37+D38 -> 31232 | E39: =E33+E36+E37+E38 -> 23467 | F39: =F33+F36+F37+F38 -> 42523 | G39: =G33+G36+G37+G38 -> 52032 | H39: =H33+H36+H37+H38 -> 50581 | I39: =I33+I36+I37+I38 -> 50540 | J39: =J33+J36+J37+J38 -> 48873 | ... L39: =L33+L36+L37+L38 -> 89800 | O39: =O33+O36+O37+O38 -> 105250 | P39: =P33+P36+P37+P38 -> 102315 | Q39: =Q33+Q36+Q37+Q38 -> 95569 | R39: =R33+R36+R37+R38 -> 95044 | S39: =S33+S36+S37+S38 -> 92344 | T39: =T33+T36+T37+T38 -> 90031 | U39: =U33+U36+U37+U38 -> 91467 | V39: =V33+V36+V37+V38 -> 88458
A41: 5. MEZZANINE AND EQUITY
A42: Preferred stock dividend obligation (mezzanine) | B42: 8.00% Mandatory Convertible Preferred Stock, Series A — issued FY2019, fully converted FY2022. | F42: 29 | G42: 27 | H42: 27
A43: Common stock and additional paid-in capital | C43: 19241 | D43: 20505 | E43: 23285 | F43: 25081 | G43: 23982 | H43: 24330 | I43: 21159 | J43: 21099 | K43: 67471 | L43: 71313 | O43: 69754 | P43: 67318 | Q43: 66853 | R43: 66694 | S43: 69016 | T43: 73140 | U43: 75317 | V43: 77335
A44: Retained earnings (accumulated deficit) | C44: -215 | D44: -129 | E44: 3487 | F44: 0 | G44: 0 | H44: 748 | I44: 1604 | J44: 2682 | K44: 0 | L44: 9761 | O44: 0 | P44: -1875 | Q44: 2729 | R44: 2686 | S44: 4040 | T44: 6520 | U44: 12166 | V44: 22151
A45: Accumulated other comprehensive income (loss) | C45: -134 | D45: -91 | E45: -115 | F45: -140 | G45: -108 | H45: -116 | I45: -54 | J45: 207 | K45: 207 | L45: 218 | O45: 207 | P45: 208 | Q45: 207 | R45: 206 | S45: 221 | T45: 212 | U45: 208 | V45: 204
A46: Total Broadcom stockholders' equity | C46: =C43+C44+C45 -> 18892 | D46: =D43+D44+D45 -> 20285 | E46: =E43+E44+E45 -> 26657 | F46: =F43+F44+F45 -> 24941 | G46: =G43+G44+G45 -> 23874 | H46: =H43+H44+H45 -> 24962 | I46: =I43+I44+I45 -> 22709 | J46: =J43+J44+J45 -> 23988 | ... L46: =L43+L44+L45 -> 81292 | O46: =O43+O44+O45 -> 69961 | P46: =P43+P44+P45 -> 65651 | Q46: =Q43+Q44+Q45 -> 69789 | R46: =R43+R44+R45 -> 69586 | S46: =S43+S44+S45 -> 73277 | T46: =T43+T44+T45 -> 79872 | U46: =U43+U44+U45 -> 87691 | V46: =V43+V44+V45 -> 99690
...

Sheet Cash Flow Statement
A1: Broadcom Inc. — Cash Flow Statement
A2: $ in millions except per-share data | USD | as of 2026-09-22
C3: FY2016 | D3: FY2017 | E3: FY2018 | F3: FY2019 | G3: FY2020 | H3: FY2021 | I3: FY2022 | J3: FY2023 | K3: FY2024 | L3: FY2025 | M3: · | N3: · | O3: 2Q FY2024 | P3: 3Q FY2024 | Q3: 1Q FY2025 | R3: 2Q FY2025 | S3: 3Q FY2025 | T3: 1Q FY2026 | U3: 2Q FY2026 | V3: 3Q FY2026
C4: 2016-10-30 | D4: 2017-10-29 | E4: 2018-11-04 | F4: 2019-11-03 | G4: 2020-11-01 | H4: 2021-10-31 | I4: 2022-10-30 | J4: 2023-10-29 | K4: 2024-11-03 | L4: 2025-11-02 | O4: 2024-05-05 | P4: 2024-08-04 | Q4: 2025-02-02 | R4: 2025-05-04 | S4: 2025-08-03 | T4: 2026-02-01 | U4: 2026-05-03 | V4: 2026-08-02
A6: CONTENTS
A7: =HYPERLINK("#'Cash Flow Statement'!A13","1. OPERATING ACTIVITIES") -> 1. OPERATING ACTIVITIES
A8: =HYPERLINK("#'Cash Flow Statement'!A35","2. INVESTING ACTIVITIES") -> 2. INVESTING ACTIVITIES
A9: =HYPERLINK("#'Cash Flow Statement'!A45","3. FINANCING ACTIVITIES") -> 3. FINANCING ACTIVITIES
A10: =HYPERLINK("#'Cash Flow Statement'!A61","4. NET CHANGE IN CASH") -> 4. NET CHANGE IN CASH
A11: =HYPERLINK("#'Cash Flow Statement'!A67","5. FREE CASH FLOW ANALYTICS") -> 5. FREE CASH FLOW ANALYTICS
A13: 1. OPERATING ACTIVITIES
A14: Net income (loss) | B14: All quarterly columns are cumulative fiscal-year-to-date figures exactly as filed in each quarter's own 10-Q (1Q columns = single quarter, since Q1 YTD = Q1 alone; 2Q columns = 6-month YTD; 3Q columns = 9-month YTD) — Broadcom's 10-Qs do not present a discrete single-quarter cash flow statement. All other CF quarterly-column figures below are likewise fiscal-YTD, consistent with this line. (IS and SEG quarterly columns, by contrast, are single-quarter, not YTD — see IS note.) | C14: -1861 | D14: 1784 | E14: 12610 | F14: 2724 | G14: 2960 | H14: 6736 | I14: 11495 | J14: 14082 | K14: 5895 | L14: 23126 | O14: 3446 | P14: 1571 | Q14: 5503 | R14: 10468 | S14: 14608 | T14: 7349 | U14: 16659 | V14: 29747
A15: Ties to IS Net Income (annual only, should be ~0) | C15: =C14-'Income Statement'!C50 -> 0 | D15: =D14-'Income Statement'!D50 -> 0 | E15: =E14-'Income Statement'!E50 -> 0 | F15: =F14-'Income Statement'!F50 -> 0 | G15: =G14-'Income Statement'!G50 -> 0 | H15: =H14-'Income Statement'!H50 -> 0 | I15: =I14-'Income Statement'!I50 -> 0 | J15: =J14-'Income Statement'!J50 -> 0 | ... L15: =L14-'Income Statement'!L50 -> 0
A16: Amortization of intangible assets (and ROU assets, later years) | B16: FY2016-FY2017: combined depreciation & amortization total (not split on face of CF). | C16: 3042 | D16: 4737 | E16: 3566 | F16: 5239 | G16: 6335 | H16: 5502 | I16: 4455 | J16: 3333 | K16: 9417 | L16: 8201 | O16: 4587 | P16: 6962 | Q16: 2032 | R16: 4056 | S16: 6116 | T16: 2003 | U16: 4005 | V16: 6047
A17: Depreciation | E17: 515 | F17: 569 | G17: 570 | H17: 539 | I17: 529 | J17: 502 | K17: 593 | L17: 574 | O17: 288 | P17: 437 | Q17: 142 | R17: 284 | S17: 426 | T17: 150 | U17: 313 | V17: 484
A18: Stock-based compensation expense | C18: 679 | D18: 921 | E18: 1227 | F18: 2185 | G18: 1976 | H18: 1704 | I18: 1533 | J18: 2171 | K18: 5741 | L18: 7568 | O18: 3039 | P18: 4427 | Q18: 1280 | R18: 3051 | S18: 5373 | T18: 2176 | U18: 4268 | V18: 6287
A19: Excess tax benefits from stock-based compensation | C19: -89
A20: Deferred income taxes and other non-cash taxes | C20: 365 | D20: -173 | E20: -8270 | F20: -934 | G20: -1142 | H20: -809 | I20: -34 | J20: -501 | K20: 1965 | L20: -4008 | O20: -805 | P20: 2833 | Q20: -696 | R20: -1267 | S20: -983 | T20: -455 | U20: -1058 | V20: -1051
A21: Impairment on investment | E21: 106
A22: Non-cash portion of loss on debt extinguishment | C22: 100 | D22: 166 | G22: 169 | H22: 198 | I22: 100 | K22: 157 | L22: 138 | P22: 105 | Q22: 65 | R22: 65 | S22: 118 | T22: 55 | U22: 86 | V22: 161
A23: Non-cash restructuring, impairment and disposal charges | C23: 662 | D23: 71 | E23: 21 | F23: 133 | G23: 44 | H23: 38 | I23: 13
A24: Non-cash interest expense / debt issuance cost amortization | C24: 36 | D24: 24 | E24: 24 | F24: 90 | G24: 108 | H24: 96 | I24: 129 | J24: 132 | K24: 427 | L24: 344 | O24: 221 | P24: 336 | Q24: 97 | R24: 191 | S24: 273 | T24: 72 | U24: 139 | V24: 204
A25: Other | C25: -6 | D25: 7 | E25: 37 | F25: -125 | G25: -52 | H25: -113 | I25: 170 | J25: 9 | K25: 404 | L25: 94 | O25: 130 | P25: 266 | Q25: 41 | R25: 81 | S25: 58 | T25: 15 | U25: 18 | V25: 31
A26: (Increase) decrease in trade accounts receivable, net | C26: -491 | D26: -267 | E26: -652 | F26: 486 | G26: 981 | H26: 210 | I26: -870 | J26: -187 | K26: 2327 | L26: -2717 | O26: 1243 | P26: 2078 | Q26: -539 | R26: -1129 | S26: -2066 | T26: -1315 | U26: -3685 | V26: -6544
A27: (Increase) decrease in inventory | C27: 996 | D27: -39 | E27: 417 | F27: 250 | G27: -31 | H27: -294 | I27: -627 | J27: 27 | K27: 150 | L27: -510 | O27: 68 | P27: 16 | Q27: -148 | R27: -257 | S27: -420 | T27: -692 | U27: -2058 | V27: -2253
A28: Increase (decrease) in accounts payable | C28: 33 | D28: -97 | E28: -325 | F28: -42 | G28: -3 | H28: 243 | I28: -79 | J28: 209 | K28: 121 | L28: -118 | O28: -167 | P28: 206 | Q28: 241 | R28: -372 | S28: -236 | T28: 534 | U28: 683 | V28: 2313
A29: Increase (decrease) in employee compensation and benefits | C29: 163 | D29: 109 | E29: 6 | F29: -294 | G29: 217 | H29: 186 | I29: 136 | J29: -279 | K29: 78 | L29: 300 | O29: -409 | P29: -118 | Q29: -908 | R29: -621 | S29: -110 | T29: -1261 | U29: -991 | V29: -619
A30: Contributions to defined benefit pension plans | D30: -361 | E30: -130
A31: Change in other current assets and current liabilities | C31: -98 | D31: -490 | E31: 369 | F31: -283 | G31: 331 | H31: -177 | I31: 222 | J31: -628 | K31: -5323 | L31: -1837 | O31: -2568 | P31: -3913 | Q31: 26 | R31: -29 | S31: -1028 | T31: -692 | U31: -218 | V31: -2893
A32: Change in other long-term assets and long-term liabilities | C32: -120 | D32: 159 | E32: -641 | F32: -301 | G32: -402 | H32: -295 | I32: -436 | J32: -785 | K32: -1990 | L32: -3618 | O32: 322 | P32: -848 | Q32: -1023 | R32: -1853 | S32: -2295 | T32: 321 | U32: 592 | V32: 1036
A33: Net cash provided by operating activities | C33: =C14+C16+C17+C18+C19+C20+C21+C22+C23+C24+C25+C26+C27+C28+C29+C30+C31+C32 -> 3411 | D33: =D14+D16+D17+D18+D19+D20+D21+D22+D23+D24+D25+D26+D27+D28+D29+D30+D31+D32 -> 6551 | E33: =E14+E16+E17+E18+E19+E20+E21+E22+E23+E24+E25+E26+E27+E28+E29+E30+E31+E32 -> 8880 | F33: =F14+F16+F17+F18+F19+F20+F21+F22+F23+F24+F25+F26+F27+F28+F29+F30+F31+F32 -> 9697 | G33: =G14+G16+G17+G18+G19+G20+G21+G22+G23+G24+G25+G26+G27+G28+G29+G30+G31+G32 -> 12061 | H33: =H14+H16+H17+H18+H19+H20+H21+H22+H23+H24+H25+H26+H27+H28+H29+H30+H31+H32 -> 13764 | I33: =I14+I16+I17+I18+I19+I20+I21+I22+I23+I24+I25+I26+I27+I28+I29+I30+I31+I32 -> 16736 | J33: =J14+J16+J17+J18+J19+J20+J21+J22+J23+J24+J25+J26+J27+J28+J29+J30+J31+J32 -> 18085 | ... L33: =L14+L16+L17+L18+L19+L20+L21+L22+L23+L24+L25+L26+L27+L28+L29+L30+L31+L32 -> 27537 | O33: =O14+O16+O17+O18+O19+O20+O21+O22+O23+O24+O25+O26+O27+O28+O29+O30+O31+O32 -> 9395 | P33: =P14+P16+P17+P18+P19+P20+P21+P22+P23+P24+P25+P26+P27+P28+P29+P30+P31+P32 -> 14358 | Q33: =Q14+Q16+Q17+Q18+Q19+Q20+Q21+Q22+Q23+Q24+Q25+Q26+Q27+Q28+Q29+Q30+Q31+Q32 -> 6113 | R33: =R14+R16+R17+R18+R19+R20+R21+R22+R23+R24+R25+R26+R27+R28+R29+R30+R31+R32 -> 12668 | S33: =S14+S16+S17+S18+S19+S20+S21+S22+S23+S24+S25+S26+S27+S28+S29+S30+S31+S32 -> 19834 | T33: =T14+T16+T17+T18+T19+T20+T21+T22+T23+T24+T25+T26+T27+T28+T29+T30+T31+T32 -> 8260 | U33: =U14+U16+U17+U18+U19+U20+U21+U22+U23+U24+U25+U26+U27+U28+U29+U30+U31+U32 -> 18753 | V33: =V14+V16+V17+V18+V19+V20+V21+V22+V23+V24+V25+V26+V27+V28+V29+V30+V31+V32 -> 32950
A35: 2. INVESTING ACTIVITIES
A36: Purchases of property, plant and equipment | C36: -723 | D36: -1069 | E36: -635 | F36: -432 | G36: -463 | H36: -443 | I36: -424 | J36: -452 | K36: -548 | L36: -623 | O36: -254 | P36: -426 | Q36: -100 | R36: -244 | S36: -386 | T36: -250 | U36: -481 | V36: -1013
A37: Proceeds from disposals of property, plant and equipment | C37: 5 | D37: 441 | E37: 239 | F37: 88 | G37: 12 | H37: 4
A38: Acquisitions of businesses, net of cash acquired | B38: FY2024: VMware acquisition (closed Nov 22, 2023). Cash outflow of $25,978M reflects only the cash-consideration portion, net of ~$6,642M cash acquired; total deal value was $86,290M, ~$54.2B of which was Broadcom stock (non-cash). | C38: -10055 | D38: -40 | E38: -4800 | F38: -16033 | G38: -10872 | H38: -8 | I38: -246 | J38: -53 | K38: -25978 | O38: -25976 | P38: -25978
A39: Proceeds from sales of businesses | B39: FY2024: $3,485M — sale of the VMware End-User Computing (EUC) business to KKR. | C39: 898 | D39: 10 | E39: 773 | F39: 957 | G39: 218 | H39: 45 | K39: 3485 | L39: 300 | P39: 3485 | S39: 300
A40: Purchases of investments | C40: -58 | D40: -207 | E40: -249 | F40: -5 | I40: -200 | J40: -346 | K40: -175 | L40: -597 | O40: -72 | P40: -145 | Q40: -105 | R40: -162 | S40: -261 | T40: -114 | U40: -137 | V40: -756
A41: Proceeds from sales/maturities of investments | C41: 104 | D41: 200 | E41: 54 | F41: 5 | H41: 169 | I41: 200 | J41: 228 | K41: 156 | L41: 248 | O41: 131 | P41: 136 | Q41: 18 | R41: 96 | S41: 147 | T41: 244 | U41: 283 | V41: 320
A42: Other | C42: -11 | D42: -9 | E42: -56 | F42: -2 | G42: -4 | H42: -12 | I42: 3 | J42: -66 | K42: -10 | L42: 92 | O42: -12 | P42: -10 | Q42: 13 | R42: 3 | S42: -13 | T42: 5 | U42: 12 | V42: 13
A43: Net cash used in investing activities | C43: =C36+C37+C38+C39+C40+C41+C42 -> -9840 | D43: =D36+D37+D38+D39+D40+D41+D42 -> -674 | E43: =E36+E37+E38+E39+E40+E41+E42 -> -4674 | F43: =F36+F37+F38+F39+F40+F41+F42 -> -15422 | G43: =G36+G37+G38+G39+G40+G41+G42 -> -11109 | H43: =H36+H37+H38+H39+H40+H41+H42 -> -245 | I43: =I36+I37+I38+I39+I40+I41+I42 -> -667 | J43: =J36+J37+J38+J39+J40+J41+J42 -> -689 | ... L43: =L36+L37+L38+L39+L40+L41+L42 -> -580 | O43: =O36+O37+O38+O39+O40+O41+O42 -> -26183 | P43: =P36+P37+P38+P39+P40+P41+P42 -> -22938 | Q43: =Q36+Q37+Q38+Q39+Q40+Q41+Q42 -> -174 | R43: =R36+R37+R38+R39+R40+R41+R42 -> -307 | S43: =S36+S37+S38+S39+S40+S41+S42 -> -213 | T43: =T36+T37+T38+T39+T40+T41+T42 -> -115 | U43: =U36+U37+U38+U39+U40+U41+U42 -> -323 | V43: =V36+V37+V38+V39+V40+V41+V42 -> -1436
...

Sheet Segments
A1: Broadcom Inc. — Segments
A2: $ in millions except per-share data | USD | as of 2026-09-22
C3: FY2016 | D3: FY2017 | E3: FY2018 | F3: FY2019 | G3: FY2020 | H3: FY2021 | I3: FY2022 | J3: FY2023 | K3: FY2024 | L3: FY2025 | M3: · | N3: · | O3: 2Q FY2024 | P3: 3Q FY2024 | Q3: 1Q FY2025 | R3: 2Q FY2025 | S3: 3Q FY2025 | T3: 1Q FY2026 | U3: 2Q FY2026 | V3: 3Q FY2026
C4: 2016-10-30 | D4: 2017-10-29 | E4: 2018-11-04 | F4: 2019-11-03 | G4: 2020-11-01 | H4: 2021-10-31 | I4: 2022-10-30 | J4: 2023-10-29 | K4: 2024-11-03 | L4: 2025-11-02 | O4: 2024-05-05 | P4: 2024-08-04 | Q4: 2025-02-02 | R4: 2025-05-04 | S4: 2025-08-03 | T4: 2026-02-01 | U4: 2026-05-03 | V4: 2026-08-02
A6: CONTENTS
A7: =HYPERLINK("#'Segments'!A11","1. LEGACY 4-SEGMENT STRUCTURE (FY2016-FY2018)") -> 1. LEGACY 4-SEGMENT STRUCTURE (FY2016-FY2018)
A8: =HYPERLINK("#'Segments'!A27","2. 3-SEGMENT STRUCTURE (FY2019 ONLY — CA Technologies year)") -> 2. 3-SEGMENT STRUCTURE (FY2019 ONLY — CA Technologies year)
A9: =HYPERLINK("#'Segments'!A41","3. 2-SEGMENT STRUCTURE (FY2020-PRESENT)") -> 3. 2-SEGMENT STRUCTURE (FY2020-PRESENT)
A11: 1. LEGACY 4-SEGMENT STRUCTURE (FY2016-FY2018)
A12: Wired Infrastructure — Revenue | C12: 6582 | D12: 8549 | E12: 8674
A13: Wireless Communications — Revenue | C13: 3724 | D13: 5404 | E13: 6490
A14: Enterprise Storage — Revenue | C14: 2291 | D14: 2799 | E14: 4673
A15: Industrial & Other — Revenue | C15: 643 | D15: 884 | E15: 1011
A16: Total segment revenue | C16: =C12+C13+C14+C15 -> 13240 | D16: =D12+D13+D14+D15 -> 17636 | E16: =E12+E13+E14+E15 -> 20848
A17: vs IS Revenue (should be ~0) | C17: =C16-'Income Statement'!C14 -> 0 | D17: =D16-'Income Statement'!D14 -> 0 | E17: =E16-'Income Statement'!E14 -> 0
A19: Wired Infrastructure — Operating income | C19: 2664 | D19: 3853 | E19: 4093
A20: Wireless Communications — Operating income | C20: 1282 | D20: 2155 | E20: 2840
A21: Enterprise Storage — Operating income | C21: 995 | D21: 1527 | E21: 2906
A22: Industrial & Other — Operating income | C22: 327 | D22: 447 | E22: 571
A23: Segment operating income before unallocated | C23: =C19+C20+C21+C22 -> 5268 | D23: =D19+D20+D21+D22 -> 7982 | E23: =E19+E20+E21+E22 -> 10410
A24: Unallocated corporate expenses (plug to consolidated OI) | C24: ='Income Statement'!C37-C23 -> -5677 | D24: ='Income Statement'!D37-D23 -> -5599 | E24: ='Income Statement'!E37-E23 -> -5275
A25: Total operating income (= IS operating income) | C25: ='Income Statement'!C37 -> -409 | D25: ='Income Statement'!D37 -> 2383 | E25: ='Income Statement'!E37 -> 5135
A27: 2. 3-SEGMENT STRUCTURE (FY2019 ONLY — CA Technologies year)
A28: Semiconductor solutions — Revenue | F28: 17368
A29: Infrastructure software — Revenue | F29: 5156
A30: IP licensing — Revenue | F30: 73
A31: Total segment revenue | F31: =F28+F29+F30 -> 22597
A32: vs IS Revenue (should be ~0) | F32: =F31-'Income Statement'!F14 -> 0
A34: Semiconductor solutions — Operating income | F34: 8150
A35: Infrastructure software — Operating income | F35: 3781
A36: IP licensing — Operating income (loss) | F36: -2
A37: Segment operating income before unallocated | F37: =F34+F35+F36 -> 11929
A38: Unallocated corporate expenses (plug to consolidated OI) | F38: ='Income Statement'!F37-F37 -> -8485
A39: Total operating income (= IS operating income) | F39: ='Income Statement'!F37 -> 3444
A41: 3. 2-SEGMENT STRUCTURE (FY2020-PRESENT)
A42: Semiconductor Solutions — Revenue | G42: 17267 | H42: 20383 | I42: 25818 | J42: 28182 | K42: 30096 | L42: 36858 | O42: 7202 | P42: 7274 | Q42: 8212 | R42: 8408 | S42: 9166 | T42: 12515 | U42: 15009 | V42: 20839
A43: yoy | H43: =H42/G42-1 -> 0.18045984 | I43: =I42/H42-1 -> 0.26664377 | J43: =J42/I42-1 -> 0.091564025 | K43: =K42/J42-1 -> 0.067915691 | L43: =L42/K42-1 -> 0.22468102 | R43: =R42/O42-1 -> 0.16745349 | S43: =S42/P42-1 -> 0.26010448 | T43: =T42/Q42-1 -> 0.52398928 | U43: =U42/R42-1 -> 0.78508563 | V43: =V42/S42-1 -> 1.2735108
A44: Infrastructure Software — Revenue | G44: 6621 | H44: 7067 | I44: 7385 | J44: 7637 | K44: 21478 | L44: 27029 | O44: 5285 | P44: 5798 | Q44: 6704 | R44: 6596 | S44: 6786 | T44: 6796 | U44: 7178 | V44: 8752
A45: yoy | H45: =H44/G44-1 -> 0.067361426 | I45: =I44/H44-1 -> 0.044997877 | J45: =J44/I44-1 -> 0.034123223 | K45: =K44/J44-1 -> 1.8123609 | L45: =L44/K44-1 -> 0.25845051 | R45: =R44/O44-1 -> 0.24806055 | S45: =S44/P44-1 -> 0.17040359 | T45: =T44/Q44-1 -> 0.01372315 | U45: =U44/R44-1 -> 0.088235294 | V45: =V44/S44-1 -> 0.28971412
A46: Total segment revenue | G46: =G42+G44 -> 23888 | H46: =H42+H44 -> 27450 | I46: =I42+I44 -> 33203 | J46: =J42+J44 -> 35819 | K46: =K42+K44 -> 51574 | L46: =L42+L44 -> 63887 | O46: =O42+O44 -> 12487 | P46: =P42+P44 -> 13072 | Q46: =Q42+Q44 -> 14916 | R46: =R42+R44 -> 15004 | S46: =S42+S44 -> 15952 | T46: =T42+T44 -> 19311 | U46: =U42+U44 -> 22187 | V46: =V42+V44 -> 29591
...

Sheet Geography & Products
A1: Broadcom Inc. — Geography & Products
A2: $ in millions except per-share data | USD | as of 2026-09-22
C3: FY2016 | D3: FY2017 | E3: FY2018 | F3: FY2019 | G3: FY2020 | H3: FY2021 | I3: FY2022 | J3: FY2023 | K3: FY2024 | L3: FY2025 | M3: · | N3: · | O3: 2Q FY2024 | P3: 3Q FY2024 | Q3: 1Q FY2025 | R3: 2Q FY2025 | S3: 3Q FY2025 | T3: 1Q FY2026 | U3: 2Q FY2026 | V3: 3Q FY2026
C4: 2016-10-30 | D4: 2017-10-29 | E4: 2018-11-04 | F4: 2019-11-03 | G4: 2020-11-01 | H4: 2021-10-31 | I4: 2022-10-30 | J4: 2023-10-29 | K4: 2024-11-03 | L4: 2025-11-02 | O4: 2024-05-05 | P4: 2024-08-04 | Q4: 2025-02-02 | R4: 2025-05-04 | S4: 2025-08-03 | T4: 2026-02-01 | U4: 2026-05-03 | V4: 2026-08-02
A6: CONTENTS
A7: =HYPERLINK("#'Geography & Products'!A10","1. REVENUE BY GEOGRAPHIC REGION (FY2019 10-K Note onward; own-period figures, not restated comparatives)") -> 1. REVENUE BY GEOGRAPHIC REGION (FY2019 10-K Note onward; own-period figures, not restated comparatives)
A8: =HYPERLINK("#'Geography & Products'!A33","2. LONG-LIVED ASSETS BY GEOGRAPHY (Annual only — disclosed in the 10-K only, not in 10-Qs)") -> 2. LONG-LIVED ASSETS BY GEOGRAPHY (Annual only — disclosed in the 10-K only, not in 10-Qs)
A10: 1. REVENUE BY GEOGRAPHIC REGION (FY2019 10-K Note onward; own-period figures, not restated comparatives)
A11: Products — Americas | B11: Own-period figures as filed in each 10-K/10-Q's own geographic revenue Note (never a later filing's restated comparative column). Not disclosed for FY2016-FY2018. See IS:rev_products note re: the FY2026 Q1 upfront-license reclassification, which also affects how Products/Subscriptions are split by region starting with the 1Q/2Q FY2026 and FY2025-annual columns (post-reclass) vs the 1Q/2Q/3Q FY2025 quarterly columns (pre-reclass, as originally filed). | F11: 2023 | G11: 1775 | H11: 1809 | I11: 2371 | J11: 2601 | K11: 2244 | L11: 7908 | O11: 473 | P11: 582 | Q11: 490 | R11: 635 | S11: 662 | T11: 2164 | U11: 2187 | V11: 2642
A12: Products — Asia Pacific | F12: 14857 | G12: 14442 | H12: 17258 | I12: 21761 | J12: 23263 | K12: 26219 | L12: 33596 | O12: 6267 | P12: 6411 | Q12: 7269 | R12: 7454 | S12: 8181 | T12: 10950 | U12: 13956 | V12: 20199
A13: Products — Europe, Middle East & Africa | F13: 1237 | G13: 1218 | H13: 1819 | I13: 2145 | J13: 2027 | K13: 1896 | L13: 3343 | O13: 452 | P13: 446 | Q13: 412 | R13: 417 | S13: 414 | T13: 1016 | U13: 749 | V13: 1438
A14: Total Products revenue | F14: =F11+F12+F13 -> 18117 | G14: =G11+G12+G13 -> 17435 | H14: =H11+H12+H13 -> 20886 | I14: =I11+I12+I13 -> 26277 | J14: =J11+J12+J13 -> 27891 | K14: =K11+K12+K13 -> 30359 | L14: =L11+L12+L13 -> 44847 | O14: =O11+O12+O13 -> 7192 | P14: =P11+P12+P13 -> 7439 | Q14: =Q11+Q12+Q13 -> 8171 | R14: =R11+R12+R13 -> 8506 | S14: =S11+S12+S13 -> 9257 | T14: =T11+T12+T13 -> 14130 | U14: =U11+U12+U13 -> 16892 | V14: =V11+V12+V13 -> 24279
A15: vs IS Products Revenue (should be ~0) | F15: =F14-'Income Statement'!F16 -> 0 | G15: =G14-'Income Statement'!G16 -> 0 | H15: =H14-'Income Statement'!H16 -> 0 | I15: =I14-'Income Statement'!I16 -> 0 | J15: =J14-'Income Statement'!J16 -> 0 | K15: =K14-'Income Statement'!K16 -> 0 | L15: =L14-'Income Statement'!L16 -> 0 | O15: =O14-'Income Statement'!O16 -> 0 | P15: =P14-'Income Statement'!P16 -> 0 | Q15: =Q14-'Income Statement'!Q16 -> 0 | R15: =R14-'Income Statement'!R16 -> 0 | S15: =S14-'Income Statement'!S16 -> 0 | T15: =T14-'Income Statement'!T16 -> 0 | U15: =U14-'Income Statement'!U16 -> 0 | V15: =V14-'Income Statement'!V16 -> 0
A17: Subscriptions & Services — Americas | F17: 3126 | G17: 4059 | H17: 4290 | I17: 4573 | J17: 5678 | K17: 12726 | L17: 11031 | O17: 3401 | P17: 3409 | Q17: 4142 | R17: 4071 | S17: 4062 | T17: 2917 | U17: 3015 | V17: 2871
A18: Subscriptions & Services — Asia Pacific | F18: 374 | G18: 881 | H18: 720 | I18: 744 | J18: 657 | K18: 2203 | L18: 2300 | O18: 487 | P18: 630 | Q18: 763 | R18: 646 | S18: 779 | T18: 665 | U18: 579 | V18: 745
A19: Subscriptions & Services — Europe, Middle East & Africa | F19: 980 | G19: 1513 | H19: 1554 | I19: 1609 | J19: 1593 | K19: 6286 | L19: 5709 | O19: 1407 | P19: 1594 | Q19: 1840 | R19: 1781 | S19: 1854 | T19: 1599 | U19: 1701 | V19: 1696
A20: Total Subscriptions & Services revenue | F20: =F17+F18+F19 -> 4480 | G20: =G17+G18+G19 -> 6453 | H20: =H17+H18+H19 -> 6564 | I20: =I17+I18+I19 -> 6926 | J20: =J17+J18+J19 -> 7928 | K20: =K17+K18+K19 -> 21215 | L20: =L17+L18+L19 -> 19040 | O20: =O17+O18+O19 -> 5295 | P20: =P17+P18+P19 -> 5633 | Q20: =Q17+Q18+Q19 -> 6745 | R20: =R17+R18+R19 -> 6498 | S20: =S17+S18+S19 -> 6695 | T20: =T17+T18+T19 -> 5181 | U20: =U17+U18+U19 -> 5295 | V20: =V17+V18+V19 -> 5312
A21: vs IS Subscriptions Revenue (should be ~0) | F21: =F20-'Income Statement'!F17 -> 0 | G21: =G20-'Income Statement'!G17 -> 0 | H21: =H20-'Income Statement'!H17 -> 0 | I21: =I20-'Income Statement'!I17 -> 0 | J21: =J20-'Income Statement'!J17 -> 0 | K21: =K20-'Income Statement'!K17 -> 0 | L21: =L20-'Income Statement'!L17 -> 0 | O21: =O20-'Income Statement'!O17 -> 0 | P21: =P20-'Income Statement'!P17 -> 0 | Q21: =Q20-'Income Statement'!Q17 -> 0 | R21: =R20-'Income Statement'!R17 -> 0 | S21: =S20-'Income Statement'!S17 -> 0 | T21: =T20-'Income Statement'!T17 -> 0 | U21: =U20-'Income Statement'!U17 -> 0 | V21: =V20-'Income Statement'!V17 -> 0
A23: Total revenue — Americas | F23: =F11+F17 -> 5149 | G23: =G11+G17 -> 5834 | H23: =H11+H17 -> 6099 | I23: =I11+I17 -> 6944 | J23: =J11+J17 -> 8279 | K23: =K11+K17 -> 14970 | L23: =L11+L17 -> 18939 | O23: =O11+O17 -> 3874 | P23: =P11+P17 -> 3991 | Q23: =Q11+Q17 -> 4632 | R23: =R11+R17 -> 4706 | S23: =S11+S17 -> 4724 | T23: =T11+T17 -> 5081 | U23: =U11+U17 -> 5202 | V23: =V11+V17 -> 5513
A24: Total revenue — Asia Pacific | F24: =F12+F18 -> 15231 | G24: =G12+G18 -> 15323 | H24: =H12+H18 -> 17978 | I24: =I12+I18 -> 22505 | J24: =J12+J18 -> 23920 | K24: =K12+K18 -> 28422 | L24: =L12+L18 -> 35896 | O24: =O12+O18 -> 6754 | P24: =P12+P18 -> 7041 | Q24: =Q12+Q18 -> 8032 | R24: =R12+R18 -> 8100 | S24: =S12+S18 -> 8960 | T24: =T12+T18 -> 11615 | U24: =U12+U18 -> 14535 | V24: =V12+V18 -> 20944
A25: Total revenue — Europe, Middle East & Africa | F25: =F13+F19 -> 2217 | G25: =G13+G19 -> 2731 | H25: =H13+H19 -> 3373 | I25: =I13+I19 -> 3754 | J25: =J13+J19 -> 3620 | K25: =K13+K19 -> 8182 | L25: =L13+L19 -> 9052 | O25: =O13+O19 -> 1859 | P25: =P13+P19 -> 2040 | Q25: =Q13+Q19 -> 2252 | R25: =R13+R19 -> 2198 | S25: =S13+S19 -> 2268 | T25: =T13+T19 -> 2615 | U25: =U13+U19 -> 2450 | V25: =V13+V19 -> 3134
A26: Total revenue — All regions | F26: =F23+F24+F25 -> 22597 | G26: =G23+G24+G25 -> 23888 | H26: =H23+H24+H25 -> 27450 | I26: =I23+I24+I25 -> 33203 | J26: =J23+J24+J25 -> 35819 | K26: =K23+K24+K25 -> 51574 | L26: =L23+L24+L25 -> 63887 | O26: =O23+O24+O25 -> 12487 | P26: =P23+P24+P25 -> 13072 | Q26: =Q23+Q24+Q25 -> 14916 | R26: =R23+R24+R25 -> 15004 | S26: =S23+S24+S25 -> 15952 | T26: =T23+T24+T25 -> 19311 | U26: =U23+U24+U25 -> 22187 | V26: =V23+V24+V25 -> 29591
A27: vs IS Total Revenue (should be ~0) | F27: =F26-'Income Statement'!F14 -> 0 | G27: =G26-'Income Statement'!G14 -> 0 | H27: =H26-'Income Statement'!H14 -> 0 | I27: =I26-'Income Statement'!I14 -> 0 | J27: =J26-'Income Statement'!J14 -> 0 | K27: =K26-'Income Statement'!K14 -> 0 | L27: =L26-'Income Statement'!L14 -> 0 | O27: =O26-'Income Statement'!O14 -> 0 | P27: =P26-'Income Statement'!P14 -> 0 | Q27: =Q26-'Income Statement'!Q14 -> 0 | R27: =R26-'Income Statement'!R14 -> 0 | S27: =S26-'Income Statement'!S14 -> 0 | T27: =T26-'Income Statement'!T14 -> 0 | U27: =U26-'Income Statement'!U14 -> 0 | V27: =V26-'Income Statement'!V14 -> 0
A29: Mix % — Americas | F29: =F23/F26 -> 0.22786211 | G29: =G23/G26 -> 0.24422304 | H29: =H23/H26 -> 0.22218579 | I29: =I23/I26 -> 0.20913773 | J29: =J23/J26 -> 0.23113431 | K29: =K23/K26 -> 0.29026254 | L29: =L23/L26 -> 0.29644529 | O29: =O23/O26 -> 0.31024265 | P29: =P23/P26 -> 0.30530906 | Q29: =Q23/Q26 -> 0.31053902 | R29: =R23/R26 -> 0.31364969 | S29: =S23/S26 -> 0.29613842 | T29: =T23/T26 -> 0.26311429 | U29: =U23/U26 -> 0.23446162 | V29: =V23/V26 -> 0.18630665
A30: Mix % — Asia Pacific | F30: =F24/F26 -> 0.67402753 | G30: =G24/G26 -> 0.64145177 | H30: =H24/H26 -> 0.65493625 | I30: =I24/I26 -> 0.6778002 | J30: =J24/J26 -> 0.667802 | K30: =K24/K26 -> 0.55109164 | L30: =L24/L26 -> 0.56186705 | O30: =O24/O26 -> 0.54088252 | P30: =P24/P26 -> 0.53863219 | Q30: =Q24/Q26 -> 0.53848217 | R30: =R24/R26 -> 0.53985604 | S30: =S24/S26 -> 0.56168506 | T30: =T24/T26 -> 0.60147066 | U30: =U24/U26 -> 0.65511335 | V30: =V24/V26 -> 0.70778277
A31: Mix % — Europe, Middle East & Africa | F31: =F25/F26 -> 0.098110369 | G31: =G25/G26 -> 0.11432518 | H31: =H25/H26 -> 0.12287796 | I31: =I25/I26 -> 0.11306207 | J31: =J25/J26 -> 0.10106368 | K31: =K25/K26 -> 0.15864583 | L31: =L25/L26 -> 0.14168767 | O31: =O25/O26 -> 0.14887483 | P31: =P25/P26 -> 0.15605875 | Q31: =Q25/Q26 -> 0.15097881 | R31: =R25/R26 -> 0.14649427 | S31: =S25/S26 -> 0.14217653 | T31: =T25/T26 -> 0.13541505 | U31: =U25/U26 -> 0.11042502 | V31: =V25/V26 -> 0.10591058
A33: 2. LONG-LIVED ASSETS BY GEOGRAPHY (Annual only — disclosed in the 10-K only, not in 10-Qs)
A34: United States | B34: This Note (long-lived assets by geographic location) is disclosed only in Broadcom's annual 10-K, not in its 10-Qs -- quarterly columns are intentionally blank by the nature of the disclosure, not a dropped extraction. Own fiscal-year-end figures each time (never a later filing's restated comparative column). | C34: 1917 | D34: 1822 | E34: 1859 | F34: 1763 | G34: 1659 | H34: 1540 | I34: 1441 | J34: 1371 | K34: 1685 | L34: 1697
A35: Malaysia | C35: 153
A36: Singapore | C36: 78 | D36: 79
A37: Taiwan | D37: 268 | E37: 264 | F37: 258 | G37: 285 | H37: 313 | I37: 318 | J37: 341 | K37: 365 | L37: 446
A38: Other | C38: 361 | D38: 430 | E38: 512 | F38: 544 | G38: 565 | H38: 495 | I38: 464 | J38: 442 | K38: 471 | L38: 387
A39: Total long-lived assets (computed) | C39: =C34+C35+C36+C37+C38 -> 2509 | D39: =D34+D35+D36+D37+D38 -> 2599 | E39: =E34+E35+E36+E37+E38 -> 2635 | F39: =F34+F35+F36+F37+F38 -> 2565 | G39: =G34+G35+G36+G37+G38 -> 2509 | H39: =H34+H35+H36+H37+H38 -> 2348 | I39: =I34+I35+I36+I37+I38 -> 2223 | J39: =J34+J35+J36+J37+J38 -> 2154 | ... L39: =L34+L35+L36+L37+L38 -> 2530
A40: Total long-lived assets (as reported) | C40: 2509 | D40: 2599 | E40: 2635 | F40: 2565 | G40: 2509 | H40: 2348 | I40: 2223 | J40: 2154 | K40: 2521 | L40: 2530
A41: Computed vs Reported (should be ~0) | C41: =C39-C40 -> 0 | D41: =D39-D40 -> 0 | E41: =E39-E40 -> 0 | F41: =F39-F40 -> 0 | G41: =G39-G40 -> 0 | H41: =H39-H40 -> 0 | I41: =I39-I40 -> 0 | J41: =J39-J40 -> 0 | ... L41: =L39-L40 -> 0

Sheet Derived Metrics
A1: Broadcom Inc. — Derived Metrics
A2: $ in millions except per-share data | USD | as of 2026-09-22
C3: FY2016 | D3: FY2017 | E3: FY2018 | F3: FY2019 | G3: FY2020 | H3: FY2021 | I3: FY2022 | J3: FY2023 | K3: FY2024 | L3: FY2025 | M3: · | N3: · | O3: 2Q FY2024 | P3: 3Q FY2024 | Q3: 1Q FY2025 | R3: 2Q FY2025 | S3: 3Q FY2025 | T3: 1Q FY2026 | U3: 2Q FY2026 | V3: 3Q FY2026
C4: 2016-10-30 | D4: 2017-10-29 | E4: 2018-11-04 | F4: 2019-11-03 | G4: 2020-11-01 | H4: 2021-10-31 | I4: 2022-10-30 | J4: 2023-10-29 | K4: 2024-11-03 | L4: 2025-11-02 | O4: 2024-05-05 | P4: 2024-08-04 | Q4: 2025-02-02 | R4: 2025-05-04 | S4: 2025-08-03 | T4: 2026-02-01 | U4: 2026-05-03 | V4: 2026-08-02
A6: CONTENTS
A7: =HYPERLINK("#'Derived Metrics'!A18","1. PROFITABILITY") -> 1. PROFITABILITY
A8: =HYPERLINK("#'Derived Metrics'!A25","2. RETURNS") -> 2. RETURNS
A9: =HYPERLINK("#'Derived Metrics'!A30","3. LEVERAGE") -> 3. LEVERAGE
A10: =HYPERLINK("#'Derived Metrics'!A35","4. SOLVENCY") -> 4. SOLVENCY
A11: =HYPERLINK("#'Derived Metrics'!A39","5. LIQUIDITY") -> 5. LIQUIDITY
A12: =HYPERLINK("#'Derived Metrics'!A43","6. COVERAGE") -> 6. COVERAGE
A13: =HYPERLINK("#'Derived Metrics'!A46","7. CASH CONVERSION") -> 7. CASH CONVERSION
A14: =HYPERLINK("#'Derived Metrics'!A51","8. EARNINGS QUALITY") -> 8. EARNINGS QUALITY
A15: =HYPERLINK("#'Derived Metrics'!A54","9. GROWTH") -> 9. GROWTH
A16: =HYPERLINK("#'Derived Metrics'!A60","10. WORKING CAPITAL") -> 10. WORKING CAPITAL
A18: 1. PROFITABILITY
A19: Gross Margin % | C19: ='Income Statement'!C28 -> 0.44864048 | D19: ='Income Statement'!D28 -> 0.48247902 | E19: ='Income Statement'!E28 -> 0.51482157 | F19: ='Income Statement'!F28 -> 0.55241846 | G19: ='Income Statement'!G28 -> 0.5658071 | H19: ='Income Statement'!H28 -> 0.61362477 | I19: ='Income Statement'!I28 -> 0.66545192 | J19: ='Income Statement'!J28 -> 0.68929898 | ... L19: ='Income Statement'!L28 -> 0.67766525 | O19: ='Income Statement'!O28 -> 0.62272764 | P19: ='Income Statement'!P28 -> 0.63922889 | Q19: ='Income Statement'!Q28 -> 0.68014213 | R19: ='Income Statement'!R28 -> 0.67961877 | S19: ='Income Statement'!S28 -> 0.67095035 | T19: ='Income Statement'!T28 -> 0.68132153 | U19: ='Income Statement'!U28 -> 0.69477622 | V19: ='Income Statement'!V28 -> 0.69129127
A20: Operating Margin % | C20: ='Income Statement'!C38 -> -0.030891239 | D20: ='Income Statement'!D38 -> 0.13512134 | E20: ='Income Statement'!E38 -> 0.2463066 | F20: ='Income Statement'!F38 -> 0.15240961 | G20: ='Income Statement'!G38 -> 0.16803416 | H20: ='Income Statement'!H38 -> 0.31034608 | I20: ='Income Statement'!I38 -> 0.42842514 | J20: ='Income Statement'!J38 -> 0.45246936 | ... L20: ='Income Statement'!L38 -> 0.39889179 | O20: ='Income Statement'!O38 -> 0.23744694 | P20: ='Income Statement'!P38 -> 0.28977968 | Q20: ='Income Statement'!Q38 -> 0.41968356 | R20: ='Income Statement'!R38 -> 0.3884964 | S20: ='Income Statement'!S38 -> 0.36904463 | T20: ='Income Statement'!T38 -> 0.44342603 | U20: ='Income Statement'!U38 -> 0.48623068 | V20: ='Income Statement'!V38 -> 0.53918421
A21: Net Margin % | C21: ='Income Statement'!C51 -> -0.14055891 | D21: ='Income Statement'!D51 -> 0.10115672 | E21: ='Income Statement'!E51 -> 0.60485418 | F21: ='Income Statement'!F51 -> 0.12054698 | G21: ='Income Statement'!G51 -> 0.12391159 | H21: ='Income Statement'!H51 -> 0.24539162 | I21: ='Income Statement'!I51 -> 0.34620366 | J21: ='Income Statement'!J51 -> 0.3931433 | ... L21: ='Income Statement'!L51 -> 0.36198288 | O21: ='Income Statement'!O51 -> 0.16985665 | P21: ='Income Statement'!P51 -> -0.14343635 | Q21: ='Income Statement'!Q51 -> 0.36893269 | R21: ='Income Statement'!R51 -> 0.33091176 | S21: ='Income Statement'!S51 -> 0.25952859 | T21: ='Income Statement'!T51 -> 0.3805603 | U21: ='Income Statement'!U51 -> 0.41961509 | V21: ='Income Statement'!V51 -> 0.44229664
A22: EBITDA | C22: ='Income Statement'!C37+'Cash Flow Statement'!C16+'Cash Flow Statement'!C17 -> 2633 | D22: ='Income Statement'!D37+'Cash Flow Statement'!D16+'Cash Flow Statement'!D17 -> 7120 | E22: ='Income Statement'!E37+'Cash Flow Statement'!E16+'Cash Flow Statement'!E17 -> 9216 | F22: ='Income Statement'!F37+'Cash Flow Statement'!F16+'Cash Flow Statement'!F17 -> 9252 | G22: ='Income Statement'!G37+'Cash Flow Statement'!G16+'Cash Flow Statement'!G17 -> 10919 | H22: ='Income Statement'!H37+'Cash Flow Statement'!H16+'Cash Flow Statement'!H17 -> 14560 | I22: ='Income Statement'!I37+'Cash Flow Statement'!I16+'Cash Flow Statement'!I17 -> 19209 | J22: ='Income Statement'!J37+'Cash Flow Statement'!J16+'Cash Flow Statement'!J17 -> 20042 | ... L22: ='Income Statement'!L37+'Cash Flow Statement'!L16+'Cash Flow Statement'!L17 -> 34259 | O22: ='Income Statement'!O37+'Cash Flow Statement'!O16+'Cash Flow Statement'!O17 -> 7840 | P22: ='Income Statement'!P37+'Cash Flow Statement'!P16+'Cash Flow Statement'!P17 -> 11187 | Q22: ='Income Statement'!Q37+'Cash Flow Statement'!Q16+'Cash Flow Statement'!Q17 -> 8434 | R22: ='Income Statement'!R37+'Cash Flow Statement'!R16+'Cash Flow Statement'!R17 -> 10169 | S22: ='Income Statement'!S37+'Cash Flow Statement'!S16+'Cash Flow Statement'!S17 -> 12429 | T22: ='Income Statement'!T37+'Cash Flow Statement'!T16+'Cash Flow Statement'!T17 -> 10716 | U22: ='Income Statement'!U37+'Cash Flow Statement'!U16+'Cash Flow Statement'!U17 -> 15106 | V22: ='Income Statement'!V37+'Cash Flow Statement'!V16+'Cash Flow Statement'!V17 -> 22486
A23: EBITDA Margin % | C23: =C22/'Income Statement'!C14 -> 0.19886707 | D23: =D22/'Income Statement'!D14 -> 0.40371966 | E23: =E22/'Income Statement'!E14 -> 0.44205679 | F23: =F22/'Income Statement'!F14 -> 0.40943488 | G23: =G22/'Income Statement'!G14 -> 0.45709143 | H23: =H22/'Income Statement'!H14 -> 0.53041894 | I23: =I22/'Income Statement'!I14 -> 0.57853206 | J23: =J22/'Income Statement'!J14 -> 0.55953544 | ... L23: =L22/'Income Statement'!L14 -> 0.53624368 | O23: =O22/'Income Statement'!O14 -> 0.62785297 | P23: =P22/'Income Statement'!P14 -> 0.85579865 | Q23: =Q22/'Income Statement'!Q14 -> 0.56543309 | R23: =R22/'Income Statement'!R14 -> 0.6777526 | S23: =S22/'Income Statement'!S14 -> 0.77914995 | T23: =T22/'Income Statement'!T14 -> 0.55491689 | U23: =U22/'Income Statement'!U14 -> 0.68084915 | V23: =V22/'Income Statement'!V14 -> 0.75989321
A25: 2. RETURNS
A26: Return on Equity (avg) | D26: ='Income Statement'!D50/(('Balance Sheet'!D48+'Balance Sheet'!C48)/2) -> 0.079179797 | E26: ='Income Statement'!E50/(('Balance Sheet'!E48+'Balance Sheet'!D48)/2) -> 0.5059888 | F26: ='Income Statement'!F50/(('Balance Sheet'!F48+'Balance Sheet'!E48)/2) -> 0.10558549 | G26: ='Income Statement'!G50/(('Balance Sheet'!G48+'Balance Sheet'!F48)/2) -> 0.1212742 | H26: ='Income Statement'!H50/(('Balance Sheet'!H48+'Balance Sheet'!G48)/2) -> 0.27586207 | I26: ='Income Statement'!I50/(('Balance Sheet'!I48+'Balance Sheet'!H48)/2) -> 0.48226385 | J26: ='Income Statement'!J50/(('Balance Sheet'!J48+'Balance Sheet'!I48)/2) -> 0.60312226 | K26: ='Income Statement'!K50/(('Balance Sheet'!K48+'Balance Sheet'!J48)/2) -> 0.12861912 | L26: ='Income Statement'!L50/(('Balance Sheet'!L48+'Balance Sheet'!K48)/2) -> 0.31047862
A27: Return on Assets (avg) | D27: ='Income Statement'!D50/(('Balance Sheet'!D26+'Balance Sheet'!C26)/2) -> 0.034181484 | E27: ='Income Statement'!E50/(('Balance Sheet'!E26+'Balance Sheet'!D26)/2) -> 0.24124275 | F27: ='Income Statement'!F50/(('Balance Sheet'!F26+'Balance Sheet'!E26)/2) -> 0.046319835 | G27: ='Income Statement'!G50/(('Balance Sheet'!G26+'Balance Sheet'!F26)/2) -> 0.04127564 | H27: ='Income Statement'!H50/(('Balance Sheet'!H26+'Balance Sheet'!G26)/2) -> 0.088922332 | I27: ='Income Statement'!I50/(('Balance Sheet'!I26+'Balance Sheet'!H26)/2) -> 0.15448296 | J27: ='Income Statement'!J50/(('Balance Sheet'!J26+'Balance Sheet'!I26)/2) -> 0.19275888 | K27: ='Income Statement'!K50/(('Balance Sheet'!K26+'Balance Sheet'!J26)/2) -> 0.049432719 | L27: ='Income Statement'!L50/(('Balance Sheet'!L26+'Balance Sheet'!K26)/2) -> 0.13735348
