Workbook

Sheet Contents
A1: Intel Corporation — Research workbook | B1: Intel Corporation — Research workbook | C1: Intel Corporation — Research workbook | D1: Intel Corporation — Research workbook | E1: Intel Corporation — Research workbook | F1: Intel Corporation — Research workbook | G1: Intel Corporation — Research workbook | H1: Intel Corporation — Research workbook
A2: USD million unless stated otherwise; annual FY2016–FY2025; latest interim 27 June 2026.
A4: Historical actuals and derived metrics
A6: Segments | C6: Segment revenue, profit and reporting frameworks
A7: Revenue & Operations | C7: Geography, customers, operating drivers and KPIs
A8: Income Statement | C8: Consolidated profit, EPS and reconciliations
A9: Balance Sheet | C9: Assets, liabilities and equity
A10: Cash Flow | C10: YTD cash flows, capital expenditure and free cash flow
A11: Derivate Metrics | C11: Profitability, working capital, net cash and operating ROIC
A12: Assets & Investments | C12: Investments, inventories, PP&E, goodwill and intangibles
A13: Debt & Leases | C13: Borrowings, maturities, interest and lease disclosures
A14: Capital & Shareholders | C14: Equity, dividends, repurchases and share-based compensation
A15: Taxes & Adjustments | C15: Taxes, restructuring and company non-GAAP reconciliations
A18: Scope: FY2016–FY2025 and available quarters through Q2 2026. USD million unless stated. | B18: Scope: FY2016–FY2025 and available quarters through Q2 2026. USD million unless stated. | C18: Scope: FY2016–FY2025 and available quarters through Q2 2026. USD million unless stated. | D18: Scope: FY2016–FY2025 and available quarters through Q2 2026. USD million unless stated. | E18: Scope: FY2016–FY2025 and available quarters through Q2 2026. USD million unless stated. | F18: Scope: FY2016–FY2025 and available quarters through Q2 2026. USD million unless stated. | G18: Scope: FY2016–FY2025 and available quarters through Q2 2026. USD million unless stated. | H18: Scope: FY2016–FY2025 and available quarters through Q2 2026. USD million unless stated.
A19: Cash Flow uses YTD; Derivate Metrics uses TTM flows. Balance-sheet data are period-end amounts. | B19: Cash Flow uses YTD; Derivate Metrics uses TTM flows. Balance-sheet data are period-end amounts. | C19: Cash Flow uses YTD; Derivate Metrics uses TTM flows. Balance-sheet data are period-end amounts. | D19: Cash Flow uses YTD; Derivate Metrics uses TTM flows. Balance-sheet data are period-end amounts. | E19: Cash Flow uses YTD; Derivate Metrics uses TTM flows. Balance-sheet data are period-end amounts. | F19: Cash Flow uses YTD; Derivate Metrics uses TTM flows. Balance-sheet data are period-end amounts. | G19: Cash Flow uses YTD; Derivate Metrics uses TTM flows. Balance-sheet data are period-end amounts. | H19: Cash Flow uses YTD; Derivate Metrics uses TTM flows. Balance-sheet data are period-end amounts.
A20: Unavailable values are blank; n.m. marks rates that are not meaningful. Q1/Q2 2023 balance sheets were not supplied. | B20: Unavailable values are blank; n.m. marks rates that are not meaningful. Q1/Q2 2023 balance sheets were not supplied. | C20: Unavailable values are blank; n.m. marks rates that are not meaningful. Q1/Q2 2023 balance sheets were not supplied. | D20: Unavailable values are blank; n.m. marks rates that are not meaningful. Q1/Q2 2023 balance sheets were not supplied. | E20: Unavailable values are blank; n.m. marks rates that are not meaningful. Q1/Q2 2023 balance sheets were not supplied. | F20: Unavailable values are blank; n.m. marks rates that are not meaningful. Q1/Q2 2023 balance sheets were not supplied. | G20: Unavailable values are blank; n.m. marks rates that are not meaningful. Q1/Q2 2023 balance sheets were not supplied. | H20: Unavailable values are blank; n.m. marks rates that are not meaningful. Q1/Q2 2023 balance sheets were not supplied.
A21: Source mappings and review records are retained outside this workbook. | B21: Source mappings and review records are retained outside this workbook. | C21: Source mappings and review records are retained outside this workbook. | D21: Source mappings and review records are retained outside this workbook. | E21: Source mappings and review records are retained outside this workbook. | F21: Source mappings and review records are retained outside this workbook. | G21: Source mappings and review records are retained outside this workbook. | H21: Source mappings and review records are retained outside this workbook.

Sheet Segments
A1: Intel Corporation — Segments | B1: Intel Corporation — Segments | C1: Intel Corporation — Segments | D1: Intel Corporation — Segments | E1: Intel Corporation — Segments | F1: Intel Corporation — Segments | G1: Intel Corporation — Segments | H1: Intel Corporation — Segments | I1: Intel Corporation — Segments | J1: Intel Corporation — Segments | K1: Intel Corporation — Segments | L1: Intel Corporation — Segments | M1: Intel Corporation — Segments | N1: Intel Corporation — Segments | O1: Intel Corporation — Segments | P1: Intel Corporation — Segments | Q1: Intel Corporation — Segments | R1: Intel Corporation — Segments | S1: Intel Corporation — Segments | T1: Intel Corporation — Segments | U1: Intel Corporation — Segments | V1: Intel Corporation — Segments | W1: Intel Corporation — Segments | X1: Intel Corporation — Segments | Y1: Intel Corporation — Segments | Z1: Intel Corporation — Segments | AA1: Intel Corporation — Segments
A2: USD million unless stated otherwise; annual FY2016–FY2025; latest interim 27 June 2026.
A3: Metric | C3: FY2016 | D3: FY2017 | E3: FY2018 | F3: FY2019 | G3: FY2020 | H3: FY2021 | I3: FY2022 | J3: FY2023 | K3: FY2024 | L3: FY2025 | N3: 1Q2023 | O3: 2Q2023 | P3: 3Q2023 | Q3: 4Q2023 | R3: 1Q2024 | S3: 2Q2024 | T3: 3Q2024 | U3: 4Q2024 | V3: 1Q2025 | W3: 2Q2025 | X3: 3Q2025 | Y3: 4Q2025 | Z3: 1Q2026 | AA3: 2Q2026
C4: 2016-12-31T00:00:00.000Z | D4: 2017-12-30T00:00:00.000Z | E4: 2018-12-29T00:00:00.000Z | F4: 2019-12-28T00:00:00.000Z | G4: 2020-12-26T00:00:00.000Z | H4: 2021-12-25T00:00:00.000Z | I4: 2022-12-31T00:00:00.000Z | J4: 2023-12-30T00:00:00.000Z | K4: 2024-12-28T00:00:00.000Z | L4: 2025-12-27T00:00:00.000Z | N4: 2023-04-01T00:00:00.000Z | O4: 2023-07-01T00:00:00.000Z | P4: 2023-09-30T00:00:00.000Z | Q4: 2023-12-30T00:00:00.000Z | R4: 2024-03-30T00:00:00.000Z | S4: 2024-06-29T00:00:00.000Z | T4: 2024-09-28T00:00:00.000Z | U4: 2024-12-28T00:00:00.000Z | V4: 2025-03-29T00:00:00.000Z | W4: 2025-06-28T00:00:00.000Z | X4: 2025-09-27T00:00:00.000Z | Y4: 2025-12-27T00:00:00.000Z | Z4: 2026-03-28T00:00:00.000Z | AA4: 2026-06-27T00:00:00.000Z
A5: Annual / discrete-quarter / instant as identified | C5: Annual | D5: Annual | E5: Annual | F5: Annual | G5: Annual | H5: Annual | I5: Annual | J5: Annual | K5: Annual | L5: Annual | N5: Quarter / note basis | O5: Quarter / note basis | P5: Quarter / note basis | Q5: Quarter / note basis | R5: Quarter / note basis | S5: Quarter / note basis | T5: Quarter / note basis | U5: Quarter / note basis | V5: Quarter / note basis | W5: Quarter / note basis | X5: Quarter / note basis | Y5: Quarter / note basis | Z5: Quarter / note basis | AA5: Quarter / note basis
A7: 2025 reporting framework: Net revenue | B7: 2025 reporting framework: Net revenue | C7: 2025 reporting framework: Net revenue | D7: 2025 reporting framework: Net revenue | E7: 2025 reporting framework: Net revenue | F7: 2025 reporting framework: Net revenue | G7: 2025 reporting framework: Net revenue | H7: 2025 reporting framework: Net revenue | I7: 2025 reporting framework: Net revenue | J7: 2025 reporting framework: Net revenue | K7: 2025 reporting framework: Net revenue | L7: 2025 reporting framework: Net revenue | M7: 2025 reporting framework: Net revenue | N7: 2025 reporting framework: Net revenue | O7: 2025 reporting framework: Net revenue | P7: 2025 reporting framework: Net revenue | Q7: 2025 reporting framework: Net revenue | R7: 2025 reporting framework: Net revenue | S7: 2025 reporting framework: Net revenue | T7: 2025 reporting framework: Net revenue | U7: 2025 reporting framework: Net revenue | V7: 2025 reporting framework: Net revenue | W7: 2025 reporting framework: Net revenue | X7: 2025 reporting framework: Net revenue | Y7: 2025 reporting framework: Net revenue | Z7: 2025 reporting framework: Net revenue | AA7: 2025 reporting framework: Net revenue
A8: 2023–2025 annuals use the 2025 segment framework. Q2 2026 CCPG is the renamed CCG where source comparatives agree; legacy frameworks below are not spliced into this series. | B8: 2023–2025 annuals use the 2025 segment framework. Q2 2026 CCPG is the renamed CCG where source comparatives agree; legacy frameworks below are not spliced into this series. | C8: 2023–2025 annuals use the 2025 segment framework. Q2 2026 CCPG is the renamed CCG where source comparatives agree; legacy frameworks below are not spliced into this series. | D8: 2023–2025 annuals use the 2025 segment framework. Q2 2026 CCPG is the renamed CCG where source comparatives agree; legacy frameworks below are not spliced into this series. | E8: 2023–2025 annuals use the 2025 segment framework. Q2 2026 CCPG is the renamed CCG where source comparatives agree; legacy frameworks below are not spliced into this series. | F8: 2023–2025 annuals use the 2025 segment framework. Q2 2026 CCPG is the renamed CCG where source comparatives agree; legacy frameworks below are not spliced into this series. | G8: 2023–2025 annuals use the 2025 segment framework. Q2 2026 CCPG is the renamed CCG where source comparatives agree; legacy frameworks below are not spliced into this series. | H8: 2023–2025 annuals use the 2025 segment framework. Q2 2026 CCPG is the renamed CCG where source comparatives agree; legacy frameworks below are not spliced into this series. | I8: 2023–2025 annuals use the 2025 segment framework. Q2 2026 CCPG is the renamed CCG where source comparatives agree; legacy frameworks below are not spliced into this series. | J8: 2023–2025 annuals use the 2025 segment framework. Q2 2026 CCPG is the renamed CCG where source comparatives agree; legacy frameworks below are not spliced into this series. | K8: 2023–2025 annuals use the 2025 segment framework. Q2 2026 CCPG is the renamed CCG where source comparatives agree; legacy frameworks below are not spliced into this series. | L8: 2023–2025 annuals use the 2025 segment framework. Q2 2026 CCPG is the renamed CCG where source comparatives agree; legacy frameworks below are not spliced into this series. | M8: 2023–2025 annuals use the 2025 segment framework. Q2 2026 CCPG is the renamed CCG where source comparatives agree; legacy frameworks below are not spliced into this series. | N8: 2023–2025 annuals use the 2025 segment framework. Q2 2026 CCPG is the renamed CCG where source comparatives agree; legacy frameworks below are not spliced into this series. | O8: 2023–2025 annuals use the 2025 segment framework. Q2 2026 CCPG is the renamed CCG where source comparatives agree; legacy frameworks below are not spliced into this series. | P8: 2023–2025 annuals use the 2025 segment framework. Q2 2026 CCPG is the renamed CCG where source comparatives agree; legacy frameworks below are not spliced into this series. | Q8: 2023–2025 annuals use the 2025 segment framework. Q2 2026 CCPG is the renamed CCG where source comparatives agree; legacy frameworks below are not spliced into this series. | R8: 2023–2025 annuals use the 2025 segment framework. Q2 2026 CCPG is the renamed CCG where source comparatives agree; legacy frameworks below are not spliced into this series. | S8: 2023–2025 annuals use the 2025 segment framework. Q2 2026 CCPG is the renamed CCG where source comparatives agree; legacy frameworks below are not spliced into this series. | T8: 2023–2025 annuals use the 2025 segment framework. Q2 2026 CCPG is the renamed CCG where source comparatives agree; legacy frameworks below are not spliced into this series. | U8: 2023–2025 annuals use the 2025 segment framework. Q2 2026 CCPG is the renamed CCG where source comparatives agree; legacy frameworks below are not spliced into this series. | V8: 2023–2025 annuals use the 2025 segment framework. Q2 2026 CCPG is the renamed CCG where source comparatives agree; legacy frameworks below are not spliced into this series. | W8: 2023–2025 annuals use the 2025 segment framework. Q2 2026 CCPG is the renamed CCG where source comparatives agree; legacy frameworks below are not spliced into this series. | X8: 2023–2025 annuals use the 2025 segment framework. Q2 2026 CCPG is the renamed CCG where source comparatives agree; legacy frameworks below are not spliced into this series. | Y8: 2023–2025 annuals use the 2025 segment framework. Q2 2026 CCPG is the renamed CCG where source comparatives agree; legacy frameworks below are not spliced into this series. | Z8: 2023–2025 annuals use the 2025 segment framework. Q2 2026 CCPG is the renamed CCG where source comparatives agree; legacy frameworks below are not spliced into this series. | AA8: 2023–2025 annuals use the 2025 segment framework. Q2 2026 CCPG is the renamed CCG where source comparatives agree; legacy frameworks below are not spliced into this series.
A9: Revenue - CCG | J9: 32305 | K9: 33346 | L9: 32228 | Q9: =IF(COUNT(J9,N9,O9,P9)=4,J9-N9-O9-P9,"") | R9: 8273 | S9: 8143 | T9: 8161 | U9: =IF(COUNT(K9,R9,S9,T9)=4,K9-R9-S9-T9,"") -> 8769 | V9: 7629 | W9: 7871 | X9: 8535 | Y9: =IF(COUNT(L9,V9,W9,X9)=4,L9-V9-W9-X9,"") -> 8193 | Z9: 7727 | AA9: 8877
A10: Revenue - DCAI | J10: 15980 | K10: 16125 | L10: 16919 | Q10: =IF(COUNT(J10,N10,O10,P10)=4,J10-N10-O10-P10,"") | R10: 3828 | S10: 3805 | T10: 4141 | U10: =IF(COUNT(K10,R10,S10,T10)=4,K10-R10-S10-T10,"") -> 4351 | V10: 4126 | W10: 3939 | X10: 4117 | Y10: =IF(COUNT(L10,V10,W10,X10)=4,L10-V10-W10-X10,"") -> 4737 | Z10: 5052 | AA10: 6262
A11: Revenue - Total Intel Products | J11: 48285 | K11: 49471 | L11: 49147 | Q11: =IF(COUNT(J11,N11,O11,P11)=4,J11-N11-O11-P11,"") | R11: 12101 | S11: 11948 | T11: 12302 | U11: =IF(COUNT(K11,R11,S11,T11)=4,K11-R11-S11-T11,"") -> 13120 | V11: 11755 | W11: 11810 | X11: 12652 | Y11: =IF(COUNT(L11,V11,W11,X11)=4,L11-V11-W11-X11,"") -> 12930 | Z11: 12779 | AA11: 15139
A12: Revenue - Intel Foundry | J12: 18504 | K12: 17317 | L12: 17826 | Q12: =IF(COUNT(J12,N12,O12,P12)=4,J12-N12-O12-P12,"") | R12: 4356 | S12: 4282 | T12: 4339 | U12: =IF(COUNT(K12,R12,S12,T12)=4,K12-R12-S12-T12,"") -> 4340 | V12: 4667 | W12: 4417 | X12: 4235 | Y12: =IF(COUNT(L12,V12,W12,X12)=4,L12-V12-W12-X12,"") -> 4507 | Z12: 5421 | AA12: 5765
A13: Revenue - All Other | J13: 5463 | K13: 3601 | L13: 3563 | Q13: =IF(COUNT(J13,N13,O13,P13)=4,J13-N13-O13-P13,"") | R13: 643 | S13: 881 | T13: 964 | U13: =IF(COUNT(K13,R13,S13,T13)=4,K13-R13-S13-T13,"") -> 1113 | V13: 943 | W13: 1053 | X13: 993 | Y13: =IF(COUNT(L13,V13,W13,X13)=4,L13-V13-W13-X13,"") -> 574 | Z13: 628 | AA13: 701
A14: Revenue - Corporate Unallocated | J14: 0 | K14: 0 | L14: 0 | Q14: =IF(COUNT(J14,N14,O14,P14)=4,J14-N14-O14-P14,"") | R14: 0 | S14: 0 | T14: 0 | U14: =IF(COUNT(K14,R14,S14,T14)=4,K14-R14-S14-T14,"") -> 0 | V14: 0 | W14: 0 | X14: 0 | Y14: =IF(COUNT(L14,V14,W14,X14)=4,L14-V14-W14-X14,"") -> 0 | Z14: 0 | AA14: 0
A15: Revenue - Intersegment Eliminations | J15: -18024 | K15: -17288 | L15: -17683 | Q15: =IF(COUNT(J15,N15,O15,P15)=4,J15-N15-O15-P15,"") | R15: -4376 | S15: -4278 | T15: -4321 | U15: =IF(COUNT(K15,R15,S15,T15)=4,K15-R15-S15-T15,"") -> -4313 | V15: -4698 | W15: -4421 | X15: -4227 | Y15: =IF(COUNT(L15,V15,W15,X15)=4,L15-V15-W15-X15,"") -> -4337 | Z15: -5251 | AA15: -5477
A16: Revenue - Total Consolidated | J16: 54228 | K16: 53101 | L16: 52853 | Q16: =IF(COUNT(J16,N16,O16,P16)=4,J16-N16-O16-P16,"") | R16: 12724 | S16: 12833 | T16: 13284 | U16: =IF(COUNT(K16,R16,S16,T16)=4,K16-R16-S16-T16,"") -> 14260 | V16: 12667 | W16: 12859 | X16: 13653 | Y16: =IF(COUNT(L16,V16,W16,X16)=4,L16-V16-W16-X16,"") -> 13674 | Z16: 13577 | AA16: 16128
A17: Check: segment lines - printed total (should be 0) | J17: =IF(COUNT(J9,J10,J12,J13,J14,J15,J16)=7,J9+J10+J12+J13+J14+J15-J16,"") -> 0 | K17: =IF(COUNT(K9,K10,K12,K13,K14,K15,K16)=7,K9+K10+K12+K13+K14+K15-K16,"") -> 0 | L17: =IF(COUNT(L9,L10,L12,L13,L14,L15,L16)=7,L9+L10+L12+L13+L14+L15-L16,"") -> 0 | Q17: =IF(COUNT(Q9,Q10,Q12,Q13,Q14,Q15,Q16)=7,Q9+Q10+Q12+Q13+Q14+Q15-Q16,"") | R17: =IF(COUNT(R9,R10,R12,R13,R14,R15,R16)=7,R9+R10+R12+R13+R14+R15-R16,"") -> 0 | S17: =IF(COUNT(S9,S10,S12,S13,S14,S15,S16)=7,S9+S10+S12+S13+S14+S15-S16,"") -> 0 | T17: =IF(COUNT(T9,T10,T12,T13,T14,T15,T16)=7,T9+T10+T12+T13+T14+T15-T16,"") -> 0 | U17: =IF(COUNT(U9,U10,U12,U13,U14,U15,U16)=7,U9+U10+U12+U13+U14+U15-U16,"") -> 0 | V17: =IF(COUNT(V9,V10,V12,V13,V14,V15,V16)=7,V9+V10+V12+V13+V14+V15-V16,"") -> 0 | W17: =IF(COUNT(W9,W10,W12,W13,W14,W15,W16)=7,W9+W10+W12+W13+W14+W15-W16,"") -> 0 | X17: =IF(COUNT(X9,X10,X12,X13,X14,X15,X16)=7,X9+X10+X12+X13+X14+X15-X16,"") -> 0 | ... AA17: =IF(COUNT(AA9,AA10,AA12,AA13,AA14,AA15,AA16)=7,AA9+AA10+AA12+AA13+AA14+AA15-AA16,"") -> 0
A19: 2025 reporting framework: Operating income (loss) | B19: 2025 reporting framework: Operating income (loss) | C19: 2025 reporting framework: Operating income (loss) | D19: 2025 reporting framework: Operating income (loss) | E19: 2025 reporting framework: Operating income (loss) | F19: 2025 reporting framework: Operating income (loss) | G19: 2025 reporting framework: Operating income (loss) | H19: 2025 reporting framework: Operating income (loss) | I19: 2025 reporting framework: Operating income (loss) | J19: 2025 reporting framework: Operating income (loss) | K19: 2025 reporting framework: Operating income (loss) | L19: 2025 reporting framework: Operating income (loss) | M19: 2025 reporting framework: Operating income (loss) | N19: 2025 reporting framework: Operating income (loss) | O19: 2025 reporting framework: Operating income (loss) | P19: 2025 reporting framework: Operating income (loss) | Q19: 2025 reporting framework: Operating income (loss) | R19: 2025 reporting framework: Operating income (loss) | S19: 2025 reporting framework: Operating income (loss) | T19: 2025 reporting framework: Operating income (loss) | U19: 2025 reporting framework: Operating income (loss) | V19: 2025 reporting framework: Operating income (loss) | W19: 2025 reporting framework: Operating income (loss) | X19: 2025 reporting framework: Operating income (loss) | Y19: 2025 reporting framework: Operating income (loss) | Z19: 2025 reporting framework: Operating income (loss) | AA19: 2025 reporting framework: Operating income (loss)
A20: 2023–2025 annuals use the 2025 segment framework. Q2 2026 CCPG is the renamed CCG where source comparatives agree; legacy frameworks below are not spliced into this series. | B20: 2023–2025 annuals use the 2025 segment framework. Q2 2026 CCPG is the renamed CCG where source comparatives agree; legacy frameworks below are not spliced into this series. | C20: 2023–2025 annuals use the 2025 segment framework. Q2 2026 CCPG is the renamed CCG where source comparatives agree; legacy frameworks below are not spliced into this series. | D20: 2023–2025 annuals use the 2025 segment framework. Q2 2026 CCPG is the renamed CCG where source comparatives agree; legacy frameworks below are not spliced into this series. | E20: 2023–2025 annuals use the 2025 segment framework. Q2 2026 CCPG is the renamed CCG where source comparatives agree; legacy frameworks below are not spliced into this series. | F20: 2023–2025 annuals use the 2025 segment framework. Q2 2026 CCPG is the renamed CCG where source comparatives agree; legacy frameworks below are not spliced into this series. | G20: 2023–2025 annuals use the 2025 segment framework. Q2 2026 CCPG is the renamed CCG where source comparatives agree; legacy frameworks below are not spliced into this series. | H20: 2023–2025 annuals use the 2025 segment framework. Q2 2026 CCPG is the renamed CCG where source comparatives agree; legacy frameworks below are not spliced into this series. | I20: 2023–2025 annuals use the 2025 segment framework. Q2 2026 CCPG is the renamed CCG where source comparatives agree; legacy frameworks below are not spliced into this series. | J20: 2023–2025 annuals use the 2025 segment framework. Q2 2026 CCPG is the renamed CCG where source comparatives agree; legacy frameworks below are not spliced into this series. | K20: 2023–2025 annuals use the 2025 segment framework. Q2 2026 CCPG is the renamed CCG where source comparatives agree; legacy frameworks below are not spliced into this series. | L20: 2023–2025 annuals use the 2025 segment framework. Q2 2026 CCPG is the renamed CCG where source comparatives agree; legacy frameworks below are not spliced into this series. | M20: 2023–2025 annuals use the 2025 segment framework. Q2 2026 CCPG is the renamed CCG where source comparatives agree; legacy frameworks below are not spliced into this series. | N20: 2023–2025 annuals use the 2025 segment framework. Q2 2026 CCPG is the renamed CCG where source comparatives agree; legacy frameworks below are not spliced into this series. | O20: 2023–2025 annuals use the 2025 segment framework. Q2 2026 CCPG is the renamed CCG where source comparatives agree; legacy frameworks below are not spliced into this series. | P20: 2023–2025 annuals use the 2025 segment framework. Q2 2026 CCPG is the renamed CCG where source comparatives agree; legacy frameworks below are not spliced into this series. | Q20: 2023–2025 annuals use the 2025 segment framework. Q2 2026 CCPG is the renamed CCG where source comparatives agree; legacy frameworks below are not spliced into this series. | R20: 2023–2025 annuals use the 2025 segment framework. Q2 2026 CCPG is the renamed CCG where source comparatives agree; legacy frameworks below are not spliced into this series. | S20: 2023–2025 annuals use the 2025 segment framework. Q2 2026 CCPG is the renamed CCG where source comparatives agree; legacy frameworks below are not spliced into this series. | T20: 2023–2025 annuals use the 2025 segment framework. Q2 2026 CCPG is the renamed CCG where source comparatives agree; legacy frameworks below are not spliced into this series. | U20: 2023–2025 annuals use the 2025 segment framework. Q2 2026 CCPG is the renamed CCG where source comparatives agree; legacy frameworks below are not spliced into this series. | V20: 2023–2025 annuals use the 2025 segment framework. Q2 2026 CCPG is the renamed CCG where source comparatives agree; legacy frameworks below are not spliced into this series. | W20: 2023–2025 annuals use the 2025 segment framework. Q2 2026 CCPG is the renamed CCG where source comparatives agree; legacy frameworks below are not spliced into this series. | X20: 2023–2025 annuals use the 2025 segment framework. Q2 2026 CCPG is the renamed CCG where source comparatives agree; legacy frameworks below are not spliced into this series. | Y20: 2023–2025 annuals use the 2025 segment framework. Q2 2026 CCPG is the renamed CCG where source comparatives agree; legacy frameworks below are not spliced into this series. | Z20: 2023–2025 annuals use the 2025 segment framework. Q2 2026 CCPG is the renamed CCG where source comparatives agree; legacy frameworks below are not spliced into this series. | AA20: 2023–2025 annuals use the 2025 segment framework. Q2 2026 CCPG is the renamed CCG where source comparatives agree; legacy frameworks below are not spliced into this series.
A21: Operating income (loss) - CCG | J21: 10128 | K21: 11594 | L21: 9317 | Q21: =IF(COUNT(J21,N21,O21,P21)=4,J21-N21-O21-P21,"") | R21: 2822 | S21: 2641 | T21: 2937 | U21: =IF(COUNT(K21,R21,S21,T21)=4,K21-R21-S21-T21,"") -> 3194 | V21: 2361 | W21: 2053 | X21: 2694 | Y21: =IF(COUNT(L21,V21,W21,X21)=4,L21-V21-W21-X21,"") -> 2209 | Z21: 2516 | AA21: 2343
A22: Operating income (loss) - DCAI | J22: 945 | K22: 1414 | L22: 3422 | Q22: =IF(COUNT(J22,N22,O22,P22)=4,J22-N22-O22-P22,"") | R22: 417 | S22: 242 | T22: 381 | U22: =IF(COUNT(K22,R22,S22,T22)=4,K22-R22-S22-T22,"") -> 374 | V22: 575 | W22: 633 | X22: 964 | Y22: =IF(COUNT(L22,V22,W22,X22)=4,L22-V22-W22-X22,"") -> 1250 | Z22: 1542 | AA22: 2474
A23: Operating income (loss) - Total Intel Products | J23: 11073 | K23: 13008 | L23: 12739 | Q23: =IF(COUNT(J23,N23,O23,P23)=4,J23-N23-O23-P23,"") | R23: 3239 | S23: 2883 | T23: 3318 | U23: =IF(COUNT(K23,R23,S23,T23)=4,K23-R23-S23-T23,"") -> 3568 | V23: 2936 | W23: 2686 | X23: 3658 | Y23: =IF(COUNT(L23,V23,W23,X23)=4,L23-V23-W23-X23,"") -> 3459 | Z23: 4058 | AA23: 4817
A24: Operating income (loss) - Intel Foundry | J24: -7083 | K24: -13291 | L24: -10318 | Q24: =IF(COUNT(J24,N24,O24,P24)=4,J24-N24-O24-P24,"") | R24: -2441 | S24: -2802 | T24: -5799 | U24: =IF(COUNT(K24,R24,S24,T24)=4,K24-R24-S24-T24,"") -> -2249 | V24: -2320 | W24: -3168 | X24: -2321 | Y24: =IF(COUNT(L24,V24,W24,X24)=4,L24-V24-W24-X24,"") -> -2509 | Z24: -2437 | AA24: -2089
A25: Operating income (loss) - All Other | J25: 1507 | K25: -57 | L25: 264 | Q25: =IF(COUNT(J25,N25,O25,P25)=4,J25-N25-O25-P25,"") | R25: -170 | S25: -46 | T25: 5 | U25: =IF(COUNT(K25,R25,S25,T25)=4,K25-R25-S25-T25,"") -> 154 | V25: 103 | W25: 69 | X25: 100 | Y25: =IF(COUNT(L25,V25,W25,X25)=4,L25-V25-W25-X25,"") -> -8 | Z25: 102 | AA25: 230
A26: Operating income (loss) - Corporate Unallocated | J26: -5199 | K26: -11177 | L26: -5518 | Q26: =IF(COUNT(J26,N26,O26,P26)=4,J26-N26-O26-P26,"") | R26: -2187 | S26: -1708 | T26: -6502 | U26: =IF(COUNT(K26,R26,S26,T26)=4,K26-R26-S26-T26,"") -> -780 | V26: -1260 | W26: -2755 | X26: -782 | Y26: =IF(COUNT(L26,V26,W26,X26)=4,L26-V26-W26-X26,"") -> -721 | Z26: -5080 | AA26: -1416
A27: Operating income (loss) - Intersegment Eliminations | J27: -205 | K27: -161 | L27: 619 | Q27: =IF(COUNT(J27,N27,O27,P27)=4,J27-N27-O27-P27,"") | R27: 490 | S27: -291 | T27: -79 | U27: =IF(COUNT(K27,R27,S27,T27)=4,K27-R27-S27-T27,"") -> -281 | V27: 240 | W27: -8 | X27: 28 | Y27: =IF(COUNT(L27,V27,W27,X27)=4,L27-V27-W27-X27,"") -> 359 | Z27: 221 | AA27: 254
A28: Operating income (loss) - Total Consolidated | J28: 93 | K28: -11678 | L28: -2214 | Q28: =IF(COUNT(J28,N28,O28,P28)=4,J28-N28-O28-P28,"") | R28: -1069 | S28: -1964 | T28: -9057 | U28: =IF(COUNT(K28,R28,S28,T28)=4,K28-R28-S28-T28,"") -> 412 | V28: -301 | W28: -3176 | X28: 683 | Y28: =IF(COUNT(L28,V28,W28,X28)=4,L28-V28-W28-X28,"") -> 580 | Z28: -3136 | AA28: 1796
A29: Check: segment lines - printed total (should be 0) | J29: =IF(COUNT(J21,J22,J24,J25,J26,J27,J28)=7,J21+J22+J24+J25+J26+J27-J28,"") -> 0 | K29: =IF(COUNT(K21,K22,K24,K25,K26,K27,K28)=7,K21+K22+K24+K25+K26+K27-K28,"") -> 0 | L29: =IF(COUNT(L21,L22,L24,L25,L26,L27,L28)=7,L21+L22+L24+L25+L26+L27-L28,"") -> 0 | Q29: =IF(COUNT(Q21,Q22,Q24,Q25,Q26,Q27,Q28)=7,Q21+Q22+Q24+Q25+Q26+Q27-Q28,"") | R29: =IF(COUNT(R21,R22,R24,R25,R26,R27,R28)=7,R21+R22+R24+R25+R26+R27-R28,"") -> 0 | S29: =IF(COUNT(S21,S22,S24,S25,S26,S27,S28)=7,S21+S22+S24+S25+S26+S27-S28,"") -> 0 | T29: =IF(COUNT(T21,T22,T24,T25,T26,T27,T28)=7,T21+T22+T24+T25+T26+T27-T28,"") -> 0 | U29: =IF(COUNT(U21,U22,U24,U25,U26,U27,U28)=7,U21+U22+U24+U25+U26+U27-U28,"") -> 0 | V29: =IF(COUNT(V21,V22,V24,V25,V26,V27,V28)=7,V21+V22+V24+V25+V26+V27-V28,"") -> 0 | W29: =IF(COUNT(W21,W22,W24,W25,W26,W27,W28)=7,W21+W22+W24+W25+W26+W27-W28,"") -> 0 | X29: =IF(COUNT(X21,X22,X24,X25,X26,X27,X28)=7,X21+X22+X24+X25+X26+X27-X28,"") -> 0 | ... AA29: =IF(COUNT(AA21,AA22,AA24,AA25,AA26,AA27,AA28)=7,AA21+AA22+AA24+AA25+AA26+AA27-AA28,"") -> 0
A31: 2025 reporting framework: Cost of sales and operating expenses | B31: 2025 reporting framework: Cost of sales and operating expenses | C31: 2025 reporting framework: Cost of sales and operating expenses | D31: 2025 reporting framework: Cost of sales and operating expenses | E31: 2025 reporting framework: Cost of sales and operating expenses | F31: 2025 reporting framework: Cost of sales and operating expenses | G31: 2025 reporting framework: Cost of sales and operating expenses | H31: 2025 reporting framework: Cost of sales and operating expenses | I31: 2025 reporting framework: Cost of sales and operating expenses | J31: 2025 reporting framework: Cost of sales and operating expenses | K31: 2025 reporting framework: Cost of sales and operating expenses | L31: 2025 reporting framework: Cost of sales and operating expenses | M31: 2025 reporting framework: Cost of sales and operating expenses | N31: 2025 reporting framework: Cost of sales and operating expenses | O31: 2025 reporting framework: Cost of sales and operating expenses | P31: 2025 reporting framework: Cost of sales and operating expenses | Q31: 2025 reporting framework: Cost of sales and operating expenses | R31: 2025 reporting framework: Cost of sales and operating expenses | S31: 2025 reporting framework: Cost of sales and operating expenses | T31: 2025 reporting framework: Cost of sales and operating expenses | U31: 2025 reporting framework: Cost of sales and operating expenses | V31: 2025 reporting framework: Cost of sales and operating expenses | W31: 2025 reporting framework: Cost of sales and operating expenses | X31: 2025 reporting framework: Cost of sales and operating expenses | Y31: 2025 reporting framework: Cost of sales and operating expenses | Z31: 2025 reporting framework: Cost of sales and operating expenses | AA31: 2025 reporting framework: Cost of sales and operating expenses
A32: 2023–2025 annuals use the 2025 segment framework. Q2 2026 CCPG is the renamed CCG where source comparatives agree; legacy frameworks below are not spliced into this series. | B32: 2023–2025 annuals use the 2025 segment framework. Q2 2026 CCPG is the renamed CCG where source comparatives agree; legacy frameworks below are not spliced into this series. | C32: 2023–2025 annuals use the 2025 segment framework. Q2 2026 CCPG is the renamed CCG where source comparatives agree; legacy frameworks below are not spliced into this series. | D32: 2023–2025 annuals use the 2025 segment framework. Q2 2026 CCPG is the renamed CCG where source comparatives agree; legacy frameworks below are not spliced into this series. | E32: 2023–2025 annuals use the 2025 segment framework. Q2 2026 CCPG is the renamed CCG where source comparatives agree; legacy frameworks below are not spliced into this series. | F32: 2023–2025 annuals use the 2025 segment framework. Q2 2026 CCPG is the renamed CCG where source comparatives agree; legacy frameworks below are not spliced into this series. | G32: 2023–2025 annuals use the 2025 segment framework. Q2 2026 CCPG is the renamed CCG where source comparatives agree; legacy frameworks below are not spliced into this series. | H32: 2023–2025 annuals use the 2025 segment framework. Q2 2026 CCPG is the renamed CCG where source comparatives agree; legacy frameworks below are not spliced into this series. | I32: 2023–2025 annuals use the 2025 segment framework. Q2 2026 CCPG is the renamed CCG where source comparatives agree; legacy frameworks below are not spliced into this series. | J32: 2023–2025 annuals use the 2025 segment framework. Q2 2026 CCPG is the renamed CCG where source comparatives agree; legacy frameworks below are not spliced into this series. | K32: 2023–2025 annuals use the 2025 segment framework. Q2 2026 CCPG is the renamed CCG where source comparatives agree; legacy frameworks below are not spliced into this series. | L32: 2023–2025 annuals use the 2025 segment framework. Q2 2026 CCPG is the renamed CCG where source comparatives agree; legacy frameworks below are not spliced into this series. | M32: 2023–2025 annuals use the 2025 segment framework. Q2 2026 CCPG is the renamed CCG where source comparatives agree; legacy frameworks below are not spliced into this series. | N32: 2023–2025 annuals use the 2025 segment framework. Q2 2026 CCPG is the renamed CCG where source comparatives agree; legacy frameworks below are not spliced into this series. | O32: 2023–2025 annuals use the 2025 segment framework. Q2 2026 CCPG is the renamed CCG where source comparatives agree; legacy frameworks below are not spliced into this series. | P32: 2023–2025 annuals use the 2025 segment framework. Q2 2026 CCPG is the renamed CCG where source comparatives agree; legacy frameworks below are not spliced into this series. | Q32: 2023–2025 annuals use the 2025 segment framework. Q2 2026 CCPG is the renamed CCG where source comparatives agree; legacy frameworks below are not spliced into this series. | R32: 2023–2025 annuals use the 2025 segment framework. Q2 2026 CCPG is the renamed CCG where source comparatives agree; legacy frameworks below are not spliced into this series. | S32: 2023–2025 annuals use the 2025 segment framework. Q2 2026 CCPG is the renamed CCG where source comparatives agree; legacy frameworks below are not spliced into this series. | T32: 2023–2025 annuals use the 2025 segment framework. Q2 2026 CCPG is the renamed CCG where source comparatives agree; legacy frameworks below are not spliced into this series. | U32: 2023–2025 annuals use the 2025 segment framework. Q2 2026 CCPG is the renamed CCG where source comparatives agree; legacy frameworks below are not spliced into this series. | V32: 2023–2025 annuals use the 2025 segment framework. Q2 2026 CCPG is the renamed CCG where source comparatives agree; legacy frameworks below are not spliced into this series. | W32: 2023–2025 annuals use the 2025 segment framework. Q2 2026 CCPG is the renamed CCG where source comparatives agree; legacy frameworks below are not spliced into this series. | X32: 2023–2025 annuals use the 2025 segment framework. Q2 2026 CCPG is the renamed CCG where source comparatives agree; legacy frameworks below are not spliced into this series. | Y32: 2023–2025 annuals use the 2025 segment framework. Q2 2026 CCPG is the renamed CCG where source comparatives agree; legacy frameworks below are not spliced into this series. | Z32: 2023–2025 annuals use the 2025 segment framework. Q2 2026 CCPG is the renamed CCG where source comparatives agree; legacy frameworks below are not spliced into this series. | AA32: 2023–2025 annuals use the 2025 segment framework. Q2 2026 CCPG is the renamed CCG where source comparatives agree; legacy frameworks below are not spliced into this series.
A33: Cost of sales and operating expenses - CCG | J33: 22177 | K33: 21752 | L33: 22911 | Q33: =IF(COUNT(J33,N33,O33,P33)=4,J33-N33-O33-P33,"") | S33: 5502 | T33: 5224 | U33: =IF(COUNT(K33,R33,S33,T33)=4,K33-R33-S33-T33,"") | V33: 5268 | W33: 5818 | X33: 5841 | Y33: =IF(COUNT(L33,V33,W33,X33)=4,L33-V33-W33-X33,"") -> 5984 | Z33: 5211 | AA33: 6534
A34: Cost of sales and operating expenses - DCAI | J34: 15035 | K34: 14711 | L34: 13497 | Q34: =IF(COUNT(J34,N34,O34,P34)=4,J34-N34-O34-P34,"") | S34: 3563 | T34: 3760 | U34: =IF(COUNT(K34,R34,S34,T34)=4,K34-R34-S34-T34,"") | V34: 3551 | W34: 3306 | X34: 3153 | Y34: =IF(COUNT(L34,V34,W34,X34)=4,L34-V34-W34-X34,"") -> 3487 | Z34: 3510 | AA34: 3788
A35: Cost of sales and operating expenses - Total Intel Products | J35: 37212 | K35: 36463 | L35: 36408 | Q35: =IF(COUNT(J35,N35,O35,P35)=4,J35-N35-O35-P35,"") | S35: 9065 | T35: 8984 | U35: =IF(COUNT(K35,R35,S35,T35)=4,K35-R35-S35-T35,"") | V35: 8819 | W35: 9124 | X35: 8994 | Y35: =IF(COUNT(L35,V35,W35,X35)=4,L35-V35-W35-X35,"") -> 9471 | Z35: 8721 | AA35: 10322
A36: Cost of sales and operating expenses - Intel Foundry | J36: 25587 | K36: 30608 | L36: 28144 | Q36: =IF(COUNT(J36,N36,O36,P36)=4,J36-N36-O36-P36,"") | S36: 7084 | T36: 10138 | U36: =IF(COUNT(K36,R36,S36,T36)=4,K36-R36-S36-T36,"") | V36: 6987 | W36: 7585 | X36: 6556 | Y36: =IF(COUNT(L36,V36,W36,X36)=4,L36-V36-W36-X36,"") -> 7016 | Z36: 7858 | AA36: 7854
A37: Cost of sales and operating expenses - All Other | J37: 3956 | K37: 3658 | L37: 3299 | Q37: =IF(COUNT(J37,N37,O37,P37)=4,J37-N37-O37-P37,"") | S37: 927 | T37: 959 | U37: =IF(COUNT(K37,R37,S37,T37)=4,K37-R37-S37-T37,"") | V37: 840 | W37: 984 | X37: 893 | Y37: =IF(COUNT(L37,V37,W37,X37)=4,L37-V37-W37-X37,"") -> 582 | Z37: 526 | AA37: 471
A38: Cost of sales and operating expenses - Corporate Unallocated | J38: 5199 | K38: 11177 | L38: 5518 | Q38: =IF(COUNT(J38,N38,O38,P38)=4,J38-N38-O38-P38,"") | S38: 1708 | T38: 6502 | U38: =IF(COUNT(K38,R38,S38,T38)=4,K38-R38-S38-T38,"") | V38: 1260 | W38: 2755 | X38: 782 | Y38: =IF(COUNT(L38,V38,W38,X38)=4,L38-V38-W38-X38,"") -> 721 | Z38: 5080 | AA38: 1416
A39: Cost of sales and operating expenses - Intersegment Eliminations | J39: -17819 | K39: -17127 | L39: -18302 | Q39: =IF(COUNT(J39,N39,O39,P39)=4,J39-N39-O39-P39,"") | S39: -3987 | T39: -4242 | U39: =IF(COUNT(K39,R39,S39,T39)=4,K39-R39-S39-T39,"") | V39: -4938 | W39: -4413 | X39: -4255 | Y39: =IF(COUNT(L39,V39,W39,X39)=4,L39-V39-W39-X39,"") -> -4696 | Z39: -5472 | AA39: -5731
A40: Cost of sales and operating expenses - Total Consolidated | J40: 54135 | K40: 64779 | L40: 55067 | Q40: =IF(COUNT(J40,N40,O40,P40)=4,J40-N40-O40-P40,"") | S40: 14797 | T40: 22341 | U40: =IF(COUNT(K40,R40,S40,T40)=4,K40-R40-S40-T40,"") | V40: 12968 | W40: 16035 | X40: 12970 | Y40: =IF(COUNT(L40,V40,W40,X40)=4,L40-V40-W40-X40,"") -> 13094 | Z40: 16713 | AA40: 14332
A41: Check: segment lines - printed total (should be 0) | J41: =IF(COUNT(J33,J34,J36,J37,J38,J39,J40)=7,J33+J34+J36+J37+J38+J39-J40,"") -> 0 | K41: =IF(COUNT(K33,K34,K36,K37,K38,K39,K40)=7,K33+K34+K36+K37+K38+K39-K40,"") -> 0 | L41: =IF(COUNT(L33,L34,L36,L37,L38,L39,L40)=7,L33+L34+L36+L37+L38+L39-L40,"") -> 0 | Q41: =IF(COUNT(Q33,Q34,Q36,Q37,Q38,Q39,Q40)=7,Q33+Q34+Q36+Q37+Q38+Q39-Q40,"") | S41: =IF(COUNT(S33,S34,S36,S37,S38,S39,S40)=7,S33+S34+S36+S37+S38+S39-S40,"") -> 0 | T41: =IF(COUNT(T33,T34,T36,T37,T38,T39,T40)=7,T33+T34+T36+T37+T38+T39-T40,"") -> 0 | U41: =IF(COUNT(U33,U34,U36,U37,U38,U39,U40)=7,U33+U34+U36+U37+U38+U39-U40,"") | V41: =IF(COUNT(V33,V34,V36,V37,V38,V39,V40)=7,V33+V34+V36+V37+V38+V39-V40,"") -> 0 | W41: =IF(COUNT(W33,W34,W36,W37,W38,W39,W40)=7,W33+W34+W36+W37+W38+W39-W40,"") -> 0 | X41: =IF(COUNT(X33,X34,X36,X37,X38,X39,X40)=7,X33+X34+X36+X37+X38+X39-X40,"") -> 0 | Y41: =IF(COUNT(Y33,Y34,Y36,Y37,Y38,Y39,Y40)=7,Y33+Y34+Y36+Y37+Y38+Y39-Y40,"") -> 0 | Z41: =IF(COUNT(Z33,Z34,Z36,Z37,Z38,Z39,Z40)=7,Z33+Z34+Z36+Z37+Z38+Z39-Z40,"") -> 0 | AA41: =IF(COUNT(AA33,AA34,AA36,AA37,AA38,AA39,AA40)=7,AA33+AA34+AA36+AA37+AA38+AA39-AA40,"") -> 0
A43: 2025 reporting framework: Cost of sales | B43: 2025 reporting framework: Cost of sales | C43: 2025 reporting framework: Cost of sales | D43: 2025 reporting framework: Cost of sales | E43: 2025 reporting framework: Cost of sales | F43: 2025 reporting framework: Cost of sales | G43: 2025 reporting framework: Cost of sales | H43: 2025 reporting framework: Cost of sales | I43: 2025 reporting framework: Cost of sales | J43: 2025 reporting framework: Cost of sales | K43: 2025 reporting framework: Cost of sales | L43: 2025 reporting framework: Cost of sales | M43: 2025 reporting framework: Cost of sales | N43: 2025 reporting framework: Cost of sales | O43: 2025 reporting framework: Cost of sales | P43: 2025 reporting framework: Cost of sales | Q43: 2025 reporting framework: Cost of sales | R43: 2025 reporting framework: Cost of sales | S43: 2025 reporting framework: Cost of sales | T43: 2025 reporting framework: Cost of sales | U43: 2025 reporting framework: Cost of sales | V43: 2025 reporting framework: Cost of sales | W43: 2025 reporting framework: Cost of sales | X43: 2025 reporting framework: Cost of sales | Y43: 2025 reporting framework: Cost of sales | Z43: 2025 reporting framework: Cost of sales | AA43: 2025 reporting framework: Cost of sales
A44: 2023–2025 annuals use the 2025 segment framework. Q2 2026 CCPG is the renamed CCG where source comparatives agree; legacy frameworks below are not spliced into this series. | B44: 2023–2025 annuals use the 2025 segment framework. Q2 2026 CCPG is the renamed CCG where source comparatives agree; legacy frameworks below are not spliced into this series. | C44: 2023–2025 annuals use the 2025 segment framework. Q2 2026 CCPG is the renamed CCG where source comparatives agree; legacy frameworks below are not spliced into this series. | D44: 2023–2025 annuals use the 2025 segment framework. Q2 2026 CCPG is the renamed CCG where source comparatives agree; legacy frameworks below are not spliced into this series. | E44: 2023–2025 annuals use the 2025 segment framework. Q2 2026 CCPG is the renamed CCG where source comparatives agree; legacy frameworks below are not spliced into this series. | F44: 2023–2025 annuals use the 2025 segment framework. Q2 2026 CCPG is the renamed CCG where source comparatives agree; legacy frameworks below are not spliced into this series. | G44: 2023–2025 annuals use the 2025 segment framework. Q2 2026 CCPG is the renamed CCG where source comparatives agree; legacy frameworks below are not spliced into this series. | H44: 2023–2025 annuals use the 2025 segment framework. Q2 2026 CCPG is the renamed CCG where source comparatives agree; legacy frameworks below are not spliced into this series. | I44: 2023–2025 annuals use the 2025 segment framework. Q2 2026 CCPG is the renamed CCG where source comparatives agree; legacy frameworks below are not spliced into this series. | J44: 2023–2025 annuals use the 2025 segment framework. Q2 2026 CCPG is the renamed CCG where source comparatives agree; legacy frameworks below are not spliced into this series. | K44: 2023–2025 annuals use the 2025 segment framework. Q2 2026 CCPG is the renamed CCG where source comparatives agree; legacy frameworks below are not spliced into this series. | L44: 2023–2025 annuals use the 2025 segment framework. Q2 2026 CCPG is the renamed CCG where source comparatives agree; legacy frameworks below are not spliced into this series. | M44: 2023–2025 annuals use the 2025 segment framework. Q2 2026 CCPG is the renamed CCG where source comparatives agree; legacy frameworks below are not spliced into this series. | N44: 2023–2025 annuals use the 2025 segment framework. Q2 2026 CCPG is the renamed CCG where source comparatives agree; legacy frameworks below are not spliced into this series. | O44: 2023–2025 annuals use the 2025 segment framework. Q2 2026 CCPG is the renamed CCG where source comparatives agree; legacy frameworks below are not spliced into this series. | P44: 2023–2025 annuals use the 2025 segment framework. Q2 2026 CCPG is the renamed CCG where source comparatives agree; legacy frameworks below are not spliced into this series. | Q44: 2023–2025 annuals use the 2025 segment framework. Q2 2026 CCPG is the renamed CCG where source comparatives agree; legacy frameworks below are not spliced into this series. | R44: 2023–2025 annuals use the 2025 segment framework. Q2 2026 CCPG is the renamed CCG where source comparatives agree; legacy frameworks below are not spliced into this series. | S44: 2023–2025 annuals use the 2025 segment framework. Q2 2026 CCPG is the renamed CCG where source comparatives agree; legacy frameworks below are not spliced into this series. | T44: 2023–2025 annuals use the 2025 segment framework. Q2 2026 CCPG is the renamed CCG where source comparatives agree; legacy frameworks below are not spliced into this series. | U44: 2023–2025 annuals use the 2025 segment framework. Q2 2026 CCPG is the renamed CCG where source comparatives agree; legacy frameworks below are not spliced into this series. | V44: 2023–2025 annuals use the 2025 segment framework. Q2 2026 CCPG is the renamed CCG where source comparatives agree; legacy frameworks below are not spliced into this series. | W44: 2023–2025 annuals use the 2025 segment framework. Q2 2026 CCPG is the renamed CCG where source comparatives agree; legacy frameworks below are not spliced into this series. | X44: 2023–2025 annuals use the 2025 segment framework. Q2 2026 CCPG is the renamed CCG where source comparatives agree; legacy frameworks below are not spliced into this series. | Y44: 2023–2025 annuals use the 2025 segment framework. Q2 2026 CCPG is the renamed CCG where source comparatives agree; legacy frameworks below are not spliced into this series. | Z44: 2023–2025 annuals use the 2025 segment framework. Q2 2026 CCPG is the renamed CCG where source comparatives agree; legacy frameworks below are not spliced into this series. | AA44: 2023–2025 annuals use the 2025 segment framework. Q2 2026 CCPG is the renamed CCG where source comparatives agree; legacy frameworks below are not spliced into this series.
...

Sheet Revenue & Operations
A1: Intel Corporation — Revenue & Operations | B1: Intel Corporation — Revenue & Operations | C1: Intel Corporation — Revenue & Operations | D1: Intel Corporation — Revenue & Operations | E1: Intel Corporation — Revenue & Operations | F1: Intel Corporation — Revenue & Operations | G1: Intel Corporation — Revenue & Operations | H1: Intel Corporation — Revenue & Operations | I1: Intel Corporation — Revenue & Operations | J1: Intel Corporation — Revenue & Operations | K1: Intel Corporation — Revenue & Operations | L1: Intel Corporation — Revenue & Operations
A2: USD million unless stated otherwise; annual FY2016–FY2025; latest interim 27 June 2026.
A3: Metric | C3: FY2016 | D3: FY2017 | E3: FY2018 | F3: FY2019 | G3: FY2020 | H3: FY2021 | I3: FY2022 | J3: FY2023 | K3: FY2024 | L3: FY2025
C4: 2016-12-31T00:00:00.000Z | D4: 2017-12-30T00:00:00.000Z | E4: 2018-12-29T00:00:00.000Z | F4: 2019-12-28T00:00:00.000Z | G4: 2020-12-26T00:00:00.000Z | H4: 2021-12-25T00:00:00.000Z | I4: 2022-12-31T00:00:00.000Z | J4: 2023-12-30T00:00:00.000Z | K4: 2024-12-28T00:00:00.000Z | L4: 2025-12-27T00:00:00.000Z
A5: Annual / discrete-quarter / instant as identified | C5: Annual | D5: Annual | E5: Annual | F5: Annual | G5: Annual | H5: Annual | I5: Annual | J5: Annual | K5: Annual | L5: Annual
A7: Net revenue by country / region | B7: Net revenue by country / region | C7: Net revenue by country / region | D7: Net revenue by country / region | E7: Net revenue by country / region | F7: Net revenue by country / region | G7: Net revenue by country / region | H7: Net revenue by country / region | I7: Net revenue by country / region | J7: Net revenue by country / region | K7: Net revenue by country / region | L7: Net revenue by country / region
A8: Revenue geography uses customer billing location; it is not end-consumer demand geography. | B8: Revenue geography uses customer billing location; it is not end-consumer demand geography. | C8: Revenue geography uses customer billing location; it is not end-consumer demand geography. | D8: Revenue geography uses customer billing location; it is not end-consumer demand geography. | E8: Revenue geography uses customer billing location; it is not end-consumer demand geography. | F8: Revenue geography uses customer billing location; it is not end-consumer demand geography. | G8: Revenue geography uses customer billing location; it is not end-consumer demand geography. | H8: Revenue geography uses customer billing location; it is not end-consumer demand geography. | I8: Revenue geography uses customer billing location; it is not end-consumer demand geography. | J8: Revenue geography uses customer billing location; it is not end-consumer demand geography. | K8: Revenue geography uses customer billing location; it is not end-consumer demand geography. | L8: Revenue geography uses customer billing location; it is not end-consumer demand geography.
A9: United States | C9: 12957 | D9: 12543 | E9: 14303 | F9: 15617 | G9: 16573 | H9: 14107 | I9: 16529 | J9: 13958 | K9: 12994 | L9: 15757
A10: China | C10: 13977 | D10: 14796 | E10: 18824 | F10: 20026 | G10: 20257 | H10: 21141 | I10: 17125 | J10: 14854 | K10: 15532 | L10: 12694
A11: Singapore | C11: 12780 | D11: 14285 | E11: 15409 | F11: 15650 | G11: 17845 | H11: 14254 | I11: 9664 | J11: 8602 | K11: 10187 | L11: 9535
A12: Taiwan | C12: 9953 | D12: 10518 | E12: 10646 | F12: 10058 | G12: 11605 | H12: 13461 | I12: 8287 | J12: 6867 | K12: 7804 | L12: 7672
A13: Other regions | C13: 9720 | D13: 10619 | E13: 11666 | F13: 10614 | G13: 11587 | H13: 16061 | I13: 11449 | J13: 9947 | K13: 6584 | L13: 7195
A14: Total net revenue | C14: 59387 | D14: 62761 | E14: 70848 | F14: 71965 | G14: 77867 | H14: 79024 | I14: 63054 | J14: 54228 | K14: 53101 | L14: 52853
A15: Check: regions - printed total (should be 0) | C15: =IF(COUNT(C9,C10,C11,C12,C13,C14)=6,C9+C10+C11+C12+C13-C14,"") -> 0 | D15: =IF(COUNT(D9,D10,D11,D12,D13,D14)=6,D9+D10+D11+D12+D13-D14,"") -> 0 | E15: =IF(COUNT(E9,E10,E11,E12,E13,E14)=6,E9+E10+E11+E12+E13-E14,"") -> 0 | F15: =IF(COUNT(F9,F10,F11,F12,F13,F14)=6,F9+F10+F11+F12+F13-F14,"") -> 0 | G15: =IF(COUNT(G9,G10,G11,G12,G13,G14)=6,G9+G10+G11+G12+G13-G14,"") -> 0 | H15: =IF(COUNT(H9,H10,H11,H12,H13,H14)=6,H9+H10+H11+H12+H13-H14,"") -> 0 | I15: =IF(COUNT(I9,I10,I11,I12,I13,I14)=6,I9+I10+I11+I12+I13-I14,"") -> 0 | J15: =IF(COUNT(J9,J10,J11,J12,J13,J14)=6,J9+J10+J11+J12+J13-J14,"") -> 0 | ... L15: =IF(COUNT(L9,L10,L11,L12,L13,L14)=6,L9+L10+L11+L12+L13-L14,"") -> 0
A16: Check: total vs income-statement net revenue (should be 0)
A18: Customer concentration (% of revenue) | B18: Customer concentration (% of revenue) | C18: Customer concentration (% of revenue) | D18: Customer concentration (% of revenue) | E18: Customer concentration (% of revenue) | F18: Customer concentration (% of revenue) | G18: Customer concentration (% of revenue) | H18: Customer concentration (% of revenue) | I18: Customer concentration (% of revenue) | J18: Customer concentration (% of revenue) | K18: Customer concentration (% of revenue) | L18: Customer concentration (% of revenue)
A19: Customer A | I19: 0.19 | J19: 0.19 | K19: 0.19 | L19: 0.19
A20: Customer B | I20: 0.12 | J20: 0.11 | K20: 0.14 | L20: 0.12
A21: Customer C | I21: 0.11 | J21: 0.1 | K21: 0.12 | L21: 0.12
A22: Dell Inc. | H22: 0.21 | I22: 0.19 | J22: 0.19
A23: Lenovo Group Limited | H23: 0.12 | I23: 0.12 | J23: 0.11
A24: HP Inc. | H24: 0.1 | I24: 0.11 | J24: 0.1
A25: Total percentage of net revenue | H25: 0.43 | I25: 0.42 | J25: 0.4 | K25: 0.45 | L25: 0.43
A27: Platform vs Adjacent revenue outside the segment note | B27: Platform vs Adjacent revenue outside the segment note | C27: Platform vs Adjacent revenue outside the segment note | D27: Platform vs Adjacent revenue outside the segment note | E27: Platform vs Adjacent revenue outside the segment note | F27: Platform vs Adjacent revenue outside the segment note | G27: Platform vs Adjacent revenue outside the segment note | H27: Platform vs Adjacent revenue outside the segment note | I27: Platform vs Adjacent revenue outside the segment note | J27: Platform vs Adjacent revenue outside the segment note | K27: Platform vs Adjacent revenue outside the segment note | L27: Platform vs Adjacent revenue outside the segment note
A28: CCG notebook platform | D28: 19414 | E28: 20930 | F28: 20779 | G28: 24903 | H28: 25475
A29: Other platform | C29: 2467 | D29: 2810 | E29: 3149 | F29: 80
A30: CCG desktop platform | D30: 11647 | E30: 12220 | F30: 11822 | G30: 10692 | H30: 11835
A31: CCG other platform1 | E31: 84 | F31: 80 | G31: 47 | H31: 66
A32: Desktop platform | C32: 12371 | D32: 11647 | E32: 12220
A33: Notebook platform | C33: 18203 | D33: 19414 | E33: 20930
A34: DCG platform | C34: 15895 | D34: 17439 | E34: 21155 | F34: 21441 | G34: 23056 | H34: 22703
A35: IOTG platform | D35: 2645 | E35: 3065 | F35: 3440 | G35: 2705 | H35: 3658
A36: [Total platform revenue] | C36: 48936 | D36: 51310 | E36: 57454 | F36: 57562 | G36: 61403 | H36: 63737
A37: Adjacent revenue | C37: 8290 | D37: 10917 | E37: 13394 | F37: 14403
A38: ISecG divested business | C38: 2161 | D38: 534 | E38: 0 | F38: 0
A39: Adjacent revenue2 | E39: 13394 | F39: 14403 | G39: 16464 | H39: 15287
A40: Total revenue | C40: 59387 | D40: 62761 | E40: 70848 | F40: 71965 | G40: 77867 | H40: 79024
A42: Platform sales volumes and average selling prices | B42: Platform sales volumes and average selling prices | C42: Platform sales volumes and average selling prices | D42: Platform sales volumes and average selling prices | E42: Platform sales volumes and average selling prices | F42: Platform sales volumes and average selling prices | G42: Platform sales volumes and average selling prices | H42: Platform sales volumes and average selling prices | I42: Platform sales volumes and average selling prices | J42: Platform sales volumes and average selling prices | K42: Platform sales volumes and average selling prices | L42: Platform sales volumes and average selling prices
A43: Desktop platform volume - CCG: change (%) | E43: -0.06 | F43: -0.06 | G43: -0.11 | H43: 0.08
A44: Desktop platform volume - CCG: revenue contribution (USD million) | E44: -608 | F44: -705 | G44: -1316 | H44: 851
...

Sheet Income Statement
A1: Intel Corporation — Income Statement | B1: Intel Corporation — Income Statement | C1: Intel Corporation — Income Statement | D1: Intel Corporation — Income Statement | E1: Intel Corporation — Income Statement | F1: Intel Corporation — Income Statement | G1: Intel Corporation — Income Statement | H1: Intel Corporation — Income Statement | I1: Intel Corporation — Income Statement | J1: Intel Corporation — Income Statement | K1: Intel Corporation — Income Statement | L1: Intel Corporation — Income Statement | M1: Intel Corporation — Income Statement | N1: Intel Corporation — Income Statement | O1: Intel Corporation — Income Statement | P1: Intel Corporation — Income Statement | Q1: Intel Corporation — Income Statement | R1: Intel Corporation — Income Statement | S1: Intel Corporation — Income Statement | T1: Intel Corporation — Income Statement | U1: Intel Corporation — Income Statement | V1: Intel Corporation — Income Statement | W1: Intel Corporation — Income Statement | X1: Intel Corporation — Income Statement | Y1: Intel Corporation — Income Statement | Z1: Intel Corporation — Income Statement | AA1: Intel Corporation — Income Statement
A2: USD million unless stated otherwise; annual FY2016–FY2025; latest interim 27 June 2026.
A3: Metric | C3: FY2016 | D3: FY2017 | E3: FY2018 | F3: FY2019 | G3: FY2020 | H3: FY2021 | I3: FY2022 | J3: FY2023 | K3: FY2024 | L3: FY2025 | N3: 1Q2023 | O3: 2Q2023 | P3: 3Q2023 | Q3: 4Q2023 | R3: 1Q2024 | S3: 2Q2024 | T3: 3Q2024 | U3: 4Q2024 | V3: 1Q2025 | W3: 2Q2025 | X3: 3Q2025 | Y3: 4Q2025 | Z3: 1Q2026 | AA3: 2Q2026
C4: 2016-12-31T00:00:00.000Z | D4: 2017-12-30T00:00:00.000Z | E4: 2018-12-29T00:00:00.000Z | F4: 2019-12-28T00:00:00.000Z | G4: 2020-12-26T00:00:00.000Z | H4: 2021-12-25T00:00:00.000Z | I4: 2022-12-31T00:00:00.000Z | J4: 2023-12-30T00:00:00.000Z | K4: 2024-12-28T00:00:00.000Z | L4: 2025-12-27T00:00:00.000Z | N4: 2023-04-01T00:00:00.000Z | O4: 2023-07-01T00:00:00.000Z | P4: 2023-09-30T00:00:00.000Z | Q4: 2023-12-30T00:00:00.000Z | R4: 2024-03-30T00:00:00.000Z | S4: 2024-06-29T00:00:00.000Z | T4: 2024-09-28T00:00:00.000Z | U4: 2024-12-28T00:00:00.000Z | V4: 2025-03-29T00:00:00.000Z | W4: 2025-06-28T00:00:00.000Z | X4: 2025-09-27T00:00:00.000Z | Y4: 2025-12-27T00:00:00.000Z | Z4: 2026-03-28T00:00:00.000Z | AA4: 2026-06-27T00:00:00.000Z
A5: Annual / discrete-quarter / instant as identified | C5: Annual | D5: Annual | E5: Annual | F5: Annual | G5: Annual | H5: Annual | I5: Annual | J5: Annual | K5: Annual | L5: Annual | N5: Quarter / note basis | O5: Quarter / note basis | P5: Quarter / note basis | Q5: Quarter / note basis | R5: Quarter / note basis | S5: Quarter / note basis | T5: Quarter / note basis | U5: Quarter / note basis | V5: Quarter / note basis | W5: Quarter / note basis | X5: Quarter / note basis | Y5: Quarter / note basis | Z5: Quarter / note basis | AA5: Quarter / note basis
A7: Revenue and gross profit | B7: Revenue and gross profit | C7: Revenue and gross profit | D7: Revenue and gross profit | E7: Revenue and gross profit | F7: Revenue and gross profit | G7: Revenue and gross profit | H7: Revenue and gross profit | I7: Revenue and gross profit | J7: Revenue and gross profit | K7: Revenue and gross profit | L7: Revenue and gross profit | M7: Revenue and gross profit | N7: Revenue and gross profit | O7: Revenue and gross profit | P7: Revenue and gross profit | Q7: Revenue and gross profit | R7: Revenue and gross profit | S7: Revenue and gross profit | T7: Revenue and gross profit | U7: Revenue and gross profit | V7: Revenue and gross profit | W7: Revenue and gross profit | X7: Revenue and gross profit | Y7: Revenue and gross profit | Z7: Revenue and gross profit | AA7: Revenue and gross profit
