Workbook

Sheet Cover
A1: Guidewire Software, Inc. — Cover
A2: $ in thousands except per-share data | USD | as of 2026-09-17
A4: Guidewire Software, Inc.
A6: Ticker | B6: GWRE
A7: Exchange | B7: NYSE
A8: Currency | B8: USD
A9: Units | B9: In thousands except per-share data
A10: Reporting Framework | B10: US GAAP
A11: Fiscal Year End | B11: July 31
A12: SIC Code | B12: 7372 — Prepackaged Software
A14: Model Date | B14: 2026-09-17
A15: As-of Date | B15: 2026-07-31
A16: Annual Periods | B16: FY2017 – FY2026 (10 years)
A17: Quarterly Periods | B17: 1Q2024 – 3Q2026 (9 quarters)
A19: Sheet Directory
A20: IS | B20: Income Statement — as-reported with margins, growth, EPS
A21: BS | B21: Balance Sheet — full detail with balance check
A22: CF | B22: Cash Flow — all line items with FCF analytics
A23: DM | B23: Derived Metrics — profitability, returns, leverage, quality
A24: SEG | B24: Segments — geographic revenue breakdown
A25: NS | B25: Note Schedules — debt, intangibles, leases, revenue contracts
A27: Color Legend
A28: Blue | B28: Input values from SEC filings
A29: Black | B29: Formulas / Calculations
A30: Green | B30: Cross-sheet links
A31: Grey Italic | B31: Memo / analytical annotations

Sheet Income Statement
A1: Guidewire Software, Inc. — Income Statement
A2: $ in thousands except per-share data | USD | as of 2026-09-17
C3: FY2017 | D3: FY2018 | E3: FY2019 | F3: FY2020 | G3: FY2021 | H3: FY2022 | I3: FY2023 | J3: FY2024 | K3: FY2025 | L3: FY2026 | M3: · | N3: · | O3: · | P3: · | Q3: · | R3: 1Q2024 | S3: 2Q2024 | T3: 3Q2024 | U3: 1Q2025 | V3: 2Q2025 | W3: 3Q2025 | X3: 1Q2026 | Y3: 2Q2026 | Z3: 3Q2026
A6: 1. INCOME STATEMENT
A7: Subscription and Support Revenue | C7: 68643 | D7: 110738 | E7: 150474 | F7: 203473 | G7: 252358 | H7: 343708 | I7: 429667 | J7: 549087 | K7: 731296 | L7: 970885 | R7: 127627 | S7: 131642 | T7: 137970 | U7: 169742 | V7: 177838 | W7: 181823 | X7: 222203 | Y7: 237209 | Z7: 244738
A8: yoy | D8: =D7/C7-1 -> 0.61324534 | E8: =E7/D7-1 -> 0.35882895 | F8: =F7/E7-1 -> 0.35221367 | G8: =G7/F7-1 -> 0.24025301 | H8: =H7/G7-1 -> 0.36198575 | I8: =I7/H7-1 -> 0.2500931 | J8: =J7/I7-1 -> 0.27793617 | K8: =K7/J7-1 -> 0.33183995 | L8: =L7/K7-1 -> 0.32762247
A9: License Revenue | C9: 271462 | D9: 275606 | E9: 320272 | F9: 331554 | G9: 303792 | H9: 258631 | I9: 265593 | J9: 250176 | K9: 251935 | L9: 234578 | R9: 34025 | S9: 71083 | T9: 56210 | U9: 37370 | V9: 63694 | W9: 57233 | X9: 41967 | Y9: 59528 | Z9: 55996
A10: yoy | D10: =D9/C9-1 -> 0.015265488 | E10: =E9/D9-1 -> 0.16206469 | F10: =F9/E9-1 -> 0.035226308 | G10: =G9/F9-1 -> -0.083732967 | H10: =H9/G9-1 -> -0.14865763 | I10: =I9/H9-1 -> 0.02691866 | J10: =J9/I9-1 -> -0.058047464 | K10: =K9/J9-1 -> 0.0070310501 | L10: =L9/K9-1 -> -0.068894755
A11: Services Revenue | C11: 174179 | D11: 266505 | E11: 248768 | F11: 207280 | G11: 187117 | H11: 210275 | I11: 210081 | J11: 181234 | K11: 219228 | L11: 269900 | R11: 45755 | S11: 38172 | T11: 46498 | U11: 55789 | V11: 47948 | W11: 54452 | X11: 68469 | Y11: 62358 | Z11: 71807
A12: yoy | D12: =D11/C11-1 -> 0.5300639 | E12: =E11/D11-1 -> -0.066554098 | F12: =F11/E11-1 -> -0.16677386 | G12: =G11/F11-1 -> -0.097274218 | H12: =H11/G11-1 -> 0.12376214 | I12: =I11/H11-1 -> -0.00092260136 | J12: =J11/I11-1 -> -0.1373137 | K12: =K11/J11-1 -> 0.20964058 | L12: =L11/K11-1 -> 0.23113836
A13: Total Revenue | C13: 509533 | D13: 652849 | E13: 719514 | F13: 742307 | G13: 743267 | H13: 812614 | I13: 905341 | J13: 980497 | K13: 1202459 | L13: 1475363 | R13: 207407 | S13: 240897 | T13: 240678 | U13: 262901 | V13: 289480 | W13: 293508 | X13: 332639 | Y13: 359095 | Z13: 372541
A14: Revenue Growth YoY | D14: =IF(N(C13)=0,"",D13/C13-1) -> 0.28126932 | E14: =IF(N(D13)=0,"",E13/D13-1) -> 0.10211397 | F14: =IF(N(E13)=0,"",F13/E13-1) -> 0.031678327 | G14: =IF(N(F13)=0,"",G13/F13-1) -> 0.0012932655 | H14: =IF(N(G13)=0,"",H13/G13-1) -> 0.093300254 | I14: =IF(N(H13)=0,"",I13/H13-1) -> 0.11410953 | J14: =IF(N(I13)=0,"",J13/I13-1) -> 0.083014025 | K14: =IF(N(J13)=0,"",K13/J13-1) -> 0.22637703 | L14: =IF(N(K13)=0,"",L13/K13-1) -> 0.22695493 | V14: =IF(N(R13)=0,"",V13/R13-1) -> 0.39570988 | W14: =IF(N(S13)=0,"",W13/S13-1) -> 0.21839624 | X14: =IF(N(T13)=0,"",X13/T13-1) -> 0.38209143 | Y14: =IF(N(U13)=0,"",Y13/U13-1) -> 0.36589439 | Z14: =IF(N(V13)=0,"",Z13/V13-1) -> 0.28693174
A16: Cost of Revenue - Subscription and Support | C16: 13397 | D16: 45134 | E16: 73597 | F16: 117158 | G16: 157488 | H16: 202832 | I16: 210507 | J16: 204794 | K16: 235106 | L16: 265203 | R16: 48054 | S16: 49934 | T16: 51185 | U16: 54024 | V16: 59096 | W16: 57411 | X16: 63927 | Y16: 63928 | Z16: 67882
A17: yoy | D17: =D16/C16-1 -> 2.3689632 | E17: =E16/D16-1 -> 0.63063323 | F17: =F16/E16-1 -> 0.59188554 | G17: =G16/F16-1 -> 0.34423599 | H17: =H16/G16-1 -> 0.28792035 | I17: =I16/H16-1 -> 0.037839197 | J17: =J16/I16-1 -> -0.02713924 | K17: =K16/J16-1 -> 0.14801215 | L17: =L16/K16-1 -> 0.1280146
A18: Cost of Revenue - License | C18: 17046 | D18: 5101 | E18: 7700 | F18: 11566 | G18: 10569 | H18: 8754 | I18: 6488 | J18: 4536 | K18: 3624 | L18: 1982 | R18: 1219 | S18: 1483 | T18: 837 | U18: 881 | V18: 942 | W18: 892 | X18: 644 | Y18: 442 | Z18: 374
A19: yoy | D19: =D18/C18-1 -> -0.70075091 | E19: =E18/D18-1 -> 0.50950794 | F19: =F18/E18-1 -> 0.50207792 | G19: =G18/F18-1 -> -0.086200934 | H19: =H18/G18-1 -> -0.17172864 | I19: =I18/H18-1 -> -0.2588531 | J19: =J18/I18-1 -> -0.30086313 | K19: =K18/J18-1 -> -0.2010582 | L19: =L18/K18-1 -> -0.45309051
A20: Cost of Revenue - Services | C20: 161116 | D20: 246548 | E20: 243053 | F20: 209291 | G20: 185650 | H20: 223852 | I20: 230135 | J20: 187806 | K20: 211676 | L20: 260810 | R20: 45842 | S20: 47074 | T20: 46429 | U20: 49604 | V20: 50290 | W20: 52507 | X20: 58546 | Y20: 63205 | Z20: 67639
A21: yoy | D21: =D20/C20-1 -> 0.5302515 | E21: =E20/D20-1 -> -0.014175739 | F21: =F20/E20-1 -> -0.13890797 | G21: =G20/F20-1 -> -0.11295756 | H21: =H20/G20-1 -> 0.20577431 | I21: =I20/H20-1 -> 0.028067652 | J21: =J20/I20-1 -> -0.18393117 | K21: =K20/J20-1 -> 0.12709924 | L21: =L20/K20-1 -> 0.2321189
A22: Total Cost of Revenue | C22: 191559 | D22: 296783 | E22: 324350 | F22: 338015 | G22: 353707 | H22: 435438 | I22: 447130 | J22: 397136 | K22: 450406 | L22: 527995 | R22: 95115 | S22: 98491 | T22: 98451 | U22: 104509 | V22: 110328 | W22: 110810 | X22: 123117 | Y22: 127574 | Z22: 135896
A24: Gross Profit - Subscription and Support | C24: 55246 | D24: 65604 | E24: 76877 | F24: 86315 | G24: 94870 | H24: 140876 | I24: 219160 | J24: 344293 | K24: 496190 | L24: 705682 | R24: 79573 | S24: 81708 | T24: 86785 | U24: 115718 | V24: 118742 | W24: 124412 | X24: 158276 | Y24: 173281 | Z24: 176856
A25: yoy | D25: =D24/C24-1 -> 0.18748869 | E25: =E24/D24-1 -> 0.17183403 | F25: =F24/E24-1 -> 0.12276754 | G25: =G24/F24-1 -> 0.099113711 | H25: =H24/G24-1 -> 0.48493728 | I25: =I24/H24-1 -> 0.55569437 | J25: =J24/I24-1 -> 0.57096642 | K25: =K24/J24-1 -> 0.44118527 | L25: =L24/K24-1 -> 0.42220117
A26: Gross Profit - License | C26: 254416 | D26: 270505 | E26: 312572 | F26: 319988 | G26: 293223 | H26: 249877 | I26: 259105 | J26: 245640 | K26: 248311 | L26: 232596 | R26: 32806 | S26: 69600 | T26: 55373 | U26: 36489 | V26: 62752 | W26: 56341 | X26: 41323 | Y26: 59086 | Z26: 55622
A27: yoy | D27: =D26/C26-1 -> 0.063238947 | E27: =E26/D26-1 -> 0.15551284 | F27: =F26/E26-1 -> 0.023725734 | G27: =G26/F26-1 -> -0.083643762 | H27: =H26/G26-1 -> -0.14782606 | I27: =I26/H26-1 -> 0.03693017 | J27: =J26/I26-1 -> -0.051967349 | K27: =K26/J26-1 -> 0.010873636 | L27: =L26/K26-1 -> -0.063287571
A28: Gross Profit - Services | C28: 13063 | D28: 19957 | E28: 5715 | F28: -2011 | G28: 1467 | H28: -13577 | I28: -20054 | J28: -6572 | K28: 7552 | L28: 9090 | R28: -87 | S28: -8902 | T28: 69 | U28: 6185 | V28: -2342 | W28: 1945 | X28: 9923 | Y28: -847 | Z28: 4167
A29: yoy | D29: =D28/C28-1 -> 0.52775013 | E29: =E28/D28-1 -> -0.71363431 | F29: =F28/E28-1 -> -1.351881 | G29: =G28/F28-1 -> -1.7294878 | H29: =H28/G28-1 -> -10.254942 | I29: =I28/H28-1 -> 0.47705679 | J29: =J28/I28-1 -> -0.67228483 | K29: =K28/J28-1 -> -2.1491175 | L29: =L28/K28-1 -> 0.20365466
A30: Total Gross Profit | C30: 317974 | D30: 356066 | E30: 395164 | F30: 404292 | G30: 389560 | H30: 377176 | I30: 458211 | J30: 583361 | K30: 752053 | L30: 947368 | R30: 112292 | S30: 142406 | T30: 142227 | U30: 158392 | V30: 179152 | W30: 182698 | X30: 209522 | Y30: 231521 | Z30: 236645
A31: Gross Margin | C31: =C30/C13 -> 0.62404987 | D31: =D30/D13 -> 0.5454033 | E31: =E30/E13 -> 0.54920961 | F31: =F30/F13 -> 0.54464258 | G31: =G30/G13 -> 0.52411852 | H31: =H30/H13 -> 0.46415149 | I31: =I30/I13 -> 0.50611979 | J31: =J30/J13 -> 0.59496459 | ... L31: =L30/L13 -> 0.64212536 | R31: =R30/R13 -> 0.54140892 | S31: =S30/S13 -> 0.59114891 | T31: =T30/T13 -> 0.59094309 | U31: =U30/U13 -> 0.60247774 | V31: =V30/V13 -> 0.61887522 | W31: =W30/W13 -> 0.62246344 | X31: =X30/X13 -> 0.62987804 | Y31: =Y30/Y13 -> 0.64473468 | Z31: =Z30/Z13 -> 0.63521867
A33: Research and Development | C33: 130323 | D33: 171657 | E33: 188541 | F33: 200575 | G33: 201465 | H33: 229230 | I33: 249746 | J33: 269381 | K33: 296160 | L33: 340097 | R33: 62469 | S33: 65458 | T33: 66134 | U33: 68880 | V33: 70268 | W33: 72915 | X33: 78317 | Y33: 83324 | Z33: 87868
A34: Sales and Marketing | C34: 109239 | D34: 124117 | E34: 130751 | F34: 142420 | G34: 150521 | H34: 182620 | I34: 188224 | J34: 199033 | K34: 230346 | L34: 258937 | R34: 44581 | S34: 49181 | T34: 50487 | U34: 51478 | V34: 55452 | W34: 57768 | X34: 64258 | Y34: 61475 | Z34: 68201
A35: General and Administrative | C35: 56551 | D35: 75916 | E35: 74401 | F35: 85183 | G35: 143158 | H35: 164773 | I35: 169731 | J35: 167520 | K35: 184479 | L35: 198460 | R35: 39023 | S35: 40177 | T35: 42302 | U35: 42754 | V35: 41709 | W35: 47547 | X35: 48469 | Y35: 48281 | Z35: 49939
A36: Total Operating Expenses | C36: 296113 | D36: 371690 | E36: 393693 | F36: 428178 | G36: 495144 | H36: 576623 | I36: 607701 | J36: 635934 | K36: 710985 | L36: 797494 | R36: 146073 | S36: 154816 | T36: 158923 | U36: 163112 | V36: 167429 | W36: 178230 | X36: 191044 | Y36: 193080 | Z36: 206008
A38: Income (Loss) from Operations | C38: 21861 | D38: -15624 | E38: 1471 | F38: -23886 | G38: -105584 | H38: -199447 | I38: -149490 | J38: -52573 | K38: 41068 | L38: 149874 | R38: -33781 | S38: -12410 | T38: -16696 | U38: -4720 | V38: 11723 | W38: 4468 | X38: 18478 | Y38: 38441 | Z38: 30637
A39: Operating Margin | C39: =C38/C13 -> 0.042903992 | D39: =D38/D13 -> -0.023932027 | E39: =E38/E13 -> 0.0020444355 | F39: =F38/F13 -> -0.032178061 | G39: =G38/G13 -> -0.14205393 | H39: =H38/H13 -> -0.24543879 | I39: =I38/I13 -> -0.1651201 | J39: =J38/J13 -> -0.053618726 | ... L39: =L38/L13 -> 0.10158449 | R39: =R38/R13 -> -0.162873 | S39: =S38/S13 -> -0.051515793 | T39: =T38/T13 -> -0.069370694 | U39: =U38/U13 -> -0.017953526 | V39: =V38/V13 -> 0.040496753 | W39: =W38/W13 -> 0.015222754 | X39: =X38/X13 -> 0.05554971 | Y39: =Y38/Y13 -> 0.10704967 | Z39: =Z38/Z13 -> 0.082237928
A41: Interest Income | C41: 5867 | D41: 13281 | E41: 30182 | F41: 24705 | G41: 7395 | H41: 6277 | I41: 24389 | J41: 43478 | K41: 56625 | L41: 48564 | R41: 10613 | S41: 10290 | T41: 10824 | U41: 13606 | V41: 15722 | W41: 13794 | X41: 14650 | Y41: 12487 | Z41: 11295
A42: Interest Expense | C42: -13 | D42: -6442 | E42: -17334 | F42: -17945 | G42: -18711 | H42: -19446 | I42: -6716 | J42: -6738 | K42: -13211 | L42: -13324 | R42: -1683 | S42: -1692 | T42: -1686 | U42: -2062 | V42: -4183 | W42: -3668 | X42: -3312 | Y42: -3334 | Z42: -3318
A43: Other Income (Expense), Net | C43: 811 | D43: 509 | E43: -1867 | F43: -7205 | G43: 12619 | H43: -17099 | I43: -2277 | J43: -11005 | K43: -35087 | L43: -20997 | R43: -13742 | S43: 10776 | T43: -6535 | U43: -4055 | V43: -66289 | W43: 34074 | X43: -5314 | Y43: 26958 | Z43: -18854
A44: Income (Loss) Before Income Taxes | C44: 28526 | D44: -8276 | E44: 12452 | F44: -24331 | G44: -104281 | H44: -229715 | I44: -134094 | J44: -26838 | K44: 49395 | L44: 164117 | R44: -38593 | S44: 6964 | T44: -14093 | U44: 2769 | V44: -43027 | W44: 48668 | X44: 24502 | Y44: 74552 | Z44: 19760
A45: Provision for (Benefit from) Income Taxes | C45: 10454 | D45: 18467 | E45: -8280 | F45: 2867 | G45: -37774 | H45: -49284 | I45: -22239 | J45: -20735 | K45: -20409 | L45: 24834 | R45: -11522 | S45: -2723 | T45: -8615 | U45: -6370 | V45: -5750 | W45: 2677 | X45: -6806 | Y45: 14442 | Z45: 3289
A46: Net Income (Loss) | C46: 18072 | D46: -26743 | E46: 20732 | F46: -27198 | G46: -66507 | H46: -180431 | I46: -111855 | J46: -6103 | K46: 69804 | L46: 139283 | R46: -27071 | S46: 9687 | T46: -5478 | U46: 9139 | V46: -37277 | W46: 45991 | X46: 31308 | Y46: 60110 | Z46: 16471
A47: Net Margin | C47: =C46/C13 -> 0.035467771 | D47: =D46/D13 -> -0.040963531 | E47: =E46/E13 -> 0.028813894 | F47: =F46/F13 -> -0.036639827 | G47: =G46/G13 -> -0.089479285 | H47: =H46/H13 -> -0.22203777 | I47: =I46/I13 -> -0.12355013 | J47: =J46/J13 -> -0.0062243944 | ... L47: =L46/L13 -> 0.094405919 | R47: =R46/R13 -> -0.13052115 | S47: =S46/S13 -> 0.040212207 | T47: =T46/T13 -> -0.022760701 | U47: =U46/U13 -> 0.034762135 | V47: =V46/V13 -> -0.12877228 | W47: =W46/W13 -> 0.1566942 | X47: =X46/X13 -> 0.094120052 | Y47: =Y46/Y13 -> 0.16739303 | Z47: =Z46/Z13 -> 0.044212583
...

Sheet Balance Sheet
A1: Guidewire Software, Inc. — Balance Sheet
A2: $ in thousands except per-share data | USD | as of 2026-09-17
C3: FY2017 | D3: FY2018 | E3: FY2019 | F3: FY2020 | G3: FY2021 | H3: FY2022 | I3: FY2023 | J3: FY2024 | K3: FY2025 | L3: FY2026 | M3: · | N3: · | O3: · | P3: · | Q3: · | R3: 1Q2024 | S3: 2Q2024 | T3: 3Q2024 | U3: 1Q2025 | V3: 2Q2025 | W3: 3Q2025 | X3: 1Q2026 | Y3: 2Q2026 | Z3: 3Q2026
A6: 1. BALANCE SHEET
A7: Cash and Cash Equivalents | C7: 263176 | D7: 437140 | E7: 254101 | F7: 366969 | G7: 384910 | H7: 606303 | I7: 401813 | J7: 547992 | K7: 697902 | L7: 372887 | R7: 301419 | S7: 349989 | T7: 359600 | U7: 823562 | V7: 697488 | W7: 510321 | X7: 492038 | Y7: 407946 | Z7: 294634
A8: Short-term Investments | C8: 310027 | D8: 630008 | E8: 870136 | F8: 766527 | G8: 734517 | H8: 369865 | I8: 396872 | J8: 455576 | K8: 451541 | L8: 380175 | R8: 411528 | S8: 427634 | T8: 422691 | U8: 514767 | V8: 471473 | W8: 410116 | X8: 519861 | Y8: 511221 | Z8: 454900
A9: Accounts Receivable, Net | C9: 79433 | D9: 124849 | E9: 138443 | F9: 114242 | G9: 104068 | H9: 143797 | I9: 151034 | J9: 137339 | K9: 140639 | L9: 193720 | R9: 93083 | S9: 128242 | T9: 104344 | U9: 97475 | V9: 123001 | W9: 147296 | X9: 94600 | Y9: 162937 | Z9: 138853
A10: Unbilled Accounts Receivable, Net (Current) | C10: 0 | D10: 0 | E10: 36728 | F10: 49491 | G10: 79061 | H10: 71515 | I10: 87752 | J10: 87031 | K10: 130959 | L10: 140832 | R10: 6883 | S10: 6796 | T10: 7288 | U10: 648 | V10: 801 | W10: 791 | X10: 83 | Y10: 83 | Z10: 83
A11: Prepaid Expenses and Other Current Assets | C11: 26604 | D11: 30464 | E11: 35566 | F11: 45989 | G11: 52729 | H11: 61223 | I11: 62132 | J11: 67596 | K11: 86374 | L11: 99363 | R11: 61537 | S11: 63799 | T11: 69345 | U11: 72059 | V11: 71683 | W11: 78311 | X11: 87509 | Y11: 89434 | Z11: 102255
A12: Total Current Assets | C12: 679240 | D12: 1222461 | E12: 1334974 | F12: 1343218 | G12: 1355285 | H12: 1252703 | I12: 1099603 | J12: 1295534 | K12: 1507415 | L12: 1186977 | R12: 976798 | S12: 1060630 | T12: 1081511 | U12: 1637292 | V12: 1478126 | W12: 1312969 | X12: 1357024 | Y12: 1346188 | Z12: 1215410
A13: Unbilled Accounts Receivable, Net (Non-current) | C13: 0 | D13: 0 | E13: 9375 | F13: 34737 | G13: 24361 | H13: 13914 | I13: 11112 | J13: 4157 | K13: 670 | L13: 0
A14: Long-term Investments | C14: 114585 | D14: 190952 | E14: 213524 | F14: 300771 | G14: 227164 | H14: 187507 | I14: 128782 | J14: 125885 | K14: 333754 | L14: 462223 | R14: 140644 | S14: 155061 | T14: 151891 | U14: 142119 | V14: 243473 | W14: 323305 | X14: 397365 | Y14: 432255 | Z14: 397267
A15: Property and Equipment, Net | C15: 14376 | D15: 18595 | E15: 65809 | F15: 65235 | G15: 80061 | H15: 80740 | I15: 54499 | J15: 55409 | K15: 60436 | L15: 67800 | R15: 55280 | S15: 55109 | T15: 55025 | U15: 55215 | V15: 54079 | W15: 55561 | X15: 65199 | Y15: 65315 | Z15: 66647
A16: Operating Lease Assets | F16: 103797 | G16: 97447 | H16: 90287 | I16: 52373 | J16: 43750 | K16: 39309 | L16: 34404 | R16: 50402 | S16: 48327 | T16: 46267 | U16: 41993 | V16: 43142 | W16: 41767 | X16: 37636 | Y16: 37430 | Z16: 36443
A17: Intangible Assets, Net | C17: 71315 | D17: 95654 | E17: 66542 | F17: 39708 | G17: 19743 | H17: 21361 | I17: 14473 | J17: 9005 | K17: 12042 | L17: 16406 | R17: 13106 | S17: 11739 | T17: 10372 | U17: 7638 | V17: 6360 | W17: 13482 | X17: 10704 | Y17: 19833 | Z17: 17727
A18: Goodwill | C18: 141851 | D18: 340877 | E18: 340877 | F18: 340877 | G18: 340877 | H18: 372192 | I18: 372214 | J18: 372214 | K18: 393978 | L18: 423267 | R18: 372214 | S18: 372214 | T18: 372214 | U18: 372214 | V18: 372214 | W18: 393592 | X18: 394300 | Y18: 422113 | Z18: 421111
A19: Deferred Tax Assets, Net | C19: 37430 | D19: 90369 | E19: 90308 | F19: 101565 | G19: 138428 | H19: 191461 | I19: 226875 | J19: 253085 | K19: 297234 | L19: 286585 | R19: 239822 | S19: 243424 | T19: 255547 | U19: 274875 | V19: 281034 | W19: 281344 | X19: 305494 | Y19: 292842 | Z19: 293911
A20: Other Assets | C20: 20104 | D20: 22525 | E20: 45554 | F20: 34944 | G20: 38479 | H20: 56732 | I20: 67957 | J20: 67255 | K20: 76261 | L20: 99283 | R20: 64448 | S20: 60220 | T20: 59910 | U20: 64703 | V20: 63560 | W20: 65260 | X20: 71526 | Y20: 75686 | Z20: 86533
A21: TOTAL ASSETS | C21: 1078901 | D21: 1981433 | E21: 2166963 | F21: 2364852 | G21: 2321845 | H21: 2266897 | I21: 2027888 | J21: 2226294 | K21: 2721099 | L21: 2576946 | R21: 1919597 | S21: 2013520 | T21: 2040025 | U21: 2596697 | V21: 2542789 | W21: 2488071 | X21: 2639331 | Y21: 2691745 | Z21: 2535132
A23: Accounts Payable | C23: 13416 | D23: 30635 | E23: 34255 | F23: 22634 | G23: 27830 | H23: 40440 | I23: 34627 | J23: 15209 | K23: 28797 | L23: 38074 | R23: 19210 | S23: 21999 | T23: 23514 | U23: 31394 | V23: 24921 | W23: 28952 | X23: 33557 | Y23: 28946 | Z23: 34972
A24: Accrued Employee Compensation | C24: 48882 | D24: 60135 | E24: 73365 | F24: 58547 | G24: 102137 | H24: 90962 | I24: 103980 | J24: 109084 | K24: 140613 | L24: 146331 | R24: 46686 | S24: 62669 | T24: 76538 | U24: 51860 | V24: 60601 | W24: 89230 | X24: 70300 | Y24: 84697 | Z24: 117531
A25: Deferred Revenue (Current) | C25: 91243 | D25: 127107 | E25: 108304 | F25: 118311 | G25: 138699 | H25: 170776 | I25: 206923 | J25: 281855 | K25: 340253 | L25: 437181 | R25: 3915 | S25: 4072 | T25: 3210 | U25: 3187 | V25: 3109 | W25: 4937 | X25: 2464 | Y25: 4977 | Z25: 3718
A26: Other Current Liabilities | C26: 10075 | D26: 20280 | E26: 16348 | F26: 25706 | G26: 31648 | H26: 35340 | I26: 27731 | J26: 32584 | K26: 35139 | L26: 42911 | R26: 25376 | S26: 27325 | T26: 24599 | U26: 29199 | V26: 29341 | W26: 28946 | X26: 32464 | Y26: 37694 | Z26: 44032
A27: Total Current Liabilities | C27: 163616 | D27: 238157 | E27: 232272 | F27: 225198 | G27: 300314 | H27: 337518 | I27: 373261 | J27: 837635 | K27: 544802 | L27: 664497 | R27: 262375 | S27: 307076 | T27: 704807 | U27: 615237 | V27: 558681 | W27: 405914 | X27: 389858 | Y27: 458983 | Z27: 497175
A28: Convertible Senior Notes, Net (Current) | C28: 0 | D28: 0 | E28: 0 | F28: 0 | G28: 0 | H28: 0 | I28: 0 | J28: 398903 | K28: 0 | L28: 0
A29: Lease Liabilities (Non-current) | F29: 119408 | G29: 115374 | H29: 105123 | I29: 42972 | J29: 34721 | K29: 30687 | L29: 25206 | R29: 40872 | S29: 39074 | T29: 37120 | U29: 32934 | V29: 33983 | W29: 33013 | X29: 29057 | Y29: 28673 | Z29: 27031
A30: Convertible Senior Notes, Net (Non-current) | D30: 305128 | E30: 317322 | F30: 330208 | G30: 343825 | H30: 358216 | I30: 397171 | J30: 0 | K30: 674568 | L30: 678094 | R30: 397601 | S30: 398033 | T30: 398467 | U30: 671820 | V30: 672828 | W30: 673696 | X30: 675443 | Y30: 676323 | Z30: 677206
A31: Deferred Revenue (Non-current) | C31: 19892 | D31: 23758 | E31: 23527 | F31: 14685 | G31: 7237 | H31: 7500 | I31: 5988 | J31: 3628 | K31: 4533 | L31: 1633
A32: Other Liabilities | C32: 2112 | D32: 774 | E32: 19641 | F32: 18585 | G32: 10201 | H32: 6883 | I32: 9030 | J32: 7578 | K32: 9279 | L32: 13828 | R32: 9185 | S32: 9152 | T32: 9522 | U32: 5490 | V32: 5452 | W32: 7936 | X32: 9091 | Y32: 12171 | Z32: 12858
A33: Total Liabilities | C33: 185620 | D33: 567817 | E33: 592762 | F33: 708084 | G33: 776951 | H33: 815240 | I33: 828422 | J33: 883562 | K33: 1263869 | L33: 1383258 | R33: 713948 | S33: 757407 | T33: 754659 | U33: 1328668 | V33: 1274053 | W33: 1125496 | X33: 1105913 | Y33: 1181127 | Z33: 1217987
A35: Common Stock | C35: 8 | D35: 8 | E35: 8 | F35: 8 | G35: 8 | H35: 8 | I35: 8 | J35: 8 | K35: 8 | L35: 8 | R35: 8 | S35: 8 | T35: 8 | U35: 8 | V35: 8 | W35: 8 | X35: 9 | Y35: 8 | Z35: 8
A36: Additional Paid-in Capital | C36: 830014 | D36: 1296380 | E36: 1391904 | F36: 1499050 | G36: 1617204 | H36: 1755476 | I36: 1831267 | J36: 1979021 | K36: 2020393 | L36: 2230308 | R36: 1867467 | S36: 1903873 | T36: 1940691 | U36: 1894904 | V36: 1936293 | W36: 1977364 | X36: 2064255 | Y36: 2124589 | Z36: 2169769
A37: Accumulated Other Comprehensive Income (Loss) | C37: -5796 | D37: -7748 | E37: -7758 | F37: -5246 | G37: -6218 | H37: -19845 | I37: -13859 | J37: -12244 | K37: -8922 | L37: -12233 | R37: -16805 | S37: -12434 | T37: -14521 | U37: -11969 | V37: -15374 | W37: -8597 | X37: -7905 | Y37: -2959 | Z37: -7105
A38: Retained Earnings (Accumulated Deficit) | C38: 69055 | D38: 124976 | E38: 190047 | F38: 162956 | G38: -66100 | H38: -283982 | I38: -617950 | J38: -624053 | K38: -554249 | L38: -1024396 | R38: -645021 | S38: -635334 | T38: -640812 | U38: -614914 | V38: -652191 | W38: -606200 | X38: -522941 | Y38: -611021 | Z38: -845527
A39: Total Stockholders' Equity | C39: 893281 | D39: 1413616 | E39: 1574201 | F39: 1656768 | G39: 1544894 | H39: 1451657 | I39: 1199466 | J39: 1342732 | K39: 1457230 | L39: 1193687 | R39: 1205649 | S39: 1256113 | T39: 1285366 | U39: 1268029 | V39: 1268736 | W39: 1362575 | X39: 1533418 | Y39: 1510618 | Z39: 1317145
A40: TOTAL LIABILITIES AND STOCKHOLDERS' EQUITY | C40: 1078901 | D40: 1981433 | E40: 2166963 | F40: 2364852 | G40: 2321845 | H40: 2266897 | I40: 2027888 | J40: 2226294 | K40: 2721099 | L40: 2576946
A42: 2. BS CHECK
A43: BS Check (should be 0) | C43: =C21-C33-C39 -> 0 | D43: =D21-D33-D39 -> 0 | E43: =E21-E33-E39 -> 0 | F43: =F21-F33-F39 -> 0 | G43: =G21-G33-G39 -> 0 | H43: =H21-H33-H39 -> 0 | I43: =I21-I33-I39 -> 0 | J43: =J21-J33-J39 -> 0 | ... L43: =L21-L33-L39 -> 1 | R43: =R21-R33-R39 -> 0 | S43: =S21-S33-S39 -> 0 | T43: =T21-T33-T39 -> 0 | U43: =U21-U33-U39 -> 0 | V43: =V21-V33-V39 -> 0 | W43: =W21-W33-W39 -> 0 | X43: =X21-X33-X39 -> 0 | Y43: =Y21-Y33-Y39 -> 0 | Z43: =Z21-Z33-Z39 -> 0

Sheet Cash Flow Statement
A1: Guidewire Software, Inc. — Cash Flow Statement
A2: $ in thousands except per-share data | USD | as of 2026-09-17
C3: FY2017 | D3: FY2018 | E3: FY2019 | F3: FY2020 | G3: FY2021 | H3: FY2022 | I3: FY2023 | J3: FY2024 | K3: FY2025 | L3: FY2026 | M3: · | N3: · | O3: · | P3: · | Q3: · | R3: 1Q2024 | S3: 2Q2024 | T3: 3Q2024 | U3: 1Q2025 | V3: 2Q2025 | W3: 3Q2025 | X3: 1Q2026 | Y3: 2Q2026 | Z3: 3Q2026
A6: 1. CASH FLOW STATEMENT
A7: Net Income (Loss) | C7: 18072 | D7: -26743 | E7: 20732 | F7: -27198 | G7: -66507 | H7: -180431 | I7: -111855 | J7: -6103 | K7: 69804 | L7: 139283 | R7: -27071 | S7: -17384 | T7: -22862 | U7: 9139 | V7: -28138 | W7: 17853 | X7: 31308 | Y7: 91418 | Z7: 107888
A9: Depreciation and Amortization | C9: 18725 | D9: 35611 | E9: 39953 | F9: 42641 | G9: 36955 | H9: 33540 | I9: 24838 | J9: 22309 | K9: 23758 | L9: 27952 | R9: 5442 | S9: 10934 | T9: 16525 | U9: 5845 | V9: 11573 | W9: 17538 | X9: 6362 | Y9: 13402 | Z9: 20632
A10: Amortization of Debt Issuance Costs | D10: 4512 | E10: 12194 | F10: 12886 | G10: 13617 | H10: 14391 | I10: 1703 | J10: 1732 | K10: 3758 | L10: 3939 | R10: 430 | S10: 862 | T10: 1296 | U10: 545 | V10: 1724 | W10: 2782 | X10: 980 | Y10: 1964 | Z10: 2947
A11: Amortization of Contract Costs | E11: 5515 | F11: 9892 | G11: 11442 | H11: 14456 | I11: 17966 | J11: 28413 | K11: 30893 | L11: 35011 | R11: 4064 | S11: 8745 | T11: 12869 | U11: 7780 | V11: 15233 | W11: 22518 | X11: 8802 | Y11: 17304 | Z11: 25812
A12: Stock-based Compensation | C12: 71794 | D12: 89614 | E12: 91516 | F12: 101817 | G12: 115009 | H12: 137011 | I12: 142842 | J12: 146460 | K12: 161556 | L12: 181799 | R12: 36097 | S12: 72524 | T12: 109174 | U12: 38060 | V12: 79008 | W12: 119365 | X12: 43316 | Y12: 90074 | Z12: 135015
A13: Changes to Allowances / Credit Losses | D13: 1062 | E13: 670 | F13: 367 | G13: 226 | H13: 2597 | I13: -131 | J13: 526 | K13: 526 | L13: 2516 | R13: 128 | S13: -194 | T13: -142 | U13: 1257 | V13: 1090 | W13: 1107 | X13: 2358 | Y13: 2337 | Z13: 2542
A14: Deferred Income Tax | C14: -1227 | D14: 14150 | E14: -13998 | F14: -11859 | G14: -35789 | H14: -54115 | I14: -27516 | J14: -26847 | K14: -31780 | L14: 8981 | R14: -13220 | S14: -17390 | T14: -29294 | U14: -7955 | V14: -14159 | W14: -15851 | X14: -8527 | Y14: 1466 | Z14: 922
A15: Amortization of Premium on Securities | C15: 1462 | D15: -1418 | E15: -7757 | F15: -1882 | G15: 6567 | H15: 5498 | I15: -4858 | J15: -12894 | K15: -10326 | L15: -6254 | R15: -2927 | S15: -6223 | T15: -9492 | U15: -3228 | V15: -6549 | W15: -8613 | X15: -1948 | Y15: -4008 | Z15: -5377
A16: Gains/Losses on Strategic Investments | J16: -1803 | K16: -3671 | L16: -632 | S16: -1758 | T16: -1758 | V16: -3671 | W16: -3671 | Z16: -632
A17: Changes in Fair Value of Strategic Investments | F17: 10672 | H17: -1545 | I17: 802 | J17: 1957 | K17: 2130 | L17: -489 | T17: -298 | U17: -53 | V17: 238 | W17: 341 | X17: 60 | Y17: 45 | Z17: -554
A18: Loss on Retirement of Debt | K18: 53565 | V18: 53565 | W18: 53565
A19: Accelerated Depreciation (Lease) | I19: 26921
A20: Gain from Lease Assignment | I20: -18419
A21: Excess Tax Benefit from Stock Options/RSUs | C21: -9067
A22: Other Non-cash Items | C22: 49 | E22: 189 | F22: 739 | G22: 863 | H22: 63 | I22: 164 | J22: -74 | K22: 186 | L22: -88 | R22: -29 | S22: -46 | T22: -74 | U22: 286 | V22: 3 | W22: 56 | X22: 17 | Y22: 7 | Z22: 18
A24: Change in Accounts Receivable | C24: -9750 | D24: -40832 | E24: -15057 | F24: 23878 | G24: 10820 | H24: -42545 | I24: -7301 | J24: 12631 | K24: -3348 | L24: -54868 | R24: 57193 | S24: 22547 | T24: 46276 | U24: 38609 | V24: 12817 | W24: -10609 | X24: 43676 | Y24: -23665 | Z24: 276
A25: Change in Unbilled Accounts Receivable | E25: -17341 | F25: -38125 | G25: -19194 | H25: 18106 | I25: -13435 | J25: 7676 | K25: -38930 | L25: -9193 | R25: -17250 | S25: 1102 | T25: -33955 | U25: -38889 | V25: -24094 | W25: -74471 | X25: -31470 | Y25: -43095 | Z25: -93214
A26: Change in Prepaid Expenses and Other Assets | C26: -9463 | D26: -2737 | E26: -21766 | F26: -18564 | G26: -16764 | H26: -23390 | I26: -22613 | J26: -44131 | K26: -58054 | L26: -55354 | R26: -6560 | S26: -12531 | T26: -22082 | U26: -8932 | V26: -17207 | W26: -29305 | X26: -4710 | Y26: -14281 | Z26: -33815
A27: Change in Operating Lease Assets | F27: -10784 | G27: 6350 | H27: 7160 | I27: -19000 | J27: 8623 | K27: 4441 | L27: 4905 | R27: 1971 | S27: 4046 | T27: 6106 | U27: 1757 | V27: 608 | W27: 1983 | X27: 1673 | Y27: 1879 | Z27: 2866
A28: Change in Accounts Payable | C28: 1311 | D28: 16794 | E28: -5521 | F28: -1209 | G28: 3627 | H28: 13580 | I28: -6080 | J28: -18933 | K28: 11399 | L28: 11712 | R28: -16982 | S28: -12212 | T28: -10538 | U28: 16206 | V28: 10150 | W28: 13589 | X28: 4264 | Y28: 1813 | Z28: 7910
A29: Change in Accrued Employee Compensation | C29: 7138 | D29: 9230 | E29: 13825 | F29: -15624 | G29: 41526 | H29: -8942 | I29: 12440 | J29: 6453 | K29: 30090 | L29: 6196 | R29: -54576 | S29: -39657 | T29: -25604 | U29: -56545 | V29: -46878 | W29: -20600 | X29: -69630 | Y29: -57657 | Z29: -23578
A30: Change in Deferred Revenue | C30: 41553 | D30: 32358 | E30: -9628 | F30: 1165 | G30: 12940 | H30: 31564 | I30: 34635 | J30: 72572 | K30: 56617 | L30: 93675 | R30: -37893 | S30: -13756 | T30: -28012 | U30: -58107 | V30: -17522 | W30: -24876 | X30: -88785 | Y30: -32515 | Z30: -40781
A31: Change in Lease Liabilities | F31: 18678 | G31: -3346 | H31: -9637 | I31: 9548 | J31: -7389 | K31: -2891 | L31: -4232 | R31: -1601 | S31: -3245 | T31: -5136 | U31: -1685 | V31: -151 | W31: -1121 | X31: -1537 | Y31: -1330 | Z31: -3572
A32: Change in Other Liabilities | C32: 6612 | D32: 8858 | E32: 22600 | F32: 15576 | G32: -6755 | H32: 4699 | I32: -2256 | J32: 4570 | K32: 1144 | L32: 4857 | R32: 701 | S32: 804 | T32: -1028 | U32: -6395 | V32: -3954 | W32: -5544 | X32: -3607 | Y32: -510 | Z32: 525
A33: Net Cash from Operating Activities | C33: 138759 | D33: 140459 | E33: 116126 | F33: 113066 | G33: 111587 | H33: -37940 | I33: 38395 | J33: 195748 | K33: 300867 | L33: 389716 | R33: -72083 | S33: -2832 | T33: 1971 | U33: -62305 | V33: 23686 | W33: 56036 | X33: -67398 | Y33: 44648 | Z33: 105830
A35: Purchases of Available-for-Sale Securities | C35: -462035 | D35: -859657 | E35: -1209312 | F35: -1280755 | G35: -1033095 | H35: -519536 | I35: -506115 | J35: -615935 | K35: -858571 | L35: -859150 | R35: -160239 | S35: -314846 | T35: -453441 | U35: -211649 | V35: -429742 | W35: -672330 | X35: -318525 | Y35: -535549 | Z35: -644915
A36: Maturities and Sales of AFS Securities | C36: 547630 | D36: 390025 | E36: 879532 | F36: 1168720 | G36: 1128524 | H36: 908914 | I36: 547094 | J36: 576886 | K36: 665012 | L36: 806049 | R36: 137386 | S36: 267416 | T36: 416299 | U36: 139896 | V36: 303111 | W36: 529887 | X36: 189726 | Y36: 382943 | Z36: 582638
A37: Purchases of Property and Equipment | C37: -5886 | D37: -9398 | E37: -44921 | F37: -21377 | G37: -19008 | H37: -9510 | I37: -5821 | J37: -6362 | K37: -5741 | L37: -12056 | R37: -998 | S37: -3990 | T37: -4668 | U37: -843 | V37: -1633 | W37: -2336 | X37: -4878 | Y37: -8162 | Z37: -9934
A38: Capitalized Software Development Costs | C38: -784 | D38: -2613 | E38: -3936 | F38: -4283 | G38: -9846 | H38: -12266 | I38: -11606 | J38: -12165 | K38: -14714 | L38: -19003 | R38: -3692 | S38: -6058 | T38: -9429 | U38: -4233 | V38: -7156 | W38: -10972 | X38: -5088 | Y38: -8192 | Z38: -13939
A39: Acquisition of Strategic Investments | C39: -4677 | F39: -2156 | G39: -2384 | H39: -11560 | I39: -10840 | J39: -1336 | K39: -1772 | L39: -14646 | R39: -250 | S39: -250 | T39: -336 | U39: -772 | V39: -772 | W39: -1772 | Y39: -2348 | Z39: -14590
A40: Sale of Strategic Investments | S40: 6508 | T40: 6508 | V40: 5671 | W40: 5671 | Z40: 781
A41: Acquisitions, Net of Cash | C41: -187590 | D41: -130059 | H41: -43830 | K41: -26850 | L41: -37953 | W41: -26724 | Y41: -33252 | Z41: -33453
A42: Net Cash from Investing Activities | C42: -113342 | D42: -537584 | E42: -301433 | F42: -5801 | G42: 64191 | H42: 312212 | I42: 12712 | J42: -52359 | K42: -236965 | L42: -135977 | R42: -27793 | S42: -51220 | T42: -45067 | U42: -77601 | V42: -130521 | W42: -178576 | X42: -138765 | Y42: -204560 | Z42: -133412
A44: Proceeds from Convertible Notes | D44: 387239 | K44: 671840 | U44: 672750 | V44: 671840 | W44: 671840
A45: Payment for Retirement of Convertible Notes | K45: -353535 | U45: -200394 | V45: -353535 | W45: -353535
A46: Payment for Maturity of Convertible Notes | K46: -179061 | W46: -179061
...

Sheet Derived Metrics
A1: Guidewire Software, Inc. — Derived Metrics
A2: $ in thousands except per-share data | USD | as of 2026-09-17
C3: FY2017 | D3: FY2018 | E3: FY2019 | F3: FY2020 | G3: FY2021 | H3: FY2022 | I3: FY2023 | J3: FY2024 | K3: FY2025 | L3: FY2026 | M3: · | N3: · | O3: · | P3: · | Q3: · | R3: 1Q2024 | S3: 2Q2024 | T3: 3Q2024 | U3: 1Q2025 | V3: 2Q2025 | W3: 3Q2025 | X3: 1Q2026 | Y3: 2Q2026 | Z3: 3Q2026
A6: 1. PROFITABILITY
A7: Gross Margin | C7: ='Income Statement'!C30/'Income Statement'!C13 -> 0.62404987 | D7: ='Income Statement'!D30/'Income Statement'!D13 -> 0.5454033 | E7: ='Income Statement'!E30/'Income Statement'!E13 -> 0.54920961 | F7: ='Income Statement'!F30/'Income Statement'!F13 -> 0.54464258 | G7: ='Income Statement'!G30/'Income Statement'!G13 -> 0.52411852 | H7: ='Income Statement'!H30/'Income Statement'!H13 -> 0.46415149 | I7: ='Income Statement'!I30/'Income Statement'!I13 -> 0.50611979 | J7: ='Income Statement'!J30/'Income Statement'!J13 -> 0.59496459 | ... L7: ='Income Statement'!L30/'Income Statement'!L13 -> 0.64212536 | R7: ='Income Statement'!R30/'Income Statement'!R13 -> 0.54140892 | S7: ='Income Statement'!S30/'Income Statement'!S13 -> 0.59114891 | T7: ='Income Statement'!T30/'Income Statement'!T13 -> 0.59094309 | U7: ='Income Statement'!U30/'Income Statement'!U13 -> 0.60247774 | V7: ='Income Statement'!V30/'Income Statement'!V13 -> 0.61887522 | W7: ='Income Statement'!W30/'Income Statement'!W13 -> 0.62246344 | X7: ='Income Statement'!X30/'Income Statement'!X13 -> 0.62987804 | Y7: ='Income Statement'!Y30/'Income Statement'!Y13 -> 0.64473468 | Z7: ='Income Statement'!Z30/'Income Statement'!Z13 -> 0.63521867
A8: Operating Margin | C8: ='Income Statement'!C38/'Income Statement'!C13 -> 0.042903992 | D8: ='Income Statement'!D38/'Income Statement'!D13 -> -0.023932027 | E8: ='Income Statement'!E38/'Income Statement'!E13 -> 0.0020444355 | F8: ='Income Statement'!F38/'Income Statement'!F13 -> -0.032178061 | G8: ='Income Statement'!G38/'Income Statement'!G13 -> -0.14205393 | H8: ='Income Statement'!H38/'Income Statement'!H13 -> -0.24543879 | I8: ='Income Statement'!I38/'Income Statement'!I13 -> -0.1651201 | J8: ='Income Statement'!J38/'Income Statement'!J13 -> -0.053618726 | ... L8: ='Income Statement'!L38/'Income Statement'!L13 -> 0.10158449 | R8: ='Income Statement'!R38/'Income Statement'!R13 -> -0.162873 | S8: ='Income Statement'!S38/'Income Statement'!S13 -> -0.051515793 | T8: ='Income Statement'!T38/'Income Statement'!T13 -> -0.069370694 | U8: ='Income Statement'!U38/'Income Statement'!U13 -> -0.017953526 | V8: ='Income Statement'!V38/'Income Statement'!V13 -> 0.040496753 | W8: ='Income Statement'!W38/'Income Statement'!W13 -> 0.015222754 | X8: ='Income Statement'!X38/'Income Statement'!X13 -> 0.05554971 | Y8: ='Income Statement'!Y38/'Income Statement'!Y13 -> 0.10704967 | Z8: ='Income Statement'!Z38/'Income Statement'!Z13 -> 0.082237928
A9: Net Margin | C9: ='Income Statement'!C46/'Income Statement'!C13 -> 0.035467771 | D9: ='Income Statement'!D46/'Income Statement'!D13 -> -0.040963531 | E9: ='Income Statement'!E46/'Income Statement'!E13 -> 0.028813894 | F9: ='Income Statement'!F46/'Income Statement'!F13 -> -0.036639827 | G9: ='Income Statement'!G46/'Income Statement'!G13 -> -0.089479285 | H9: ='Income Statement'!H46/'Income Statement'!H13 -> -0.22203777 | I9: ='Income Statement'!I46/'Income Statement'!I13 -> -0.12355013 | J9: ='Income Statement'!J46/'Income Statement'!J13 -> -0.0062243944 | ... L9: ='Income Statement'!L46/'Income Statement'!L13 -> 0.094405919 | R9: ='Income Statement'!R46/'Income Statement'!R13 -> -0.13052115 | S9: ='Income Statement'!S46/'Income Statement'!S13 -> 0.040212207 | T9: ='Income Statement'!T46/'Income Statement'!T13 -> -0.022760701 | U9: ='Income Statement'!U46/'Income Statement'!U13 -> 0.034762135 | V9: ='Income Statement'!V46/'Income Statement'!V13 -> -0.12877228 | W9: ='Income Statement'!W46/'Income Statement'!W13 -> 0.1566942 | X9: ='Income Statement'!X46/'Income Statement'!X13 -> 0.094120052 | Y9: ='Income Statement'!Y46/'Income Statement'!Y13 -> 0.16739303 | Z9: ='Income Statement'!Z46/'Income Statement'!Z13 -> 0.044212583
A10: Effective Tax Rate | C10: ='Income Statement'!C45/'Income Statement'!C44 -> 0.36647269 | D10: ='Income Statement'!D45/'Income Statement'!D44 -> -2.231392 | E10: ='Income Statement'!E45/'Income Statement'!E44 -> -0.66495342 | F10: ='Income Statement'!F45/'Income Statement'!F44 -> -0.11783322 | G10: ='Income Statement'!G45/'Income Statement'!G44 -> 0.36223281 | H10: ='Income Statement'!H45/'Income Statement'!H44 -> 0.21454411 | I10: ='Income Statement'!I45/'Income Statement'!I44 -> 0.16584635 | J10: ='Income Statement'!J45/'Income Statement'!J44 -> 0.77259855 | ... L10: ='Income Statement'!L45/'Income Statement'!L44 -> 0.15131888 | R10: ='Income Statement'!R45/'Income Statement'!R44 -> 0.29855155 | S10: ='Income Statement'!S45/'Income Statement'!S44 -> -0.39101091 | T10: ='Income Statement'!T45/'Income Statement'!T44 -> 0.61129639 | U10: ='Income Statement'!U45/'Income Statement'!U44 -> -2.3004695 | V10: ='Income Statement'!V45/'Income Statement'!V44 -> 0.13363702 | W10: ='Income Statement'!W45/'Income Statement'!W44 -> 0.055005342 | X10: ='Income Statement'!X45/'Income Statement'!X44 -> -0.27777324 | Y10: ='Income Statement'!Y45/'Income Statement'!Y44 -> 0.19371714 | Z10: ='Income Statement'!Z45/'Income Statement'!Z44 -> 0.16644737
A11: Subscription & Support Gross Margin | C11: ='Income Statement'!C24/'Income Statement'!C7 -> 0.80483079 | D11: ='Income Statement'!D24/'Income Statement'!D7 -> 0.59242536 | E11: ='Income Statement'!E24/'Income Statement'!E7 -> 0.51089889 | F11: ='Income Statement'!F24/'Income Statement'!F7 -> 0.42420862 | G11: ='Income Statement'!G24/'Income Statement'!G7 -> 0.37593419 | H11: ='Income Statement'!H24/'Income Statement'!H7 -> 0.40987117 | I11: ='Income Statement'!I24/'Income Statement'!I7 -> 0.51006943 | J11: ='Income Statement'!J24/'Income Statement'!J7 -> 0.62702814 | ... L11: ='Income Statement'!L24/'Income Statement'!L7 -> 0.72684406 | R11: ='Income Statement'!R24/'Income Statement'!R7 -> 0.62348092 | S11: ='Income Statement'!S24/'Income Statement'!S7 -> 0.62068337 | T11: ='Income Statement'!T24/'Income Statement'!T7 -> 0.62901355 | U11: ='Income Statement'!U24/'Income Statement'!U7 -> 0.68172874 | V11: ='Income Statement'!V24/'Income Statement'!V7 -> 0.66769757 | W11: ='Income Statement'!W24/'Income Statement'!W7 -> 0.68424787 | X11: ='Income Statement'!X24/'Income Statement'!X7 -> 0.71230361 | Y11: ='Income Statement'!Y24/'Income Statement'!Y7 -> 0.73049926 | Z11: ='Income Statement'!Z24/'Income Statement'!Z7 -> 0.722634
A13: 2. RETURNS
A14: Return on Assets (ROA) | C14: ='Income Statement'!C46/'Balance Sheet'!C21 -> 0.016750378 | D14: ='Income Statement'!D46/'Balance Sheet'!D21 -> -0.013496798 | E14: ='Income Statement'!E46/'Balance Sheet'!E21 -> 0.0095673069 | F14: ='Income Statement'!F46/'Balance Sheet'!F21 -> -0.011500931 | G14: ='Income Statement'!G46/'Balance Sheet'!G21 -> -0.028644031 | H14: ='Income Statement'!H46/'Balance Sheet'!H21 -> -0.079593824 | I14: ='Income Statement'!I46/'Balance Sheet'!I21 -> -0.055158372 | J14: ='Income Statement'!J46/'Balance Sheet'!J21 -> -0.0027413271 | ... L14: ='Income Statement'!L46/'Balance Sheet'!L21 -> 0.054049639 | R14: ='Income Statement'!R46/'Balance Sheet'!R21 -> -0.014102439 | S14: ='Income Statement'!S46/'Balance Sheet'!S21 -> 0.0048109778 | T14: ='Income Statement'!T46/'Balance Sheet'!T21 -> -0.0026852612 | U14: ='Income Statement'!U46/'Balance Sheet'!U21 -> 0.0035194711 | V14: ='Income Statement'!V46/'Balance Sheet'!V21 -> -0.014659887 | W14: ='Income Statement'!W46/'Balance Sheet'!W21 -> 0.018484601 | X14: ='Income Statement'!X46/'Balance Sheet'!X21 -> 0.011862097 | Y14: ='Income Statement'!Y46/'Balance Sheet'!Y21 -> 0.022331239 | Z14: ='Income Statement'!Z46/'Balance Sheet'!Z21 -> 0.0064970976
A15: Return on Equity (ROE) | C15: ='Income Statement'!C46/'Balance Sheet'!C39 -> 0.020231036 | D15: ='Income Statement'!D46/'Balance Sheet'!D39 -> -0.01891815 | E15: ='Income Statement'!E46/'Balance Sheet'!E39 -> 0.013169856 | F15: ='Income Statement'!F46/'Balance Sheet'!F39 -> -0.0164163 | G15: ='Income Statement'!G46/'Balance Sheet'!G39 -> -0.043049556 | H15: ='Income Statement'!H46/'Balance Sheet'!H39 -> -0.12429314 | I15: ='Income Statement'!I46/'Balance Sheet'!I39 -> -0.093253998 | J15: ='Income Statement'!J46/'Balance Sheet'!J39 -> -0.0045452108 | ... L15: ='Income Statement'!L46/'Balance Sheet'!L39 -> 0.11668302 | R15: ='Income Statement'!R46/'Balance Sheet'!R39 -> -0.022453467 | S15: ='Income Statement'!S46/'Balance Sheet'!S39 -> 0.0077118858 | T15: ='Income Statement'!T46/'Balance Sheet'!T39 -> -0.0042618211 | U15: ='Income Statement'!U46/'Balance Sheet'!U39 -> 0.0072072484 | V15: ='Income Statement'!V46/'Balance Sheet'!V39 -> -0.029381211 | W15: ='Income Statement'!W46/'Balance Sheet'!W39 -> 0.033753004 | X15: ='Income Statement'!X46/'Balance Sheet'!X39 -> 0.020417133 | Y15: ='Income Statement'!Y46/'Balance Sheet'!Y39 -> 0.039791661 | Z15: ='Income Statement'!Z46/'Balance Sheet'!Z39 -> 0.012505077
A16: Asset Turnover | C16: ='Income Statement'!C13/'Balance Sheet'!C21 -> 0.47227039 | D16: ='Income Statement'!D13/'Balance Sheet'!D21 -> 0.32948326 | E16: ='Income Statement'!E13/'Balance Sheet'!E21 -> 0.33203797 | F16: ='Income Statement'!F13/'Balance Sheet'!F21 -> 0.31389152 | G16: ='Income Statement'!G13/'Balance Sheet'!G21 -> 0.32011913 | H16: ='Income Statement'!H13/'Balance Sheet'!H21 -> 0.35846975 | I16: ='Income Statement'!I13/'Balance Sheet'!I21 -> 0.44644527 | J16: ='Income Statement'!J13/'Balance Sheet'!J21 -> 0.44041667 | ... L16: ='Income Statement'!L13/'Balance Sheet'!L21 -> 0.57252383 | R16: ='Income Statement'!R13/'Balance Sheet'!R21 -> 0.10804716 | S16: ='Income Statement'!S13/'Balance Sheet'!S21 -> 0.11963974 | T16: ='Income Statement'!T13/'Balance Sheet'!T21 -> 0.11797797 | U16: ='Income Statement'!U13/'Balance Sheet'!U21 -> 0.10124439 | V16: ='Income Statement'!V13/'Balance Sheet'!V21 -> 0.1138435 | W16: ='Income Statement'!W13/'Balance Sheet'!W21 -> 0.11796609 | X16: ='Income Statement'!X13/'Balance Sheet'!X21 -> 0.12603156 | Y16: ='Income Statement'!Y13/'Balance Sheet'!Y21 -> 0.13340602 | Z16: ='Income Statement'!Z13/'Balance Sheet'!Z21 -> 0.14695132
A18: 3. SOLVENCY
A19: Equity Ratio | C19: ='Balance Sheet'!C39/'Balance Sheet'!C21 -> 0.82795456 | D19: ='Balance Sheet'!D39/'Balance Sheet'!D21 -> 0.71343114 | E19: ='Balance Sheet'!E39/'Balance Sheet'!E21 -> 0.72645495 | F19: ='Balance Sheet'!F39/'Balance Sheet'!F21 -> 0.70057999 | G19: ='Balance Sheet'!G39/'Balance Sheet'!G21 -> 0.66537344 | H19: ='Balance Sheet'!H39/'Balance Sheet'!H21 -> 0.64037184 | I19: ='Balance Sheet'!I39/'Balance Sheet'!I21 -> 0.59148533 | J19: ='Balance Sheet'!J39/'Balance Sheet'!J21 -> 0.6031243 | ... L19: ='Balance Sheet'!L39/'Balance Sheet'!L21 -> 0.4632177 | R19: ='Balance Sheet'!R39/'Balance Sheet'!R21 -> 0.62807402 | S19: ='Balance Sheet'!S39/'Balance Sheet'!S21 -> 0.62383935 | T19: ='Balance Sheet'!T39/'Balance Sheet'!T21 -> 0.63007365 | U19: ='Balance Sheet'!U39/'Balance Sheet'!U21 -> 0.48832382 | V19: ='Balance Sheet'!V39/'Balance Sheet'!V21 -> 0.49895449 | W19: ='Balance Sheet'!W39/'Balance Sheet'!W21 -> 0.54764313 | X19: ='Balance Sheet'!X39/'Balance Sheet'!X21 -> 0.58098738 | Y19: ='Balance Sheet'!Y39/'Balance Sheet'!Y21 -> 0.56120398 | Z19: ='Balance Sheet'!Z39/'Balance Sheet'!Z21 -> 0.51955677
A20: Debt to Assets | C20: ='Balance Sheet'!C30/'Balance Sheet'!C21 -> 0 | D20: ='Balance Sheet'!D30/'Balance Sheet'!D21 -> 0.1539936 | E20: ='Balance Sheet'!E30/'Balance Sheet'!E21 -> 0.14643628 | F20: ='Balance Sheet'!F30/'Balance Sheet'!F21 -> 0.13963157 | G20: ='Balance Sheet'!G30/'Balance Sheet'!G21 -> 0.14808267 | H20: ='Balance Sheet'!H30/'Balance Sheet'!H21 -> 0.15802041 | I20: ='Balance Sheet'!I30/'Balance Sheet'!I21 -> 0.1958545 | J20: ='Balance Sheet'!J30/'Balance Sheet'!J21 -> 0 | ... L20: ='Balance Sheet'!L30/'Balance Sheet'!L21 -> 0.26313861 | R20: ='Balance Sheet'!R30/'Balance Sheet'!R21 -> 0.20712733 | S20: ='Balance Sheet'!S30/'Balance Sheet'!S21 -> 0.19768018 | T20: ='Balance Sheet'!T30/'Balance Sheet'!T21 -> 0.19532457 | U20: ='Balance Sheet'!U30/'Balance Sheet'!U21 -> 0.25872098 | V20: ='Balance Sheet'!V30/'Balance Sheet'!V21 -> 0.26460237 | W20: ='Balance Sheet'!W30/'Balance Sheet'!W21 -> 0.27077041 | X20: ='Balance Sheet'!X30/'Balance Sheet'!X21 -> 0.25591447 | Y20: ='Balance Sheet'!Y30/'Balance Sheet'!Y21 -> 0.2512582 | Z20: ='Balance Sheet'!Z30/'Balance Sheet'!Z21 -> 0.2671285
A22: 4. LIQUIDITY
A23: Current Ratio | C23: ='Balance Sheet'!C12/'Balance Sheet'!C27 -> 4.1514277 | D23: ='Balance Sheet'!D12/'Balance Sheet'!D27 -> 5.1330047 | E23: ='Balance Sheet'!E12/'Balance Sheet'!E27 -> 5.7474599 | F23: ='Balance Sheet'!F12/'Balance Sheet'!F27 -> 5.9646089 | G23: ='Balance Sheet'!G12/'Balance Sheet'!G27 -> 4.5128932 | H23: ='Balance Sheet'!H12/'Balance Sheet'!H27 -> 3.7115146 | I23: ='Balance Sheet'!I12/'Balance Sheet'!I27 -> 2.945936 | J23: ='Balance Sheet'!J12/'Balance Sheet'!J27 -> 1.546657 | ... L23: ='Balance Sheet'!L12/'Balance Sheet'!L27 -> 1.7862789 | R23: ='Balance Sheet'!R12/'Balance Sheet'!R27 -> 3.7229081 | S23: ='Balance Sheet'!S12/'Balance Sheet'!S27 -> 3.4539658 | T23: ='Balance Sheet'!T12/'Balance Sheet'!T27 -> 1.5344782 | U23: ='Balance Sheet'!U12/'Balance Sheet'!U27 -> 2.6612379 | V23: ='Balance Sheet'!V12/'Balance Sheet'!V27 -> 2.6457424 | W23: ='Balance Sheet'!W12/'Balance Sheet'!W27 -> 3.234599 | X23: ='Balance Sheet'!X12/'Balance Sheet'!X27 -> 3.4808161 | Y23: ='Balance Sheet'!Y12/'Balance Sheet'!Y27 -> 2.9329801 | Z23: ='Balance Sheet'!Z12/'Balance Sheet'!Z27 -> 2.4446322
A24: Cash Ratio | C24: =('Balance Sheet'!C7+'Balance Sheet'!C8)/'Balance Sheet'!C27 -> 3.5033432 | D24: =('Balance Sheet'!D7+'Balance Sheet'!D8)/'Balance Sheet'!D27 -> 4.4808593 | E24: =('Balance Sheet'!E7+'Balance Sheet'!E8)/'Balance Sheet'!E27 -> 4.8401745 | F24: =('Balance Sheet'!F7+'Balance Sheet'!F8)/'Balance Sheet'!F27 -> 5.0333307 | G24: =('Balance Sheet'!G7+'Balance Sheet'!G8)/'Balance Sheet'!G27 -> 3.7275219 | H24: =('Balance Sheet'!H7+'Balance Sheet'!H8)/'Balance Sheet'!H27 -> 2.8921954 | I24: =('Balance Sheet'!I7+'Balance Sheet'!I8)/'Balance Sheet'!I27 -> 2.1397494 | J24: =('Balance Sheet'!J7+'Balance Sheet'!J8)/'Balance Sheet'!J27 -> 1.198097 | ... L24: =('Balance Sheet'!L7+'Balance Sheet'!L8)/'Balance Sheet'!L27 -> 1.1332813 | R24: =('Balance Sheet'!R7+'Balance Sheet'!R8)/'Balance Sheet'!R27 -> 2.7172825 | S24: =('Balance Sheet'!S7+'Balance Sheet'!S8)/'Balance Sheet'!S27 -> 2.532347 | T24: =('Balance Sheet'!T7+'Balance Sheet'!T8)/'Balance Sheet'!T27 -> 1.1099365 | U24: =('Balance Sheet'!U7+'Balance Sheet'!U8)/'Balance Sheet'!U27 -> 2.1753064 | V24: =('Balance Sheet'!V7+'Balance Sheet'!V8)/'Balance Sheet'!V27 -> 2.0923586 | W24: =('Balance Sheet'!W7+'Balance Sheet'!W8)/'Balance Sheet'!W27 -> 2.2675665 | X24: =('Balance Sheet'!X7+'Balance Sheet'!X8)/'Balance Sheet'!X27 -> 2.5955579 | Y24: =('Balance Sheet'!Y7+'Balance Sheet'!Y8)/'Balance Sheet'!Y27 -> 2.0026167 | Z24: =('Balance Sheet'!Z7+'Balance Sheet'!Z8)/'Balance Sheet'!Z27 -> 1.5075859
A26: 5. COVERAGE
A27: Interest Coverage | C27: ='Income Statement'!C38/'Income Statement'!C42*-1 -> 1681.6154 | D27: ='Income Statement'!D38/'Income Statement'!D42*-1 -> -2.4253337 | E27: ='Income Statement'!E38/'Income Statement'!E42*-1 -> 0.084862121 | F27: ='Income Statement'!F38/'Income Statement'!F42*-1 -> -1.3310671 | G27: ='Income Statement'!G38/'Income Statement'!G42*-1 -> -5.6428839 | H27: ='Income Statement'!H38/'Income Statement'!H42*-1 -> -10.256454 | I27: ='Income Statement'!I38/'Income Statement'!I42*-1 -> -22.258785 | J27: ='Income Statement'!J38/'Income Statement'!J42*-1 -> -7.8024636 | ... L27: ='Income Statement'!L38/'Income Statement'!L42*-1 -> 11.248424 | R27: ='Income Statement'!R38/'Income Statement'!R42*-1 -> -20.071895 | S27: ='Income Statement'!S38/'Income Statement'!S42*-1 -> -7.3345154 | T27: ='Income Statement'!T38/'Income Statement'!T42*-1 -> -9.9027284 | U27: ='Income Statement'!U38/'Income Statement'!U42*-1 -> -2.2890398 | V27: ='Income Statement'!V38/'Income Statement'!V42*-1 -> 2.8025341 | W27: ='Income Statement'!W38/'Income Statement'!W42*-1 -> 1.2181025 | X27: ='Income Statement'!X38/'Income Statement'!X42*-1 -> 5.5791063 | Y27: ='Income Statement'!Y38/'Income Statement'!Y42*-1 -> 11.529994 | Z27: ='Income Statement'!Z38/'Income Statement'!Z42*-1 -> 9.2335744
A29: 6. CASH CONVERSION
A30: CFO Margin | C30: ='Cash Flow Statement'!C33/'Income Statement'!C13 -> 0.27232584 | D30: ='Cash Flow Statement'!D33/'Income Statement'!D13 -> 0.21514776 | E30: ='Cash Flow Statement'!E33/'Income Statement'!E13 -> 0.16139505 | F30: ='Cash Flow Statement'!F33/'Income Statement'!F13 -> 0.15231703 | G30: ='Cash Flow Statement'!G33/'Income Statement'!G13 -> 0.15013044 | H30: ='Cash Flow Statement'!H33/'Income Statement'!H13 -> -0.046688834 | I30: ='Cash Flow Statement'!I33/'Income Statement'!I13 -> 0.042409435 | J30: ='Cash Flow Statement'!J33/'Income Statement'!J13 -> 0.19964161 | ... L30: ='Cash Flow Statement'!L33/'Income Statement'!L13 -> 0.26414923 | R30: ='Cash Flow Statement'!R33/'Income Statement'!R13 -> -0.34754372 | S30: ='Cash Flow Statement'!S33/'Income Statement'!S13 -> -0.011756062 | T30: ='Cash Flow Statement'!T33/'Income Statement'!T13 -> 0.008189365 | U30: ='Cash Flow Statement'!U33/'Income Statement'!U13 -> -0.23699035 | V30: ='Cash Flow Statement'!V33/'Income Statement'!V13 -> 0.081822578 | W30: ='Cash Flow Statement'!W33/'Income Statement'!W13 -> 0.19091814 | X30: ='Cash Flow Statement'!X33/'Income Statement'!X13 -> -0.20261605 | Y30: ='Cash Flow Statement'!Y33/'Income Statement'!Y13 -> 0.12433479 | Z30: ='Cash Flow Statement'!Z33/'Income Statement'!Z13 -> 0.28407612
A31: Capex Intensity | C31: =('Cash Flow Statement'!C37+'Cash Flow Statement'!C38)/'Income Statement'!C13*-1 -> 0.013090418 | D31: =('Cash Flow Statement'!D37+'Cash Flow Statement'!D38)/'Income Statement'!D13*-1 -> 0.018397822 | E31: =('Cash Flow Statement'!E37+'Cash Flow Statement'!E38)/'Income Statement'!E13*-1 -> 0.067902779 | F31: =('Cash Flow Statement'!F37+'Cash Flow Statement'!F38)/'Income Statement'!F13*-1 -> 0.034567908 | G31: =('Cash Flow Statement'!G37+'Cash Flow Statement'!G38)/'Income Statement'!G13*-1 -> 0.038820505 | H31: =('Cash Flow Statement'!H37+'Cash Flow Statement'!H38)/'Income Statement'!H13*-1 -> 0.026797471 | I31: =('Cash Flow Statement'!I37+'Cash Flow Statement'!I38)/'Income Statement'!I13*-1 -> 0.019249101 | J31: =('Cash Flow Statement'!J37+'Cash Flow Statement'!J38)/'Income Statement'!J13*-1 -> 0.018895519 | ... L31: =('Cash Flow Statement'!L37+'Cash Flow Statement'!L38)/'Income Statement'!L13*-1 -> 0.021051768 | R31: =('Cash Flow Statement'!R37+'Cash Flow Statement'!R38)/'Income Statement'!R13*-1 -> 0.022612544 | S31: =('Cash Flow Statement'!S37+'Cash Flow Statement'!S38)/'Income Statement'!S13*-1 -> 0.041710773 | T31: =('Cash Flow Statement'!T37+'Cash Flow Statement'!T38)/'Income Statement'!T13*-1 -> 0.058572034 | U31: =('Cash Flow Statement'!U37+'Cash Flow Statement'!U38)/'Income Statement'!U13*-1 -> 0.019307648 | V31: =('Cash Flow Statement'!V37+'Cash Flow Statement'!V38)/'Income Statement'!V13*-1 -> 0.030361338 | W31: =('Cash Flow Statement'!W37+'Cash Flow Statement'!W38)/'Income Statement'!W13*-1 -> 0.045341183 | X31: =('Cash Flow Statement'!X37+'Cash Flow Statement'!X38)/'Income Statement'!X13*-1 -> 0.029960408 | Y31: =('Cash Flow Statement'!Y37+'Cash Flow Statement'!Y38)/'Income Statement'!Y13*-1 -> 0.045542266 | Z31: =('Cash Flow Statement'!Z37+'Cash Flow Statement'!Z38)/'Income Statement'!Z13*-1 -> 0.064081537
A32: FCF Margin | C32: =('Cash Flow Statement'!C33+'Cash Flow Statement'!C37+'Cash Flow Statement'!C38)/'Income Statement'!C13 -> 0.25923542 | D32: =('Cash Flow Statement'!D33+'Cash Flow Statement'!D37+'Cash Flow Statement'!D38)/'Income Statement'!D13 -> 0.19674994 | E32: =('Cash Flow Statement'!E33+'Cash Flow Statement'!E37+'Cash Flow Statement'!E38)/'Income Statement'!E13 -> 0.093492274 | F32: =('Cash Flow Statement'!F33+'Cash Flow Statement'!F37+'Cash Flow Statement'!F38)/'Income Statement'!F13 -> 0.11774913 | G32: =('Cash Flow Statement'!G33+'Cash Flow Statement'!G37+'Cash Flow Statement'!G38)/'Income Statement'!G13 -> 0.11130993 | H32: =('Cash Flow Statement'!H33+'Cash Flow Statement'!H37+'Cash Flow Statement'!H38)/'Income Statement'!H13 -> -0.073486305 | I32: =('Cash Flow Statement'!I33+'Cash Flow Statement'!I37+'Cash Flow Statement'!I38)/'Income Statement'!I13 -> 0.023160334 | J32: =('Cash Flow Statement'!J33+'Cash Flow Statement'!J37+'Cash Flow Statement'!J38)/'Income Statement'!J13 -> 0.18074609 | ... L32: =('Cash Flow Statement'!L33+'Cash Flow Statement'!L37+'Cash Flow Statement'!L38)/'Income Statement'!L13 -> 0.24309746 | R32: =('Cash Flow Statement'!R33+'Cash Flow Statement'!R37+'Cash Flow Statement'!R38)/'Income Statement'!R13 -> -0.37015626 | S32: =('Cash Flow Statement'!S33+'Cash Flow Statement'!S37+'Cash Flow Statement'!S38)/'Income Statement'!S13 -> -0.053466834 | T32: =('Cash Flow Statement'!T33+'Cash Flow Statement'!T37+'Cash Flow Statement'!T38)/'Income Statement'!T13 -> -0.050382669 | U32: =('Cash Flow Statement'!U33+'Cash Flow Statement'!U37+'Cash Flow Statement'!U38)/'Income Statement'!U13 -> -0.256298 | V32: =('Cash Flow Statement'!V33+'Cash Flow Statement'!V37+'Cash Flow Statement'!V38)/'Income Statement'!V13 -> 0.051461241 | W32: =('Cash Flow Statement'!W33+'Cash Flow Statement'!W37+'Cash Flow Statement'!W38)/'Income Statement'!W13 -> 0.14557695 | X32: =('Cash Flow Statement'!X33+'Cash Flow Statement'!X37+'Cash Flow Statement'!X38)/'Income Statement'!X13 -> -0.23257646 | Y32: =('Cash Flow Statement'!Y33+'Cash Flow Statement'!Y37+'Cash Flow Statement'!Y38)/'Income Statement'!Y13 -> 0.07879252 | Z32: =('Cash Flow Statement'!Z33+'Cash Flow Statement'!Z37+'Cash Flow Statement'!Z38)/'Income Statement'!Z13 -> 0.21999458
A33: FCF Conversion (FCF/Net Income) | C33: =('Cash Flow Statement'!C33+'Cash Flow Statement'!C37+'Cash Flow Statement'!C38)/'Income Statement'!C46 -> 7.3090416 | D33: =('Cash Flow Statement'!D33+'Cash Flow Statement'!D37+'Cash Flow Statement'!D38)/'Income Statement'!D46 -> -4.8030513 | E33: =('Cash Flow Statement'!E33+'Cash Flow Statement'!E37+'Cash Flow Statement'!E38)/'Income Statement'!E46 -> 3.2446942 | F33: =('Cash Flow Statement'!F33+'Cash Flow Statement'!F37+'Cash Flow Statement'!F38)/'Income Statement'!F46 -> -3.2136922 | G33: =('Cash Flow Statement'!G33+'Cash Flow Statement'!G37+'Cash Flow Statement'!G38)/'Income Statement'!G46 -> -1.2439743 | H33: =('Cash Flow Statement'!H33+'Cash Flow Statement'!H37+'Cash Flow Statement'!H38)/'Income Statement'!H46 -> 0.33096308 | I33: =('Cash Flow Statement'!I33+'Cash Flow Statement'!I37+'Cash Flow Statement'!I38)/'Income Statement'!I46 -> -0.18745698 | J33: =('Cash Flow Statement'!J33+'Cash Flow Statement'!J37+'Cash Flow Statement'!J38)/'Income Statement'!J46 -> -29.038342 | ... L33: =('Cash Flow Statement'!L33+'Cash Flow Statement'!L37+'Cash Flow Statement'!L38)/'Income Statement'!L46 -> 2.5750235 | R33: =('Cash Flow Statement'!R33+'Cash Flow Statement'!R37+'Cash Flow Statement'!R38)/'Income Statement'!R46 -> 2.8359868 | S33: =('Cash Flow Statement'!S33+'Cash Flow Statement'!S37+'Cash Flow Statement'!S38)/'Income Statement'!S46 -> -1.329617 | T33: =('Cash Flow Statement'!T33+'Cash Flow Statement'!T37+'Cash Flow Statement'!T38)/'Income Statement'!T46 -> 2.2135816 | U33: =('Cash Flow Statement'!U33+'Cash Flow Statement'!U37+'Cash Flow Statement'!U38)/'Income Statement'!U46 -> -7.3729073 | V33: =('Cash Flow Statement'!V33+'Cash Flow Statement'!V37+'Cash Flow Statement'!V38)/'Income Statement'!V46 -> -0.3996298 | W33: =('Cash Flow Statement'!W33+'Cash Flow Statement'!W37+'Cash Flow Statement'!W38)/'Income Statement'!W46 -> 0.92905134 | X33: =('Cash Flow Statement'!X33+'Cash Flow Statement'!X37+'Cash Flow Statement'!X38)/'Income Statement'!X46 -> -2.4710617 | Y33: =('Cash Flow Statement'!Y33+'Cash Flow Statement'!Y37+'Cash Flow Statement'!Y38)/'Income Statement'!Y46 -> 0.47070371 | Z33: =('Cash Flow Statement'!Z33+'Cash Flow Statement'!Z37+'Cash Flow Statement'!Z38)/'Income Statement'!Z46 -> 4.9758363
A34: D&A / Capex | C34: ='Cash Flow Statement'!C9/('Cash Flow Statement'!C37+'Cash Flow Statement'!C38)*-1 -> 2.8073463 | D34: ='Cash Flow Statement'!D9/('Cash Flow Statement'!D37+'Cash Flow Statement'!D38)*-1 -> 2.9648655 | E34: ='Cash Flow Statement'!E9/('Cash Flow Statement'!E37+'Cash Flow Statement'!E38)*-1 -> 0.81775385 | F34: ='Cash Flow Statement'!F9/('Cash Flow Statement'!F37+'Cash Flow Statement'!F38)*-1 -> 1.6617693 | G34: ='Cash Flow Statement'!G9/('Cash Flow Statement'!G37+'Cash Flow Statement'!G38)*-1 -> 1.2807583 | H34: ='Cash Flow Statement'!H9/('Cash Flow Statement'!H37+'Cash Flow Statement'!H38)*-1 -> 1.5402278 | I34: ='Cash Flow Statement'!I9/('Cash Flow Statement'!I37+'Cash Flow Statement'!I38)*-1 -> 1.4252597 | J34: ='Cash Flow Statement'!J9/('Cash Flow Statement'!J37+'Cash Flow Statement'!J38)*-1 -> 1.2041345 | ... L34: ='Cash Flow Statement'!L9/('Cash Flow Statement'!L37+'Cash Flow Statement'!L38)*-1 -> 0.89996458 | R34: ='Cash Flow Statement'!R9/('Cash Flow Statement'!R37+'Cash Flow Statement'!R38)*-1 -> 1.1603412 | S34: ='Cash Flow Statement'!S9/('Cash Flow Statement'!S37+'Cash Flow Statement'!S38)*-1 -> 1.0881768 | T34: ='Cash Flow Statement'!T9/('Cash Flow Statement'!T37+'Cash Flow Statement'!T38)*-1 -> 1.1722352 | U34: ='Cash Flow Statement'!U9/('Cash Flow Statement'!U37+'Cash Flow Statement'!U38)*-1 -> 1.1514972 | V34: ='Cash Flow Statement'!V9/('Cash Flow Statement'!V37+'Cash Flow Statement'!V38)*-1 -> 1.3167596 | W34: ='Cash Flow Statement'!W9/('Cash Flow Statement'!W37+'Cash Flow Statement'!W38)*-1 -> 1.3178539 | X34: ='Cash Flow Statement'!X9/('Cash Flow Statement'!X37+'Cash Flow Statement'!X38)*-1 -> 0.63837046 | Y34: ='Cash Flow Statement'!Y9/('Cash Flow Statement'!Y37+'Cash Flow Statement'!Y38)*-1 -> 0.8194937 | Z34: ='Cash Flow Statement'!Z9/('Cash Flow Statement'!Z37+'Cash Flow Statement'!Z38)*-1 -> 0.86423994
A36: 7. EARNINGS QUALITY
A37: CFO / Net Income | C37: ='Cash Flow Statement'!C33/'Income Statement'!C46 -> 7.6781208 | D37: ='Cash Flow Statement'!D33/'Income Statement'!D46 -> -5.2521781 | E37: ='Cash Flow Statement'!E33/'Income Statement'!E46 -> 5.6012927 | F37: ='Cash Flow Statement'!F33/'Income Statement'!F46 -> -4.1571439 | G37: ='Cash Flow Statement'!G33/'Income Statement'!G46 -> -1.6778234 | H37: ='Cash Flow Statement'!H33/'Income Statement'!H46 -> 0.21027429 | I37: ='Cash Flow Statement'!I33/'Income Statement'!I46 -> -0.3432569 | J37: ='Cash Flow Statement'!J33/'Income Statement'!J46 -> -32.074062 | ... L37: ='Cash Flow Statement'!L33/'Income Statement'!L46 -> 2.7980156 | R37: ='Cash Flow Statement'!R33/'Income Statement'!R46 -> 2.6627387 | S37: ='Cash Flow Statement'!S33/'Income Statement'!S46 -> -0.29235057 | T37: ='Cash Flow Statement'!T33/'Income Statement'!T46 -> -0.35980285 | U37: ='Cash Flow Statement'!U33/'Income Statement'!U46 -> -6.8174855 | V37: ='Cash Flow Statement'!V33/'Income Statement'!V46 -> -0.63540521 | W37: ='Cash Flow Statement'!W33/'Income Statement'!W46 -> 1.2184123 | X37: ='Cash Flow Statement'!X33/'Income Statement'!X46 -> -2.1527405 | Y37: ='Cash Flow Statement'!Y33/'Income Statement'!Y46 -> 0.74277159 | Z37: ='Cash Flow Statement'!Z33/'Income Statement'!Z46 -> 6.4252322
