Workbook

Sheet Cover
A1: Mondelez International, Inc. — Cover
A2: $ in millions except per-share data | USD | as of 2026-09-15
A4: Mondelez International, Inc.
A5: Financial Model — Historical As-Reported Statements
A7: Ticker | B7: MDLZ
A8: CIK | B8: 0001103982
A9: Exchange | B9: Nasdaq
A10: Fiscal Year End | B10: December 31
A11: Currency / Units | B11: USD, $ in millions except per-share data
A12: Reporting Framework | B12: US GAAP
A14: Annual periods covered | B14: FY2016 - FY2025 (10 fiscal years)
A15: Quarterly periods covered | B15: 3Q2024, 1Q2025, 2Q2025, 3Q2025, 1Q2026, 2Q2026
A16: Model date | B16: 2026-09-15
A18: Scope note
A19: This workbook is a mechanical financial model / data-prep artifact built directly from SEC filings (10-K and 10-Q source HTML). It contains no valuation opinion, price target, investment thesis, or buy/sell/hold recommendation.

Sheet Income Statement
A1: Mondelez International, Inc. — Income Statement
A2: $ in millions except per-share data | USD | as of 2026-09-15
C3: FY2016 | D3: FY2017 | E3: FY2018 | F3: FY2019 | G3: FY2020 | H3: FY2021 | I3: FY2022 | J3: FY2023 | K3: FY2024 | L3: FY2025 | M3: · | N3: · | O3: · | P3: 3Q2024 | Q3: 1Q2025 | R3: 2Q2025 | S3: 3Q2025 | T3: 1Q2026 | U3: 2Q2026
C4: 2016-12-31 | D4: 2017-12-31 | E4: 2018-12-31 | F4: 2019-12-31 | G4: 2020-12-31 | H4: 2021-12-31 | I4: 2022-12-31 | J4: 2023-12-31 | K4: 2024-12-31 | L4: 2025-12-31 | P4: 2024-09-30 | Q4: 2025-03-31 | R4: 2025-06-30 | S4: 2025-09-30 | T4: 2026-03-31 | U4: 2026-06-30
A6: CONTENTS
A7: =HYPERLINK("#'Income Statement'!A11","1. INCOME STATEMENT — AS REPORTED")
A8: =HYPERLINK("#'Income Statement'!A40","2. EPS & SHARE COUNT")
A9: =HYPERLINK("#'Income Statement'!A48","3. CHECKS")
A11: 1. INCOME STATEMENT — AS REPORTED
A12: Net revenues | C12: 25923 | D12: 25896 | E12: 25938 | F12: 25868 | G12: 26581 | H12: 28720 | I12: 31496 | J12: 36016 | K12: 36441 | L12: 38537 | P12: 9204 | Q12: 9313 | R12: 8984 | S12: 9744 | T12: 10080 | U12: 9355
A13: YoY Growth | D13: =IF(N(C12)=0,"",D12/C12-1) | E13: =IF(N(D12)=0,"",E12/D12-1) | F13: =IF(N(E12)=0,"",F12/E12-1) | G13: =IF(N(F12)=0,"",G12/F12-1) | H13: =IF(N(G12)=0,"",H12/G12-1) | I13: =IF(N(H12)=0,"",I12/H12-1) | J13: =IF(N(I12)=0,"",J12/I12-1) | K13: =IF(N(J12)=0,"",K12/J12-1) | L13: =IF(N(K12)=0,"",L12/K12-1) | T13: =IF(N(P12)=0,"",T12/P12-1) | U13: =IF(N(Q12)=0,"",U12/Q12-1)
A14: Cost of sales | B14: FY2016-22 sign-flipped from filed positive-subtract convention to true economic sign; FY2023-25 & quarters filed additive | C14: -15795 | D14: -15831 | E14: -15586 | F14: -15531 | G14: -16135 | H14: -17466 | I14: -20184 | J14: -22252 | K14: -22184 | L14: -27602 | P14: -6205 | Q14: -6883 | R14: -6047 | S14: -7132 | T14: -7277 | U14: -5369
A15: Gross profit | C15: 10128 | D15: 10065 | E15: 10352 | F15: 10337 | G15: 10446 | H15: 11254 | I15: 11312 | J15: 13764 | K15: 14257 | L15: 10935 | P15: 2999 | Q15: 2430 | R15: 2937 | S15: 2612 | T15: 2803 | U15: 3986
A16: Gross Margin | C16: =C15/C12 | D16: =D15/D12 | E16: =E15/E12 | F16: =F15/F12 | G16: =G15/G12 | H16: =H15/H12 | I16: =I15/I12 | J16: =J15/J12 | ... L16: =L15/L12 | P16: =P15/P12 | Q16: =Q15/Q12 | R16: =R15/R12 | S16: =S15/S12 | T16: =T15/T12 | U16: =U15/U12
A18: Selling, general and administrative expenses | C18: -6540 | D18: -5911 | E18: -6475 | F18: -6136 | G18: -6098 | H18: -6263 | I18: -7384 | J18: -8002 | K18: -7439 | L18: -7173 | P18: -1630 | Q18: -1711 | R18: -1725 | S18: -1795 | T18: -1916 | U18: -2001
A19: Asset impairment and exit costs | C19: -852 | D19: -656 | E19: -389 | F19: -228 | G19: -301 | H19: -212 | I19: -262 | J19: -217 | K19: -324 | L19: -85 | P19: -176 | Q19: -2 | R19: -2 | S19: -41 | T19: -53 | U19: -13
A20: Gain on divestitures and acquisitions, net | C20: 9 | D20: 186 | F20: 44 | H20: 8 | J20: 108 | K20: 4 | L20: 13 | T20: 1
A21: Amortization of intangible assets | C21: -176 | D21: -178 | E21: -176 | F21: -174 | G21: -194 | H21: -134 | I21: -132 | J21: -151 | K21: -153 | L21: -142 | P21: -40 | Q21: -37 | R21: -38 | S21: -32 | T21: -27 | U21: -26
A22: Operating income | C22: 2569 | D22: 3506 | E22: 3312 | F22: 3843 | G22: 3853 | H22: 4653 | I22: 3534 | J22: 5502 | K22: 6345 | L22: 3548 | P22: 1153 | Q22: 680 | R22: 1172 | S22: 744 | T22: 808 | U22: 1946
A23: Operating Margin | C23: =C22/C12 | D23: =D22/D12 | E23: =E22/E12 | F23: =F22/F12 | G23: =G22/G12 | H23: =H22/H12 | I23: =I22/I12 | J23: =J22/J12 | ... L23: =L22/L12 | P23: =P22/P12 | Q23: =Q22/Q12 | R23: =R22/R12 | S23: =S22/S12 | T23: =T22/T12 | U23: =U22/U12
A24: YoY Growth | D24: =IF(N(C22)=0,"",D22/C22-1) | E24: =IF(N(D22)=0,"",E22/D22-1) | F24: =IF(N(E22)=0,"",F22/E22-1) | G24: =IF(N(F22)=0,"",G22/F22-1) | H24: =IF(N(G22)=0,"",H22/G22-1) | I24: =IF(N(H22)=0,"",I22/H22-1) | J24: =IF(N(I22)=0,"",J22/I22-1) | K24: =IF(N(J22)=0,"",K22/J22-1) | L24: =IF(N(K22)=0,"",L22/K22-1) | T24: =IF(N(P22)=0,"",T22/P22-1) | U24: =IF(N(Q22)=0,"",U22/Q22-1)
A26: Benefit plan non-service income/(expense) | B26: Line does not exist in FY2016-2017 filings | E26: 50 | F26: 60 | G26: 138 | H26: 163 | I26: 117 | J26: 82 | K26: 96 | L26: -252 | P26: 25 | Q26: 18 | R26: -264 | S26: -27 | T26: 31 | U26: 27
A27: Interest and other expense, net | C27: -1115 | D27: -382 | E27: -520 | F27: -456 | G27: -608 | H27: -447 | I27: -423 | J27: -310 | K27: -180 | L27: -282 | P27: -46 | Q27: -153 | R27: -53 | S27: -22 | T27: -64 | U27: -74
A28: Gain on marketable securities | B28: One-time item, FY2023 only (JDE Peet's share sale) | J28: 606
A29: Earnings before income taxes | C29: 1454 | D29: 3124 | E29: 2842 | F29: 3447 | G29: 3383 | H29: 4369 | I29: 3228 | J29: 5880 | K29: 6261 | L29: 3014 | P29: 1132 | Q29: 545 | R29: 855 | S29: 695 | T29: 775 | U29: 1899
A30: Income tax provision | C30: -129 | D30: -688 | E30: -773 | F30: -2 | G30: -1224 | H30: -1190 | I30: -865 | J30: -1537 | K30: -1469 | L30: -782 | P30: -326 | Q30: -154 | R30: -230 | S30: -137 | T30: -228 | U30: -364
A31: Effective Tax Rate | C31: =0-C30/C29 | D31: =0-D30/D29 | E31: =0-E30/E29 | F31: =0-F30/F29 | G31: =0-G30/G29 | H31: =0-H30/H29 | I31: =0-I30/I29 | J31: =0-J30/J29 | ... L31: =0-L30/L29 | P31: =0-P30/P29 | Q31: =0-Q30/Q29 | R31: =0-R30/R29 | S31: =0-S30/S29 | T31: =0-T30/T29 | U31: =0-U30/U29
A32: Gain/(loss) on equity method investment transactions | B32: FY2024 value (-337) recovered from FY2025 10-K comparative column; corrupted in FY2024 filing's own raw table extraction | C32: 43 | D32: 40 | E32: 778 | F32: -2 | G32: 989 | H32: 742 | I32: -22 | J32: 465 | K32: -337 | L32: 169 | P32: -4 | S32: 169 | T32: -3
A33: Equity method investment net earnings | C33: 301 | D33: 460 | E33: 548 | F33: 442 | G33: 421 | H33: 393 | I33: 385 | J33: 160 | K33: 168 | L33: 65 | P33: 54 | Q33: 16 | R33: 19 | S33: 19 | T33: 20 | U33: 17
A34: Net earnings | C34: 1669 | D34: 2936 | E34: 3395 | F34: 3885 | G34: 3569 | H34: 4314 | I34: 2726 | J34: 4968 | K34: 4623 | L34: 2466 | P34: 856 | Q34: 407 | R34: 644 | S34: 746 | T34: 564 | U34: 1552
A35: Net Margin | C35: =C34/C12 | D35: =D34/D12 | E35: =E34/E12 | F35: =F34/F12 | G35: =G34/G12 | H35: =H34/H12 | I35: =I34/I12 | J35: =J34/J12 | ... L35: =L34/L12 | P35: =P34/P12 | Q35: =Q34/Q12 | R35: =R34/R12 | S35: =S34/S12 | T35: =T34/T12 | U35: =U34/U12
A36: Noncontrolling interest earnings | C36: -10 | D36: -14 | E36: -14 | F36: -15 | G36: -14 | H36: -14 | I36: -9 | J36: -9 | K36: -12 | L36: -15 | P36: -3 | Q36: -5 | R36: -3 | S36: -3 | T36: -4 | U36: -4
A37: Net earnings attributable to Mondelez International | C37: 1659 | D37: 2922 | E37: 3381 | F37: 3870 | G37: 3555 | H37: 4300 | I37: 2717 | J37: 4959 | K37: 4611 | L37: 2451 | P37: 853 | Q37: 402 | R37: 641 | S37: 743 | T37: 560 | U37: 1548
A38: YoY Growth | D38: =IF(N(C37)=0,"",D37/C37-1) | E38: =IF(N(D37)=0,"",E37/D37-1) | F38: =IF(N(E37)=0,"",F37/E37-1) | G38: =IF(N(F37)=0,"",G37/F37-1) | H38: =IF(N(G37)=0,"",H37/G37-1) | I38: =IF(N(H37)=0,"",I37/H37-1) | J38: =IF(N(I37)=0,"",J37/I37-1) | K38: =IF(N(J37)=0,"",K37/J37-1) | L38: =IF(N(K37)=0,"",L37/K37-1) | T38: =IF(N(P37)=0,"",T37/P37-1) | U38: =IF(N(Q37)=0,"",U37/Q37-1)
A40: 2. EPS & SHARE COUNT
A41: Basic EPS | C41: 1.07 | D41: 1.93 | E41: 2.3 | F41: 2.68 | G41: 2.48 | H41: 3.06 | I41: 1.97 | J41: 3.64 | K41: 3.44 | L41: 1.89 | P41: 0.64 | Q41: 0.31 | R41: 0.49 | S41: 0.57 | T41: 0.44 | U41: 1.21
A42: Diluted EPS | C42: 1.05 | D42: 1.91 | E42: 2.28 | F42: 2.65 | G42: 2.47 | H42: 3.04 | I42: 1.96 | J42: 3.62 | K42: 3.42 | L42: 1.89 | P42: 0.63 | Q42: 0.31 | R42: 0.49 | S42: 0.57 | T42: 0.44 | U42: 1.2
A43: YoY Growth | D43: =IF(N(C42)=0,"",D42/C42-1) | E43: =IF(N(D42)=0,"",E42/D42-1) | F43: =IF(N(E42)=0,"",F42/E42-1) | G43: =IF(N(F42)=0,"",G42/F42-1) | H43: =IF(N(G42)=0,"",H42/G42-1) | I43: =IF(N(H42)=0,"",I42/H42-1) | J43: =IF(N(I42)=0,"",J42/I42-1) | K43: =IF(N(J42)=0,"",K42/J42-1) | L43: =IF(N(K42)=0,"",L42/K42-1) | T43: =IF(N(P42)=0,"",T42/P42-1) | U43: =IF(N(Q42)=0,"",U42/Q42-1)
A44: Weighted Avg Shares — Basic | C44: 1556 | D44: 1513 | E44: 1472 | F44: 1445 | G44: 1431 | H44: 1403 | I44: 1378 | J44: 1363 | K44: 1341 | L44: 1294 | P44: 1339 | Q44: 1301 | R44: 1295 | S44: 1293 | T44: 1283 | U44: 1284
A45: Weighted Avg Shares — Diluted | C45: 1573 | D45: 1531 | E45: 1486 | F45: 1458 | G45: 1441 | H45: 1413 | I45: 1385 | J45: 1370 | K45: 1347 | L45: 1298 | P45: 1344 | Q45: 1305 | R45: 1299 | S45: 1296 | T45: 1286 | U45: 1287
...

Sheet Balance Sheet
A1: Mondelez International, Inc. — Balance Sheet
A2: $ in millions except per-share data | USD | as of 2026-09-15
C3: FY2016 | D3: FY2017 | E3: FY2018 | F3: FY2019 | G3: FY2020 | H3: FY2021 | I3: FY2022 | J3: FY2023 | K3: FY2024 | L3: FY2025 | M3: · | N3: · | O3: · | P3: 3Q2024 | Q3: 1Q2025 | R3: 2Q2025 | S3: 3Q2025 | T3: 1Q2026 | U3: 2Q2026
C4: 2016-12-31 | D4: 2017-12-31 | E4: 2018-12-31 | F4: 2019-12-31 | G4: 2020-12-31 | H4: 2021-12-31 | I4: 2022-12-31 | J4: 2023-12-31 | K4: 2024-12-31 | L4: 2025-12-31 | P4: 2024-09-30 | Q4: 2025-03-31 | R4: 2025-06-30 | S4: 2025-09-30 | T4: 2026-03-31 | U4: 2026-06-30
A6: CONTENTS
A7: =HYPERLINK("#'Balance Sheet'!A13","1. ASSETS")
A8: =HYPERLINK("#'Balance Sheet'!A33","2. LIABILITIES")
A9: =HYPERLINK("#'Balance Sheet'!A52","3. EQUITY")
A10: =HYPERLINK("#'Balance Sheet'!A63","4. BALANCE CHECK")
A11: =HYPERLINK("#'Balance Sheet'!A66","5. WORKING CAPITAL ANALYTICS")
A13: 1. ASSETS
A14: Cash and cash equivalents | C14: 1741 | D14: 761 | E14: 1100 | F14: 1291 | G14: 3619 | H14: 3546 | I14: 1923 | J14: 1810 | K14: 1351 | L14: 2125 | P14: 1517 | Q14: 1561 | R14: 1504 | S14: 1367 | T14: 1524 | U14: 1716
A15: Trade receivables, net | C15: 2611 | D15: 2691 | E15: 2262 | F15: 2212 | G15: 2297 | H15: 2337 | I15: 3088 | J15: 3634 | K15: 3874 | L15: 3903 | P15: 3800 | Q15: 4318 | R15: 3528 | S15: 4189 | T15: 4397 | U15: 4010
A16: Other receivables, net | C16: 859 | D16: 835 | E16: 744 | F16: 715 | G16: 657 | H16: 851 | I16: 819 | J16: 878 | K16: 937 | L16: 955 | P16: 891 | Q16: 941 | R16: 1103 | S16: 1049 | T16: 985 | U16: 998
A17: Inventories, net | C17: 2469 | D17: 2557 | E17: 2592 | F17: 2546 | G17: 2647 | H17: 2708 | I17: 3381 | J17: 3615 | K17: 3827 | L17: 4419 | P17: 4270 | Q17: 4255 | R17: 4951 | S17: 5098 | T17: 4079 | U17: 4405
A18: Other current assets | C18: 800 | D18: 676 | E18: 906 | F18: 866 | G18: 759 | H18: 900 | I18: 880 | J18: 1766 | K18: 3253 | L18: 1549 | P18: 2723 | Q18: 1655 | R18: 1664 | S18: 1444 | T18: 1760 | U18: 1809
A19: Total current assets | C19: 8480 | D19: 7520 | E19: 7604 | F19: 7630 | G19: 9979 | H19: 10342 | I19: 10091 | J19: 11703 | K19: 13242 | L19: 12951 | P19: 13201 | Q19: 12730 | R19: 12750 | S19: 13147 | T19: 12745 | U19: 12938
A20: Current Assets Check (should be ~0) | C20: =C14+C15+C16+C17+C18-C19 | D20: =D14+D15+D16+D17+D18-D19 | E20: =E14+E15+E16+E17+E18-E19 | F20: =F14+F15+F16+F17+F18-F19 | G20: =G14+G15+G16+G17+G18-G19 | H20: =H14+H15+H16+H17+H18-H19 | I20: =I14+I15+I16+I17+I18-I19 | J20: =J14+J15+J16+J17+J18-J19 | ... L20: =L14+L15+L16+L17+L18-L19 | P20: =P14+P15+P16+P17+P18-P19 | Q20: =Q14+Q15+Q16+Q17+Q18-Q19 | R20: =R14+R15+R16+R17+R18-R19 | S20: =S14+S15+S16+S17+S18-S19 | T20: =T14+T15+T16+T17+T18-T19 | U20: =U14+U15+U16+U17+U18-U19
A22: Property, plant and equipment, net | C22: 8229 | D22: 8677 | E22: 8482 | F22: 8733 | G22: 9026 | H22: 8658 | I22: 9020 | J22: 9694 | K22: 9481 | L22: 10667 | P22: 9696 | Q22: 9767 | R22: 10313 | S22: 10333 | T22: 10567 | U22: 10649
A23: Operating lease right-of-use assets | B23: Recognized starting FY2019 (ASU 2016-02 adoption) | F23: 568 | G23: 638 | H23: 613 | I23: 660 | J23: 683 | K23: 767 | L23: 731 | P23: 774 | Q23: 761 | R23: 761 | S23: 750 | T23: 725 | U23: 732
A24: Goodwill | C24: 20276 | D24: 21085 | E24: 20725 | F24: 20848 | G24: 21895 | H24: 21978 | I24: 23450 | J24: 23896 | K24: 23017 | L24: 24336 | P24: 23773 | Q24: 23439 | R24: 24344 | S24: 24250 | T24: 24226 | U24: 24180
A25: Intangible assets, net | C25: 18101 | D25: 18639 | E25: 18002 | F25: 17957 | G25: 18482 | H25: 18291 | I25: 19710 | J25: 19836 | K25: 18848 | L25: 19628 | P25: 19459 | Q25: 19130 | R25: 19729 | S25: 19611 | T25: 19533 | U25: 19509
A26: Prepaid pension assets | C26: 159 | D26: 158 | E26: 132 | F26: 516 | G26: 672 | H26: 1009 | I26: 1016 | J26: 1043 | K26: 987 | L26: 1220 | P26: 1146 | Q26: 993 | R26: 1121 | S26: 1132 | T26: 1259 | U26: 1251
A27: Deferred income taxes | C27: 358 | D27: 319 | E27: 255 | F27: 726 | G27: 790 | H27: 541 | I27: 473 | J27: 408 | K27: 333 | L27: 336 | P27: 372 | Q27: 400 | R27: 415 | S27: 437 | T27: 316 | U27: 184
A28: Equity method investments | C28: 5585 | D28: 6345 | E28: 7123 | F28: 7212 | G28: 6036 | H28: 5289 | I28: 4879 | J28: 3242 | K28: 635 | L28: 667 | P28: 2576 | Q28: 610 | R28: 665 | S28: 669 | T28: 610 | U28: 619
A29: Other assets | C29: 350 | D29: 366 | E29: 406 | F29: 359 | G29: 292 | H29: 371 | I29: 1862 | J29: 886 | K29: 1187 | L29: 951 | P29: 1194 | Q29: 1097 | R29: 922 | S29: 1029 | T29: 1141 | U29: 1185
A30: TOTAL ASSETS | C30: 61538 | D30: 63109 | E30: 62729 | F30: 64549 | G30: 67810 | H30: 67092 | I30: 71161 | J30: 71391 | K30: 68497 | L30: 71487 | P30: 72191 | Q30: 68927 | R30: 71020 | S30: 71358 | T30: 71122 | U30: 71247
A31: Total Assets Check (should be ~0) | C31: =C19+C22+C23+C24+C25+C26+C27+C28+C29-C30 | D31: =D19+D22+D23+D24+D25+D26+D27+D28+D29-D30 | E31: =E19+E22+E23+E24+E25+E26+E27+E28+E29-E30 | F31: =F19+F22+F23+F24+F25+F26+F27+F28+F29-F30 | G31: =G19+G22+G23+G24+G25+G26+G27+G28+G29-G30 | H31: =H19+H22+H23+H24+H25+H26+H27+H28+H29-H30 | I31: =I19+I22+I23+I24+I25+I26+I27+I28+I29-I30 | J31: =J19+J22+J23+J24+J25+J26+J27+J28+J29-J30 | ... L31: =L19+L22+L23+L24+L25+L26+L27+L28+L29-L30 | P31: =P19+P22+P23+P24+P25+P26+P27+P28+P29-P30 | Q31: =Q19+Q22+Q23+Q24+Q25+Q26+Q27+Q28+Q29-Q30 | R31: =R19+R22+R23+R24+R25+R26+R27+R28+R29-R30 | S31: =S19+S22+S23+S24+S25+S26+S27+S28+S29-S30 | T31: =T19+T22+T23+T24+T25+T26+T27+T28+T29-T30 | U31: =U19+U22+U23+U24+U25+U26+U27+U28+U29-U30
A33: 2. LIABILITIES
A34: Short-term borrowings | C34: 2531 | D34: 3517 | E34: 3192 | F34: 2638 | G34: 29 | H34: 216 | I34: 2299 | J34: 420 | K34: 71 | L34: 2688 | P34: 1484 | Q34: 1914 | R34: 1664 | S34: 2645 | T34: 2881 | U34: 2327
A35: Current portion of long-term debt | C35: 1451 | D35: 1163 | E35: 2648 | F35: 1581 | G35: 2741 | H35: 1746 | I35: 383 | J35: 2101 | K35: 2014 | L35: 1295 | P35: 1821 | Q35: 1828 | R35: 1107 | S35: 1543 | T35: 2675 | U35: 2663
A36: Accounts payable | C36: 5318 | D36: 5705 | E36: 5794 | F36: 5853 | G36: 6209 | H36: 6730 | I36: 7562 | J36: 8321 | K36: 9433 | L36: 10139 | P36: 9110 | Q36: 9921 | R36: 9975 | S36: 10022 | T36: 9744 | U36: 9411
A37: Accrued marketing | C37: 1745 | D37: 1728 | E37: 1756 | F37: 1836 | G37: 2130 | H37: 2097 | I37: 2370 | J37: 2683 | K37: 2558 | L37: 2787 | P37: 2721 | Q37: 2697 | R37: 2423 | S37: 2650 | T37: 2968 | U37: 2612
A38: Accrued employment costs | C38: 736 | D38: 721 | E38: 701 | F38: 769 | G38: 834 | H38: 822 | I38: 949 | J38: 1158 | K38: 928 | L38: 1000 | P38: 905 | Q38: 774 | R38: 836 | S38: 956 | T38: 865 | U38: 875
A39: Other current liabilities | C39: 2636 | D39: 2959 | E39: 2646 | F39: 2645 | G39: 3216 | H39: 2397 | I39: 3168 | J39: 4330 | K39: 4545 | L39: 3955 | P39: 5032 | Q39: 3869 | R39: 3878 | S39: 3696 | T39: 4368 | U39: 3705
A40: Total current liabilities | C40: 14417 | D40: 15793 | E40: 16737 | F40: 15322 | G40: 15159 | H40: 14008 | I40: 16731 | J40: 19013 | K40: 19549 | L40: 21864 | P40: 21073 | Q40: 21003 | R40: 19883 | S40: 21512 | T40: 23501 | U40: 21593
A41: Current Liabilities Check (should be ~0) | C41: =C34+C35+C36+C37+C38+C39-C40 | D41: =D34+D35+D36+D37+D38+D39-D40 | E41: =E34+E35+E36+E37+E38+E39-E40 | F41: =F34+F35+F36+F37+F38+F39-F40 | G41: =G34+G35+G36+G37+G38+G39-G40 | H41: =H34+H35+H36+H37+H38+H39-H40 | I41: =I34+I35+I36+I37+I38+I39-I40 | J41: =J34+J35+J36+J37+J38+J39-J40 | ... L41: =L34+L35+L36+L37+L38+L39-L40 | P41: =P34+P35+P36+P37+P38+P39-P40 | Q41: =Q34+Q35+Q36+Q37+Q38+Q39-Q40 | R41: =R34+R35+R36+R37+R38+R39-R40 | S41: =S34+S35+S36+S37+S38+S39-S40 | T41: =T34+T35+T36+T37+T38+T39-T40 | U41: =U34+U35+U36+U37+U38+U39-U40
A43: Long-term debt | C43: 13217 | D43: 12972 | E43: 12532 | F43: 14207 | G43: 17276 | H43: 17550 | I43: 20251 | J43: 16887 | K43: 15664 | L43: 17222 | P43: 16499 | Q43: 15796 | R43: 18116 | S43: 17134 | T43: 15468 | U43: 16460
A44: Long-term operating lease liabilities | B44: Recognized starting FY2019 (ASU 2016-02 adoption) | F44: 403 | G44: 470 | H44: 459 | I44: 514 | J44: 537 | K44: 623 | L44: 599 | P44: 621 | Q44: 617 | R44: 618 | S44: 611 | T44: 598 | U44: 609
A45: Deferred income taxes | C45: 4721 | D45: 3376 | E45: 3552 | F45: 3338 | G45: 3346 | H45: 3444 | I45: 3437 | J45: 3292 | K45: 3425 | L45: 3530 | P45: 3423 | Q45: 3429 | R45: 3550 | S45: 3451 | T45: 3549 | U45: 3539
...

Sheet Cash Flow
A1: Mondelez International, Inc. — Cash Flow
A2: $ in millions except per-share data | USD | as of 2026-09-15
C3: FY2016 | D3: FY2017 | E3: FY2018 | F3: FY2019 | G3: FY2020 | H3: FY2021 | I3: FY2022 | J3: FY2023 | K3: FY2024 | L3: FY2025 | M3: · | N3: · | O3: · | P3: 3Q2024 | Q3: 1Q2025 | R3: 2Q2025 | S3: 3Q2025 | T3: 1Q2026 | U3: 2Q2026
C4: 2016-12-31 | D4: 2017-12-31 | E4: 2018-12-31 | F4: 2019-12-31 | G4: 2020-12-31 | H4: 2021-12-31 | I4: 2022-12-31 | J4: 2023-12-31 | K4: 2024-12-31 | L4: 2025-12-31 | P4: 2024-09-30 | Q4: 2025-03-31 | R4: 2025-06-30 | S4: 2025-09-30 | T4: 2026-03-31 | U4: 2026-06-30
A6: CONTENTS
A7: =HYPERLINK("#'Cash Flow'!A12","1. CASH FLOW FROM OPERATING ACTIVITIES")
A8: =HYPERLINK("#'Cash Flow'!A38","2. CASH FLOW FROM INVESTING ACTIVITIES")
A9: =HYPERLINK("#'Cash Flow'!A49","3. CASH FLOW FROM FINANCING ACTIVITIES")
A10: =HYPERLINK("#'Cash Flow'!A61","4. NET CHANGE IN CASH & FCF ANALYTICS")
A12: 1. CASH FLOW FROM OPERATING ACTIVITIES
A13: Net earnings | B13: Quarterly CF columns are fiscal-YTD cumulative (per MDLZ 10-Q presentation), not discrete-quarter | C13: 1669 | D13: 2936 | E13: 3395 | F13: 3885 | G13: 3569 | H13: 4314 | I13: 2726 | J13: 4968 | K13: 4623 | L13: 2466 | P13: 2875 | Q13: 407 | R13: 1051 | S13: 1797 | T13: 564 | U13: 2116
A14: Depreciation and amortization | C14: 823 | D14: 816 | E14: 811 | F14: 1047 | G14: 1116 | H14: 1113 | I14: 1107 | J14: 1215 | K14: 1302 | L14: 1358 | P14: 971 | Q14: 324 | R14: 663 | S14: 1006 | T14: 343 | U14: 693
A15: Stock-based compensation expense | C15: 140 | D15: 137 | E15: 128 | F15: 135 | G15: 126 | H15: 121 | I15: 120 | J15: 146 | K15: 147 | L15: 114 | P15: 112 | Q15: 18 | R15: 65 | S15: 84 | T15: 29 | U15: 87
A16: Deferred income tax provision/(benefit) | C16: -141 | D16: -1206 | E16: 233 | F16: -631 | G16: -70 | H16: 205 | I16: -42 | J16: -37 | K16: 257 | L16: 16 | P16: 167 | Q16: -96 | R16: -69 | S16: -158 | T16: 8 | U16: 149
A17: U.S. tax reform transition tax | B17: FY2017-2019 only (Tax Cuts and Jobs Act transition tax) | D17: 1317 | E17: -38 | F17: 5
A18: Asset impairments and accelerated depreciation | C18: 446 | D18: 334 | E18: 141 | F18: 109 | G18: 136 | H18: 128 | I18: 233 | J18: 128 | K18: 267 | L18: 85 | P18: 210 | Q18: 4 | R18: 9 | S18: 55 | T18: 4 | U18: 10
A19: Loss on early extinguishment of debt | B19: FY2016-2023 only | C19: 428 | D19: 11 | E19: 140 | G19: 185 | H19: 110 | I19: 38 | J19: 1
A20: Gain on divestitures and acquisitions, net | C20: -9 | D20: -186 | F20: -44 | H20: -8 | J20: -108 | K20: -4 | L20: -13 | T20: -1 | U20: -1
A21: Loss/(gain) on equity method investment transactions | C21: -43 | D21: -40 | E21: -778 | F21: 2 | G21: -989 | H21: -742 | I21: 22 | J21: -465 | K21: 337 | P21: 669 | T21: 3 | U21: 3
A22: Equity method investment net earnings | C22: -301 | D22: -460 | E22: -548 | F22: -442 | G22: -421 | H22: -393 | I22: -385 | J22: -160 | K22: -175 | L22: -65 | P22: -140 | Q22: -16 | R22: -35 | S22: -54 | T22: -20 | U22: -37
A23: Distributions from equity method investments | C23: 75 | D23: 152 | E23: 180 | F23: 250 | G23: 246 | H23: 172 | I23: 184 | J23: 137 | K23: 115 | L23: 45 | P23: 115 | Q23: 44 | R23: 44 | S23: 45 | T23: 43 | U23: 44
A24: Unrealized loss/(gain) on derivative contracts | B24: FY2023 onward only | J24: -171 | K24: -627 | L24: 1379 | P24: 104 | Q24: 689 | R24: 800 | S24: 1161 | T24: 257 | U24: -509
A25: Gain on marketable securities | B25: FY2023 only | J25: -593
A26: Contingent consideration adjustments | B26: FY2024 onward only | K26: -389 | L26: -34 | P26: -311 | Q26: -12 | R26: -38 | S26: -26 | T26: -8 | U26: 3
A27: Other non-cash items, net | C27: -43 | D27: -225 | E27: 381 | F27: 97 | G27: 243 | H27: -230 | I27: 426 | J27: 140 | K27: 26 | L27: 137 | P27: 93 | Q27: 56 | R27: 105 | S27: 109 | T27: -36 | U27: -5
A29: Change in receivables | C29: 31 | D29: -24 | E29: 257 | F29: 124 | G29: 59 | H29: -197 | I29: -719 | J29: -628 | K29: -519 | L29: 433 | P29: -270 | Q29: -379 | R29: 536 | S29: -92 | T29: -728 | U29: -424
A30: Change in inventories | C30: 62 | D30: -18 | E30: -204 | F30: 31 | G30: -24 | H30: -170 | I30: -635 | J30: -193 | K30: -458 | L30: -253 | P30: -710 | Q30: -300 | R30: -775 | S30: -967 | T30: 314 | U30: -16
A31: Change in accounts payable | C31: 409 | D31: 5 | E31: 236 | F31: 4 | G31: 436 | H31: 702 | I31: 715 | J31: 264 | K31: 1682 | L31: -145 | P31: 951 | Q31: 222 | R31: -177 | S31: -159 | T31: -320 | U31: -538
A32: Change in other current assets | C32: -176 | D32: 14 | E32: -25 | F32: -77 | G32: -207 | H32: -169 | I32: -286 | J32: -120 | K32: -591 | L32: -225 | P32: -287 | Q32: 196 | R32: 108 | S32: -30 | T32: -1 | U32: 142
A33: Change in other current liabilities | C33: 60 | D33: -637 | E33: -136 | F33: -362 | G33: -208 | H33: -502 | I33: 630 | J33: 376 | K33: -932 | L33: -1026 | P33: -992 | Q33: -58 | R33: -1125 | S33: -903 | T33: 83 | U33: -296
A34: Change in pension and postretirement assets/liabilities | C34: -592 | D34: -333 | E34: -225 | F34: -168 | G34: -233 | H34: -313 | I34: -226 | J34: -186 | K34: -151 | L34: 242 | P34: -106 | Q34: -7 | R34: 238 | S34: 249 | T34: -67 | U34: -99
A35: Net cash provided by operating activities | C35: 2838 | D35: 2593 | E35: 3948 | F35: 3965 | G35: 3964 | H35: 4141 | I35: 3908 | J35: 4714 | K35: 4910 | L35: 4514 | P35: 3451 | Q35: 1092 | R35: 1400 | S35: 2117 | T35: 467 | U35: 1322
A36: CFO Check (should be ~0) | C36: =C13+C14+C15+C16+C17+C18+C19+C20+C21+C22+C23+C24+C25+C26+C27+C29+C30+C31+C32+C33+C34-C35 | D36: =D13+D14+D15+D16+D17+D18+D19+D20+D21+D22+D23+D24+D25+D26+D27+D29+D30+D31+D32+D33+D34-D35 | E36: =E13+E14+E15+E16+E17+E18+E19+E20+E21+E22+E23+E24+E25+E26+E27+E29+E30+E31+E32+E33+E34-E35 | F36: =F13+F14+F15+F16+F17+F18+F19+F20+F21+F22+F23+F24+F25+F26+F27+F29+F30+F31+F32+F33+F34-F35 | G36: =G13+G14+G15+G16+G17+G18+G19+G20+G21+G22+G23+G24+G25+G26+G27+G29+G30+G31+G32+G33+G34-G35 | H36: =H13+H14+H15+H16+H17+H18+H19+H20+H21+H22+H23+H24+H25+H26+H27+H29+H30+H31+H32+H33+H34-H35 | I36: =I13+I14+I15+I16+I17+I18+I19+I20+I21+I22+I23+I24+I25+I26+I27+I29+I30+I31+I32+I33+I34-I35 | J36: =J13+J14+J15+J16+J17+J18+J19+J20+J21+J22+J23+J24+J25+J26+J27+J29+J30+J31+J32+J33+J34-J35 | ... L36: =L13+L14+L15+L16+L17+L18+L19+L20+L21+L22+L23+L24+L25+L26+L27+L29+L30+L31+L32+L33+L34-L35 | P36: =P13+P14+P15+P16+P17+P18+P19+P20+P21+P22+P23+P24+P25+P26+P27+P29+P30+P31+P32+P33+P34-P35 | Q36: =Q13+Q14+Q15+Q16+Q17+Q18+Q19+Q20+Q21+Q22+Q23+Q24+Q25+Q26+Q27+Q29+Q30+Q31+Q32+Q33+Q34-Q35 | R36: =R13+R14+R15+R16+R17+R18+R19+R20+R21+R22+R23+R24+R25+R26+R27+R29+R30+R31+R32+R33+R34-R35 | S36: =S13+S14+S15+S16+S17+S18+S19+S20+S21+S22+S23+S24+S25+S26+S27+S29+S30+S31+S32+S33+S34-S35 | T36: =T13+T14+T15+T16+T17+T18+T19+T20+T21+T22+T23+T24+T25+T26+T27+T29+T30+T31+T32+T33+T34-T35 | U36: =U13+U14+U15+U16+U17+U18+U19+U20+U21+U22+U23+U24+U25+U26+U27+U29+U30+U31+U32+U33+U34-U35
A38: 2. CASH FLOW FROM INVESTING ACTIVITIES
A39: Capital expenditures | C39: -1224 | D39: -1014 | E39: -1095 | F39: -925 | G39: -863 | H39: -965 | I39: -906 | J39: -1112 | K39: -1387 | L39: -1279 | P39: -982 | Q39: -277 | R39: -582 | S39: -881 | T39: -312 | U39: -654
A40: Acquisitions, net of cash acquired | C40: -246 | E40: -528 | F40: -284 | G40: -1136 | H40: -833 | I40: -5286 | J40: 19 | K40: -240 | L40: -15 | Q40: -15 | R40: -15 | S40: -15
A41: Proceeds from divestitures | C41: 303 | D41: 604 | E41: 1 | F41: 167 | G41: 2489 | H41: 1539 | I41: 601 | J41: 4099 | K41: 2294 | L41: 127 | P41: 4 | Q41: 4 | R41: 4 | S41: 4 | T41: 1 | U41: 1
A42: Proceeds from settlement of derivatives | I42: 703 | J42: 177 | K42: 320 | L42: 54 | P42: 191 | Q42: 14 | R42: 19 | S42: 54 | T42: 52 | U42: 179
A43: Payments for settlement of derivatives | J43: -81 | K43: -199 | L43: -165 | P43: -150 | R43: -55 | S43: -165 | T43: -179 | U43: -270
A44: Contributions to (proceeds from) other investments | J44: -309 | K44: -278 | L44: 73 | P44: -249 | Q44: 22 | R44: 30 | S44: 65 | T44: 16 | U44: 25
...

Sheet Segments
A1: Mondelez International, Inc. — Segments
A2: $ in millions except per-share data | USD | as of 2026-09-15
C3: FY2016 | D3: FY2017 | E3: FY2018 | F3: FY2019 | G3: FY2020 | H3: FY2021 | I3: FY2022 | J3: FY2023 | K3: FY2024 | L3: FY2025 | M3: · | N3: · | O3: · | P3: 3Q2024 | Q3: 1Q2025 | R3: 2Q2025 | S3: 3Q2025 | T3: 1Q2026 | U3: 2Q2026
C4: 2016-12-31 | D4: 2017-12-31 | E4: 2018-12-31 | F4: 2019-12-31 | G4: 2020-12-31 | H4: 2021-12-31 | I4: 2022-12-31 | J4: 2023-12-31 | K4: 2024-12-31 | L4: 2025-12-31 | P4: 2024-09-30 | Q4: 2025-03-31 | R4: 2025-06-30 | S4: 2025-09-30 | T4: 2026-03-31 | U4: 2026-06-30
A6: CONTENTS
A7: =HYPERLINK("#'Segments'!A12","1. SEGMENT REVENUE (Latin America / AMEA / Europe / North America)")
A8: =HYPERLINK("#'Segments'!A25","2. SEGMENT OPERATING INCOME")
A9: =HYPERLINK("#'Segments'!A32","3. RECONCILIATION TO CONSOLIDATED OPERATING INCOME")
A10: =HYPERLINK("#'Segments'!A41","4. RECONCILIATION TO EARNINGS BEFORE TAX")
A12: 1. SEGMENT REVENUE (Latin America / AMEA / Europe / North America)
A13: Latin America | C13: 3392 | D13: 3566 | E13: 3202 | F13: 3018 | G13: 2477 | H13: 2797 | I13: 3629 | J13: 5006 | K13: 4926 | L13: 4899 | P13: 1204 | Q13: 1203 | R13: 1194 | S13: 1238 | T13: 1348 | U13: 1374
A14: Asia, Middle East and Africa (AMEA) | C14: 5816 | D14: 5739 | E14: 5729 | F14: 5770 | G14: 5740 | H14: 6465 | I14: 6767 | J14: 7075 | K14: 7296 | L14: 7932 | P14: 1851 | Q14: 2016 | R14: 1821 | S14: 2017 | T14: 2304 | U14: 1971
A15: Europe | C15: 9755 | D15: 9794 | E15: 10122 | F15: 9972 | G15: 10207 | H15: 11156 | I15: 11420 | J15: 12857 | K15: 13309 | L15: 15027 | P15: 3323 | Q15: 3550 | R15: 3412 | S15: 3674 | T15: 3871 | U15: 3377
A16: North America | C16: 6960 | D16: 6797 | E16: 6885 | F16: 7108 | G16: 8157 | H16: 8302 | I16: 9680 | J16: 11078 | K16: 10910 | L16: 10679 | P16: 2826 | Q16: 2544 | R16: 2557 | S16: 2815 | T16: 2557 | U16: 2633
A17: Total Segment Net Revenues | C17: =C13+C14+C15+C16 | D17: =D13+D14+D15+D16 | E17: =E13+E14+E15+E16 | F17: =F13+F14+F15+F16 | G17: =G13+G14+G15+G16 | H17: =H13+H14+H15+H16 | I17: =I13+I14+I15+I16 | J17: =J13+J14+J15+J16 | ... L17: =L13+L14+L15+L16 | P17: =P13+P14+P15+P16 | Q17: =Q13+Q14+Q15+Q16 | R17: =R13+R14+R15+R16 | S17: =S13+S14+S15+S16 | T17: =T13+T14+T15+T16 | U17: =U13+U14+U15+U16
A18: vs IS Net Revenues (should be ~0) | C18: =C17-'Income Statement'!C12 | D18: =D17-'Income Statement'!D12 | E18: =E17-'Income Statement'!E12 | F18: =F17-'Income Statement'!F12 | G18: =G17-'Income Statement'!G12 | H18: =H17-'Income Statement'!H12 | I18: =I17-'Income Statement'!I12 | J18: =J17-'Income Statement'!J12 | ... L18: =L17-'Income Statement'!L12 | P18: =P17-'Income Statement'!P12 | Q18: =Q17-'Income Statement'!Q12 | R18: =R17-'Income Statement'!R12 | S18: =S17-'Income Statement'!S12 | T18: =T17-'Income Statement'!T12 | U18: =U17-'Income Statement'!U12
A20: Latin America % of total | C20: =C13/C17 | D20: =D13/D17 | E20: =E13/E17 | F20: =F13/F17 | G20: =G13/G17 | H20: =H13/H17 | I20: =I13/I17 | J20: =J13/J17 | ... L20: =L13/L17 | P20: =P13/P17 | Q20: =Q13/Q17 | R20: =R13/R17 | S20: =S13/S17 | T20: =T13/T17 | U20: =U13/U17
A21: AMEA % of total | C21: =C14/C17 | D21: =D14/D17 | E21: =E14/E17 | F21: =F14/F17 | G21: =G14/G17 | H21: =H14/H17 | I21: =I14/I17 | J21: =J14/J17 | ... L21: =L14/L17 | P21: =P14/P17 | Q21: =Q14/Q17 | R21: =R14/R17 | S21: =S14/S17 | T21: =T14/T17 | U21: =U14/U17
A22: Europe % of total | C22: =C15/C17 | D22: =D15/D17 | E22: =E15/E17 | F22: =F15/F17 | G22: =G15/G17 | H22: =H15/H17 | I22: =I15/I17 | J22: =J15/J17 | ... L22: =L15/L17 | P22: =P15/P17 | Q22: =Q15/Q17 | R22: =R15/R17 | S22: =S15/S17 | T22: =T15/T17 | U22: =U15/U17
A23: North America % of total | C23: =C16/C17 | D23: =D16/D17 | E23: =E16/E17 | F23: =F16/F17 | G23: =G16/G17 | H23: =H16/H17 | I23: =I16/I17 | J23: =J16/J17 | ... L23: =L16/L17 | P23: =P16/P17 | Q23: =Q16/Q17 | R23: =R16/R17 | S23: =S16/S17 | T23: =T16/T17 | U23: =U16/U17
A25: 2. SEGMENT OPERATING INCOME
A26: Latin America | C26: 271 | D26: 565 | E26: 410 | F26: 341 | G26: 189 | H26: 261 | I26: 388 | J26: 529 | K26: 532 | L26: 569 | P26: 125 | Q26: 139 | R26: 133 | S26: 147 | T26: 149 | U26: 166
A27: Asia, Middle East and Africa (AMEA) | C27: 506 | D27: 516 | E27: 702 | F27: 691 | G27: 821 | H27: 1054 | I27: 929 | J27: 1113 | K27: 1192 | L27: 985 | P27: 335 | Q27: 343 | R27: 271 | S27: 199 | T27: 326 | U27: 254
A28: Europe | C28: 1267 | D28: 1680 | E28: 1734 | F28: 1732 | G28: 1775 | H28: 2092 | I28: 1481 | J28: 1978 | K28: 2068 | L28: 1820 | P28: 605 | Q28: 462 | R28: 514 | S28: 275 | T28: 294 | U28: 382
A29: North America | C29: 1078 | D29: 1120 | E29: 849 | F29: 1451 | G29: 1587 | H29: 1371 | I29: 1769 | J29: 2092 | K29: 2492 | L29: 1904 | P29: 918 | Q29: 485 | R29: 454 | S29: 547 | T29: 384 | U29: 431
A30: Total Segment Operating Income | C30: =C26+C27+C28+C29 | D30: =D26+D27+D28+D29 | E30: =E26+E27+E28+E29 | F30: =F26+F27+F28+F29 | G30: =G26+G27+G28+G29 | H30: =H26+H27+H28+H29 | I30: =I26+I27+I28+I29 | J30: =J26+J27+J28+J29 | ... L30: =L26+L27+L28+L29 | P30: =P26+P27+P28+P29 | Q30: =Q26+Q27+Q28+Q29 | R30: =R26+R27+R28+R29 | S30: =S26+S27+S28+S29 | T30: =T26+T27+T28+T29 | U30: =U26+U27+U28+U29
A32: 3. RECONCILIATION TO CONSOLIDATED OPERATING INCOME
A33: Mark-to-market gains/(losses) on hedging activities | C33: -94 | D33: -96 | E33: 141 | F33: 91 | G33: 16 | H33: 279 | I33: -326 | J33: 189 | K33: 543 | L33: -1341 | P33: -710 | Q33: -669 | R33: -93 | S33: -348 | T33: -273 | U33: 827
A34: General corporate expenses | C34: -291 | D34: -287 | E34: -335 | F34: -330 | G34: -326 | H34: -253 | I34: -245 | J34: -356 | K34: -330 | L34: -260 | P34: -78 | Q34: -43 | R34: -69 | S34: -44 | T34: -46 | U34: -88
A35: Amortization of intangible assets | C35: -176 | D35: -178 | E35: -176 | F35: -174 | G35: -194 | H35: -134 | I35: -132 | J35: -151 | K35: -153 | L35: -142 | P35: -40 | Q35: -37 | R35: -38 | S35: -32 | T35: -27 | U35: -26
A36: Gain on divestitures | C36: 9 | D36: 186 | E36: 0 | F36: 44 | G36: 0 | H36: 8 | I36: 0 | J36: 108 | K36: 4 | L36: 13 | T36: 1
A37: Acquisition-related costs | C37: -1 | D37: 0 | E37: -13 | F37: -3 | G37: -15 | H37: -25 | I37: -330 | J37: 0 | K37: -3 | L37: 0 | P37: -2
A38: Operating Income (reconciled) | C38: =C30+C33+C34+C35+C36+C37 | D38: =D30+D33+D34+D35+D36+D37 | E38: =E30+E33+E34+E35+E36+E37 | F38: =F30+F33+F34+F35+F36+F37 | G38: =G30+G33+G34+G35+G36+G37 | H38: =H30+H33+H34+H35+H36+H37 | I38: =I30+I33+I34+I35+I36+I37 | J38: =J30+J33+J34+J35+J36+J37 | ... L38: =L30+L33+L34+L35+L36+L37 | P38: =P30+P33+P34+P35+P36+P37 | Q38: =Q30+Q33+Q34+Q35+Q36+Q37 | R38: =R30+R33+R34+R35+R36+R37 | S38: =S30+S33+S34+S35+S36+S37 | T38: =T30+T33+T34+T35+T36+T37 | U38: =U30+U33+U34+U35+U36+U37
A39: vs IS Operating Income (should be ~0) | C39: =C38-'Income Statement'!C22 | D39: =D38-'Income Statement'!D22 | E39: =E38-'Income Statement'!E22 | F39: =F38-'Income Statement'!F22 | G39: =G38-'Income Statement'!G22 | H39: =H38-'Income Statement'!H22 | I39: =I38-'Income Statement'!I22 | J39: =J38-'Income Statement'!J22 | ... L39: =L38-'Income Statement'!L22 | P39: =P38-'Income Statement'!P22 | Q39: =Q38-'Income Statement'!Q22 | R39: =R38-'Income Statement'!R22 | S39: =S38-'Income Statement'!S22 | T39: =T38-'Income Statement'!T22 | U39: =U38-'Income Statement'!U22
A41: 4. RECONCILIATION TO EARNINGS BEFORE TAX
A42: Benefit plan non-service income/(expense) | C42: ='Income Statement'!C26 | D42: ='Income Statement'!D26 | E42: ='Income Statement'!E26 | F42: ='Income Statement'!F26 | G42: ='Income Statement'!G26 | H42: ='Income Statement'!H26 | I42: ='Income Statement'!I26 | J42: ='Income Statement'!J26 | ... L42: ='Income Statement'!L26 | P42: ='Income Statement'!P26 | Q42: ='Income Statement'!Q26 | R42: ='Income Statement'!R26 | S42: ='Income Statement'!S26 | T42: ='Income Statement'!T26 | U42: ='Income Statement'!U26
A43: Interest and other expense, net | C43: ='Income Statement'!C27 | D43: ='Income Statement'!D27 | E43: ='Income Statement'!E27 | F43: ='Income Statement'!F27 | G43: ='Income Statement'!G27 | H43: ='Income Statement'!H27 | I43: ='Income Statement'!I27 | J43: ='Income Statement'!J27 | ... L43: ='Income Statement'!L27 | P43: ='Income Statement'!P27 | Q43: ='Income Statement'!Q27 | R43: ='Income Statement'!R27 | S43: ='Income Statement'!S27 | T43: ='Income Statement'!T27 | U43: ='Income Statement'!U27
A44: Gain on marketable securities | C44: ='Income Statement'!C28 | D44: ='Income Statement'!D28 | E44: ='Income Statement'!E28 | F44: ='Income Statement'!F28 | G44: ='Income Statement'!G28 | H44: ='Income Statement'!H28 | I44: ='Income Statement'!I28 | J44: ='Income Statement'!J28 | ... L44: ='Income Statement'!L28 | P44: ='Income Statement'!P28 | Q44: ='Income Statement'!Q28 | R44: ='Income Statement'!R28 | S44: ='Income Statement'!S28 | T44: ='Income Statement'!T28 | U44: ='Income Statement'!U28
A45: Earnings Before Income Taxes (reconciled) | C45: =C38+C42+C43+C44 | D45: =D38+D42+D43+D44 | E45: =E38+E42+E43+E44 | F45: =F38+F42+F43+F44 | G45: =G38+G42+G43+G44 | H45: =H38+H42+H43+H44 | I45: =I38+I42+I43+I44 | J45: =J38+J42+J43+J44 | ... L45: =L38+L42+L43+L44 | P45: =P38+P42+P43+P44 | Q45: =Q38+Q42+Q43+Q44 | R45: =R38+R42+R43+R44 | S45: =S38+S42+S43+S44 | T45: =T38+T42+T43+T44 | U45: =U38+U42+U43+U44
A46: vs IS Earnings Before Tax (should be ~0) | C46: =C45-'Income Statement'!C29 | D46: =D45-'Income Statement'!D29 | E46: =E45-'Income Statement'!E29 | F46: =F45-'Income Statement'!F29 | G46: =G45-'Income Statement'!G29 | H46: =H45-'Income Statement'!H29 | I46: =I45-'Income Statement'!I29 | J46: =J45-'Income Statement'!J29 | ... L46: =L45-'Income Statement'!L29 | P46: =P45-'Income Statement'!P29 | Q46: =Q45-'Income Statement'!Q29 | R46: =R45-'Income Statement'!R29 | S46: =S45-'Income Statement'!S29 | T46: =T45-'Income Statement'!T29 | U46: =U45-'Income Statement'!U29

Sheet Geography & Products
A1: Mondelez International, Inc. — Geography & Products
A2: $ in millions except per-share data | USD | as of 2026-09-15
C3: FY2016 | D3: FY2017 | E3: FY2018 | F3: FY2019 | G3: FY2020 | H3: FY2021 | I3: FY2022 | J3: FY2023 | K3: FY2024 | L3: FY2025 | M3: · | N3: · | O3: · | P3: 3Q2024 | Q3: 1Q2025 | R3: 2Q2025 | S3: 3Q2025 | T3: 1Q2026 | U3: 2Q2026
C4: 2016-12-31 | D4: 2017-12-31 | E4: 2018-12-31 | F4: 2019-12-31 | G4: 2020-12-31 | H4: 2021-12-31 | I4: 2022-12-31 | J4: 2023-12-31 | K4: 2024-12-31 | L4: 2025-12-31 | P4: 2024-09-30 | Q4: 2025-03-31 | R4: 2025-06-30 | S4: 2025-09-30 | T4: 2026-03-31 | U4: 2026-06-30
A6: CONTENTS
A7: =HYPERLINK("#'Geography & Products'!A13","1. PRODUCT CATEGORY REVENUE — TOTAL COMPANY")
A8: =HYPERLINK("#'Geography & Products'!A22","2. BISCUITS & BAKED SNACKS BY SEGMENT")
A9: =HYPERLINK("#'Geography & Products'!A28","3. CHOCOLATE BY SEGMENT")
A10: =HYPERLINK("#'Geography & Products'!A34","4. GUM & CANDY BY SEGMENT")
A11: =HYPERLINK("#'Geography & Products'!A40","5. BEVERAGES & CHEESE/GROCERY BY SEGMENT")
A13: 1. PRODUCT CATEGORY REVENUE — TOTAL COMPANY
A14: Biscuits & Baked Snacks | B14: FY2023-2025 & 3Q2024 only; earlier years use an incompatible product-category taxonomy (no separate Gum & Candy category, $ not disclosed) | J14: 17629 | K14: 17802 | L14: 18391 | P14: 4605
A15: Chocolate | J15: 10619 | K15: 11248 | L15: 12696 | P15: 2783
A16: Gum & Candy | J16: 4426 | K16: 4040 | L16: 4060 | P16: 1023
A17: Beverages | J17: 1185 | K17: 1096 | L17: 1006 | P17: 237
A18: Cheese & Grocery | J18: 2157 | K18: 2255 | L18: 2384 | P18: 556
A19: Total Net Revenues (product categories) | J19: =J14+J15+J16+J17+J18 | K19: =K14+K15+K16+K17+K18 | L19: =L14+L15+L16+L17+L18 | P19: =P14+P15+P16+P17+P18
A20: vs IS Net Revenues (should be ~0) | J20: =J19-'Income Statement'!J12 | K20: =K19-'Income Statement'!K12 | L20: =L19-'Income Statement'!L12 | P20: =P19-'Income Statement'!P12
A22: 2. BISCUITS & BAKED SNACKS BY SEGMENT
A23: Latin America | J23: 1193 | K23: 1199 | L23: 1155 | P23: 312
A24: AMEA | J24: 2488 | K24: 2573 | L24: 2935 | P24: 661
A25: Europe | J25: 4429 | K25: 4425 | L25: 4970 | P25: 1162
A26: North America | J26: 9519 | K26: 9605 | L26: 9331 | P26: 2470
A28: 3. CHOCOLATE BY SEGMENT
A29: Latin America | J29: 1357 | K29: 1276 | L29: 1414 | P29: 299
A30: AMEA | J30: 2690 | K30: 2831 | L30: 3047 | P30: 752
A31: Europe | J31: 6225 | K31: 6773 | L31: 7799 | P31: 1640
A32: North America | J32: 347 | K32: 368 | L32: 436 | P32: 92
A34: 4. GUM & CANDY BY SEGMENT
A35: Latin America | J35: 1509 | K35: 1512 | L35: 1507 | P35: 374
A36: AMEA | J36: 893 | K36: 947 | L36: 989 | P36: 240
A37: Europe | J37: 812 | K37: 644 | L37: 652 | P37: 145
A38: North America | J38: 1212 | K38: 937 | L38: 912 | P38: 264
A40: 5. BEVERAGES & CHEESE/GROCERY BY SEGMENT
A41: Beverages — Latin America | J41: 457 | K41: 454 | L41: 344 | P41: 104
A42: Beverages — AMEA | J42: 593 | K42: 525 | L42: 517 | P42: 105
A43: Beverages — Europe | J43: 135 | K43: 117 | L43: 145 | P43: 28
A44: Cheese & Grocery — Latin America | J44: 490 | K44: 485 | L44: 479 | P44: 115
A45: Cheese & Grocery — AMEA | J45: 411 | K45: 420 | L45: 444 | P45: 93
A46: Cheese & Grocery — Europe | J46: 1256 | K46: 1350 | L46: 1461 | P46: 348

Sheet Derived Metrics
A1: Mondelez International, Inc. — Derived Metrics
A2: $ in millions except per-share data | USD | as of 2026-09-15
C3: FY2016 | D3: FY2017 | E3: FY2018 | F3: FY2019 | G3: FY2020 | H3: FY2021 | I3: FY2022 | J3: FY2023 | K3: FY2024 | L3: FY2025 | M3: · | N3: · | O3: · | P3: 3Q2024 | Q3: 1Q2025 | R3: 2Q2025 | S3: 3Q2025 | T3: 1Q2026 | U3: 2Q2026
C4: 2016-12-31 | D4: 2017-12-31 | E4: 2018-12-31 | F4: 2019-12-31 | G4: 2020-12-31 | H4: 2021-12-31 | I4: 2022-12-31 | J4: 2023-12-31 | K4: 2024-12-31 | L4: 2025-12-31 | P4: 2024-09-30 | Q4: 2025-03-31 | R4: 2025-06-30 | S4: 2025-09-30 | T4: 2026-03-31 | U4: 2026-06-30
A6: CONTENTS
A7: =HYPERLINK("#'Derived Metrics'!A18","1. PROFITABILITY")
A8: =HYPERLINK("#'Derived Metrics'!A26","2. RETURNS")
A9: =HYPERLINK("#'Derived Metrics'!A34","3. LEVERAGE")
A10: =HYPERLINK("#'Derived Metrics'!A40","4. SOLVENCY")
A11: =HYPERLINK("#'Derived Metrics'!A44","5. LIQUIDITY")
A12: =HYPERLINK("#'Derived Metrics'!A49","6. COVERAGE")
A13: =HYPERLINK("#'Derived Metrics'!A53","7. CASH CONVERSION")
A14: =HYPERLINK("#'Derived Metrics'!A61","8. EARNINGS QUALITY")
A15: =HYPERLINK("#'Derived Metrics'!A65","9. GROWTH")
A16: =HYPERLINK("#'Derived Metrics'!A73","10. WORKING CAPITAL")
A18: 1. PROFITABILITY
A19: Gross Margin | C19: ='Income Statement'!C16 | D19: ='Income Statement'!D16 | E19: ='Income Statement'!E16 | F19: ='Income Statement'!F16 | G19: ='Income Statement'!G16 | H19: ='Income Statement'!H16 | I19: ='Income Statement'!I16 | J19: ='Income Statement'!J16 | ... L19: ='Income Statement'!L16 | P19: ='Income Statement'!P16 | Q19: ='Income Statement'!Q16 | R19: ='Income Statement'!R16 | S19: ='Income Statement'!S16 | T19: ='Income Statement'!T16 | U19: ='Income Statement'!U16
A20: Operating Margin | C20: ='Income Statement'!C23 | D20: ='Income Statement'!D23 | E20: ='Income Statement'!E23 | F20: ='Income Statement'!F23 | G20: ='Income Statement'!G23 | H20: ='Income Statement'!H23 | I20: ='Income Statement'!I23 | J20: ='Income Statement'!J23 | ... L20: ='Income Statement'!L23 | P20: ='Income Statement'!P23 | Q20: ='Income Statement'!Q23 | R20: ='Income Statement'!R23 | S20: ='Income Statement'!S23 | T20: ='Income Statement'!T23 | U20: ='Income Statement'!U23
A21: EBITDA | C21: ='Income Statement'!C22+'Cash Flow'!C14 | D21: ='Income Statement'!D22+'Cash Flow'!D14 | E21: ='Income Statement'!E22+'Cash Flow'!E14 | F21: ='Income Statement'!F22+'Cash Flow'!F14 | G21: ='Income Statement'!G22+'Cash Flow'!G14 | H21: ='Income Statement'!H22+'Cash Flow'!H14 | I21: ='Income Statement'!I22+'Cash Flow'!I14 | J21: ='Income Statement'!J22+'Cash Flow'!J14 | ... L21: ='Income Statement'!L22+'Cash Flow'!L14 | P21: ='Income Statement'!P22+'Cash Flow'!P14 | Q21: ='Income Statement'!Q22+'Cash Flow'!Q14 | R21: ='Income Statement'!R22+'Cash Flow'!R14 | S21: ='Income Statement'!S22+'Cash Flow'!S14 | T21: ='Income Statement'!T22+'Cash Flow'!T14 | U21: ='Income Statement'!U22+'Cash Flow'!U14
A22: EBITDA Margin | C22: =C21/'Income Statement'!C12 | D22: =D21/'Income Statement'!D12 | E22: =E21/'Income Statement'!E12 | F22: =F21/'Income Statement'!F12 | G22: =G21/'Income Statement'!G12 | H22: =H21/'Income Statement'!H12 | I22: =I21/'Income Statement'!I12 | J22: =J21/'Income Statement'!J12 | ... L22: =L21/'Income Statement'!L12 | P22: =P21/'Income Statement'!P12 | Q22: =Q21/'Income Statement'!Q12 | R22: =R21/'Income Statement'!R12 | S22: =S21/'Income Statement'!S12 | T22: =T21/'Income Statement'!T12 | U22: =U21/'Income Statement'!U12
A23: Net Margin (attributable) | C23: ='Income Statement'!C37/'Income Statement'!C12 | D23: ='Income Statement'!D37/'Income Statement'!D12 | E23: ='Income Statement'!E37/'Income Statement'!E12 | F23: ='Income Statement'!F37/'Income Statement'!F12 | G23: ='Income Statement'!G37/'Income Statement'!G12 | H23: ='Income Statement'!H37/'Income Statement'!H12 | I23: ='Income Statement'!I37/'Income Statement'!I12 | J23: ='Income Statement'!J37/'Income Statement'!J12 | ... L23: ='Income Statement'!L37/'Income Statement'!L12 | P23: ='Income Statement'!P37/'Income Statement'!P12 | Q23: ='Income Statement'!Q37/'Income Statement'!Q12 | R23: ='Income Statement'!R37/'Income Statement'!R12 | S23: ='Income Statement'!S37/'Income Statement'!S12 | T23: ='Income Statement'!T37/'Income Statement'!T12 | U23: ='Income Statement'!U37/'Income Statement'!U12
A24: Effective Tax Rate | C24: ='Income Statement'!C31 | D24: ='Income Statement'!D31 | E24: ='Income Statement'!E31 | F24: ='Income Statement'!F31 | G24: ='Income Statement'!G31 | H24: ='Income Statement'!H31 | I24: ='Income Statement'!I31 | J24: ='Income Statement'!J31 | ... L24: ='Income Statement'!L31 | P24: ='Income Statement'!P31 | Q24: ='Income Statement'!Q31 | R24: ='Income Statement'!R31 | S24: ='Income Statement'!S31 | T24: ='Income Statement'!T31 | U24: ='Income Statement'!U31
A26: 2. RETURNS
A27: Average Total Assets | C27: =('Balance Sheet'!C30+'Balance Sheet'!B30)/2 | D27: =('Balance Sheet'!D30+'Balance Sheet'!C30)/2 | E27: =('Balance Sheet'!E30+'Balance Sheet'!D30)/2 | F27: =('Balance Sheet'!F30+'Balance Sheet'!E30)/2 | G27: =('Balance Sheet'!G30+'Balance Sheet'!F30)/2 | H27: =('Balance Sheet'!H30+'Balance Sheet'!G30)/2 | I27: =('Balance Sheet'!I30+'Balance Sheet'!H30)/2 | J27: =('Balance Sheet'!J30+'Balance Sheet'!I30)/2 | ... L27: =('Balance Sheet'!L30+'Balance Sheet'!K30)/2 | P27: =('Balance Sheet'!P30+'Balance Sheet'!O30)/2 | Q27: =('Balance Sheet'!Q30+'Balance Sheet'!P30)/2 | R27: =('Balance Sheet'!R30+'Balance Sheet'!Q30)/2 | S27: =('Balance Sheet'!S30+'Balance Sheet'!R30)/2 | T27: =('Balance Sheet'!T30+'Balance Sheet'!S30)/2 | U27: =('Balance Sheet'!U30+'Balance Sheet'!T30)/2
A28: Average Total Equity | C28: =('Balance Sheet'!C60+'Balance Sheet'!B60)/2 | D28: =('Balance Sheet'!D60+'Balance Sheet'!C60)/2 | E28: =('Balance Sheet'!E60+'Balance Sheet'!D60)/2 | F28: =('Balance Sheet'!F60+'Balance Sheet'!E60)/2 | G28: =('Balance Sheet'!G60+'Balance Sheet'!F60)/2 | H28: =('Balance Sheet'!H60+'Balance Sheet'!G60)/2 | I28: =('Balance Sheet'!I60+'Balance Sheet'!H60)/2 | J28: =('Balance Sheet'!J60+'Balance Sheet'!I60)/2 | ... L28: =('Balance Sheet'!L60+'Balance Sheet'!K60)/2 | P28: =('Balance Sheet'!P60+'Balance Sheet'!O60)/2 | Q28: =('Balance Sheet'!Q60+'Balance Sheet'!P60)/2 | R28: =('Balance Sheet'!R60+'Balance Sheet'!Q60)/2 | S28: =('Balance Sheet'!S60+'Balance Sheet'!R60)/2 | T28: =('Balance Sheet'!T60+'Balance Sheet'!S60)/2 | U28: =('Balance Sheet'!U60+'Balance Sheet'!T60)/2
A29: Return on Assets (ROA) | C29: ='Income Statement'!C37/C27 | D29: ='Income Statement'!D37/D27 | E29: ='Income Statement'!E37/E27 | F29: ='Income Statement'!F37/F27 | G29: ='Income Statement'!G37/G27 | H29: ='Income Statement'!H37/H27 | I29: ='Income Statement'!I37/I27 | J29: ='Income Statement'!J37/J27 | ... L29: ='Income Statement'!L37/L27 | P29: ='Income Statement'!P37/P27 | Q29: ='Income Statement'!Q37/Q27 | R29: ='Income Statement'!R37/R27 | S29: ='Income Statement'!S37/S27 | T29: ='Income Statement'!T37/T27 | U29: ='Income Statement'!U37/U27
A30: Return on Equity (ROE) | C30: ='Income Statement'!C37/C28 | D30: ='Income Statement'!D37/D28 | E30: ='Income Statement'!E37/E28 | F30: ='Income Statement'!F37/F28 | G30: ='Income Statement'!G37/G28 | H30: ='Income Statement'!H37/H28 | I30: ='Income Statement'!I37/I28 | J30: ='Income Statement'!J37/J28 | ... L30: ='Income Statement'!L37/L28 | P30: ='Income Statement'!P37/P28 | Q30: ='Income Statement'!Q37/Q28 | R30: ='Income Statement'!R37/R28 | S30: ='Income Statement'!S37/S28 | T30: ='Income Statement'!T37/T28 | U30: ='Income Statement'!U37/U28
A31: Return on Invested Capital (ROIC, approx.) | C31: ='Income Statement'!C22*(1-'Income Statement'!C31)/('Balance Sheet'!C60+'Balance Sheet'!C43+'Balance Sheet'!C35+'Balance Sheet'!C34-'Balance Sheet'!C14) | D31: ='Income Statement'!D22*(1-'Income Statement'!D31)/('Balance Sheet'!D60+'Balance Sheet'!D43+'Balance Sheet'!D35+'Balance Sheet'!D34-'Balance Sheet'!D14) | E31: ='Income Statement'!E22*(1-'Income Statement'!E31)/('Balance Sheet'!E60+'Balance Sheet'!E43+'Balance Sheet'!E35+'Balance Sheet'!E34-'Balance Sheet'!E14) | F31: ='Income Statement'!F22*(1-'Income Statement'!F31)/('Balance Sheet'!F60+'Balance Sheet'!F43+'Balance Sheet'!F35+'Balance Sheet'!F34-'Balance Sheet'!F14) | G31: ='Income Statement'!G22*(1-'Income Statement'!G31)/('Balance Sheet'!G60+'Balance Sheet'!G43+'Balance Sheet'!G35+'Balance Sheet'!G34-'Balance Sheet'!G14) | H31: ='Income Statement'!H22*(1-'Income Statement'!H31)/('Balance Sheet'!H60+'Balance Sheet'!H43+'Balance Sheet'!H35+'Balance Sheet'!H34-'Balance Sheet'!H14) | I31: ='Income Statement'!I22*(1-'Income Statement'!I31)/('Balance Sheet'!I60+'Balance Sheet'!I43+'Balance Sheet'!I35+'Balance Sheet'!I34-'Balance Sheet'!I14) | J31: ='Income Statement'!J22*(1-'Income Statement'!J31)/('Balance Sheet'!J60+'Balance Sheet'!J43+'Balance Sheet'!J35+'Balance Sheet'!J34-'Balance Sheet'!J14) | ... L31: ='Income Statement'!L22*(1-'Income Statement'!L31)/('Balance Sheet'!L60+'Balance Sheet'!L43+'Balance Sheet'!L35+'Balance Sheet'!L34-'Balance Sheet'!L14) | P31: ='Income Statement'!P22*(1-'Income Statement'!P31)/('Balance Sheet'!P60+'Balance Sheet'!P43+'Balance Sheet'!P35+'Balance Sheet'!P34-'Balance Sheet'!P14) | Q31: ='Income Statement'!Q22*(1-'Income Statement'!Q31)/('Balance Sheet'!Q60+'Balance Sheet'!Q43+'Balance Sheet'!Q35+'Balance Sheet'!Q34-'Balance Sheet'!Q14) | R31: ='Income Statement'!R22*(1-'Income Statement'!R31)/('Balance Sheet'!R60+'Balance Sheet'!R43+'Balance Sheet'!R35+'Balance Sheet'!R34-'Balance Sheet'!R14) | S31: ='Income Statement'!S22*(1-'Income Statement'!S31)/('Balance Sheet'!S60+'Balance Sheet'!S43+'Balance Sheet'!S35+'Balance Sheet'!S34-'Balance Sheet'!S14) | T31: ='Income Statement'!T22*(1-'Income Statement'!T31)/('Balance Sheet'!T60+'Balance Sheet'!T43+'Balance Sheet'!T35+'Balance Sheet'!T34-'Balance Sheet'!T14) | U31: ='Income Statement'!U22*(1-'Income Statement'!U31)/('Balance Sheet'!U60+'Balance Sheet'!U43+'Balance Sheet'!U35+'Balance Sheet'!U34-'Balance Sheet'!U14)
A32: Asset Turnover | C32: ='Income Statement'!C12/C27 | D32: ='Income Statement'!D12/D27 | E32: ='Income Statement'!E12/E27 | F32: ='Income Statement'!F12/F27 | G32: ='Income Statement'!G12/G27 | H32: ='Income Statement'!H12/H27 | I32: ='Income Statement'!I12/I27 | J32: ='Income Statement'!J12/J27 | ... L32: ='Income Statement'!L12/L27 | P32: ='Income Statement'!P12/P27 | Q32: ='Income Statement'!Q12/Q27 | R32: ='Income Statement'!R12/R27 | S32: ='Income Statement'!S12/S27 | T32: ='Income Statement'!T12/T27 | U32: ='Income Statement'!U12/U27
A34: 3. LEVERAGE
A35: Total Debt (ST borrowings + Current LTD + LT debt) | C35: ='Balance Sheet'!C34+'Balance Sheet'!C35+'Balance Sheet'!C43 | D35: ='Balance Sheet'!D34+'Balance Sheet'!D35+'Balance Sheet'!D43 | E35: ='Balance Sheet'!E34+'Balance Sheet'!E35+'Balance Sheet'!E43 | F35: ='Balance Sheet'!F34+'Balance Sheet'!F35+'Balance Sheet'!F43 | G35: ='Balance Sheet'!G34+'Balance Sheet'!G35+'Balance Sheet'!G43 | H35: ='Balance Sheet'!H34+'Balance Sheet'!H35+'Balance Sheet'!H43 | I35: ='Balance Sheet'!I34+'Balance Sheet'!I35+'Balance Sheet'!I43 | J35: ='Balance Sheet'!J34+'Balance Sheet'!J35+'Balance Sheet'!J43 | ... L35: ='Balance Sheet'!L34+'Balance Sheet'!L35+'Balance Sheet'!L43 | P35: ='Balance Sheet'!P34+'Balance Sheet'!P35+'Balance Sheet'!P43 | Q35: ='Balance Sheet'!Q34+'Balance Sheet'!Q35+'Balance Sheet'!Q43 | R35: ='Balance Sheet'!R34+'Balance Sheet'!R35+'Balance Sheet'!R43 | S35: ='Balance Sheet'!S34+'Balance Sheet'!S35+'Balance Sheet'!S43 | T35: ='Balance Sheet'!T34+'Balance Sheet'!T35+'Balance Sheet'!T43 | U35: ='Balance Sheet'!U34+'Balance Sheet'!U35+'Balance Sheet'!U43
A36: Net Debt | C36: =C35-'Balance Sheet'!C14 | D36: =D35-'Balance Sheet'!D14 | E36: =E35-'Balance Sheet'!E14 | F36: =F35-'Balance Sheet'!F14 | G36: =G35-'Balance Sheet'!G14 | H36: =H35-'Balance Sheet'!H14 | I36: =I35-'Balance Sheet'!I14 | J36: =J35-'Balance Sheet'!J14 | ... L36: =L35-'Balance Sheet'!L14 | P36: =P35-'Balance Sheet'!P14 | Q36: =Q35-'Balance Sheet'!Q14 | R36: =R35-'Balance Sheet'!R14 | S36: =S35-'Balance Sheet'!S14 | T36: =T35-'Balance Sheet'!T14 | U36: =U35-'Balance Sheet'!U14
A37: Net Debt / EBITDA | C37: =C36/C21 | D37: =D36/D21 | E37: =E36/E21 | F37: =F36/F21 | G37: =G36/G21 | H37: =H36/H21 | I37: =I36/I21 | J37: =J36/J21 | ... L37: =L36/L21 | P37: =P36/P21 | Q37: =Q36/Q21 | R37: =R36/R21 | S37: =S36/S21 | T37: =T36/T21 | U37: =U36/U21
A38: Debt / Equity | C38: =C35/'Balance Sheet'!C60 | D38: =D35/'Balance Sheet'!D60 | E38: =E35/'Balance Sheet'!E60 | F38: =F35/'Balance Sheet'!F60 | G38: =G35/'Balance Sheet'!G60 | H38: =H35/'Balance Sheet'!H60 | I38: =I35/'Balance Sheet'!I60 | J38: =J35/'Balance Sheet'!J60 | ... L38: =L35/'Balance Sheet'!L60 | P38: =P35/'Balance Sheet'!P60 | Q38: =Q35/'Balance Sheet'!Q60 | R38: =R35/'Balance Sheet'!R60 | S38: =S35/'Balance Sheet'!S60 | T38: =T35/'Balance Sheet'!T60 | U38: =U35/'Balance Sheet'!U60
A40: 4. SOLVENCY
A41: Equity Ratio (Equity / Assets) | C41: ='Balance Sheet'!C60/'Balance Sheet'!C30 | D41: ='Balance Sheet'!D60/'Balance Sheet'!D30 | E41: ='Balance Sheet'!E60/'Balance Sheet'!E30 | F41: ='Balance Sheet'!F60/'Balance Sheet'!F30 | G41: ='Balance Sheet'!G60/'Balance Sheet'!G30 | H41: ='Balance Sheet'!H60/'Balance Sheet'!H30 | I41: ='Balance Sheet'!I60/'Balance Sheet'!I30 | J41: ='Balance Sheet'!J60/'Balance Sheet'!J30 | ... L41: ='Balance Sheet'!L60/'Balance Sheet'!L30 | P41: ='Balance Sheet'!P60/'Balance Sheet'!P30 | Q41: ='Balance Sheet'!Q60/'Balance Sheet'!Q30 | R41: ='Balance Sheet'!R60/'Balance Sheet'!R30 | S41: ='Balance Sheet'!S60/'Balance Sheet'!S30 | T41: ='Balance Sheet'!T60/'Balance Sheet'!T30 | U41: ='Balance Sheet'!U60/'Balance Sheet'!U30
A42: Debt / Assets | C42: =C35/'Balance Sheet'!C30 | D42: =D35/'Balance Sheet'!D30 | E42: =E35/'Balance Sheet'!E30 | F42: =F35/'Balance Sheet'!F30 | G42: =G35/'Balance Sheet'!G30 | H42: =H35/'Balance Sheet'!H30 | I42: =I35/'Balance Sheet'!I30 | J42: =J35/'Balance Sheet'!J30 | ... L42: =L35/'Balance Sheet'!L30 | P42: =P35/'Balance Sheet'!P30 | Q42: =Q35/'Balance Sheet'!Q30 | R42: =R35/'Balance Sheet'!R30 | S42: =S35/'Balance Sheet'!S30 | T42: =T35/'Balance Sheet'!T30 | U42: =U35/'Balance Sheet'!U30
A44: 5. LIQUIDITY
A45: Current Ratio | C45: ='Balance Sheet'!C19/'Balance Sheet'!C40 | D45: ='Balance Sheet'!D19/'Balance Sheet'!D40 | E45: ='Balance Sheet'!E19/'Balance Sheet'!E40 | F45: ='Balance Sheet'!F19/'Balance Sheet'!F40 | G45: ='Balance Sheet'!G19/'Balance Sheet'!G40 | H45: ='Balance Sheet'!H19/'Balance Sheet'!H40 | I45: ='Balance Sheet'!I19/'Balance Sheet'!I40 | J45: ='Balance Sheet'!J19/'Balance Sheet'!J40 | ... L45: ='Balance Sheet'!L19/'Balance Sheet'!L40 | P45: ='Balance Sheet'!P19/'Balance Sheet'!P40 | Q45: ='Balance Sheet'!Q19/'Balance Sheet'!Q40 | R45: ='Balance Sheet'!R19/'Balance Sheet'!R40 | S45: ='Balance Sheet'!S19/'Balance Sheet'!S40 | T45: ='Balance Sheet'!T19/'Balance Sheet'!T40 | U45: ='Balance Sheet'!U19/'Balance Sheet'!U40
A46: Quick Ratio | C46: =('Balance Sheet'!C14+'Balance Sheet'!C15+'Balance Sheet'!C16)/'Balance Sheet'!C40 | D46: =('Balance Sheet'!D14+'Balance Sheet'!D15+'Balance Sheet'!D16)/'Balance Sheet'!D40 | E46: =('Balance Sheet'!E14+'Balance Sheet'!E15+'Balance Sheet'!E16)/'Balance Sheet'!E40 | F46: =('Balance Sheet'!F14+'Balance Sheet'!F15+'Balance Sheet'!F16)/'Balance Sheet'!F40 | G46: =('Balance Sheet'!G14+'Balance Sheet'!G15+'Balance Sheet'!G16)/'Balance Sheet'!G40 | H46: =('Balance Sheet'!H14+'Balance Sheet'!H15+'Balance Sheet'!H16)/'Balance Sheet'!H40 | I46: =('Balance Sheet'!I14+'Balance Sheet'!I15+'Balance Sheet'!I16)/'Balance Sheet'!I40 | J46: =('Balance Sheet'!J14+'Balance Sheet'!J15+'Balance Sheet'!J16)/'Balance Sheet'!J40 | ... L46: =('Balance Sheet'!L14+'Balance Sheet'!L15+'Balance Sheet'!L16)/'Balance Sheet'!L40 | P46: =('Balance Sheet'!P14+'Balance Sheet'!P15+'Balance Sheet'!P16)/'Balance Sheet'!P40 | Q46: =('Balance Sheet'!Q14+'Balance Sheet'!Q15+'Balance Sheet'!Q16)/'Balance Sheet'!Q40 | R46: =('Balance Sheet'!R14+'Balance Sheet'!R15+'Balance Sheet'!R16)/'Balance Sheet'!R40 | S46: =('Balance Sheet'!S14+'Balance Sheet'!S15+'Balance Sheet'!S16)/'Balance Sheet'!S40 | T46: =('Balance Sheet'!T14+'Balance Sheet'!T15+'Balance Sheet'!T16)/'Balance Sheet'!T40 | U46: =('Balance Sheet'!U14+'Balance Sheet'!U15+'Balance Sheet'!U16)/'Balance Sheet'!U40
...

Sheet Sources
A1: Mondelez International, Inc. — Sources
A2: $ in millions except per-share data | USD | as of 2026-09-15
A4: Sources & Methodology
A6: Data provenance
A7: All figures extracted from SEC EDGAR filings (10-K / 10-Q primary financial statement HTML tables) collected under research/companies/US/MDLZ-mondelez/outputs/company-research-to-excel-20260915/tables.json (1,598 tables). No financial_input.json existed for this company; the model was built in bundle-only mode directly from the collector output.
A9: Filings used
A10: 10-K FY2016 (period end 2016-12-31)
A11: 10-K FY2017 (2017-12-31)
A12: 10-K FY2018 (2018-12-31)
A13: 10-K FY2019 (2019-12-31)
A14: 10-K FY2020 (2020-12-31)
A15: 10-K FY2021 (2021-12-31)
... A52: This workbook is a mechanical financial-model / data-preparation artifact only. It contains no investment thesis, valuation opinion, price target, or buy/sell/hold recommendation.
