Workbook

Sheet Cover
A1: McDonald's Corporation — Cover
A2: $ in millions except per-share data | USD | as of 2026-10-08
A4: McDonald's Corporation - Financial Model Workbook
A6: Ticker / exchange | B6: MCD / NYSE
A7: SEC registrant / CIK | B7: MCDONALDS CORP / 0000063908
A8: Reporting framework | B8: US GAAP (per SEC Form 10-K / 10-Q); consolidated
A9: Fiscal year end | B9: December 31
A10: Currency and units | B10: USD millions except per-share data and restaurant counts
A11: Annual window | B11: FY2016-FY2025 (10 Form 10-K filings; latest-filing-wins precedence for restated periods)
A12: Quarterly window | B12: 3Q2024-2Q2026 (6 Form 10-Q filings: 3Q24, 1Q25, 2Q25, 3Q25, 1Q26, 2Q26)
A13: Latest filing covered | B13: Form 10-Q for the quarter ended 2026-06-30 (filed 2026-08-07); 3Q2026 10-Q not yet filed at 2026-10-08
A14: Research as-of date | B14: 2026-10-08
A16: Colour legend
A17: Blue | B17: Hard-coded value copied from a filed statement table
A18: Black | B18: Formula / analyst calculation
A19: Green | B19: Cross-sheet link
A20: Grey italic | B20: Memo / ratio rows
A21: Amber check rows | B21: Rounding tie-outs of as-filed integers (+/-2 expected); red = strict tie-out failure
A23: Sheet directory
A24: Income Statement (IS) | B24: As-reported income statement, per-share data, tie-outs
A25: Balance Sheet (BS) | B25: As-reported balance sheet, tie-outs, debt and lease summary
A26: Cash Flow (CF) | B26: As-reported cash flow, cash walk, free cash flow analytics
A27: Segments (SEG) | B27: Reportable-segment revenue, operating income, assets, capex, D&A; revenue by type; restaurant margins by segment; SG&A by segment and incentive compensation; superseded FY2016-FY2018 structure
A28: Operating Metrics (OM) | B28: Restaurant counts (type and segment), net additions, comparable sales and guest counts, systemwide sales growth, franchised sales, franchised revenue mix, currency translation impact, non-GAAP reconciliations, capex by purpose, shareholder returns, debt statistics
A29: Note Schedules (NS) | B29: Property and equipment, income taxes, other operating and nonoperating components, goodwill by segment, debt by currency and maturity, rent and lease commitments, franchise-arrangement assets, advertising, share-based compensation, text-only operating facts
A30: Year-End Schedules | B30: Debt, lease and minimum-rent maturity ladders (Dec 2025 and Dec 2024), restructuring reserve roll-forward, equity-method investees
A31: Outlook & Text KPIs | B31: Verbatim management outlook statements FY2016-FY2025 10-Ks (FORWARD-LOOKING, not realised) and operating-KPI sentences FY2021-FY2025 with line locators
A32: Derived Metrics (DM) | B32: Margins, returns, leverage, liquidity, cash conversion, growth (formulas on the statements)
A33: Sources | B33: Filing register, extraction method, comparability and restatement notes
A35: Comparability and method notes
A36: 4Q columns marked * | B36: Income statement and cash flow 4Q = FY (10-K) less nine-month YTD (10-Q): analyst derivation, not a filed quarterly statement. Balance-sheet 4Q columns are the filed 10-K year-end balances. EPS / share counts are not derived.
A37: Revenue recast | B37: FY2018-FY2019 were recast in the FY2020 10-K (new 'Other revenues' and 'Other restaurant expenses' lines; revenue and cost both higher, operating income unchanged). FY2016-FY2017 are as originally reported and are not comparable at line level.
A38: Segment structure | B38: Current segments (U.S. / International Operated Markets / International Developmental Licensed Markets & Corporate) available from FY2017 (FY2019 10-K recast). FY2016 exists only under the superseded structure.
A39: Negative equity | B39: Shareholders' equity is a deficit in every period; ROE and debt/equity are not meaningful and are omitted.
A40: Precision | B40: FY2016-FY2019 10-K tables show one decimal; FY2018 onward as later recast are whole millions. Tie-outs therefore show +/-1-2 rounding in recent years.
A41: Systemwide sales | B41: The company does not tabulate Systemwide sales in dollars; the OM row reconstructs it as franchised sales + Company-owned and operated sales (analyst calculation). Cross-check: 2025 SG&A / reconstructed Systemwide sales = 2.2%, equal to the company's own 'about 2.2% of Systemwide sales' statement.
A42: Text-only facts | B42: Rows built from MD&A / note prose (advertising, variable rent, franchise-arrangement property, debt fair value, segment franchised %, employees, delivery / drive thru) are company statements rounded as printed; they are not audited tables.
A43: Guidance | B43: The Outlook & Text KPIs sheet quotes management guidance and targets verbatim. They are forward-looking company statements (SEC filing text), not realised data.
A44: Not loaded | B44: Official-site material and earnings-call transcripts (out of scope); 1Q/2Q 2024 quarterly flows (prior-year comparatives in the 2025 10-Qs); deferred-tax components, effective-tax-rate reconciliation, unrecognised tax benefits, derivative / fair-value tables, option and RSU activity, monthly repurchase table and the 5-year shareholder-return index (financial-reporting detail outside the operating scope of this pass); FY2016-FY2018 old-structure MD&A tables other than those shown in the superseded-structure block; 10-Q MD&A KPI tables.

Sheet Income Statement
A1: McDonald's Corporation — Income Statement
A2: $ in millions except per-share data | USD | as of 2026-10-08
C3: FY2016 | D3: FY2017 | E3: FY2018 | F3: FY2019 | G3: FY2020 | H3: FY2021 | I3: FY2022 | J3: FY2023 | K3: FY2024 | L3: FY2025 | M3: · | N3: 3Q2024 | O3: 4Q2024* | P3: 1Q2025 | Q3: 2Q2025 | R3: 3Q2025 | S3: 4Q2025* | T3: 1Q2026 | U3: 2Q2026
C4: 2016-12-31 | D4: 2017-12-31 | E4: 2018-12-31 | F4: 2019-12-31 | G4: 2020-12-31 | H4: 2021-12-31 | I4: 2022-12-31 | J4: 2023-12-31 | K4: 2024-12-31 | L4: 2025-12-31 | N4: 2024-09-30 | O4: 2024-12-31 | P4: 2025-03-31 | Q4: 2025-06-30 | R4: 2025-09-30 | S4: 2025-12-31 | T4: 2026-03-31 | U4: 2026-06-30
A6: CONTENTS
A7: =HYPERLINK("#'Income Statement'!A11","1. INCOME STATEMENT - AS REPORTED") -> 1. INCOME STATEMENT - AS REPORTED
A8: =HYPERLINK("#'Income Statement'!A43","2. PER-SHARE DATA AND SHARE COUNT") -> 2. PER-SHARE DATA AND SHARE COUNT
A9: =HYPERLINK("#'Income Statement'!A51","3. TIE-OUT CHECKS") -> 3. TIE-OUT CHECKS
A11: 1. INCOME STATEMENT - AS REPORTED
A12: Revenues from franchised restaurants | C12: 9326.9 | D12: 10101.5 | E12: 11012.5 | F12: 11655.7 | G12: 10726.1 | H12: 13085.4 | I12: 14106 | J12: 15437 | K12: 15715 | L12: 16548 | N12: 4094 | O12: 3959 | P12: 3661 | Q12: 4213 | R12: 4363 | S12: 4310 | T12: 4007 | U12: 4393
A13: YoY Growth | D13: =IF(N(C12)=0,"",D12/C12-1) -> 0.083050102 | E13: =IF(N(D12)=0,"",E12/D12-1) -> 0.090184626 | F13: =IF(N(E12)=0,"",F12/E12-1) -> 0.058406356 | G13: =IF(N(F12)=0,"",G12/F12-1) -> -0.07975497 | H13: =IF(N(G12)=0,"",H12/G12-1) -> 0.21995879 | I13: =IF(N(H12)=0,"",I12/H12-1) -> 0.077995323 | J13: =IF(N(I12)=0,"",J12/I12-1) -> 0.094357011 | K13: =IF(N(J12)=0,"",K12/J12-1) -> 0.01800868 | L13: =IF(N(K12)=0,"",L12/K12-1) -> 0.053006682 | R13: =R12/N12-1 -> 0.065705911 | S13: =S12/O12-1 -> 0.088658752 | T13: =T12/P12-1 -> 0.094509697 | U13: =U12/Q12-1 -> 0.042724899
A14: Sales by Company-owned and operated restaurants | B14: Captioned 'Sales by Company-operated restaurants' in 10-Ks through FY2023 | C14: 15295 | D14: 12718.9 | E14: 10012.7 | F14: 9420.8 | G14: 8139.2 | H14: 9787.4 | I14: 8748 | J14: 9742 | K14: 9782 | L14: 9690 | N14: 2656 | O14: 2310 | P14: 2132 | Q14: 2458 | R14: 2563 | S14: 2536 | T14: 2317 | U14: 2525
A15: YoY Growth | D15: =IF(N(C14)=0,"",D14/C14-1) -> -0.16842759 | E15: =IF(N(D14)=0,"",E14/D14-1) -> -0.21276997 | F15: =IF(N(E14)=0,"",F14/E14-1) -> -0.059114924 | G15: =IF(N(F14)=0,"",G14/F14-1) -> -0.1360394 | H15: =IF(N(G14)=0,"",H14/G14-1) -> 0.20250147 | I15: =IF(N(H14)=0,"",I14/H14-1) -> -0.10619776 | J15: =IF(N(I14)=0,"",J14/I14-1) -> 0.11362597 | K15: =IF(N(J14)=0,"",K14/J14-1) -> 0.0041059331 | L15: =IF(N(K14)=0,"",L14/K14-1) -> -0.0094050296
A16: Other revenues | B16: Line first presented in FY2020 10-K with FY2018-FY2019 recast; FY2016-FY2017 pre-date the recast (no separate line) | E16: 232.7 | F16: 287.9 | G16: 342.5 | H16: 350.1 | I16: 328 | J16: 316 | K16: 423 | L16: 647 | N16: 124 | O16: 119 | P16: 162 | Q16: 172 | R16: 151 | S16: 162 | T16: 193 | U16: 182
A17: Total revenues | C17: 24621.9 | D17: 22820.4 | E17: 21257.9 | F17: 21364.4 | G17: 19207.8 | H17: 23222.9 | I17: 23183 | J17: 25494 | K17: 25920 | L17: 26885 | N17: 6873 | O17: 6388 | P17: 5956 | Q17: 6843 | R17: 7078 | S17: 7009 | T17: 6517 | U17: 7099
A18: YoY Growth | D18: =IF(N(C17)=0,"",D17/C17-1) -> -0.073166571 | E18: =IF(N(D17)=0,"",E17/D17-1) -> -0.06846944 | F18: =IF(N(E17)=0,"",F17/E17-1) -> 0.0050099022 | G18: =IF(N(F17)=0,"",G17/F17-1) -> -0.10094363 | H18: =IF(N(G17)=0,"",H17/G17-1) -> 0.20903487 | I18: =IF(N(H17)=0,"",I17/H17-1) -> -0.0017181317 | J18: =IF(N(I17)=0,"",J17/I17-1) -> 0.099685114 | K18: =IF(N(J17)=0,"",K17/J17-1) -> 0.016709814 | L18: =IF(N(K17)=0,"",L17/K17-1) -> 0.037229938 | R18: =IF(N(N17)=0,"",R17/N17-1) -> 0.029826859 | S18: =IF(N(O17)=0,"",S17/O17-1) -> 0.097213525 | T18: =IF(N(P17)=0,"",T17/P17-1) -> 0.094190732 | U18: =IF(N(Q17)=0,"",U17/Q17-1) -> 0.037410492
A20: Franchised restaurants-occupancy expenses | C20: 1718.4 | D20: 1790 | E20: 1973.3 | F20: 2200.6 | G20: 2207.5 | H20: 2335 | I20: 2350 | J20: 2475 | K20: 2536 | L20: 2618 | N20: 646 | O20: 634 | P20: 620 | Q20: 654 | R20: 666 | S20: 678 | T20: 676 | U20: 680
A21: Company-owned and operated: Food & paper | C21: 4896.9 | D21: 4033.5 | E21: 3153.8 | F21: 2980.3 | G21: 2564.2 | H21: 3096.8 | I21: 2737 | J21: 3039 | K21: 2995 | L21: 3006
A22: Company-owned and operated: Payroll & employee benefits | C22: 4134.2 | D22: 3528.5 | E22: 2937.9 | F22: 2704.4 | G22: 2416.4 | H22: 2677.2 | I22: 2617 | J22: 2886 | K22: 2959 | L22: 2905
A23: Company-owned and operated: Occupancy & other operating expenses | C23: 3667.7 | D23: 2847.6 | E23: 2174.2 | F23: 2075.9 | G23: 2000.6 | H23: 2273.3 | I23: 2026 | J23: 2299 | K23: 2381 | L23: 2358
A24: Company-owned and operated restaurant expenses (10-Q single-line) | B24: 10-Q presents one line; 10-K presents the three components above. 4Q* = FY components less 9M YTD | N24: 2248 | O24: 1977 | P24: 1859 | Q24: 2078 | R24: 2172 | S24: 2160 | T24: 2032 | U24: 2138
A25: Company-owned and operated restaurant expenses | C25: =C21+C22+C23 -> 12698.8 | D25: =D21+D22+D23 -> 10409.6 | E25: =E21+E22+E23 -> 8265.9 | F25: =F21+F22+F23 -> 7760.6 | G25: =G21+G22+G23 -> 6981.2 | H25: =H21+H22+H23 -> 8047.3 | I25: =I21+I22+I23 -> 7380 | J25: =J21+J22+J23 -> 8224 | ... L25: =L21+L22+L23 -> 8269 | N25: =N24 -> 2248 | O25: =O24 -> 1977 | P25: =P24 -> 1859 | Q25: =Q24 -> 2078 | R25: =R24 -> 2172 | S25: =S24 -> 2160 | T25: =T24 -> 2032 | U25: =U24 -> 2138
A26: Other restaurant expenses | B26: Line first presented in FY2020 10-K with FY2018-FY2019 recast | E26: 186.1 | F26: 223.8 | G26: 267 | H26: 260.4 | I26: 245 | J26: 232 | K26: 339 | L26: 564 | N26: 104 | O26: 98 | P26: 140 | Q26: 149 | R26: 135 | S26: 140 | T26: 166 | U26: 163
A27: SG&A (single-line presentation, FY2016-FY2017) | C27: 2384.5 | D27: 2231.3
A28: SG&A: Depreciation and amortization | E28: 214.8 | F28: 262.5 | G28: 300.6 | H28: 329.7 | I28: 370 | J28: 382 | K28: 447 | L28: 457 | N28: 111 | O28: 136 | P28: 107 | Q28: 106 | R28: 121 | S28: 124 | T28: 111 | U28: 111
A29: SG&A: Other | E29: 1985.4 | F29: 1966.9 | G29: 2245 | H29: 2377.8 | I29: 2492 | J29: 2435 | K29: 2412 | L29: 2583 | N29: 536 | O29: 664 | P29: 575 | Q29: 595 | R29: 664 | S29: 749 | T29: 648 | U29: 706
A30: Selling, general & administrative expenses | B30: Analyst sum of as-filed components; filed as one line FY2016-FY2017 | C30: =C27+C28+C29 -> 2384.5 | D30: =D27+D28+D29 -> 2231.3 | E30: =E27+E28+E29 -> 2200.2 | F30: =F27+F28+F29 -> 2229.4 | G30: =G27+G28+G29 -> 2545.6 | H30: =H27+H28+H29 -> 2707.5 | I30: =I27+I28+I29 -> 2862 | J30: =J27+J28+J29 -> 2817 | ... L30: =L27+L28+L29 -> 3040 | N30: =N27+N28+N29 -> 647 | O30: =O27+O28+O29 -> 800 | P30: =P27+P28+P29 -> 682 | Q30: =Q27+Q28+Q29 -> 701 | R30: =R27+R28+R29 -> 785 | S30: =S27+S28+S29 -> 873 | T30: =T27+T28+T29 -> 759 | U30: =U27+U28+U29 -> 817
A31: Other operating (income) expense, net | C31: 75.7 | D31: -1163.2 | E31: -190.2 | F31: -119.8 | G31: -117.5 | H31: -483.3 | I31: 974 | J31: 99 | K31: 139 | L31: 2 | N31: 39 | O31: 10 | P31: 7 | Q31: 29 | R31: -37 | S31: 3 | T31: -69 | U31: -37
A32: Total operating costs and expenses | C32: 16877.4 | D32: 13267.7 | E32: 12435.3 | F32: 12294.6 | G32: 11883.8 | H32: 12866.9 | I32: 13812 | J32: 13847 | K32: 14208 | L32: 14492 | N32: 3685 | O32: 3520 | P32: 3308 | Q32: 3611 | R32: 3721 | S32: 3853 | T32: 3564 | U32: 3760
A33: Operating income | C33: 7744.5 | D33: 9552.7 | E33: 8822.6 | F33: 9069.8 | G33: 7324 | H33: 10356 | I33: 9371 | J33: 11647 | K33: 11712 | L33: 12393 | N33: 3188 | O33: 2868 | P33: 2648 | Q33: 3232 | R33: 3357 | S33: 3156 | T33: 2953 | U33: 3338
A34: Operating Margin | C34: =C33/C17 -> 0.31453706 | D34: =D33/D17 -> 0.41860353 | E34: =E33/E17 -> 0.41502688 | F34: =F33/F17 -> 0.42452866 | G34: =G33/G17 -> 0.38130343 | H34: =H33/H17 -> 0.44593914 | I34: =I33/I17 -> 0.40421861 | J34: =J33/J17 -> 0.45685259 | ... L34: =L33/L17 -> 0.46096336 | N34: =N33/N17 -> 0.46384403 | O34: =O33/O17 -> 0.44896681 | P34: =P33/P17 -> 0.44459369 | Q34: =Q33/Q17 -> 0.47230747 | R34: =R33/R17 -> 0.47428652 | S34: =S33/S17 -> 0.45027821 | T34: =T33/T17 -> 0.4531226 | U34: =U33/U17 -> 0.47020707
A35: YoY Growth | D35: =IF(N(C33)=0,"",D33/C33-1) -> 0.23348183 | E35: =IF(N(D33)=0,"",E33/D33-1) -> -0.076428654 | F35: =IF(N(E33)=0,"",F33/E33-1) -> 0.028018951 | G35: =IF(N(F33)=0,"",G33/F33-1) -> -0.19248495 | H35: =IF(N(G33)=0,"",H33/G33-1) -> 0.41398143 | I35: =IF(N(H33)=0,"",I33/H33-1) -> -0.095113944 | J35: =IF(N(I33)=0,"",J33/I33-1) -> 0.24287696 | K35: =IF(N(J33)=0,"",K33/J33-1) -> 0.0055808363 | L35: =IF(N(K33)=0,"",L33/K33-1) -> 0.058145492 | R35: =IF(N(N33)=0,"",R33/N33-1) -> 0.053011292 | S35: =IF(N(O33)=0,"",S33/O33-1) -> 0.10041841 | T35: =IF(N(P33)=0,"",T33/P33-1) -> 0.11518127 | U35: =IF(N(Q33)=0,"",U33/Q33-1) -> 0.03279703
A37: Interest expense, net of capitalized interest | C37: 884.8 | D37: 921.3 | E37: 981.2 | F37: 1121.9 | G37: 1218.1 | H37: 1185.8 | I37: 1207 | J37: 1361 | K37: 1506 | L37: 1582 | N37: 381 | O37: 380 | P37: 376 | Q37: 390 | R37: 406 | S37: 410 | T37: 400 | U37: 409
A38: Nonoperating (income) expense, net | C38: -6.3 | D38: 57.9 | E38: 25.3 | F38: -70.2 | G38: -34.8 | H38: 42.3 | I38: 339 | J38: -236 | K38: -139 | L38: -87 | N38: -36 | O38: -49 | P38: -57 | Q38: -18 | R38: 1 | S38: -12 | T38: 11 | U38: -6
A39: Income before provision for income taxes | C39: 6866 | D39: 8573.5 | E39: 7816.1 | F39: 8018.1 | G39: 6140.7 | H39: 9127.9 | I39: 7825 | J39: 10522 | K39: 10345 | L39: 10897 | N39: 2843 | O39: 2538 | P39: 2330 | Q39: 2861 | R39: 2949 | S39: 2757 | T39: 2542 | U39: 2936
A40: Provision for income taxes | C40: 2179.5 | D40: 3381.2 | E40: 1891.8 | F40: 1992.7 | G40: 1410.2 | H40: 1582.7 | I40: 1648 | J40: 2053 | K40: 2121 | L40: 2334 | N40: 588 | O40: 521 | P40: 461 | Q40: 608 | R40: 671 | S40: 594 | T40: 559 | U40: 574
A41: Net income | C41: 4686.5 | D41: 5192.3 | E41: 5924.3 | F41: 6025.4 | G41: 4730.5 | H41: 7545.2 | I41: 6177 | J41: 8469 | K41: 8223 | L41: 8563 | N41: 2255 | O41: 2016 | P41: 1868 | Q41: 2253 | R41: 2278 | S41: 2164 | T41: 1983 | U41: 2362
A42: Net Margin | C42: =C41/C17 -> 0.19033868 | D42: =D41/D17 -> 0.22752888 | E42: =E41/E17 -> 0.27868698 | F42: =F41/F17 -> 0.28202992 | G42: =G41/G17 -> 0.24628016 | H42: =H41/H17 -> 0.32490344 | I42: =I41/I17 -> 0.26644524 | J42: =J41/J17 -> 0.33219581 | ... L42: =L41/L17 -> 0.31850474 | N42: =N41/N17 -> 0.32809545 | O42: =O41/O17 -> 0.31559173 | P42: =P41/P17 -> 0.31363331 | Q42: =Q41/Q17 -> 0.32924156 | R42: =R41/R17 -> 0.32184233 | S42: =S41/S17 -> 0.3087459 | T42: =T41/T17 -> 0.30428111 | U42: =U41/U17 -> 0.33272292
A43: YoY Growth | D43: =IF(N(C41)=0,"",D41/C41-1) -> 0.10792702 | E43: =IF(N(D41)=0,"",E41/D41-1) -> 0.14097799 | F43: =IF(N(E41)=0,"",F41/E41-1) -> 0.017065307 | G43: =IF(N(F41)=0,"",G41/F41-1) -> -0.21490689 | H43: =IF(N(G41)=0,"",H41/G41-1) -> 0.5950111 | I43: =IF(N(H41)=0,"",I41/H41-1) -> -0.18133383 | J43: =IF(N(I41)=0,"",J41/I41-1) -> 0.37105391 | K43: =IF(N(J41)=0,"",K41/J41-1) -> -0.029047113 | L43: =IF(N(K41)=0,"",L41/K41-1) -> 0.04134744 | R43: =IF(N(N41)=0,"",R41/N41-1) -> 0.010199557 | S43: =IF(N(O41)=0,"",S41/O41-1) -> 0.073412698 | T43: =IF(N(P41)=0,"",T41/P41-1) -> 0.061563169 | U43: =IF(N(Q41)=0,"",U41/Q41-1) -> 0.048379938
A45: 2. PER-SHARE DATA AND SHARE COUNT
...

Sheet Balance Sheet
A1: McDonald's Corporation — Balance Sheet
A2: $ in millions except per-share data | USD | as of 2026-10-08
C3: FY2016 | D3: FY2017 | E3: FY2018 | F3: FY2019 | G3: FY2020 | H3: FY2021 | I3: FY2022 | J3: FY2023 | K3: FY2024 | L3: FY2025 | M3: · | N3: 3Q2024 | O3: 4Q2024* | P3: 1Q2025 | Q3: 2Q2025 | R3: 3Q2025 | S3: 4Q2025* | T3: 1Q2026 | U3: 2Q2026
C4: 2016-12-31 | D4: 2017-12-31 | E4: 2018-12-31 | F4: 2019-12-31 | G4: 2020-12-31 | H4: 2021-12-31 | I4: 2022-12-31 | J4: 2023-12-31 | K4: 2024-12-31 | L4: 2025-12-31 | N4: 2024-09-30 | O4: 2024-12-31 | P4: 2025-03-31 | Q4: 2025-06-30 | R4: 2025-09-30 | S4: 2025-12-31 | T4: 2026-03-31 | U4: 2026-06-30
A6: CONTENTS
A7: =HYPERLINK("#'Balance Sheet'!A13","1. ASSETS") -> 1. ASSETS
A8: =HYPERLINK("#'Balance Sheet'!A31","2. LIABILITIES") -> 2. LIABILITIES
A9: =HYPERLINK("#'Balance Sheet'!A49","3. SHAREHOLDERS' EQUITY (DEFICIT)") -> 3. SHAREHOLDERS' EQUITY (DEFICIT)
A10: =HYPERLINK("#'Balance Sheet'!A60","4. TIE-OUT CHECKS") -> 4. TIE-OUT CHECKS
A11: =HYPERLINK("#'Balance Sheet'!A68","5. DEBT AND LEASE SUMMARY (ANALYST CALCULATION FROM FILED LINES)") -> 5. DEBT AND LEASE SUMMARY (ANALYST CALCULATION FROM FILED LINES)
A13: 1. ASSETS
A14: Cash and equivalents | C14: 1223.4 | D14: 2463.8 | E14: 866 | F14: 898.5 | G14: 3449.1 | H14: 4709.2 | I14: 2583.8 | J14: 4579 | K14: 1085 | L14: 774 | N14: 1221 | O14: 1085 | P14: 1238 | Q14: 1876 | R14: 2413 | S14: 774 | T14: 1170 | U14: 822
A15: Accounts and notes receivable | C15: 1474.1 | D15: 1976.2 | E15: 2441.5 | F15: 2224.2 | G15: 2110.3 | H15: 1872.4 | I15: 2115 | J15: 2488 | K15: 2383 | L15: 2466 | N15: 2460 | O15: 2383 | P15: 2387 | Q15: 2550 | R15: 2579 | S15: 2466 | T15: 2432 | U15: 2485
A16: Inventories, at cost, not in excess of market | C16: 58.9 | D16: 58.8 | E16: 51.1 | F16: 50.2 | G16: 51.1 | H16: 55.6 | I16: 52 | J16: 53 | K16: 56 | L16: 61 | N16: 54 | O16: 56 | P16: 51 | Q16: 55 | R16: 55 | S16: 61 | T16: 61 | U16: 58
A17: Prepaid expenses and other current assets | C17: 565.2 | D17: 828.4 | E17: 694.6 | F17: 385 | G17: 632.7 | H17: 511.3 | I17: 673.4 | J17: 866 | K17: 1074 | L17: 863 | N17: 1176 | O17: 1074 | P17: 1060 | Q17: 1120 | R17: 1032 | S17: 863 | T17: 1046 | U17: 980
A18: Assets of businesses held for sale | C18: 1527 | D18: 0
A19: Total current assets | C19: 4848.6 | D19: 5327.2 | E19: 4053.2 | F19: 3557.9 | G19: 6243.2 | H19: 7148.5 | I19: 5424.2 | J19: 7986 | K19: 4599 | L19: 4163 | N19: 4912 | O19: 4599 | P19: 4735 | Q19: 5601 | R19: 6079 | S19: 4163 | T19: 4709 | U19: 4345
A21: Investments in and advances to affiliates | C21: 725.9 | D21: 1085.7 | E21: 1202.8 | F21: 1270.3 | G21: 1297.2 | H21: 1201.2 | I21: 1064.5 | J21: 1080 | K21: 2710 | L21: 2820 | N21: 2960 | O21: 2710 | P21: 2751 | Q21: 2827 | R21: 2864 | S21: 2820 | T21: 2865 | U21: 2896
A22: Goodwill | C22: 2336.5 | D22: 2379.7 | E22: 2331.5 | F22: 2677.4 | G22: 2773.1 | H22: 2782.5 | I22: 2900.4 | J22: 3040 | K22: 3145 | L22: 3354 | N22: 3220 | O22: 3145 | P22: 3186 | Q22: 3308 | R22: 3306 | S22: 3354 | T22: 3349 | U22: 3347
A23: Miscellaneous other assets | C23: 1855.3 | D23: 2562.8 | E23: 2381 | F23: 2584 | G23: 3527.4 | H23: 4449.5 | I23: 4707.2 | J23: 5618 | K23: 6095 | L23: 6331 | N23: 5673 | O23: 6095 | P23: 6265 | Q23: 6492 | R23: 6588 | S23: 6331 | T23: 6357 | U23: 6393
A24: Total other assets | C24: 4917.7 | D24: 6028.2 | E24: 5915.3 | F24: 6531.7 | G24: 7597.7 | H24: 8433.2 | I24: 8672.1 | J24: 9738 | K24: 11950 | L24: 12505 | N24: 11853 | O24: 11950 | P24: 12202 | Q24: 12628 | R24: 12758 | S24: 12505 | T24: 12571 | U24: 12637
A25: Lease right-of-use asset, net | B25: Presented from FY2019 (ASC 842 adoption); no comparable line for FY2016-FY2018 | E25: 0 | F25: 13261.2 | G25: 13827.7 | H25: 13552 | I25: 12565.7 | J25: 13514 | K25: 13339 | L25: 14606 | N25: 13632 | O25: 13339 | P25: 13642 | Q25: 14286 | R25: 14285 | S25: 14606 | T25: 14513 | U25: 14459
A26: Property and equipment, at cost | C26: 34443.4 | D26: 36626.4 | E26: 37193.6 | F26: 39050.9 | G26: 41476.5 | H26: 41916.6 | I26: 41037.6 | J26: 43570 | K26: 44177 | L26: 49290 | N26: 45178 | O26: 44177 | P26: 45258 | Q26: 47609 | R26: 48215 | S26: 49290 | T26: 49477 | U26: 49943
A27: Accumulated depreciation and amortization | C27: -13185.8 | D27: -14178.1 | E27: -14350.9 | F27: -14890.9 | G27: -16518.3 | H27: -17196 | I27: -17264 | J27: -18662 | K27: -18882 | L27: -21049 | N27: -19403 | O27: -18882 | P27: -19509 | Q27: -20570 | R27: -20729 | S27: -21049 | T27: -21232 | U27: -21464
A28: Net property and equipment | C28: 21257.6 | D28: 22448.3 | E28: 22842.7 | F28: 24160 | G28: 24958.2 | H28: 24720.6 | I28: 23773.6 | J28: 24908 | K28: 25295 | L28: 28241 | N28: 25775 | O28: 25295 | P28: 25749 | Q28: 27039 | R28: 27486 | S28: 28241 | T28: 28245 | U28: 28479
A29: Total assets | C29: 31023.9 | D29: 33803.7 | E29: 32811.2 | F29: 47510.8 | G29: 52626.8 | H29: 53854.3 | I29: 50435.6 | J29: 56147 | K29: 55182 | L29: 59515 | N29: 56172 | O29: 55182 | P29: 56329 | Q29: 59555 | R29: 60608 | S29: 59515 | T29: 60037 | U29: 59920
A31: 2. LIABILITIES
A32: Accounts payable | C32: 756 | D32: 924.8 | E32: 1207.9 | F32: 988.2 | G32: 741.3 | H32: 1006.8 | I32: 980.2 | J32: 1103 | K32: 1029 | L32: 1149 | N32: 944 | O32: 1029 | P32: 882 | Q32: 838 | R32: 972 | S32: 1149 | T32: 1091 | U32: 1114
A33: Lease liability (current) | E33: 0 | F33: 621 | G33: 701.5 | H33: 705.5 | I33: 661.1 | J33: 688 | K33: 636 | L33: 694 | N33: 668 | O33: 636 | P33: 663 | Q33: 686 | R33: 698 | S33: 694 | T33: 707 | U33: 690
A34: Income taxes | C34: 267.2 | D34: 265.8 | E34: 228.3 | F34: 331.7 | G34: 741.1 | H34: 360.7 | I34: 274.9 | J34: 705 | K34: 361 | L34: 250 | N34: 786 | O34: 361 | P34: 556 | Q34: 24 | R34: 367 | S34: 250 | T34: 391 | U34: 327
A35: Other taxes | C35: 266.3 | D35: 275.4 | E35: 253.7 | F35: 247.5 | G35: 227 | H35: 236.7 | I35: 255.1 | J35: 268 | K35: 224 | L35: 247 | N35: 263 | O35: 224 | P35: 235 | Q35: 245 | R35: 242 | S35: 247 | T35: 253 | U35: 261
A36: Accrued interest | C36: 247.5 | D36: 278.4 | E36: 297 | F36: 337.8 | G36: 388.4 | H36: 363.3 | I36: 393.4 | J36: 469 | K36: 482 | L36: 533 | N36: 433 | O36: 482 | P36: 401 | Q36: 451 | R36: 471 | S36: 533 | T36: 448 | U36: 428
A37: Accrued payroll and other liabilities | C37: 1159.3 | D37: 1146.2 | E37: 986.6 | F37: 1035.7 | G37: 1138.3 | H37: 1347 | I37: 1237.4 | J37: 1434 | K37: 1129 | L37: 1488 | N37: 1353 | O37: 1129 | P37: 1191 | Q37: 1452 | R37: 1529 | S37: 1488 | T37: 1257 | U37: 1198
A38: Dividend payable | B38: Separate line only in the 3Q2024 10-Q | N38: 1265
A39: Short-term borrowings and current maturities of long-term debt | B39: Captioned 'Current maturities of long-term debt' through FY2021; line absent (nil) where blank | C39: 77.2 | D39: 0 | E39: 0 | F39: 59.1 | G39: 2243.6 | H39: 0 | I39: 0 | J39: 2192 | K39: 0 | N39: 596 | O39: 0 | P39: 80 | Q39: 602 | R39: 1800
A40: Liabilities of businesses held for sale | C40: 694.8 | D40: 0
A41: Total current liabilities | C41: 3468.3 | D41: 2890.6 | E41: 2973.5 | F41: 3621 | G41: 6181.2 | H41: 4020 | I41: 3802.1 | J41: 6859 | K41: 3861 | L41: 4361 | N41: 6308 | O41: 3861 | P41: 4008 | Q41: 4298 | R41: 6079 | S41: 4361 | T41: 4146 | U41: 4018
A42: Long-term debt | C42: 25878.5 | D42: 29536.4 | E42: 31075.3 | F42: 34118.1 | G42: 35196.8 | H42: 35622.7 | I42: 35903.5 | J42: 37153 | K42: 38424 | L42: 39973 | N42: 38990 | O42: 38424 | P42: 38845 | Q42: 40801 | R42: 39483 | S42: 39973 | T42: 40105 | U42: 39863
A43: Long-term lease liability | E43: 0 | F43: 12757.8 | G43: 13321.3 | H43: 13020.9 | I43: 12134.4 | J43: 13058 | K43: 12888 | L43: 14147 | N43: 13157 | O43: 12888 | P43: 13175 | Q43: 13778 | R43: 13837 | S43: 14147 | T43: 14069 | U43: 14039
A44: Long-term income taxes | B44: Separate line from FY2017 10-K; FY2016 amount is within Other long-term liabilities (see restatement log) | C44: 1010.6 | D44: 2370.9 | E44: 2081.2 | F44: 2265.9 | G44: 1970.7 | H44: 1896.8 | I44: 791.9 | J44: 363 | K44: 344 | L44: 139 | N44: 74 | O44: 344 | P44: 365 | Q44: 292 | R44: 285 | S44: 139 | T44: 151 | U44: 176
...

Sheet Cash Flow
A1: McDonald's Corporation — Cash Flow
A2: $ in millions except per-share data | USD | as of 2026-10-08
C3: FY2016 | D3: FY2017 | E3: FY2018 | F3: FY2019 | G3: FY2020 | H3: FY2021 | I3: FY2022 | J3: FY2023 | K3: FY2024 | L3: FY2025 | M3: · | N3: 3Q2024 | O3: 4Q2024* | P3: 1Q2025 | Q3: 2Q2025 | R3: 3Q2025 | S3: 4Q2025* | T3: 1Q2026 | U3: 2Q2026
C4: 2016-12-31 | D4: 2017-12-31 | E4: 2018-12-31 | F4: 2019-12-31 | G4: 2020-12-31 | H4: 2021-12-31 | I4: 2022-12-31 | J4: 2023-12-31 | K4: 2024-12-31 | L4: 2025-12-31 | N4: 2024-09-30 | O4: 2024-12-31 | P4: 2025-03-31 | Q4: 2025-06-30 | R4: 2025-09-30 | S4: 2025-12-31 | T4: 2026-03-31 | U4: 2026-06-30
A6: CONTENTS
A7: =HYPERLINK("#'Cash Flow'!A14","1. OPERATING ACTIVITIES") -> 1. OPERATING ACTIVITIES
A8: =HYPERLINK("#'Cash Flow'!A30","2. INVESTING ACTIVITIES") -> 2. INVESTING ACTIVITIES
A9: =HYPERLINK("#'Cash Flow'!A40","3. FINANCING ACTIVITIES") -> 3. FINANCING ACTIVITIES
A10: =HYPERLINK("#'Cash Flow'!A51","4. CASH RECONCILIATION AND SUPPLEMENTAL") -> 4. CASH RECONCILIATION AND SUPPLEMENTAL
A11: =HYPERLINK("#'Cash Flow'!A61","5. TIE-OUT CHECKS") -> 5. TIE-OUT CHECKS
A12: =HYPERLINK("#'Cash Flow'!A70","6. FREE CASH FLOW ANALYTICS (ANALYST CALCULATION)") -> 6. FREE CASH FLOW ANALYTICS (ANALYST CALCULATION)
A14: 1. OPERATING ACTIVITIES
A15: Net income | C15: 4686.5 | D15: 5192.3 | E15: 5924.3 | F15: 6025.4 | G15: 4730.5 | H15: 7545.2 | I15: 6177 | J15: 8469 | K15: 8223 | L15: 8563 | N15: 2255 | O15: 2016 | P15: 1868 | Q15: 2253 | R15: 2278 | S15: 2164 | T15: 1983 | U15: 2362
A16: Depreciation and amortization | C16: 1516.5 | D16: 1363.4 | E16: 1482 | F16: 1617.9 | G16: 1751.4 | H16: 1868.1 | I16: 1871 | J16: 1978 | K16: 2097 | L16: 2199 | N16: 532 | O16: 553 | P16: 520 | Q16: 544 | R16: 559 | S16: 576 | T16: 566 | U16: 565
A17: Deferred income taxes | C17: -538.6 | D17: -36.4 | E17: 102.6 | F17: 149.7 | G17: 6.4 | H17: -428.3 | I17: -346 | J17: -686 | K17: -574 | L17: -126 | N17: -137 | O17: -73 | P17: -44 | Q17: -41 | R17: 35 | S17: -77 | T17: 63 | U17: -58
A18: Share-based compensation | C18: 131.3 | D18: 117.5 | E18: 125.1 | F18: 109.6 | G18: 92.4 | H18: 139.2 | I18: 167 | J18: 175 | K18: 172 | L18: 165 | N18: 40 | O18: 44 | P18: 45 | Q18: 44 | R18: 39 | S18: 37 | T18: 60 | U18: 39
A19: Net (gain) loss on sale of restaurant and other businesses | B19: Separate line FY2017+ (recast); in 10-Qs it is included in 'Other' below | C19: -310.7 | D19: -1155.8 | E19: -308.8 | F19: -128.2 | G19: -28.2 | H19: -97.8 | I19: 733 | J19: -103 | K19: -37 | L19: -149
A20: Other | B20: 10-Q 'Other' and 4Q* include the net gain/loss on sale line | C20: 407.6 | D20: 1050.7 | E20: 114.2 | F20: 49.2 | G20: -75.2 | H20: -339.1 | I20: -570 | J20: -113 | K20: 3 | L20: -207 | N20: -33 | O20: 14 | P20: -73 | Q20: -71 | R20: -53 | S20: -159 | T20: -92 | U20: -51
A21: Working capital: Accounts receivable | C21: -159 | D21: -340.7 | E21: -479.4 | F21: 27 | G21: -6.8 | H21: 309.9 | I21: -264 | J21: -161 | K21: 10 | L21: 231
A22: Working capital: Inventories, prepaid expenses and other current assets | C22: 28.1 | D22: -37.3 | E22: -1.9 | F22: 128.8 | G22: -68.6 | H22: -62.2 | I22: 6 | J22: 17 | K22: 71 | L22: -140
A23: Working capital: Accounts payable | C23: 89.8 | D23: -59.7 | E23: 129.4 | F23: -26.8 | G23: -137.5 | H23: 225 | I23: 31 | J23: 50 | K23: -10 | L23: 100
A24: Working capital: Income taxes | C24: 169.7 | D24: -396.4 | E24: -33.4 | F24: 173.4 | G24: -43.6 | H24: -302.5 | I24: -547 | J24: -220 | K24: -292 | L24: -239
A25: Working capital: Other accrued liabilities | C25: 38.4 | D25: -146.4 | E25: -87.4 | F25: -3.9 | G25: 44.4 | H25: 284 | I25: 129 | J25: 206 | K25: -217 | L25: 154
A26: Changes in working capital items (10-Q single-line) | B26: 10-Q presents one line; 4Q* = FY sum of the five lines less 9M YTD | N26: 79 | O26: 76 | P26: 111 | Q26: -731 | R26: 570 | S26: 156 | T26: -168 | U26: -50
A27: Changes in working capital items | C27: =C21+C22+C23+C24+C25 -> 167 | D27: =D21+D22+D23+D24+D25 -> -980.5 | E27: =E21+E22+E23+E24+E25 -> -472.7 | F27: =F21+F22+F23+F24+F25 -> 298.5 | G27: =G21+G22+G23+G24+G25 -> -212.1 | H27: =H21+H22+H23+H24+H25 -> 454.2 | I27: =I21+I22+I23+I24+I25 -> -645 | J27: =J21+J22+J23+J24+J25 -> -108 | ... L27: =L21+L22+L23+L24+L25 -> 106 | N27: =N26 -> 79 | O27: =O26 -> 76 | P27: =P26 -> 111 | Q27: =Q26 -> -731 | R27: =R26 -> 570 | S27: =S26 -> 156 | T27: =T26 -> -168 | U27: =U26 -> -50
A28: Cash provided by operations | C28: 6059.6 | D28: 5551.2 | E28: 6966.7 | F28: 8122.1 | G28: 6265.2 | H28: 9141.5 | I28: 7387 | J28: 9612 | K28: 9447 | L28: 10551 | N28: 2736 | O28: 2631 | P28: 2428 | Q28: 1998 | R28: 3428 | S28: 2697 | T28: 2412 | U28: 2807
A30: 2. INVESTING ACTIVITIES
A31: Capital expenditures | C31: -1821.1 | D31: -1853.7 | E31: -2741.7 | F31: -2393.7 | G31: -1640.8 | H31: -2040 | I31: -1899 | J31: -2357 | K31: -2775 | L31: -3365 | N31: -794 | O31: -807 | P31: -551 | Q31: -744 | R31: -1011 | S31: -1059 | T31: -682 | U31: -831
A32: Purchases of restaurant (and other) businesses | C32: -109.5 | D32: -77 | E32: -101.7 | F32: -540.9 | G32: -66.1 | H32: -374.2 | I32: -807 | J32: -441 | K32: -669 | L32: -354 | N32: -433 | O32: -74 | P32: -75 | Q32: -56 | R32: -109 | S32: -114 | T32: -79 | U32: -74
A33: Purchases of equity method investments | I33: 0 | J33: 0 | K33: -1837 | L33: 0 | N33: 0 | O33: 0 | P33: 0 | Q33: 0 | R33: 0 | S33: 0
A34: Sales of restaurant (and other) businesses | C34: 975.6 | D34: 974.8 | E34: 530.8 | F34: 340.8 | G34: 76.3 | H34: 196.2 | I34: 446 | J34: 195 | K34: 311 | L34: 346 | N34: 54 | O34: 155 | P34: 49 | Q34: 34 | R34: 102 | S34: 161 | T34: 72 | U34: 137
A35: Proceeds from sale of businesses in China and Hong Kong | C35: 0 | D35: 1597 | E35: 0 | F35: 0
A36: Sales of property | C36: 82.9 | D36: 166.8 | E36: 160.4 | F36: 151.2 | G36: 27.4 | H36: 106.2 | I36: 39 | J36: 95 | K36: 122 | L36: 130 | N36: 10 | O36: 90 | P36: 5 | Q36: 11 | R36: 22 | S36: 92 | T36: 34 | U36: 21
A37: Other investing | C37: -109.5 | D37: -245.9 | E37: -302.9 | F37: -628.5 | G37: 57.4 | H37: -53.9 | I37: -457 | J37: -676 | K37: -498 | L37: -579 | N37: -103 | O37: -106 | P37: -200 | Q37: -114 | R37: -116 | S37: -149 | T37: -122 | U37: -121
A38: Cash provided by (used for) investing activities | C38: -981.6 | D38: 562 | E38: -2455.1 | F38: -3071.1 | G38: -1545.8 | H38: -2165.7 | I38: -2678 | J38: -3185 | K38: -5346 | L38: -3822 | N38: -1266 | O38: -742 | P38: -771 | Q38: -869 | R38: -1112 | S38: -1069 | T38: -777 | U38: -868
A40: 3. FINANCING ACTIVITIES
A41: Net short-term borrowings (repayments) | C41: -286.2 | D41: -1050.3 | E41: 95.9 | F41: 799.2 | G41: -893.1 | H41: 15.1 | I41: 26 | J41: 213 | K41: 326 | L41: 6 | N41: 474 | O41: 193 | P41: -792 | Q41: 597 | R41: -599 | S41: 800 | T41: -791 | U41: 492
A42: Long-term financing issuances | C42: 3779.5 | D42: 4727.5 | E42: 3794.5 | F42: 4499 | G42: 5543 | H42: 1154.4 | I42: 3374 | J42: 5221 | K42: 2380 | L42: 4724 | N42: 0 | O42: 649 | P42: 1498 | Q42: 1403 | R42: 1833 | S42: -10 | T42: 1159 | U42: 0
A43: Long-term financing repayments | C43: -822.9 | D43: -1649.4 | E43: -1759.6 | F43: -2061.9 | G43: -2411.7 | H43: -2240 | I43: -2202 | J43: -2441 | K43: -2777 | L43: -4802 | N43: 0 | O43: -992 | P43: -693 | Q43: -700 | R43: -1251 | S43: -2158 | T43: -1 | U43: -580
A44: Treasury stock purchases | C44: -11171 | D44: -4685.7 | E44: -5207.7 | F44: -4976.2 | G44: -907.8 | H44: -845.5 | I44: -3896 | J44: -3054 | K44: -2824 | L44: -2056 | N44: -469 | O44: -503 | P44: -477 | Q44: -505 | R44: -501 | S44: -573 | T44: -396 | U44: -856
...

Sheet Segments
A1: McDonald's Corporation — Segments
A2: $ in millions except per-share data | USD | as of 2026-10-08
C3: FY2016 | D3: FY2017 | E3: FY2018 | F3: FY2019 | G3: FY2020 | H3: FY2021 | I3: FY2022 | J3: FY2023 | K3: FY2024 | L3: FY2025 | M3: · | N3: 3Q2024 | O3: 4Q2024* | P3: 1Q2025 | Q3: 2Q2025 | R3: 3Q2025 | S3: 4Q2025* | T3: 1Q2026 | U3: 2Q2026
C4: 2016-12-31 | D4: 2017-12-31 | E4: 2018-12-31 | F4: 2019-12-31 | G4: 2020-12-31 | H4: 2021-12-31 | I4: 2022-12-31 | J4: 2023-12-31 | K4: 2024-12-31 | L4: 2025-12-31 | N4: 2024-09-30 | O4: 2024-12-31 | P4: 2025-03-31 | Q4: 2025-06-30 | R4: 2025-09-30 | S4: 2025-12-31 | T4: 2026-03-31 | U4: 2026-06-30
A6: CONTENTS
A7: =HYPERLINK("#'Segments'!A18","1. SEGMENT REVENUES (CURRENT REPORTABLE-SEGMENT STRUCTURE, FY2017-FY2025)") -> 1. SEGMENT REVENUES (CURRENT REPORTABLE-SEGMENT STRUCTURE, FY2017-FY2025)
A8: =HYPERLINK("#'Segments'!A29","2. SEGMENT OPERATING INCOME") -> 2. SEGMENT OPERATING INCOME
A9: =HYPERLINK("#'Segments'!A40","3. SEGMENT TOTAL ASSETS") -> 3. SEGMENT TOTAL ASSETS
A10: =HYPERLINK("#'Segments'!A47","4. SEGMENT CAPITAL EXPENDITURES") -> 4. SEGMENT CAPITAL EXPENDITURES
A11: =HYPERLINK("#'Segments'!A54","5. SEGMENT DEPRECIATION AND AMORTIZATION") -> 5. SEGMENT DEPRECIATION AND AMORTIZATION
A12: =HYPERLINK("#'Segments'!A61","6. SEGMENT EXPENSE DETAIL (DISCLOSED FROM FY2022 10-K, ASU 2023-07 PRESENTATION)") -> 6. SEGMENT EXPENSE DETAIL (DISCLOSED FROM FY2022 10-K, ASU 2023-07 PRESENTATION)
A13: =HYPERLINK("#'Segments'!A82","7. REVENUE BY TYPE AND SEGMENT (MD&A REVENUE TABLE)") -> 7. REVENUE BY TYPE AND SEGMENT (MD&A REVENUE TABLE)
A14: =HYPERLINK("#'Segments'!A97","8. RESTAURANT MARGINS BY SEGMENT (MD&A, FY2017-FY2025)") -> 8. RESTAURANT MARGINS BY SEGMENT (MD&A, FY2017-FY2025)
A15: =HYPERLINK("#'Segments'!A123","9. SELLING, GENERAL & ADMINISTRATIVE EXPENSES BY SEGMENT AND INCENTIVE COMPENSATION (MD&A, FY2017-FY2025)") -> 9. SELLING, GENERAL & ADMINISTRATIVE EXPENSES BY SEGMENT AND INCENTIVE COMPENSATION (MD&A, FY2017-FY2025)
A16: =HYPERLINK("#'Segments'!A137","10. SUPERSEDED SEGMENT STRUCTURE (U.S. / INT'L LEAD / HIGH GROWTH / FOUNDATIONAL), FY2016-FY2018 - NOT COMPARABLE WITH BLOCKS ABOVE") -> 10. SUPERSEDED SEGMENT STRUCTURE (U.S. / INT'L LEAD / HIGH GROWTH / FOUNDATIONAL), FY2016-FY2018 - NOT COMPARABLE WITH BLOCKS ABOVE
A18: 1. SEGMENT REVENUES (CURRENT REPORTABLE-SEGMENT STRUCTURE, FY2017-FY2025)
A19: U.S. | D19: 8006.4 | E19: 7798.7 | F19: 8002.8 | G19: 7828.5 | H19: 8865 | I19: 9588 | J19: 10568 | K19: 10631 | L19: 10825
A20: International Operated Markets | D20: 11115.9 | E20: 11578.1 | F20: 11480.1 | G20: 9570.7 | H20: 12219.8 | I20: 11297 | J20: 12382 | K20: 12628 | L20: 13633
A21: International Developmental Licensed Markets & Corporate | D21: 3698.1 | E21: 1881.1 | F21: 1881.5 | G21: 1808.6 | H21: 2138.1 | I21: 2297 | J21: 2543 | K21: 2661 | L21: 2427
A22: Total revenues | D22: =D19+D20+D21 -> 22820.4 | E22: =E19+E20+E21 -> 21257.9 | F22: =F19+F20+F21 -> 21364.4 | G22: =G19+G20+G21 -> 19207.8 | H22: =H19+H20+H21 -> 23222.9 | I22: =I19+I20+I21 -> 23182 | J22: =J19+J20+J21 -> 25493 | K22: =K19+K20+K21 -> 25920 | L22: =L19+L20+L21 -> 26885
A23: U.S. % of total | D23: =D19/D22 -> 0.35084398 | E23: =E19/E22 -> 0.36686126 | F23: =F19/F22 -> 0.37458576 | G23: =G19/G22 -> 0.4075688 | H23: =H19/H22 -> 0.38173527 | I23: =I19/I22 -> 0.41359676 | J23: =J19/J22 -> 0.41454517 | K23: =K19/K22 -> 0.4101466 | L23: =L19/L22 -> 0.40264088
A24: International Operated Markets % of total | D24: =D20/D22 -> 0.48710364 | E24: =E20/E22 -> 0.54464928 | F24: =F20/F22 -> 0.53734718 | G24: =G20/G22 -> 0.49827154 | H24: =H20/H22 -> 0.52619613 | I24: =I20/I22 -> 0.48731775 | J24: =J20/J22 -> 0.48570196 | K24: =K20/K22 -> 0.48719136 | L24: =L20/L22 -> 0.50708574
A25: International Developmental Licensed Markets & Corporate % of total | D25: =D21/D22 -> 0.16205237 | E25: =E21/E22 -> 0.088489456 | F25: =F21/F22 -> 0.088067065 | G25: =G21/G22 -> 0.094159664 | H25: =H21/H22 -> 0.092068605 | I25: =I21/I22 -> 0.099085497 | J25: =J21/J22 -> 0.099752873 | K25: =K21/K22 -> 0.10266204 | L25: =L21/L22 -> 0.090273387
A26: Segment revenue vs IS total revenues (rounding / recast timing) | D26: =D22-'Income Statement'!D17 -> 0 | E26: =E22-'Income Statement'!E17 -> 0 | F26: =F22-'Income Statement'!F17 -> 0 | G26: =G22-'Income Statement'!G17 -> 0 | H26: =H22-'Income Statement'!H17 -> 0 | I26: =I22-'Income Statement'!I17 -> -1 | J26: =J22-'Income Statement'!J17 -> -1 | K26: =K22-'Income Statement'!K17 -> 0 | L26: =L22-'Income Statement'!L17 -> 0
A27: YoY Growth | D27: =IF(N(C22)=0,"",D22/C22-1) | E27: =IF(N(D22)=0,"",E22/D22-1) -> -0.06846944 | F27: =IF(N(E22)=0,"",F22/E22-1) -> 0.0050099022 | G27: =IF(N(F22)=0,"",G22/F22-1) -> -0.10094363 | H27: =IF(N(G22)=0,"",H22/G22-1) -> 0.20903487 | I27: =IF(N(H22)=0,"",I22/H22-1) -> -0.0017611926 | J27: =IF(N(I22)=0,"",J22/I22-1) -> 0.099689414 | K27: =IF(N(J22)=0,"",K22/J22-1) -> 0.016749696 | L27: =IF(N(K22)=0,"",L22/K22-1) -> 0.037229938
A29: 2. SEGMENT OPERATING INCOME
A30: U.S. | D30: 4022.4 | E30: 4015.6 | F30: 4068.7 | G30: 3789.1 | H30: 4754.7 | I30: 5136 | J30: 5694 | K30: 5733 | L30: 5808
A31: International Operated Markets | D31: 4173.6 | E31: 4643.2 | F31: 4789 | G31: 3315.1 | H31: 5130.6 | I31: 3926 | J31: 5831 | K31: 5946 | L31: 6382
A32: International Developmental Licensed Markets & Corporate | D32: 1356.7 | E32: 163.8 | F32: 212.1 | G32: 219.8 | H32: 470.7 | I32: 309 | J32: 121 | K32: 33 | L32: 203
A33: Total operating income | D33: =D30+D31+D32 -> 9552.7 | E33: =E30+E31+E32 -> 8822.6 | F33: =F30+F31+F32 -> 9069.8 | G33: =G30+G31+G32 -> 7324 | H33: =H30+H31+H32 -> 10356 | I33: =I30+I31+I32 -> 9371 | J33: =J30+J31+J32 -> 11646 | K33: =K30+K31+K32 -> 11712 | L33: =L30+L31+L32 -> 12393
A34: U.S. margin | D34: =D30/D19 -> 0.50239808 | E34: =E30/E19 -> 0.51490633 | F34: =F30/F19 -> 0.50840956 | G34: =G30/G19 -> 0.48401354 | H34: =H30/H19 -> 0.53634518 | I34: =I30/I19 -> 0.53566959 | J34: =J30/J19 -> 0.53879637 | K34: =K30/K19 -> 0.53927194 | L34: =L30/L19 -> 0.5365358
A35: International Operated Markets margin | D35: =D31/D20 -> 0.37546218 | E35: =E31/E20 -> 0.40103298 | F35: =F31/F20 -> 0.41715664 | G35: =G31/G20 -> 0.3463801 | H35: =H31/H20 -> 0.41985957 | I35: =I31/I20 -> 0.34752589 | J35: =J31/J20 -> 0.47092554 | K35: =K31/K20 -> 0.47085841 | L35: =L31/L20 -> 0.46812881
A36: International Developmental Licensed Markets & Corporate margin | D36: =D32/D21 -> 0.36686407 | E36: =E32/E21 -> 0.08707671 | F36: =F32/F21 -> 0.11272921 | G36: =G32/G21 -> 0.12153047 | H36: =H32/H21 -> 0.22014873 | I36: =I32/I21 -> 0.13452329 | J36: =J32/J21 -> 0.047581597 | K36: =K32/K21 -> 0.012401353 | L36: =L32/L21 -> 0.083642357
A37: Total margin | D37: =D33/D22 -> 0.41860353 | E37: =E33/E22 -> 0.41502688 | F37: =F33/F22 -> 0.42452866 | G37: =G33/G22 -> 0.38130343 | H37: =H33/H22 -> 0.44593914 | I37: =I33/I22 -> 0.40423605 | J37: =J33/J22 -> 0.45683129 | K37: =K33/K22 -> 0.45185185 | L37: =L33/L22 -> 0.46096336
A38: Segment operating income vs IS operating income | D38: =D33-'Income Statement'!D33 -> 0 | E38: =E33-'Income Statement'!E33 -> 0 | F38: =F33-'Income Statement'!F33 -> 0 | G38: =G33-'Income Statement'!G33 -> 0 | H38: =H33-'Income Statement'!H33 -> 0 | I38: =I33-'Income Statement'!I33 -> 0 | J38: =J33-'Income Statement'!J33 -> -1 | K38: =K33-'Income Statement'!K33 -> 0 | L38: =L33-'Income Statement'!L33 -> 0
A40: 3. SEGMENT TOTAL ASSETS
A41: U.S. | D41: 12648.6 | E41: 14483.8 | F41: 21376.9 | G41: 21010 | H41: 21280.3 | I41: 21793 | J41: 22477 | K41: 22547 | L41: 23008
A42: International Operated Markets | D42: 16254.8 | E42: 17302.3 | F42: 22847.5 | G42: 24744 | H42: 24186.1 | I42: 21979 | J42: 23947 | K42: 23491 | L42: 27487
A43: International Developmental Licensed Markets & Corporate | D43: 4900.3 | E43: 1025.1 | F43: 3286.4 | G43: 6872.8 | H43: 8387.9 | I43: 6663 | J43: 9723 | K43: 9143 | L43: 9020
A44: Total assets | D44: =D41+D42+D43 -> 33803.7 | E44: =E41+E42+E43 -> 32811.2 | F44: =F41+F42+F43 -> 47510.8 | G44: =G41+G42+G43 -> 52626.8 | H44: =H41+H42+H43 -> 53854.3 | I44: =I41+I42+I43 -> 50435 | J44: =J41+J42+J43 -> 56147 | K44: =K41+K42+K43 -> 55181 | L44: =L41+L42+L43 -> 59515
...

Sheet Operating Metrics
A1: McDonald's Corporation — Operating Metrics
A2: $ in millions except per-share data | USD | as of 2026-10-08
C3: FY2016 | D3: FY2017 | E3: FY2018 | F3: FY2019 | G3: FY2020 | H3: FY2021 | I3: FY2022 | J3: FY2023 | K3: FY2024 | L3: FY2025 | M3: · | N3: 3Q2024 | O3: 4Q2024* | P3: 1Q2025 | Q3: 2Q2025 | R3: 3Q2025 | S3: 4Q2025* | T3: 1Q2026 | U3: 2Q2026
C4: 2016-12-31 | D4: 2017-12-31 | E4: 2018-12-31 | F4: 2019-12-31 | G4: 2020-12-31 | H4: 2021-12-31 | I4: 2022-12-31 | J4: 2023-12-31 | K4: 2024-12-31 | L4: 2025-12-31 | N4: 2024-09-30 | O4: 2024-12-31 | P4: 2025-03-31 | Q4: 2025-06-30 | R4: 2025-09-30 | S4: 2025-12-31 | T4: 2026-03-31 | U4: 2026-06-30
A6: CONTENTS
A7: =HYPERLINK("#'Operating Metrics'!A22","1. RESTAURANT COUNT (YEAR END)") -> 1. RESTAURANT COUNT (YEAR END)
A8: =HYPERLINK("#'Operating Metrics'!A33","2. FRANCHISED SALES AND SYSTEMWIDE SALES (MD&A; FY2016 TOTAL FROM ITEM 6)") -> 2. FRANCHISED SALES AND SYSTEMWIDE SALES (MD&A; FY2016 TOTAL FROM ITEM 6)
A9: =HYPERLINK("#'Operating Metrics'!A51","3. RESTAURANTS BY SEGMENT AND NET ADDITIONS") -> 3. RESTAURANTS BY SEGMENT AND NET ADDITIONS
A10: =HYPERLINK("#'Operating Metrics'!A64","4. COMPARABLE SALES GROWTH (U.S. / TOTAL FROM FY2016; SEGMENTS FROM FY2018; SEGMENT DEFINITIONS PER FY2019+ 10-KS)") -> 4. COMPARABLE SALES GROWTH (U.S. / TOTAL FROM FY2016; SEGMENTS FROM FY2018; SEGMENT DEFINITIONS PER FY2019+ 10-KS)
A11: =HYPERLINK("#'Operating Metrics'!A75","5. SYSTEMWIDE SALES GROWTH (FY2019-FY2025)") -> 5. SYSTEMWIDE SALES GROWTH (FY2019-FY2025)
A12: =HYPERLINK("#'Operating Metrics'!A85","6. MARKET DATA (ITEM 6 SELECTED FINANCIAL DATA, FY2016-FY2021 ONLY)") -> 6. MARKET DATA (ITEM 6 SELECTED FINANCIAL DATA, FY2016-FY2021 ONLY)
A13: =HYPERLINK("#'Operating Metrics'!A89","7. FRANCHISED REVENUE COMPOSITION") -> 7. FRANCHISED REVENUE COMPOSITION
A14: =HYPERLINK("#'Operating Metrics'!A98","8. SHAREHOLDER RETURNS (MD&A TABLE)") -> 8. SHAREHOLDER RETURNS (MD&A TABLE)
A15: =HYPERLINK("#'Operating Metrics'!A108","9. DEBT STRUCTURE STATISTICS (MD&A TABLE)") -> 9. DEBT STRUCTURE STATISTICS (MD&A TABLE)
A16: =HYPERLINK("#'Operating Metrics'!A115","10. CURRENCY TRANSLATION IMPACT ON REPORTED RESULTS (COMPANY-DISCLOSED BENEFIT / (COST) VS PRIOR-YEAR RATES)") -> 10. CURRENCY TRANSLATION IMPACT ON REPORTED RESULTS (COMPANY-DISCLOSED BENEFIT / (COST) VS PRIOR-YEAR RATES)
A17: =HYPERLINK("#'Operating Metrics'!A126","11. NON-GAAP RECONCILIATION: EARNINGS PER SHARE (ADJUSTMENT LINES AS PRESENTED IN THE FILING SUPPLYING EACH NON-GAAP FIGURE)") -> 11. NON-GAAP RECONCILIATION: EARNINGS PER SHARE (ADJUSTMENT LINES AS PRESENTED IN THE FILING SUPPLYING EACH NON-GAAP FIGURE)
A18: =HYPERLINK("#'Operating Metrics'!A135","12. NON-GAAP RECONCILIATION: NET INCOME (FY2021+)") -> 12. NON-GAAP RECONCILIATION: NET INCOME (FY2021+)
A19: =HYPERLINK("#'Operating Metrics'!A144","13. NON-GAAP RECONCILIATION: OPERATING INCOME (FY2021+)") -> 13. NON-GAAP RECONCILIATION: OPERATING INCOME (FY2021+)
A20: =HYPERLINK("#'Operating Metrics'!A157","14. CAPITAL EXPENDITURES BY PURPOSE (DISCLOSED FY2016-FY2019 ONLY)") -> 14. CAPITAL EXPENDITURES BY PURPOSE (DISCLOSED FY2016-FY2019 ONLY)
A22: 1. RESTAURANT COUNT (YEAR END)
A23: Conventional franchised | D23: 21366 | E23: 21685 | F23: 21837 | G23: 21712 | H23: 21607 | I23: 21720 | J23: 21818 | K23: 22077 | L23: 22570
A24: Developmental licensed | D24: 6945 | E24: 7225 | F24: 7648 | G24: 7663 | H24: 7913 | I24: 8229 | J24: 8684 | K24: 9247 | L24: 9675
A25: Foreign affiliated | D25: 5797 | E25: 6175 | F25: 6574 | G25: 7146 | H25: 7775 | I25: 8220 | J25: 9178 | K25: 10108 | L25: 11072
A26: Total franchised restaurants | B26: FY2016 from Item 6 selected data (no type split) | C26: 31230 | D26: 34108 | E26: 35085 | F26: 36059 | G26: 36521 | H26: 37295 | I26: 38169 | J26: 39680 | K26: 41432 | L26: 43317
A27: Company-owned and operated restaurants | C27: 5669 | D27: 3133 | E27: 2770 | F27: 2636 | G27: 2677 | H27: 2736 | I27: 2106 | J27: 2142 | K27: 2045 | L27: 2039
A28: Total systemwide restaurants | C28: 36899 | D28: 37241 | E28: 37855 | F28: 38695 | G28: 39198 | H28: 40031 | I28: 40275 | J28: 41822 | K28: 43477 | L28: 45356
A29: Conventional franchised 净增 | E29: =E23-D23 -> 319 | F29: =F23-E23 -> 152 | G29: =G23-F23 -> -125 | H29: =H23-G23 -> -105 | I29: =I23-H23 -> 113 | J29: =J23-I23 -> 98 | K29: =K23-J23 -> 259 | L29: =L23-K23 -> 493
A30: Developmental licensed 净增 | E30: =E24-D24 -> 280 | F30: =F24-E24 -> 423 | G30: =G24-F24 -> 15 | H30: =H24-G24 -> 250 | I30: =I24-H24 -> 316 | J30: =J24-I24 -> 455 | K30: =K24-J24 -> 563 | L30: =L24-K24 -> 428
A31: Foreign affiliated 净增 | E31: =E25-D25 -> 378 | F31: =F25-E25 -> 399 | G31: =G25-F25 -> 572 | H31: =H25-G25 -> 629 | I31: =I25-H25 -> 445 | J31: =J25-I25 -> 958 | K31: =K25-J25 -> 930 | L31: =L25-K25 -> 964
A32: Total franchised restaurants 净增 | E32: =E26-D26 -> 977 | F32: =F26-E26 -> 974 | G32: =G26-F26 -> 462 | H32: =H26-G26 -> 774 | I32: =I26-H26 -> 874 | J32: =J26-I26 -> 1511 | K32: =K26-J26 -> 1752 | L32: =L26-K26 -> 1885
A33: Company-owned and operated restaurants 净增 | E33: =E27-D27 -> -363 | F33: =F27-E27 -> -134 | G33: =G27-F27 -> 41 | H33: =H27-G27 -> 59 | I33: =I27-H27 -> -630 | J33: =J27-I27 -> 36 | K33: =K27-J27 -> -97 | L33: =L27-K27 -> -6
A34: Total systemwide restaurants 净增 | E34: =E28-D28 -> 614 | F34: =F28-E28 -> 840 | G34: =G28-F28 -> 503 | H34: =H28-G28 -> 833 | I34: =I28-H28 -> 244 | J34: =J28-I28 -> 1547 | K34: =K28-J28 -> 1655 | L34: =L28-K28 -> 1879
A35: YoY Growth | D35: =IF(N(C28)=0,"",D28/C28-1) -> 0.0092685439 | E35: =IF(N(D28)=0,"",E28/D28-1) -> 0.016487205 | F35: =IF(N(E28)=0,"",F28/E28-1) -> 0.022189935 | G35: =IF(N(F28)=0,"",G28/F28-1) -> 0.012999095 | H35: =IF(N(G28)=0,"",H28/G28-1) -> 0.021251084 | I35: =IF(N(H28)=0,"",I28/H28-1) -> 0.0060952762 | J35: =IF(N(I28)=0,"",J28/I28-1) -> 0.038410925 | K35: =IF(N(J28)=0,"",K28/J28-1) -> 0.039572474 | L35: =IF(N(K28)=0,"",L28/K28-1) -> 0.043218253
A36: Franchised % of systemwide restaurants | C36: =C26/C28 -> 0.8463644 | D36: =D26/D28 -> 0.91587229 | E36: =E26/E28 -> 0.92682605 | F36: =F26/F28 -> 0.9318775 | G36: =G26/G28 -> 0.9317057 | H36: =H26/H28 -> 0.93165297 | I36: =I26/I28 -> 0.9477095 | J36: =J26/J28 -> 0.94878294 | ... L36: =L26/L28 -> 0.95504454
A37: Franchised + company-operated vs systemwide | C37: =C26+C27-C28 -> 0 | D37: =D26+D27-D28 -> 0 | E37: =E26+E27-E28 -> 0 | F37: =F26+F27-F28 -> 0 | G37: =G26+G27-G28 -> 0 | H37: =H26+H27-H28 -> 0 | I37: =I26+I27-I28 -> 0 | J37: =J26+J27-J28 -> 0 | ... L37: =L26+L27-L28 -> 0
A39: 2. FRANCHISED SALES AND SYSTEMWIDE SALES (MD&A; FY2016 TOTAL FROM ITEM 6)
A40: U.S. | D40: 34379 | E40: 35860 | F40: 37923 | G40: 38123 | H40: 43344 | I40: 45898 | J40: 49914 | K40: 50272 | L40: 51946
A41: International Operated Markets | D41: 24386 | E41: 27557 | F41: 28853 | G41: 25446 | H41: 33097 | I41: 34537 | J41: 38264 | K41: 39132 | L41: 42440
A42: International Developmental Licensed Markets | D42: 19426 | E42: 22717 | F42: 23981 | G42: 21609 | H42: 26234 | I42: 29038 | J42: 31573 | K42: 31529 | L42: 35289
A43: Franchised sales: total | B43: FY2016 from Item 6 selected financial data (segment split not comparable); FY2017+ from the MD&A franchised-sales table | C43: 69707 | D43: 78191 | E43: 86134 | F43: 90757 | G43: 85178 | H43: 102675 | I43: 109473 | J43: 119750 | K43: 120933 | L43: 129675
...

Sheet Note Schedules
A1: McDonald's Corporation — Note Schedules
A2: $ in millions except per-share data | USD | as of 2026-10-08
C3: FY2016 | D3: FY2017 | E3: FY2018 | F3: FY2019 | G3: FY2020 | H3: FY2021 | I3: FY2022 | J3: FY2023 | K3: FY2024 | L3: FY2025 | M3: · | N3: 3Q2024 | O3: 4Q2024* | P3: 1Q2025 | Q3: 2Q2025 | R3: 3Q2025 | S3: 4Q2025* | T3: 1Q2026 | U3: 2Q2026
C4: 2016-12-31 | D4: 2017-12-31 | E4: 2018-12-31 | F4: 2019-12-31 | G4: 2020-12-31 | H4: 2021-12-31 | I4: 2022-12-31 | J4: 2023-12-31 | K4: 2024-12-31 | L4: 2025-12-31 | N4: 2024-09-30 | O4: 2024-12-31 | P4: 2025-03-31 | Q4: 2025-06-30 | R4: 2025-09-30 | S4: 2025-12-31 | T4: 2026-03-31 | U4: 2026-06-30
A6: CONTENTS
A7: =HYPERLINK("#'Note Schedules'!A17","1. PROPERTY AND EQUIPMENT (NOTE)") -> 1. PROPERTY AND EQUIPMENT (NOTE)
A8: =HYPERLINK("#'Note Schedules'!A29","2. INCOME TAXES (NOTE)") -> 2. INCOME TAXES (NOTE)
A9: =HYPERLINK("#'Note Schedules'!A47","3. OTHER OPERATING (INCOME) EXPENSE, NET - COMPONENTS (MD&A / NOTE)") -> 3. OTHER OPERATING (INCOME) EXPENSE, NET - COMPONENTS (MD&A / NOTE)
A10: =HYPERLINK("#'Note Schedules'!A56","4. NONOPERATING (INCOME) EXPENSE, NET - COMPONENTS (MD&A)") -> 4. NONOPERATING (INCOME) EXPENSE, NET - COMPONENTS (MD&A)
A11: =HYPERLINK("#'Note Schedules'!A64","5. GOODWILL BY SEGMENT (YEAR END; NOTE)") -> 5. GOODWILL BY SEGMENT (YEAR END; NOTE)
A12: =HYPERLINK("#'Note Schedules'!A71","6. DEBT BY CURRENCY, FAIR VALUE AND MATURITY (FINANCING NOTE)") -> 6. DEBT BY CURRENCY, FAIR VALUE AND MATURITY (FINANCING NOTE)
A13: =HYPERLINK("#'Note Schedules'!A92","7. RENT, LEASE COMMITMENTS AND MINIMUM RENT RECEIVABLE") -> 7. RENT, LEASE COMMITMENTS AND MINIMUM RENT RECEIVABLE
A14: =HYPERLINK("#'Note Schedules'!A106","8. FRANCHISE-ARRANGEMENT ASSETS, ADVERTISING AND SHARE-BASED COMPENSATION") -> 8. FRANCHISE-ARRANGEMENT ASSETS, ADVERTISING AND SHARE-BASED COMPENSATION
A15: =HYPERLINK("#'Note Schedules'!A121","9. OTHER OPERATING FACTS DISCLOSED IN TEXT ONLY (APPROXIMATE; NOT TABULATED BY THE COMPANY)") -> 9. OTHER OPERATING FACTS DISCLOSED IN TEXT ONLY (APPROXIMATE; NOT TABULATED BY THE COMPANY)
A17: 1. PROPERTY AND EQUIPMENT (NOTE)
A18: Land | D18: 5662.2 | E18: 5521.4 | F18: 6026.4 | G18: 6349.1 | H18: 6487.6 | I18: 6686.3 | J18: 7081 | K18: 7253 | L18: 8169
A19: Buildings and improvements on owned land | D19: 14776.9 | E19: 15377.4 | F19: 17003.7 | G19: 18218.9 | H19: 18666 | I19: 18934.2 | J19: 20059 | K19: 20487 | L19: 22202
A20: Buildings and improvements on leased land | D20: 12509.2 | E20: 12863.6 | F20: 12605.9 | G20: 13364.5 | H20: 13283.3 | I20: 12492 | J20: 13322 | K20: 13417 | L20: 15506
A21: Equipment, signs and seating | D21: 3165.7 | E21: 2942.6 | F21: 2994.5 | G21: 3119 | H21: 3032 | I21: 2498.6 | J21: 2693 | K21: 2586 | L21: 2954
A22: Other | D22: 512.4 | E22: 488.6 | F22: 420.4 | G22: 425 | H22: 447.7 | I22: 426.5 | J22: 414 | K22: 434 | L22: 459
A23: Property and equipment, at cost | D23: 36626.4 | E23: 37193.6 | F23: 39050.9 | G23: 41476.5 | H23: 41916.6 | I23: 41037.6 | J23: 43570 | K23: 44177 | L23: 49290
A24: Accumulated depreciation and amortization | D24: -14178.1 | E24: -14350.9 | F24: -14890.9 | G24: -16518.3 | H24: -17196 | I24: -17264 | J24: -18662 | K24: -18882 | L24: -21049
A25: Net property and equipment | D25: 22448.3 | E25: 22842.7 | F25: 24160 | G25: 24958.2 | H25: 24720.6 | I25: 23773.6 | J25: 24908 | K25: 25295 | L25: 28241
A26: Components vs cost (rounding) | D26: =D18+D19+D20+D21+D22-D23 -> 0 | E26: =E18+E19+E20+E21+E22-E23 -> 0 | F26: =F18+F19+F20+F21+F22-F23 -> 0 | G26: =G18+G19+G20+G21+G22-G23 -> 0 | H26: =H18+H19+H20+H21+H22-H23 -> 0 | I26: =I18+I19+I20+I21+I22-I23 -> 0 | J26: =J18+J19+J20+J21+J22-J23 -> -1 | K26: =K18+K19+K20+K21+K22-K23 -> 0 | L26: =L18+L19+L20+L21+L22-L23 -> 0
A27: Note net PP&E vs balance sheet (rounding) | D27: =D25-'Balance Sheet'!D28 -> 0 | E27: =E25-'Balance Sheet'!E28 -> 0 | F27: =F25-'Balance Sheet'!F28 -> 0 | G27: =G25-'Balance Sheet'!G28 -> 0 | H27: =H25-'Balance Sheet'!H28 -> 0 | I27: =I25-'Balance Sheet'!I28 -> 0 | J27: =J25-'Balance Sheet'!J28 -> 0 | K27: =K25-'Balance Sheet'!K28 -> 0 | L27: =L25-'Balance Sheet'!L28 -> 0
A29: 2. INCOME TAXES (NOTE)
A30: Income before taxes: U.S. | C30: 2059.4 | D30: 2242 | E30: 2218 | F30: 2159.1 | G30: 1390.4 | H30: 2413.9 | I30: 1846 | J30: 3665 | K30: 3282 | L30: 3291
A31: Income before taxes: outside the U.S. | C31: 4806.6 | D31: 6331.5 | E31: 5598.1 | F31: 5859 | G31: 4750.3 | H31: 6714 | I31: 5980 | J31: 6857 | K31: 7062 | L31: 7606
A32: Income before provision for income taxes | C32: 6866 | D32: 8573.5 | E32: 7816.1 | F32: 8018.1 | G32: 6140.7 | H32: 9127.9 | I32: 7825 | J32: 10522 | K32: 10345 | L32: 10897
A33: Current: U.S. federal | C33: 1046.6 | D33: 2030.8 | E33: 292.9 | F33: 521.8 | G33: 554.1 | H33: 887.6 | I33: 517 | J33: 1340 | K33: 1412 | L33: 1085
A34: Current: U.S. state | C34: 121.3 | D34: 169.8 | E34: 183.9 | F34: 194.7 | G34: 119.1 | H34: 228.1 | I34: 246 | J34: 263 | K34: 269 | L34: 198
A35: Current: outside the U.S. | C35: 1550.2 | D35: 1217 | E35: 1312.4 | F35: 1126.5 | G35: 730.6 | H35: 895.3 | I35: 1230 | J35: 1137 | K35: 1014 | L35: 1177
A36: Current tax provision | C36: 2718.1 | D36: 3417.6 | E36: 1789.2 | F36: 1843 | G36: 1403.8 | H36: 2011 | I36: 1994 | J36: 2740 | K36: 2695 | L36: 2460
A37: Deferred: U.S. federal | C37: -122.1 | D37: -120.1 | E37: 145.7 | F37: 38.5 | G37: 870.3 | H37: -177.4 | I37: -80 | J37: -146 | K37: -76 | L37: -349
A38: Deferred: U.S. state | C38: 14.1 | D38: 12.8 | E38: 18.7 | F38: 20 | G38: 73.3 | H38: -24.1 | I38: -46 | J38: -30 | K38: -20 | L38: -84
A39: Deferred: outside the U.S. | C39: -430.6 | D39: 70.9 | E39: -61.8 | F39: 91.2 | G39: -937.2 | H39: -226.8 | I39: -220 | J39: -511 | K39: -478 | L39: 307
A40: Deferred tax (benefit) provision | C40: -538.6 | D40: -36.4 | E40: 102.6 | F40: 149.7 | G40: 6.4 | H40: -428.3 | I40: -346 | J40: -686 | K40: -574 | L40: -126
A41: Provision for income taxes | C41: 2179.5 | D41: 3381.2 | E41: 1891.8 | F41: 1992.7 | G41: 1410.2 | H41: 1582.7 | I41: 1648 | J41: 2053 | K41: 2121 | L41: 2334
A42: U.S. share of pre-tax income | C42: =C30/C32 -> 0.29994174 | D42: =D30/D32 -> 0.26150347 | E42: =E30/E32 -> 0.28377324 | F42: =F30/F32 -> 0.26927826 | G42: =G30/G32 -> 0.2264237 | H42: =H30/H32 -> 0.26445294 | I42: =I30/I32 -> 0.23591054 | J42: =J30/J32 -> 0.34831781 | ... L42: =L30/L32 -> 0.30200973
A43: Pre-tax split vs IS (rounding) | C43: =C32-'Income Statement'!C39 -> 0 | D43: =D32-'Income Statement'!D39 -> 0 | E43: =E32-'Income Statement'!E39 -> 0 | F43: =F32-'Income Statement'!F39 -> 0 | G43: =G32-'Income Statement'!G39 -> 0 | H43: =H32-'Income Statement'!H39 -> 0 | I43: =I32-'Income Statement'!I39 -> 0 | J43: =J32-'Income Statement'!J39 -> 0 | ... L43: =L32-'Income Statement'!L39 -> 0
...

Sheet Derived Metrics
A1: McDonald's Corporation — Derived Metrics
A2: $ in millions except per-share data | USD | as of 2026-10-08
C3: FY2016 | D3: FY2017 | E3: FY2018 | F3: FY2019 | G3: FY2020 | H3: FY2021 | I3: FY2022 | J3: FY2023 | K3: FY2024 | L3: FY2025 | M3: · | N3: 3Q2024 | O3: 4Q2024* | P3: 1Q2025 | Q3: 2Q2025 | R3: 3Q2025 | S3: 4Q2025* | T3: 1Q2026 | U3: 2Q2026
C4: 2016-12-31 | D4: 2017-12-31 | E4: 2018-12-31 | F4: 2019-12-31 | G4: 2020-12-31 | H4: 2021-12-31 | I4: 2022-12-31 | J4: 2023-12-31 | K4: 2024-12-31 | L4: 2025-12-31 | N4: 2024-09-30 | O4: 2024-12-31 | P4: 2025-03-31 | Q4: 2025-06-30 | R4: 2025-09-30 | S4: 2025-12-31 | T4: 2026-03-31 | U4: 2026-06-30
A6: CONTENTS
A7: =HYPERLINK("#'Derived Metrics'!A16","1. PROFITABILITY") -> 1. PROFITABILITY
A8: =HYPERLINK("#'Derived Metrics'!A29","2. RETURNS AND EFFICIENCY (ANNUAL; AVERAGE BALANCES)") -> 2. RETURNS AND EFFICIENCY (ANNUAL; AVERAGE BALANCES)
A9: =HYPERLINK("#'Derived Metrics'!A37","3. LEVERAGE AND COVERAGE (ANNUAL)") -> 3. LEVERAGE AND COVERAGE (ANNUAL)
A10: =HYPERLINK("#'Derived Metrics'!A45","4. LIQUIDITY (PERIOD-END)") -> 4. LIQUIDITY (PERIOD-END)
A11: =HYPERLINK("#'Derived Metrics'!A50","5. CASH CONVERSION AND CAPITAL ALLOCATION") -> 5. CASH CONVERSION AND CAPITAL ALLOCATION
A12: =HYPERLINK("#'Derived Metrics'!A62","6. SYSTEMWIDE AND FRANCHISE ECONOMICS") -> 6. SYSTEMWIDE AND FRANCHISE ECONOMICS
A13: =HYPERLINK("#'Derived Metrics'!A73","7. EARNINGS QUALITY") -> 7. EARNINGS QUALITY
A14: =HYPERLINK("#'Derived Metrics'!A77","8. GROWTH") -> 8. GROWTH
A16: 1. PROFITABILITY
A17: Franchised margin ($mm) | C17: ='Income Statement'!C12-'Income Statement'!C20 -> 7608.5 | D17: ='Income Statement'!D12-'Income Statement'!D20 -> 8311.5 | E17: ='Income Statement'!E12-'Income Statement'!E20 -> 9039.2 | F17: ='Income Statement'!F12-'Income Statement'!F20 -> 9455.1 | G17: ='Income Statement'!G12-'Income Statement'!G20 -> 8518.6 | H17: ='Income Statement'!H12-'Income Statement'!H20 -> 10750.4 | I17: ='Income Statement'!I12-'Income Statement'!I20 -> 11756 | J17: ='Income Statement'!J12-'Income Statement'!J20 -> 12962 | ... L17: ='Income Statement'!L12-'Income Statement'!L20 -> 13930 | N17: ='Income Statement'!N12-'Income Statement'!N20 -> 3448 | O17: ='Income Statement'!O12-'Income Statement'!O20 -> 3325 | P17: ='Income Statement'!P12-'Income Statement'!P20 -> 3041 | Q17: ='Income Statement'!Q12-'Income Statement'!Q20 -> 3559 | R17: ='Income Statement'!R12-'Income Statement'!R20 -> 3697 | S17: ='Income Statement'!S12-'Income Statement'!S20 -> 3632 | T17: ='Income Statement'!T12-'Income Statement'!T20 -> 3331 | U17: ='Income Statement'!U12-'Income Statement'!U20 -> 3713
A18: Franchised margin % of franchised revenues | C18: =('Income Statement'!C12-'Income Statement'!C20)/'Income Statement'!C12 -> 0.81575872 | D18: =('Income Statement'!D12-'Income Statement'!D20)/'Income Statement'!D12 -> 0.82279859 | E18: =('Income Statement'!E12-'Income Statement'!E20)/'Income Statement'!E12 -> 0.82081271 | F18: =('Income Statement'!F12-'Income Statement'!F20)/'Income Statement'!F12 -> 0.81119967 | G18: =('Income Statement'!G12-'Income Statement'!G20)/'Income Statement'!G12 -> 0.7941936 | H18: =('Income Statement'!H12-'Income Statement'!H20)/'Income Statement'!H12 -> 0.82155685 | I18: =('Income Statement'!I12-'Income Statement'!I20)/'Income Statement'!I12 -> 0.83340423 | J18: =('Income Statement'!J12-'Income Statement'!J20)/'Income Statement'!J12 -> 0.83967092 | ... L18: =('Income Statement'!L12-'Income Statement'!L20)/'Income Statement'!L12 -> 0.84179357 | N18: =('Income Statement'!N12-'Income Statement'!N20)/'Income Statement'!N12 -> 0.84220811 | O18: =('Income Statement'!O12-'Income Statement'!O20)/'Income Statement'!O12 -> 0.83985855 | P18: =('Income Statement'!P12-'Income Statement'!P20)/'Income Statement'!P12 -> 0.83064736 | Q18: =('Income Statement'!Q12-'Income Statement'!Q20)/'Income Statement'!Q12 -> 0.8447662 | R18: =('Income Statement'!R12-'Income Statement'!R20)/'Income Statement'!R12 -> 0.84735274 | S18: =('Income Statement'!S12-'Income Statement'!S20)/'Income Statement'!S12 -> 0.84269142 | T18: =('Income Statement'!T12-'Income Statement'!T20)/'Income Statement'!T12 -> 0.83129523 | U18: =('Income Statement'!U12-'Income Statement'!U20)/'Income Statement'!U12 -> 0.84520829
