Workbook

Sheet Cover
A1: The Coca-Cola Company — Cover
A2: $ in millions except per-share data | USD | as of 2026-10-14
A4: The Coca-Cola Company (NYSE: KO)
A6: Ticker / exchange | B6: KO / NYSE
A7: CIK | B7: 0000021344
A8: Reporting framework | B8: US GAAP, consolidated
A9: Currency / units | B9: USD; $ in millions except per-share data
A10: Fiscal year end | B10: December 31 (10-Q quarters end on the Friday nearest the calendar quarter end)
A11: Annual window | B11: FY2016-FY2025 (ten 10-Ks)
A12: Quarterly window | B12: 3Q2024, 1Q2025, 2Q2025, 3Q2025, 1Q2026, 2Q2026 (six 10-Qs; no 4Q columns because a 10-K is not a quarterly filing)
A13: Latest covered period | B13: 2Q2026 (quarter ended July 3, 2026; 10-Q filed 2026-07-29)
A14: Workbook date | B14: 2026-10-14 (reviewed; original export 2026-10-13)
A16: Sheet directory
A17: Income Statement (IS) | B17: As-reported income statement, growth/margin rows, six tie-out checks
A18: Balance Sheet (BS) | B18: As-reported balance sheet, eight tie-out checks, working-capital days
A19: Cash Flow (CF) | B19: As-reported cash flow statement (quarterly columns are fiscal year-to-date), four checks, FCF and shareowner-return analytics
A20: Segments (SEG) | B20: Three segment bases kept separate (A: FY2016-FY2018, B: FY2017-FY2024, C: FY2023-FY2025), each tied to consolidated totals
A21: Geography (GEO) | B21: US / International net operating revenues and PP&E
A22: Derived Metrics (DM) | B22: Live formulas from verified IS/BS/CF and segment D&A; annual and selected discrete-quarter ratios. Cash-flow ratios retain annual coverage where quarterly inputs are cumulative.
A23: Sources | B23: Filing accessions, file paths, SHA-256, annual-column provenance, restatement log
A25: Colour legend
A26: Blue font | B26: Hard-coded value copied from a filing
A27: Black font | B27: Formula
A28: Green font | B28: Cross-sheet link
A29: Grey italic | B29: Memo / analytic row
A31: How annual columns were sourced
A32: Income statement and cash flow | B32: Each fiscal year is taken from the 10-K filed two years later (or the FY2025 10-K for FY2024 and FY2025), so later reclassifications are reflected. The first-filed value is compared with the value used in the Sources sheet.
A33: Balance sheet | B33: Each year-end is taken from the 10-K for the following year (the FY2025 10-K for FY2025), i.e. the later comparative column.
A34: Quarterly | B34: IS: three-month column of each 10-Q. BS: period-end balance of each 10-Q. CF: fiscal year-to-date column of each 10-Q (Q1 = 3 months, Q2 = 6 months, Q3 = 9 months).
A36: Comparability notes
A37: Sign convention | B37: Income-statement expenses are shown positive as filed (cost of goods sold, SG&A, interest expense, income taxes). Cash-flow outflows are negative as filed.
A38: Discontinued operations | B38: FY2016-FY2018 filings present a discontinued-operations line (FY2017-FY2018). The latest filing presenting each year is used, so FY2017 and FY2018 follow the FY2019 and FY2020 10-K presentation.
A39: Recast years | B39: Later 10-Ks recast earlier years: FY2016 operating income (FY2018 10-K), FY2017 and FY2018 net operating revenues and operating income (FY2019 and FY2020 10-Ks), and operating cash flow for FY2016-FY2018. FY2016 is on the older pre-recast basis because no later 10-K presents it; FY2016-to-FY2017 growth rates therefore mix bases. The differences are listed in the Sources sheet; the cause is not analysed here.
A40: Caption changes | B40: FY2021 onward: 'prepaid expenses and other current assets', 'other noncurrent assets/liabilities' replace earlier captions; debt issuance/payment captions were renamed in the FY2023 10-K with identical values. Equivalent lines share one row.
A41: Segments | B41: KO re-segmented in the FY2019 10-K (Global Ventures added) and again in the FY2025 10-K (Global Ventures dissolved). Segment series are not stitched across bases. The FY2025 10-K recast covers FY2023-FY2025 only.
A42: Fiscal 2025 events | B42: Large FY2024 'Other operating charges' and FY2024-FY2025 cash-flow movements relate to the IRS tax litigation deposit and the settlement of the fairlife contingent consideration (see 10-K notes). The workbook does not adjust them.
A44: Not built in this pass
A45: Valuation / forecast sheets | B45: Excluded by instruction.
A46: Operating Metrics and Note Schedules coverage | B46: Built and verified: volume, revenue factors, line of business, debt, income taxes, equity-method investees, and assets/liabilities held for sale. Standalone BS Detail remains absent.
A47: Non-GAAP bridge | B47: Not built: KO's comparable (non-GAAP) measures are in the 8-K earnings releases and IR schedules acquired in the research package; they are not included here.
...

Sheet Income Statement
A1: The Coca-Cola Company — Income Statement
A2: $ in millions except per-share data | USD | as of 2026-10-14
C3: FY2016 | D3: FY2017 | E3: FY2018 | F3: FY2019 | G3: FY2020 | H3: FY2021 | I3: FY2022 | J3: FY2023 | K3: FY2024 | L3: FY2025 | M3: · | N3: · | O3: · | P3: 3Q2024 | Q3: 1Q2025 | R3: 2Q2025 | S3: 3Q2025 | T3: 1Q2026 | U3: 2Q2026
C4: 2016-12-31 | D4: 2017-12-31 | E4: 2018-12-31 | F4: 2019-12-31 | G4: 2020-12-31 | H4: 2021-12-31 | I4: 2022-12-31 | J4: 2023-12-31 | K4: 2024-12-31 | L4: 2025-12-31 | P4: 2024-09-27 | Q4: 2025-03-28 | R4: 2025-06-27 | S4: 2025-09-26 | T4: 2026-04-03 | U4: 2026-07-03
A6: CONTENTS
A7: =HYPERLINK("#'Income Statement'!A10","1. INCOME STATEMENT — AS REPORTED (expenses shown positive, as filed)") -> 1. INCOME STATEMENT — AS REPORTED (expenses shown positive, as filed)
A8: =HYPERLINK("#'Income Statement'!A47","2. CHECKS") -> 2. CHECKS
A10: 1. INCOME STATEMENT — AS REPORTED (expenses shown positive, as filed)
A11: Net Operating Revenues | C11: 41863 | D11: 36212 | E11: 34300 | F11: 37266 | G11: 33014 | H11: 38655 | I11: 43004 | J11: 45754 | K11: 47061 | L11: 47941 | P11: 11854 | Q11: 11129 | R11: 12535 | S11: 12455 | T11: 12472 | U11: 13380
A12: YoY Growth | D12: =IF(N(C11)=0,"",D11/C11-1) -> -0.13498794 | E12: =IF(N(D11)=0,"",E11/D11-1) -> -0.052800177 | F12: =IF(N(E11)=0,"",F11/E11-1) -> 0.086472303 | G12: =IF(N(F11)=0,"",G11/F11-1) -> -0.11409864 | H12: =IF(N(G11)=0,"",H11/G11-1) -> 0.1708669 | I12: =IF(N(H11)=0,"",I11/H11-1) -> 0.11250808 | J12: =IF(N(I11)=0,"",J11/I11-1) -> 0.06394754 | K12: =IF(N(J11)=0,"",K11/J11-1) -> 0.028565808 | L12: =IF(N(K11)=0,"",L11/K11-1) -> 0.018699135
A13: Cost of goods sold | C13: 16465 | D13: 13721 | E13: 13067 | F13: 14619 | G13: 13433 | H13: 15357 | I13: 18000 | J13: 18520 | K13: 18324 | L13: 18397 | P13: 4664 | Q13: 4163 | R13: 4714 | S13: 4797 | T13: 4620 | U13: 4965
A14: Gross Profit | C14: 25398 | D14: 22491 | E14: 21233 | F14: 22647 | G14: 19581 | H14: 23298 | I14: 25004 | J14: 27234 | K14: 28737 | L14: 29544 | P14: 7190 | Q14: 6966 | R14: 7821 | S14: 7658 | T14: 7852 | U14: 8415
A15: Gross Margin | C15: =C14/C11 -> 0.60669326 | D15: =D14/D11 -> 0.62109246 | E15: =E14/E11 -> 0.6190379 | F15: =F14/F11 -> 0.60771212 | G15: =G14/G11 -> 0.59311201 | H15: =H14/H11 -> 0.60271634 | I15: =I14/I11 -> 0.58143429 | J15: =J14/J11 -> 0.59522665 | ... L15: =L14/L11 -> 0.61625748 | P15: =P14/P11 -> 0.60654631 | Q15: =Q14/Q11 -> 0.62593225 | R15: =R14/R11 -> 0.62393299 | S15: =S14/S11 -> 0.61485347 | T15: =T14/T11 -> 0.62957024 | U15: =U14/U11 -> 0.62892377
A16: Selling, general and administrative expenses | C16: 15370 | D16: 12834 | E16: 11002 | F16: 12103 | G16: 9731 | H16: 12144 | I16: 12880 | J16: 13972 | K16: 14582 | L16: 14521 | P16: 3636 | Q16: 3234 | R16: 3470 | S16: 3618 | T16: 3472 | U16: 3720
A17: Other operating charges | C17: 1371 | D17: 1902 | E17: 1079 | F17: 458 | G17: 853 | H17: 846 | I17: 1215 | J17: 1951 | K17: 4163 | L17: 1261 | P17: 1044 | Q17: 73 | R17: 71 | S17: 58 | T17: 21 | U17: 23
A18: Operating Income | C18: 8657 | D18: 7755 | E18: 9152 | F18: 10086 | G18: 8997 | H18: 10308 | I18: 10909 | J18: 11311 | K18: 9992 | L18: 13762 | P18: 2510 | Q18: 3659 | R18: 4280 | S18: 3982 | T18: 4359 | U18: 4672
A19: Operating Margin | C19: =C18/C11 -> 0.20679359 | D19: =D18/D11 -> 0.21415553 | E19: =E18/E11 -> 0.26682216 | F19: =F18/F11 -> 0.27064885 | G19: =G18/G11 -> 0.27252075 | H19: =H18/H11 -> 0.26666667 | I19: =I18/I11 -> 0.25367408 | J19: =J18/J11 -> 0.24721336 | ... L19: =L18/L11 -> 0.28706118 | P19: =P18/P11 -> 0.21174287 | Q19: =Q18/Q11 -> 0.32878066 | R19: =R18/R11 -> 0.34144396 | S19: =S18/S11 -> 0.31971096 | T19: =T18/T11 -> 0.34950289 | U19: =U18/U11 -> 0.34917788
A20: YoY Growth | D20: =IF(N(C18)=0,"",D18/C18-1) -> -0.10419314 | E20: =IF(N(D18)=0,"",E18/D18-1) -> 0.18014184 | F20: =IF(N(E18)=0,"",F18/E18-1) -> 0.1020542 | G20: =IF(N(F18)=0,"",G18/F18-1) -> -0.10797145 | H20: =IF(N(G18)=0,"",H18/G18-1) -> 0.14571524 | I20: =IF(N(H18)=0,"",I18/H18-1) -> 0.05830423 | J20: =IF(N(I18)=0,"",J18/I18-1) -> 0.036850307 | K20: =IF(N(J18)=0,"",K18/J18-1) -> -0.11661215 | L20: =IF(N(K18)=0,"",L18/K18-1) -> 0.37730184
A21: Interest income | C21: 642 | D21: 679 | E21: 689 | F21: 563 | G21: 370 | H21: 276 | I21: 449 | J21: 907 | K21: 988 | L21: 786 | P21: 263 | Q21: 180 | R21: 188 | S21: 185 | T21: 222 | U21: 198
A22: Interest expense | C22: 733 | D22: 853 | E22: 950 | F22: 946 | G22: 1437 | H22: 1597 | I22: 882 | J22: 1527 | K22: 1656 | L22: 1654 | P22: 425 | Q22: 387 | R22: 445 | S22: 391 | T22: 375 | U22: 369
A23: Equity income (loss) — net | C23: 835 | D23: 1072 | E23: 1008 | F23: 1049 | G23: 978 | H23: 1438 | I23: 1472 | J23: 1691 | K23: 1770 | L23: 2031 | P23: 541 | Q23: 351 | R23: 561 | S23: 644 | T23: 384 | U23: 604
A24: Other income (loss) — net | C24: -1265 | D24: -1763 | E24: -1674 | F24: 34 | G24: 841 | H24: 2000 | I24: -262 | J24: 570 | K24: 1992 | L24: 1073 | P24: 491 | Q24: 254 | R24: 212 | S24: -237 | T24: 21 | U24: 370
A25: Income Before Income Taxes | B25: FY2016 from the FY2018 10-K: income from continuing operations before income taxes. | C25: 8136 | D25: 6890 | E25: 8225 | F25: 10786 | G25: 9749 | H25: 12425 | I25: 11686 | J25: 12952 | K25: 13086 | L25: 15998 | P25: 3380 | Q25: 4057 | R25: 4796 | S25: 4183 | T25: 4611 | U25: 5475
A26: Income taxes | C26: 1586 | D26: 5607 | E26: 1749 | F26: 1801 | G26: 1981 | H26: 2621 | I26: 2115 | J26: 2249 | K26: 2437 | L26: 2861 | P26: 530 | Q26: 722 | R26: 993 | S26: 500 | T26: 645 | U26: 1037
A27: Effective Tax Rate | C27: =C26/C25 -> 0.19493609 | D27: =D26/D25 -> 0.8137881 | E27: =E26/E25 -> 0.21264438 | F27: =F26/F25 -> 0.16697571 | G27: =G26/G25 -> 0.20320033 | H27: =H26/H25 -> 0.21094567 | I27: =I26/I25 -> 0.18098579 | J27: =J26/J25 -> 0.17364114 | ... L27: =L26/L25 -> 0.17883485 | P27: =P26/P25 -> 0.15680473 | Q27: =Q26/Q25 -> 0.17796401 | R27: =R26/R25 -> 0.20704754 | S27: =S26/S25 -> 0.11953144 | T27: =T26/T25 -> 0.13988289 | U27: =U26/U25 -> 0.18940639
A28: Net income from continuing operations | C28: 6550
A29: Income (loss) from discontinued operations, net of income taxes | B29: Shown only where the latest filing presenting the year reports it. | C29: 0
A30: Consolidated Net Income | C30: 6550 | D30: 1283 | E30: 6476 | F30: 8985 | G30: 7768 | H30: 9804 | I30: 9571 | J30: 10703 | K30: 10649 | L30: 13137 | P30: 2850 | Q30: 3335 | R30: 3803 | S30: 3683 | T30: 3966 | U30: 4438
A31: Less: Net income (loss) attributable to noncontrolling interests | C31: 23 | D31: 35 | E31: 42 | F31: 65 | G31: 21 | H31: 33 | I31: 29 | J31: -11 | K31: 18 | L31: 30 | P31: 2 | Q31: 5 | R31: -7 | S31: -13 | T31: 42 | U31: 13
A32: Net Income Attributable to Shareowners of The Coca-Cola Company | C32: 6527 | D32: 1248 | E32: 6434 | F32: 8920 | G32: 7747 | H32: 9771 | I32: 9542 | J32: 10714 | K32: 10631 | L32: 13107 | P32: 2848 | Q32: 3330 | R32: 3810 | S32: 3696 | T32: 3924 | U32: 4425
A33: Net Margin (attributable) | C33: =C32/C11 -> 0.15591334 | D33: =D32/D11 -> 0.034463714 | E33: =E32/E11 -> 0.18758017 | F33: =F32/F11 -> 0.23936027 | G33: =G32/G11 -> 0.23465802 | H33: =H32/H11 -> 0.25277454 | I33: =I32/I11 -> 0.22188634 | J33: =J32/J11 -> 0.23416532 | ... L33: =L32/L11 -> 0.27339855 | P33: =P32/P11 -> 0.24025645 | Q33: =Q32/Q11 -> 0.29921826 | R33: =R32/R11 -> 0.30394894 | S33: =S32/S11 -> 0.29674829 | T33: =T32/T11 -> 0.31462476 | U33: =U32/U11 -> 0.33071749
A34: YoY Growth | D34: =IF(N(C32)=0,"",D32/C32-1) -> -0.80879424 | E34: =IF(N(D32)=0,"",E32/D32-1) -> 4.1554487 | F34: =IF(N(E32)=0,"",F32/E32-1) -> 0.38638483 | G34: =IF(N(F32)=0,"",G32/F32-1) -> -0.13150224 | H34: =IF(N(G32)=0,"",H32/G32-1) -> 0.26126242 | I34: =IF(N(H32)=0,"",I32/H32-1) -> -0.0234367 | J34: =IF(N(I32)=0,"",J32/I32-1) -> 0.1228254 | K34: =IF(N(J32)=0,"",K32/J32-1) -> -0.0077468732 | L34: =IF(N(K32)=0,"",L32/K32-1) -> 0.23290377
A35: Basic net income per share from continuing operations | C35: 1.51
A36: Basic net income per share from discontinued operations
A37: Basic net income (loss) per share from discontinued operations | C37: 0
A38: Basic Net Income Per Share | C38: 1.51 | D38: 0.29 | E38: 1.51 | F38: 2.09 | G38: 1.8 | H38: 2.26 | I38: 2.2 | J38: 2.48 | K38: 2.47 | L38: 3.05 | P38: 0.66 | Q38: 0.77 | R38: 0.89 | S38: 0.86 | T38: 0.91 | U38: 1.03
A39: Diluted net income per share from continuing operations | C39: 1.49
A40: Diluted net income per share from discontinued operations
A41: Diluted net income (loss) per share from discontinued operations | C41: 0
A42: Diluted Net Income Per Share | C42: 1.49 | D42: 0.29 | E42: 1.5 | F42: 2.07 | G42: 1.79 | H42: 2.25 | I42: 2.19 | J42: 2.47 | K42: 2.46 | L42: 3.04 | P42: 0.66 | Q42: 0.77 | R42: 0.88 | S42: 0.86 | T42: 0.91 | U42: 1.03
...

Sheet Balance Sheet
A1: The Coca-Cola Company — Balance Sheet
A2: $ in millions except per-share data | USD | as of 2026-10-14
C3: FY2016 | D3: FY2017 | E3: FY2018 | F3: FY2019 | G3: FY2020 | H3: FY2021 | I3: FY2022 | J3: FY2023 | K3: FY2024 | L3: FY2025 | M3: · | N3: · | O3: · | P3: 3Q2024 | Q3: 1Q2025 | R3: 2Q2025 | S3: 3Q2025 | T3: 1Q2026 | U3: 2Q2026
C4: 2016-12-31 | D4: 2017-12-31 | E4: 2018-12-31 | F4: 2019-12-31 | G4: 2020-12-31 | H4: 2021-12-31 | I4: 2022-12-31 | J4: 2023-12-31 | K4: 2024-12-31 | L4: 2025-12-31 | P4: 2024-09-27 | Q4: 2025-03-28 | R4: 2025-06-27 | S4: 2025-09-26 | T4: 2026-04-03 | U4: 2026-07-03
A6: CONTENTS
A7: =HYPERLINK("#'Balance Sheet'!A11","1. BALANCE SHEET — AS REPORTED (year-end values from the first 10-K after the year-end; quarterly columns are 10-Q period-end)") -> 1. BALANCE SHEET — AS REPORTED (year-end values from the first 10-K after the year-end; quarterly columns are 10-Q period-end)
A8: =HYPERLINK("#'Balance Sheet'!A58","2. CHECKS") -> 2. CHECKS
A9: =HYPERLINK("#'Balance Sheet'!A68","3. WORKING CAPITAL ANALYTICS (quarterly uses 91 days; the 10-Q IS is a three-month column)") -> 3. WORKING CAPITAL ANALYTICS (quarterly uses 91 days; the 10-Q IS is a three-month column)
A11: 1. BALANCE SHEET — AS REPORTED (year-end values from the first 10-K after the year-end; quarterly columns are 10-Q period-end)
A12: Assets
A13: Current Assets
A14: Cash and cash equivalents | C14: 8555 | D14: 6006 | E14: 9077 | F14: 6480 | G14: 6795 | H14: 9684 | I14: 9519 | J14: 9366 | K14: 10828 | L14: 10270 | P14: 13938 | Q14: 8417 | R14: 9590 | S14: 12732 | T14: 10574 | U14: 12907
A15: Short-term investments | C15: 9595 | D15: 9352 | E15: 2025 | F15: 1467 | G15: 1771 | H15: 1242 | I15: 1043 | J15: 2997 | K15: 2020 | L15: 3602 | P15: 2439 | Q15: 3579 | R15: 2658 | S15: 1142 | T15: 509 | U15: 622
A16: Total Cash, Cash Equivalents and Short-Term Investments | C16: 18150 | D16: 15358 | E16: 11102 | F16: 7947 | G16: 8566 | H16: 10926 | I16: 10562 | J16: 12363 | K16: 12848 | L16: 13872 | P16: 16377 | Q16: 11996 | R16: 12248 | S16: 13874 | T16: 11083 | U16: 13529
A17: Marketable securities | C17: 4051 | D17: 5317 | E17: 5013 | F17: 3228 | G17: 2348 | H17: 1699 | I17: 1069 | J17: 1300 | K17: 1723 | L17: 1934 | P17: 1787 | Q17: 1791 | R17: 2049 | S17: 1907 | T17: 2737 | U17: 2842
A18: Trade accounts receivable, less allowances | C18: 3856 | D18: 3667 | E18: 3685 | F18: 3971 | G18: 3144 | H18: 3512 | I18: 3487 | J18: 3410 | K18: 3569 | L18: 3038 | P18: 4233 | Q18: 4091 | R18: 4168 | S18: 3946 | T18: 3675 | U18: 3732
A19: Inventories | C19: 2675 | D19: 2655 | E19: 3071 | F19: 3379 | G19: 3266 | H19: 3414 | I19: 4233 | J19: 4424 | K19: 4728 | L19: 4425 | P19: 4714 | Q19: 5102 | R19: 5082 | S19: 4802 | T19: 4730 | U19: 4647
A20: Prepaid expenses and other current assets | C20: 2481 | D20: 2000 | E20: 2059 | F20: 1886 | G20: 1916 | H20: 2994 | I20: 3240 | J20: 5235 | K20: 2998 | L20: 2433 | P20: 3177 | Q20: 3198 | R20: 3062 | S20: 2718 | T20: 2953 | U20: 2688
A21: Assets held for sale | C21: 2797 | D21: 219 | K21: 131 | L21: 5342 | T21: 5212 | U21: 5438
A22: Assets held for sale — discontinued operations | C22: 0 | D22: 7329
A23: Total Current Assets | C23: 34010 | D23: 36545 | E23: 24930 | F23: 20411 | G23: 19240 | H23: 22545 | I23: 22591 | J23: 26732 | K23: 25997 | L23: 31044 | P23: 30288 | Q23: 26178 | R23: 26609 | S23: 27247 | T23: 30390 | U23: 32876
A24: Equity method investments | C24: 16260 | D24: 20856 | E24: 19412 | F24: 19025 | G24: 19273 | H24: 17598 | I24: 18264 | J24: 19671 | K24: 18087 | L24: 20235 | P24: 18993 | Q24: 18369 | R24: 19379 | S24: 20323 | T24: 20403 | U24: 20782
A25: Other investments | C25: 989 | D25: 1096 | E25: 867 | F25: 854 | G25: 812 | H25: 818 | I25: 501 | P25: 44
A26: Deferred income tax assets | D26: 330 | E26: 2674 | F26: 2412 | G26: 2460 | H26: 2129 | I26: 1746 | J26: 1561 | K26: 1319 | L26: 1206 | P26: 1428 | Q26: 1311 | R26: 1325 | S26: 1267 | T26: 1141 | U26: 1090
A27: Property, plant and equipment — net | C27: 10635 | D27: 8203 | E27: 9598 | F27: 10838 | G27: 10777 | H27: 9920 | I27: 9841 | J27: 9236 | K27: 10303 | L27: 9613 | P27: 9864 | Q27: 10431 | R27: 10784 | S27: 10902 | T27: 9522 | U27: 9636
A28: Trademarks with indefinite lives | C28: 6097 | D28: 6729 | E28: 6682 | F28: 9266 | G28: 10395 | H28: 14465 | I28: 14214 | J28: 14349 | K28: 13301 | L28: 12531 | P28: 13598 | Q28: 13425 | R28: 13615 | S28: 13515 | T28: 12463 | U28: 12500
A29: Bottlers' franchise rights with indefinite lives | C29: 3676 | D29: 138 | E29: 51
A30: Goodwill | C30: 10629 | D30: 9401 | E30: 14109 | F30: 16764 | G30: 17506 | H30: 19363 | I30: 18782 | J30: 18358 | K30: 18139 | L30: 15491 | P30: 18686 | Q30: 18333 | R30: 18663 | S30: 18662 | T30: 15411 | U30: 15456
A31: Other intangible assets | C31: 726 | D31: 368 | E31: 745 | F31: 736 | G31: 649 | H31: 785 | I31: 635 | P31: 461
A32: Other noncurrent assets | C32: 4248 | D32: 4230 | E32: 4148 | F32: 6075 | G32: 6184 | H32: 6731 | I32: 6189 | J32: 7796 | K32: 13403 | L32: 14696 | P32: 12904 | Q32: 13669 | R32: 13958 | S32: 14129 | T32: 14887 | U32: 15582
A33: Total Assets | C33: 87270 | D33: 87896 | E33: 83216 | F33: 86381 | G33: 87296 | H33: 94354 | I33: 92763 | J33: 97703 | K33: 100549 | L33: 104816 | P33: 106266 | Q33: 101716 | R33: 104333 | S33: 106045 | T33: 104217 | U33: 107922
A34: Liabilities and equity
A35: Current Liabilities
A36: Accounts payable and accrued expenses | C36: 9490 | D36: 8748 | E36: 9533 | F36: 11312 | G36: 11145 | H36: 14619 | I36: 15749 | J36: 15485 | K36: 21712 | L36: 14813 | P36: 23820 | Q36: 16499 | R36: 17030 | S36: 17692 | T36: 14409 | U36: 15434
A37: Loans and notes payable | C37: 12498 | D37: 13205 | E37: 13835 | F37: 10994 | G37: 2183 | H37: 3307 | I37: 2373 | J37: 4557 | K37: 1499 | L37: 1551 | P37: 2203 | Q37: 5418 | R37: 4379 | S37: 2319 | T37: 332 | U37: 48
A38: Current maturities of long-term debt | C38: 3527 | D38: 3298 | E38: 5003 | F38: 4253 | G38: 485 | H38: 1338 | I38: 399 | J38: 1960 | K38: 648 | L38: 1822 | P38: 1067 | Q38: 163 | R38: 91 | S38: 1920 | T38: 4493 | U38: 6494
A39: Accrued income taxes | C39: 307 | D39: 410 | E39: 411 | F39: 414 | G39: 788 | H39: 686 | I39: 1203 | J39: 1569 | K39: 1387 | L39: 525 | P39: 1479 | Q39: 1728 | R39: 444 | S39: 568 | T39: 717 | U39: 782
A40: Liabilities held for sale | C40: 710 | D40: 37 | K40: 3 | L40: 2570 | T40: 2427 | U40: 2442
A41: Liabilities held for sale — discontinued operations | C41: 0 | D41: 1496
A42: Total Current Liabilities | C42: 26532 | D42: 27194 | E42: 28782 | F42: 26973 | G42: 14601 | H42: 19950 | I42: 19724 | J42: 23571 | K42: 25249 | L42: 21281 | P42: 28569 | Q42: 23808 | R42: 21944 | S42: 22499 | T42: 22378 | U42: 25200
...

Sheet Cash Flow
A1: The Coca-Cola Company — Cash Flow
A2: $ in millions except per-share data | USD | as of 2026-10-14
C3: FY2016 | D3: FY2017 | E3: FY2018 | F3: FY2019 | G3: FY2020 | H3: FY2021 | I3: FY2022 | J3: FY2023 | K3: FY2024 | L3: FY2025 | M3: · | N3: · | O3: · | P3: 3Q2024 | Q3: 1Q2025 | R3: 2Q2025 | S3: 3Q2025 | T3: 1Q2026 | U3: 2Q2026
C4: 2016-12-31 | D4: 2017-12-31 | E4: 2018-12-31 | F4: 2019-12-31 | G4: 2020-12-31 | H4: 2021-12-31 | I4: 2022-12-31 | J4: 2023-12-31 | K4: 2024-12-31 | L4: 2025-12-31 | P4: 2024-09-27 | Q4: 2025-03-28 | R4: 2025-06-27 | S4: 2025-09-26 | T4: 2026-04-03 | U4: 2026-07-03
A6: CONTENTS
A7: =HYPERLINK("#'Cash Flow'!A11","1. CASH FLOW STATEMENT — AS REPORTED (quarterly columns are fiscal year-to-date)") -> 1. CASH FLOW STATEMENT — AS REPORTED (quarterly columns are fiscal year-to-date)
A8: =HYPERLINK("#'Cash Flow'!A64","2. CHECKS") -> 2. CHECKS
A9: =HYPERLINK("#'Cash Flow'!A70","3. FREE CASH FLOW AND SHAREOWNER RETURN ANALYTICS (annual; quarterly shown where inputs are YTD)") -> 3. FREE CASH FLOW AND SHAREOWNER RETURN ANALYTICS (annual; quarterly shown where inputs are YTD)
A11: 1. CASH FLOW STATEMENT — AS REPORTED (quarterly columns are fiscal year-to-date)
A12: Operating Activities
A13: Consolidated net income | C13: 6550 | D13: 1283 | E13: 6476 | F13: 8985 | G13: 7768 | H13: 9804 | I13: 9571 | J13: 10703 | K13: 10649 | L13: 13137 | P13: 8436 | Q13: 3335 | R13: 7138 | S13: 10821 | T13: 3966 | U13: 8404
A14: (Income) loss from discontinued operations | C14: 0
A15: Net income from continuing operations | C15: 6550
A16: Adjustments to reconcile net income to operating cash flow: | B16: Filed caption: Adjustments to reconcile consolidated net income to net cash provided by operating activities:
A17: Depreciation and amortization | C17: 1787 | D17: 1260 | E17: 1086 | F17: 1365 | G17: 1536 | H17: 1452 | I17: 1260 | J17: 1128 | K17: 1075 | L17: 1050 | P17: 799 | Q17: 267 | R17: 546 | S17: 814 | T17: 264 | U17: 530
A18: Stock-based compensation expense | C18: 258 | D18: 219 | E18: 225 | F18: 201 | G18: 126 | H18: 337 | I18: 356 | J18: 254 | K18: 286 | L18: 279 | P18: 207 | Q18: 63 | R18: 130 | S18: 204 | T18: 56 | U18: 117
A19: Deferred income taxes | C19: -856 | D19: -1252 | E19: -413 | F19: -280 | G19: -18 | H19: 894 | I19: -122 | J19: -2 | K19: -11 | L19: 517 | P19: 0 | Q19: 95 | R19: 459 | S19: 496 | T19: 205 | U19: 353
A20: Equity (income) loss — net of dividends | C20: -449 | D20: -628 | E20: -457 | F20: -421 | G20: -511 | H20: -615 | I20: -838 | J20: -1019 | K20: -802 | L20: -1038 | P20: -693 | Q20: -264 | R20: -387 | S20: -859 | T20: -375 | U20: -520
A21: Foreign currency adjustments | C21: 158 | D21: 292 | E21: -50 | F21: 91 | G21: -88 | H21: 86 | I21: 203 | J21: 175 | K21: -110 | L21: 191 | P21: -61 | Q21: 50 | R21: 111 | S21: 127 | T21: 33 | U21: 107
A22: Significant (gains) losses — net | C22: 1146 | D22: 1459 | E22: 743 | F22: -467 | G22: -914 | H22: -1365 | I22: -129 | J22: -492 | K22: -1737 | L22: -713 | P22: -1722 | Q22: -331 | R22: -433 | S22: -396 | T22: 10 | U22: -56
A23: Other operating charges | C23: 647 | D23: 1218 | E23: 558 | F23: 127 | G23: 556 | H23: 506 | I23: 1086 | J23: 1741 | K23: 4000 | L23: 1052 | P23: 3874 | Q23: 0 | R23: 38 | S23: 38 | T23: 10 | U23: 0
A24: Other items | C24: -224 | D24: -252 | E24: 699 | F24: 504 | G24: 699 | H24: 201 | I24: 236 | J24: -43 | K24: -311 | L24: 141 | P24: -143 | Q24: 104 | R24: 238 | S24: 447 | T24: 115 | U24: -125
A25: Net change in operating assets and liabilities | C25: -225 | D25: 3442 | E25: -1240 | F25: 366 | G25: 690 | H25: 1325 | I25: -605 | J25: -846 | K25: -6234 | L25: -7208 | P25: -7843 | Q25: -8521 | R25: -9231 | S25: -8040 | T25: -2263 | U25: -1267
A26: Net Cash Provided by Operating Activities | C26: 8792 | D26: 7041 | E26: 7627 | F26: 10471 | G26: 9844 | H26: 12625 | I26: 11018 | J26: 11599 | K26: 6805 | L26: 7408 | P26: 2854 | Q26: -5202 | R26: -1391 | S26: 3652 | T26: 2021 | U26: 7543
A27: Investing Activities
A28: Purchases of investments | C28: -16626 | D28: -17296 | E28: -7789 | F28: -4704 | G28: -13583 | H28: -6030 | I28: -3751 | J28: -6698 | K28: -5640 | L28: -6160 | P28: -4398 | Q28: -2507 | R28: -2865 | S28: -3292 | T28: -1459 | U28: -2799
A29: Proceeds from disposals of investments | C29: 17842 | D29: 16694 | E29: 14977 | F29: 6973 | G29: 13835 | H29: 7059 | I29: 4771 | J29: 4354 | K29: 6589 | L29: 4665 | P29: 5125 | Q29: 1005 | R29: 2201 | S29: 4300 | T29: 3503 | U29: 4574
A30: Acquisitions of businesses, equity method inv. & nonmkt. securities | B30: Filed caption: Acquisitions of businesses, equity method investments and nonmarketable securities | C30: -838 | D30: -3809 | E30: -1263 | F30: -5542 | G30: -1052 | H30: -4766 | I30: -73 | J30: -62 | K30: -315 | L30: -461 | P30: -153 | Q30: -42 | R30: -179 | S30: -356 | T30: -37 | U30: -199
A31: Proceeds from disposals of businesses, equity method inv. & nonmkt… | B31: Filed caption: Proceeds from disposals of businesses, equity method investments and nonmarketable securities Full label: Proceeds from disposals of businesses, equity method inv. & nonmkt. securities | C31: 1035 | D31: 3821 | E31: 1362 | F31: 429 | G31: 189 | H31: 2180 | I31: 458 | J31: 430 | K31: 3485 | L31: 3567 | P31: 3468 | Q31: 748 | R31: 973 | S31: 1020 | T31: 0 | U31: 1
A32: Purchases of property, plant and equipment | C32: -2262 | D32: -1750 | E32: -1548 | F32: -2054 | G32: -1177 | H32: -1367 | I32: -1484 | J32: -1852 | K32: -2064 | L32: -2112 | P32: -1261 | Q32: -309 | R32: -751 | S32: -1230 | T32: -266 | U32: -684
A33: Proceeds from disposals of property, plant and equipment | C33: 150 | D33: 108 | E33: 248 | F33: 978 | G33: 189 | H33: 108 | I33: 75 | J33: 74 | K33: 40 | L33: 13 | P33: 33 | Q33: 8 | R33: 13 | S33: 21 | T33: 2 | U33: 7
A34: Collateral (paid) received associated with hedging activities — net | G34: 0 | H34: 0 | I34: -1465 | J34: 366 | K34: 235 | L34: 330 | P34: 299 | Q34: -15 | R34: 206 | S34: 300 | T34: -20 | U34: -37
A35: Other investing activities | C35: -305 | D35: -80 | E35: -60 | F35: -56 | G35: 122 | H35: 51 | I35: 706 | J35: 39 | K35: 194 | L35: 91 | P35: 194 | Q35: 45 | R35: 124 | S35: 214 | T35: 23 | U35: 241
A36: Net Cash Provided by (Used in) Investing Activities | C36: -1004 | D36: -2312 | E36: 5927 | F36: -3976 | G36: -1477 | H36: -2765 | I36: -763 | J36: -3349 | K36: 2524 | L36: -67 | P36: 3307 | Q36: -1067 | R36: -278 | S36: 977 | T36: 1746 | U36: 1104
A37: Financing Activities
A38: Issuances of loans, notes payable and long-term debt | C38: 27281 | D38: 29926 | E38: 27605 | F38: 23009 | G38: 26934 | H38: 13094 | I38: 3972 | J38: 6891 | K38: 12061 | L38: 4980 | P38: 11298 | Q38: 5436 | R38: 5320 | S38: 4854 | T38: 0 | U38: 9
A39: Payments of loans, notes payable and long-term debt | C39: -25615 | D39: -28871 | E39: -30600 | F39: -24850 | G39: -28796 | H39: -12866 | I39: -4930 | J39: -5034 | K39: -9533 | L39: -4967 | P39: -7925 | Q39: -1599 | R39: -2630 | S39: -4166 | T39: -1262 | U39: -1559
A40: Issuances of stock | C40: 1434 | D40: 1595 | E40: 1476 | F40: 1012 | G40: 647 | H40: 702 | I40: 837 | J40: 539 | K40: 747 | L40: 313 | P40: 717 | Q40: 159 | R40: 223 | S40: 243 | T40: 155 | U40: 251
A41: Purchases of stock for treasury | C41: -3681 | D41: -3682 | E41: -1912 | F41: -1103 | G41: -118 | H41: -111 | I41: -1418 | J41: -2289 | K41: -1795 | L41: -746 | P41: -1228 | Q41: -370 | R41: -472 | S41: -644 | T41: -477 | U41: -663
A42: Dividends | C42: -6043 | D42: -6320 | E42: -6644 | F42: -6845 | G42: -7047 | H42: -7252 | I42: -7616 | J42: -7952 | K42: -8359 | L42: -8779 | P42: -4274 | Q42: -89 | R42: -2283 | S42: -4391 | T42: -2281 | U42: -4562
...

Sheet Segments
A1: The Coca-Cola Company — Segments
A2: $ in millions except per-share data | USD | as of 2026-10-14
C3: FY2016 | D3: FY2017 | E3: FY2018 | F3: FY2019 | G3: FY2020 | H3: FY2021 | I3: FY2022 | J3: FY2023 | K3: FY2024 | L3: FY2025 | M3: · | N3: · | O3: · | P3: 3Q2024 | Q3: 1Q2025 | R3: 2Q2025 | S3: 3Q2025 | T3: 1Q2026 | U3: 2Q2026
C4: 2016-12-31 | D4: 2017-12-31 | E4: 2018-12-31 | F4: 2019-12-31 | G4: 2020-12-31 | H4: 2021-12-31 | I4: 2022-12-31 | J4: 2023-12-31 | K4: 2024-12-31 | L4: 2025-12-31 | P4: 2024-09-27 | Q4: 2025-03-28 | R4: 2025-06-27 | S4: 2025-09-26 | T4: 2026-04-03 | U4: 2026-07-03
A6: CONTENTS
A7: =HYPERLINK("#'Segments'!A11","1. SEGMENTS — BASIS C (FY2025 10-K recast: Global Ventures dissolved into the geographic segments; FY2023-FY2025 only)") -> 1. SEGMENTS — BASIS C (FY2025 10-K recast: Global Ventures dissolved into the geographic segments; FY2023-FY2025 only)
A8: =HYPERLINK("#'Segments'!A86","2. SEGMENTS — BASIS B (FY2019-FY2024 10-K presentation incl. Global Ventures; FY2017-FY2024, each year from the latest 10-K presenting it on this basis)") -> 2. SEGMENTS — BASIS B (FY2019-FY2024 10-K presentation incl. Global Ventures; FY2017-FY2024, each year from the latest 10-K presenting it on this basis)
A9: =HYPERLINK("#'Segments'!A168","3. SEGMENTS — BASIS A (FY2018 10-K presentation: no Global Ventures; FY2016-FY2018)") -> 3. SEGMENTS — BASIS A (FY2018 10-K presentation: no Global Ventures; FY2016-FY2018)
A11: 1. SEGMENTS — BASIS C (FY2025 10-K recast: Global Ventures dissolved into the geographic segments; FY2023-FY2025 only)
A12: Third-party net operating revenues
A13: EMEA | J13: 10152 | K13: 10278 | L13: 10833 | Q13: 2481 | R13: 3008 | S13: 2818 | T13: 2807 | U13: 3087
A14: Latin America | J14: 5834 | K14: 6471 | L14: 6331 | Q14: 1477 | R14: 1587 | S14: 1572 | T14: 1678 | U14: 1839
A15: North America | J15: 16965 | K15: 18860 | L15: 19579 | Q15: 4359 | R15: 5028 | S15: 5249 | T15: 4891 | U15: 5405
A16: Asia Pacific | J16: 4811 | K16: 5127 | L16: 5328 | Q16: 1325 | R16: 1464 | S16: 1438 | T16: 1426 | U16: 1487
A17: Bottling Investments | J17: 7852 | K17: 6215 | L17: 5726 | Q17: 1461 | R17: 1409 | S17: 1344 | T17: 1638 | U17: 1525
A18: Corporate | J18: 140 | K18: 110 | L18: 144 | Q18: 26 | R18: 39 | S18: 34 | T18: 32 | U18: 37
A19: Consolidated (as reported) | J19: 45754 | K19: 47061 | L19: 47941 | Q19: 11129 | R19: 12535 | S19: 12455 | T19: 12472 | U19: 13380
A20: Check: segments + Corporate - Consolidated (≈0) | J20: =J13+J14+J15+J16+J17+J18-J19 -> 0 | K20: =K13+K14+K15+K16+K17+K18-K19 -> 0 | L20: =L13+L14+L15+L16+L17+L18-L19 -> 0
A22: Intersegment net operating revenues
A23: EMEA | J23: 686 | K23: 680 | L23: 680 | Q23: 176 | R23: 168 | S23: 178 | T23: 205 | U23: 153
A24: Latin America | J24: 0 | K24: 0 | L24: 3 | Q24: 0 | R24: 0 | S24: 1 | T24: 0 | U24: 0
A25: North America | J25: 8 | K25: 9 | L25: 7 | Q25: 2 | R25: 1 | S25: 4 | T25: 2 | U25: 3
A26: Asia Pacific | J26: 731 | K26: 467 | L26: 310 | Q26: 96 | R26: 108 | S26: 68 | T26: 82 | U26: 94
A27: Bottling Investments | J27: 8 | K27: 8 | L27: 9 | Q27: 2 | R27: 2 | S27: 2 | T27: 2 | U27: 2
A28: Corporate | J28: 0 | K28: 0 | L28: 0 | Q28: 0 | R28: 0 | S28: 0 | T28: 0 | U28: 0
A29: Eliminations | J29: -1433 | K29: -1164 | L29: -1009 | Q29: -276 | R29: -279 | S29: -253 | T29: -291 | U29: -252
A30: Consolidated (as reported) | J30: 0 | K30: 0 | L30: 0 | Q30: =Q23+Q24+Q25+Q26+Q27+Q28+Q29 -> 0 | R30: =R23+R24+R25+R26+R27+R28+R29 -> 0 | S30: =S23+S24+S25+S26+S27+S28+S29 -> 0 | T30: =T23+T24+T25+T26+T27+T28+T29 -> 0 | U30: =U23+U24+U25+U26+U27+U28+U29 -> 0
A31: Check: segments + Corporate - Consolidated (≈0) | J31: =J23+J24+J25+J26+J27+J28+J29-J30 -> 0 | K31: =K23+K24+K25+K26+K27+K28+K29-K30 -> 0 | L31: =L23+L24+L25+L26+L27+L28+L29-L30 -> 0
A33: Total net operating revenues (third-party + intersegment)
A34: EMEA | J34: 10838 | K34: 10958 | L34: 11513 | Q34: 2657 | R34: 3176 | S34: 2996 | T34: 3012 | U34: 3240
A35: Latin America | J35: 5834 | K35: 6471 | L35: 6334 | Q35: 1477 | R35: 1587 | S35: 1573 | T35: 1678 | U35: 1839
A36: North America | J36: 16973 | K36: 18869 | L36: 19586 | Q36: 4361 | R36: 5029 | S36: 5253 | T36: 4893 | U36: 5408
A37: Asia Pacific | J37: 5542 | K37: 5594 | L37: 5638 | Q37: 1421 | R37: 1572 | S37: 1506 | T37: 1508 | U37: 1581
A38: Bottling Investments | J38: 7860 | K38: 6223 | L38: 5735 | Q38: 1463 | R38: 1411 | S38: 1346 | T38: 1640 | U38: 1527
A39: Corporate | J39: 140 | K39: 110 | L39: 144 | Q39: 26 | R39: 39 | S39: 34 | T39: 32 | U39: 37
A40: Eliminations | J40: -1433 | K40: -1164 | L40: -1009 | Q40: -276 | R40: -279 | S40: -253 | T40: -291 | U40: -252
A41: Consolidated (as reported) | J41: 45754 | K41: 47061 | L41: 47941 | Q41: ='Income Statement'!Q11 -> 11129 | R41: ='Income Statement'!R11 -> 12535 | S41: ='Income Statement'!S11 -> 12455 | T41: ='Income Statement'!T11 -> 12472 | U41: ='Income Statement'!U11 -> 13380
A42: Check: segments + Corporate - Consolidated (≈0) | J42: =J34+J35+J36+J37+J38+J39+J40-J41 -> 0 | K42: =K34+K35+K36+K37+K38+K39+K40-K41 -> 0 | L42: =L34+L35+L36+L37+L38+L39+L40-L41 -> 0
A44: Operating income (loss)
A45: EMEA | J45: 4323 | K45: 4255 | L45: 4298 | Q45: 1065 | R45: 1325 | S45: 1097 | T45: 1259 | U45: 1309
...

Sheet Geography
A1: The Coca-Cola Company — Geography
A2: $ in millions except per-share data | USD | as of 2026-10-14
C3: FY2016 | D3: FY2017 | E3: FY2018 | F3: FY2019 | G3: FY2020 | H3: FY2021 | I3: FY2022 | J3: FY2023 | K3: FY2024 | L3: FY2025 | M3: · | N3: · | O3: · | P3: 3Q2024 | Q3: 1Q2025 | R3: 2Q2025 | S3: 3Q2025 | T3: 1Q2026 | U3: 2Q2026
C4: 2016-12-31 | D4: 2017-12-31 | E4: 2018-12-31 | F4: 2019-12-31 | G4: 2020-12-31 | H4: 2021-12-31 | I4: 2022-12-31 | J4: 2023-12-31 | K4: 2024-12-31 | L4: 2025-12-31 | P4: 2024-09-27 | Q4: 2025-03-28 | R4: 2025-06-27 | S4: 2025-09-26 | T4: 2026-04-03 | U4: 2026-07-03
A6: CONTENTS
A7: =HYPERLINK("#'Geography'!A10","1. NET OPERATING REVENUES BY GEOGRAPHY (Note: Operating Segments — Geographic and Customer Data)") -> 1. NET OPERATING REVENUES BY GEOGRAPHY (Note: Operating Segments — Geographic and Customer Data)
A8: =HYPERLINK("#'Geography'!A20","2. PROPERTY, PLANT AND EQUIPMENT — NET BY GEOGRAPHY") -> 2. PROPERTY, PLANT AND EQUIPMENT — NET BY GEOGRAPHY
A10: 1. NET OPERATING REVENUES BY GEOGRAPHY (Note: Operating Segments — Geographic and Customer Data)
A11: United States | C11: 19899 | D11: 14727 | E11: 11344 | F11: 11715 | G11: 11281 | H11: 13010 | I11: 15413 | J11: 16550 | K11: 18362 | L11: 19127 | P11: 4903 | Q11: 4253 | R11: 4935 | S11: 5118 | T11: 4745 | U11: 5260
A12: International | C12: 21964 | D12: 21485 | E12: 22956 | F12: 25551 | G12: 21733 | H12: 25645 | I12: 27591 | J12: 29204 | K12: 28699 | L12: 28814 | P12: 6951 | Q12: 6876 | R12: 7600 | S12: 7337 | T12: 7727 | U12: 8120
A13: Net operating revenues (as reported) | C13: 41863 | D13: 36212 | E13: 34300 | F13: 37266 | G13: 33014 | H13: 38655 | I13: 43004 | J13: 45754 | K13: 47061 | L13: 47941 | P13: 11854 | Q13: 11129 | R13: 12535 | S13: 12455 | T13: 12472 | U13: 13380
A14: United States % of revenue | C14: =C11/C13 -> 0.47533622 | D14: =D11/D13 -> 0.40668839 | E14: =E11/E13 -> 0.33072886 | F14: =F11/F13 -> 0.31436162 | G14: =G11/G13 -> 0.34170352 | H14: =H11/H13 -> 0.33656707 | I14: =I11/I13 -> 0.35840852 | J14: =J11/J13 -> 0.36171701 | ... L14: =L11/L13 -> 0.39896957 | P14: =IFERROR(P11/P13,"") -> 0.41361566 | Q14: =IFERROR(Q11/Q13,"") -> 0.38215473 | R14: =IFERROR(R11/R13,"") -> 0.39369765 | S14: =IFERROR(S11/S13,"") -> 0.41091931 | T14: =IFERROR(T11/T13,"") -> 0.38045221 | U14: =IFERROR(U11/U13,"") -> 0.39312407
A15: International YoY Growth | D15: =IF(N(C12)=0,"",D12/C12-1) -> -0.021808414 | E15: =IF(N(D12)=0,"",E12/D12-1) -> 0.068466372 | F15: =IF(N(E12)=0,"",F12/E12-1) -> 0.11304234 | G15: =IF(N(F12)=0,"",G12/F12-1) -> -0.14942664 | H15: =IF(N(G12)=0,"",H12/G12-1) -> 0.18000276 | I15: =IF(N(H12)=0,"",I12/H12-1) -> 0.075882238 | J15: =IF(N(I12)=0,"",J12/I12-1) -> 0.058461092 | K15: =IF(N(J12)=0,"",K12/J12-1) -> -0.017292152 | L15: =IF(N(K12)=0,"",L12/K12-1) -> 0.0040071083 | S15: =IFERROR(S12/P12-1,"") -> 0.055531578 | T15: =IFERROR(T12/Q12-1,"") -> 0.12376382 | U15: =IFERROR(U12/R12-1,"") -> 0.068421053
A16: United States YoY Growth | D16: =IF(N(C11)=0,"",D11/C11-1) -> -0.25991256 | E16: =IF(N(D11)=0,"",E11/D11-1) -> -0.22971413 | F16: =IF(N(E11)=0,"",F11/E11-1) -> 0.032704513 | G16: =IF(N(F11)=0,"",G11/F11-1) -> -0.037046522 | H16: =IF(N(G11)=0,"",H11/G11-1) -> 0.15326655 | I16: =IF(N(H11)=0,"",I11/H11-1) -> 0.18470407 | J16: =IF(N(I11)=0,"",J11/I11-1) -> 0.073768896 | K16: =IF(N(J11)=0,"",K11/J11-1) -> 0.1094864 | L16: =IF(N(K11)=0,"",L11/K11-1) -> 0.041662128 | S16: =IFERROR(S11/P11-1,"") -> 0.043850704 | T16: =IFERROR(T11/Q11-1,"") -> 0.11568305 | U16: =IFERROR(U11/R11-1,"") -> 0.06585613
A17: Check: US + International - reported total (≈0) | C17: =C11+C12-C13 -> 0 | D17: =D11+D12-D13 -> 0 | E17: =E11+E12-E13 -> 0 | F17: =F11+F12-F13 -> 0 | G17: =G11+G12-G13 -> 0 | H17: =H11+H12-H13 -> 0 | I17: =I11+I12-I13 -> 0 | J17: =J11+J12-J13 -> 0 | ... L17: =L11+L12-L13 -> 0 | P17: =P11+P12-P13 -> 0 | Q17: =Q11+Q12-Q13 -> 0 | R17: =R11+R12-R13 -> 0 | S17: =S11+S12-S13 -> 0 | T17: =T11+T12-T13 -> 0 | U17: =U11+U12-U13 -> 0
A18: Check: geography total vs IS net operating revenues (≈0) | C18: =C13-'Income Statement'!C11 -> 0 | D18: =D13-'Income Statement'!D11 -> 0 | E18: =E13-'Income Statement'!E11 -> 0 | F18: =F13-'Income Statement'!F11 -> 0 | G18: =G13-'Income Statement'!G11 -> 0 | H18: =H13-'Income Statement'!H11 -> 0 | I18: =I13-'Income Statement'!I11 -> 0 | J18: =J13-'Income Statement'!J11 -> 0 | ... L18: =L13-'Income Statement'!L11 -> 0 | P18: =P13-'Income Statement'!P11 -> 0 | Q18: =Q13-'Income Statement'!Q11 -> 0 | R18: =R13-'Income Statement'!R11 -> 0 | S18: =S13-'Income Statement'!S11 -> 0 | T18: =T13-'Income Statement'!T11 -> 0 | U18: =U13-'Income Statement'!U11 -> 0
A20: 2. PROPERTY, PLANT AND EQUIPMENT — NET BY GEOGRAPHY
A21: United States | C21: 6784 | D21: 4163 | E21: 4154 | F21: 4062 | G21: 3988 | H21: 3420 | I21: 3494 | J21: 3682 | K21: 4364 | L21: 4825
A22: International | C22: 3851 | D22: 4040 | E22: 5444 | F22: 6776 | G22: 6789 | H22: 6500 | I22: 6347 | J22: 5554 | K22: 5939 | L22: 4788
A23: Property, plant and equipment — net (as reported) | C23: 10635 | D23: 8203 | E23: 9598 | F23: 10838 | G23: 10777 | H23: 9920 | I23: 9841 | J23: 9236 | K23: 10303 | L23: 9613
A24: Check: US + International - reported total (≈0) | C24: =C21+C22-C23 -> 0 | D24: =D21+D22-D23 -> 0 | E24: =E21+E22-E23 -> 0 | F24: =F21+F22-F23 -> 0 | G24: =G21+G22-G23 -> 0 | H24: =H21+H22-H23 -> 0 | I24: =I21+I22-I23 -> 0 | J24: =J21+J22-J23 -> 0 | ... L24: =L21+L22-L23 -> 0
A25: Check: geography total vs BS property, plant and equipment - net (≈0) | C25: =C23-'Balance Sheet'!C27 -> 0 | D25: =D23-'Balance Sheet'!D27 -> 0 | E25: =E23-'Balance Sheet'!E27 -> 0 | F25: =F23-'Balance Sheet'!F27 -> 0 | G25: =G23-'Balance Sheet'!G27 -> 0 | H25: =H23-'Balance Sheet'!H27 -> 0 | I25: =I23-'Balance Sheet'!I27 -> 0 | J25: =J23-'Balance Sheet'!J27 -> 0 | ... L25: =L23-'Balance Sheet'!L27 -> 0

Sheet Operating Metrics
A1: The Coca-Cola Company — Operating Metrics
A2: $ in millions except per-share data | USD | as of 2026-10-14
C3: FY2016 | D3: FY2017 | E3: FY2018 | F3: FY2019 | G3: FY2020 | H3: FY2021 | I3: FY2022 | J3: FY2023 | K3: FY2024 | L3: FY2025 | M3: · | N3: · | O3: · | P3: 3Q2024 | Q3: 1Q2025 | R3: 2Q2025 | S3: 3Q2025 | T3: 1Q2026 | U3: 2Q2026
C4: 2016-12-31 | D4: 2017-12-31 | E4: 2018-12-31 | F4: 2019-12-31 | G4: 2020-12-31 | H4: 2021-12-31 | I4: 2022-12-31 | J4: 2023-12-31 | K4: 2024-12-31 | L4: 2025-12-31 | P4: 2024-09-27 | Q4: 2025-03-28 | R4: 2025-06-27 | S4: 2025-09-26 | T4: 2026-04-03 | U4: 2026-07-03
A6: CONTENTS
A7: =HYPERLINK("#'Operating Metrics'!A13","1. BEVERAGE VOLUME — SYSTEM UNIT CASE VOLUME (Company disclosure, not from the financial statements)") -> 1. BEVERAGE VOLUME — SYSTEM UNIT CASE VOLUME (Company disclosure, not from the financial statements)
A8: =HYPERLINK("#'Operating Metrics'!A33","2. NET OPERATING REVENUE FACTORS — VOLUME / PRICE-MIX / FX / ACQUISITIONS & DIVESTITURES (% impact, as reported)") -> 2. NET OPERATING REVENUE FACTORS — VOLUME / PRICE-MIX / FX / ACQUISITIONS & DIVESTITURES (% impact, as reported)
A9: =HYPERLINK("#'Operating Metrics'!A87","3. NET OPERATING REVENUES BY LINE OF BUSINESS — CONCENTRATE VS FINISHED PRODUCT OPERATIONS (Note 3)") -> 3. NET OPERATING REVENUES BY LINE OF BUSINESS — CONCENTRATE VS FINISHED PRODUCT OPERATIONS (Note 3)
A10: =HYPERLINK("#'Operating Metrics'!A108","4. REVENUE MIX — OPERATING SEGMENT % OF COMPANY NET OPERATING REVENUES (as reported; Global Ventures exists FY2019-FY2024 only)") -> 4. REVENUE MIX — OPERATING SEGMENT % OF COMPANY NET OPERATING REVENUES (as reported; Global Ventures exists FY2019-FY2024 only)
A11: =HYPERLINK("#'Operating Metrics'!A118","5. CUSTOMER CONCENTRATION") -> 5. CUSTOMER CONCENTRATION
A13: 1. BEVERAGE VOLUME — SYSTEM UNIT CASE VOLUME (Company disclosure, not from the financial statements)
A14: Unit case volume (billion unit cases) | B14: Company-reported Coca-Cola system unit case volume; the sentence in each 10-K lists that year and the two prior years. Values are in billion unit cases as printed. | C14: 29.3 | D14: 29.2 | E14: 29.6 | F14: 30.3 | G14: 29 | H14: 31.3 | I14: 32.7 | J14: 33.3 | K14: 33.7 | L14: 33.8
A15: YoY Growth | B15: Growth calculated from rounded billion-case totals; may differ from issuer-reported comparable volume growth below (calendar and structural adjustments). | D15: =IF(N(C14)=0,"",D14/C14-1) -> -0.0034129693 | E15: =IF(N(D14)=0,"",E14/D14-1) -> 0.01369863 | F15: =IF(N(E14)=0,"",F14/E14-1) -> 0.023648649 | G15: =IF(N(F14)=0,"",G14/F14-1) -> -0.04290429 | H15: =IF(N(G14)=0,"",H14/G14-1) -> 0.079310345 | I15: =IF(N(H14)=0,"",I14/H14-1) -> 0.044728435 | J15: =IF(N(I14)=0,"",J14/I14-1) -> 0.018348624 | K15: =IF(N(J14)=0,"",K14/J14-1) -> 0.012012012 | L15: =IF(N(K14)=0,"",L14/K14-1) -> 0.0029673591
A17: Unit case volume growth by operating segment (as reported)
A18: Worldwide | C18: 0.01 | D18: 0 | E18: 0.02 | F18: 0.02 | G18: -0.06 | H18: 0.08 | I18: 0.05 | J18: 0.02 | K18: 0.01 | L18: 0 | P18: -0.01 | Q18: 0.02 | R18: -0.01 | S18: 0.01 | T18: 0.03 | U18: 0.05
A19: EMEA | C19: 0.01 | D19: 0.01 | E19: 0.02 | F19: 0.02 | G19: -0.06 | H19: 0.09 | I19: 0.03 | J19: -0.02 | K19: 0 | L19: 0.03 | P19: -0.02 | Q19: 0.03 | R19: 0.03 | S19: 0.04 | T19: 0.02 | U19: 0.04
A20: Latin America | C20: -0.01 | D20: -0.02 | E20: 0 | F20: 0.01 | G20: -0.02 | H20: 0.06 | I20: 0.06 | J20: 0.05 | K20: 0.03 | L20: 0 | P20: 0 | Q20: 0 | R20: -0.02 | S20: 0 | T20: 0.01 | U20: 0.03
A21: North America | C21: 0.01 | D21: 0 | E21: 0 | F21: 0 | G21: -0.07 | H21: 0.05 | I21: 0.02 | J21: -0.01 | K21: 0 | L21: -0.01 | P21: 0 | Q21: -0.03 | R21: -0.01 | S21: 0 | T21: 0.04 | U21: 0.03
A22: Bottling Investments | C22: -0.16 | D22: -0.41 | E22: -0.15 | F22: 0.24 | G22: -0.15 | H22: 0.11 | I22: 0.12 | J22: -0.01 | K22: -0.23 | L22: -0.08 | P22: -0.31 | Q22: -0.17 | R22: -0.05 | S22: 0.02 | T22: 0.01 | U22: 0.05
A23: Asia Pacific | C23: 0.02 | D23: 0.01 | E23: 0.04 | F23: 0.05 | G23: -0.09 | H23: 0.1 | I23: 0.06 | J23: 0.03 | K23: 0.01 | L23: 0 | P23: -0.02 | Q23: 0.06 | R23: -0.03 | S23: -0.01 | T23: 0.05 | U23: 0.08
A24: Global Ventures | B24: Global Ventures FY2018 is the comparative disclosed in FY2019 10-K, including acquired-business history; FY2019 excludes Costa non-ready-to-drink volume. See the volume footnotes; segment dissolved in FY2025. | E24: 0.08 | F24: 0.07 | G24: -0.13 | H24: 0.17 | I24: 0.13 | J24: 0.04 | K24: 0.02 | P24: 0.01
A26: Concentrate sales volume growth by operating segment (as reported)
A27: Worldwide | C27: 0 | D27: 0 | E27: 0.03 | F27: 0.02 | G27: -0.07 | H27: 0.09 | I27: 0.05 | J27: 0.02 | K27: 0.01 | L27: 0.01 | P27: -0.01 | Q27: 0.01 | R27: -0.01 | S27: 0 | T27: 0.08 | U27: 0.04
A28: EMEA | C28: 0 | D28: 0.01 | E28: 0.06 | F28: 0.01 | G28: -0.08 | H28: 0.12 | I28: 0.02 | J28: 0 | K28: -0.01 | L28: 0.03 | P28: -0.07 | Q28: 0.01 | R28: 0.02 | S28: 0.03 | T28: 0.05 | U28: 0.01
A29: Latin America | C29: -0.01 | D29: -0.03 | E29: 0.01 | F29: 0.01 | G29: -0.02 | H29: 0.06 | I29: 0.07 | J29: 0.06 | K29: 0.03 | L29: -0.01 | P29: 0.02 | Q29: -0.03 | R29: -0.01 | S29: -0.03 | T29: 0.07 | U29: 0.01
A30: Bottling Investments | B30: Company explicitly reports concentrate sales for Bottling Investments as N/A; N/A is neither zero nor the adjacent footnote number. | C30: N/A | D30: N/A | E30: N/A | F30: N/A | G30: N/A | H30: N/A | I30: N/A | J30: N/A | K30: N/A | L30: N/A | P30: N/A | Q30: N/A | R30: N/A | S30: N/A | T30: N/A | U30: N/A
A31: North America | C31: 0.02 | D31: 0.02 | E31: -0.02 | F31: -0.01 | G31: -0.07 | H31: 0.07 | I31: 0.01 | J31: -0.01 | K31: 0.01 | L31: -0.01 | P31: 0.01 | Q31: -0.04 | R31: 0 | S31: -0.02 | T31: 0.11 | U31: 0.03
A32: Asia Pacific | C32: 0.03 | D32: 0.04 | E32: 0.04 | F32: 0.04 | G32: -0.09 | H32: 0.11 | I32: 0.08 | J32: 0 | K32: 0.03 | L32: 0 | P32: -0.03 | Q32: 0.02 | R32: -0.05 | S32: -0.01 | T32: 0.1 | U32: 0.1
A33: 2. NET OPERATING REVENUE FACTORS — VOLUME / PRICE-MIX / FX / ACQUISITIONS & DIVESTITURES (% impact, as reported)
A34: Net operating revenue impact — Volume
A35: Consolidated | F35: 0.01 | G35: -0.07 | H35: 0.09 | I35: 0.05 | J35: 0.02 | K35: 0.02 | L35: 0.01 | P35: -0.02 | Q35: 0.01 | R35: -0.01 | S35: 0 | T35: 0.08 | U35: 0.04
A36: Asia Pacific | F36: 0.05 | G36: -0.1 | H36: 0.11 | I36: 0.08 | J36: 0 | K36: 0.02 | L36: 0.01 | P36: -0.04 | Q36: 0.08 | R36: -0.05 | S36: -0.01 | T36: 0.1 | U36: 0.11
A37: Bottling Investments | F37: 0.06 | G37: -0.13 | H37: 0.11 | I37: 0.12 | J37: 0.06 | K37: 0.05 | L37: 0 | P37: -0.01 | Q37: -0.01 | R37: -0.02 | S37: 0.05 | T37: 0.11 | U37: 0.08
A38: EMEA | F38: 0.01 | G38: -0.08 | H38: 0.12 | I38: 0.02 | J38: 0 | K38: -0.01 | L38: 0.04 | P38: -0.07 | Q38: 0.01 | R38: 0.02 | S38: 0.03 | T38: 0.05 | U38: 0.01
A39: Global Ventures | F39: 0.08 | G39: -0.13 | H39: 0.2 | I39: 0.13 | J39: 0.05 | K39: 0.04 | P39: 0.01
A40: Latin America | F40: 0.01 | G40: -0.02 | H40: 0.06 | I40: 0.07 | J40: 0.06 | K40: 0.03 | L40: -0.01 | P40: 0.02 | Q40: -0.03 | R40: -0.01 | S40: -0.03 | T40: 0.07 | U40: 0.01
A41: North America | F41: 0 | G41: -0.07 | H41: 0.07 | I41: 0.01 | J41: -0.01 | K41: 0.01 | L41: -0.01 | P41: 0.01 | Q41: -0.04 | R41: 0 | S41: -0.02 | T41: 0.11 | U41: 0.03
A43: Net operating revenue impact — Price/Mix
A44: Consolidated | F44: 0.05 | G44: -0.02 | H44: 0.06 | I44: 0.11 | J44: 0.1 | K44: 0.11 | L44: 0.04 | P44: 0.1 | Q44: 0.05 | R44: 0.06 | S44: 0.06 | T44: 0.02 | U44: 0.02
A45: Asia Pacific | F45: 0 | G45: -0.02 | H45: -0.02 | I45: 0.03 | J45: 0.05 | K45: 0.02 | L45: 0.04 | P45: 0.07 | Q45: -0.01 | R45: 0.1 | S45: 0.08 | T45: -0.06 | U45: -0.09
...

Sheet 产品销量
A1: 可口可乐产品销量
A2: 截至2026-10-14。年度数据覆盖FY2016—FY2025。单位、估算和口径变更在各表旁说明。
C3: FY2016 | D3: FY2017 | E3: FY2018 | F3: FY2019 | G3: FY2020 | H3: FY2021 | I3: FY2022 | J3: FY2023 | K3: FY2024 | L3: FY2025
A4: 0.0%表示公司披露持平。双位数保留定性表述。估算绝对量使用四舍五入的销量和占比。
A6: 1. 体系销量与销量结构
A7: 体系销量（十亿单位箱） | C7: ='Operating Metrics'!C14 -> 29.3 | D7: ='Operating Metrics'!D14 -> 29.2 | E7: ='Operating Metrics'!E14 -> 29.6 | F7: ='Operating Metrics'!F14 -> 30.3 | G7: ='Operating Metrics'!G14 -> 29 | H7: ='Operating Metrics'!H14 -> 31.3 | I7: ='Operating Metrics'!I14 -> 32.7 | J7: ='Operating Metrics'!J14 -> 33.3 | ... L7: ='Operating Metrics'!L14 -> 33.8
A8: 体系销量（亿单位箱） | C8: =C7*10 -> 293 | D8: =D7*10 -> 292 | E8: =E7*10 -> 296 | F8: =F7*10 -> 303 | G8: =G7*10 -> 290 | H8: =H7*10 -> 313 | I8: =I7*10 -> 327 | J8: =J7*10 -> 333 | ... L8: =L7*10 -> 338
A9: 全球销量同比（公司披露） | C9: ='Operating Metrics'!C18 -> 0.01 | D9: ='Operating Metrics'!D18 -> 0 | E9: ='Operating Metrics'!E18 -> 0.02 | F9: ='Operating Metrics'!F18 -> 0.02 | G9: ='Operating Metrics'!G18 -> -0.06 | H9: ='Operating Metrics'!H18 -> 0.08 | I9: ='Operating Metrics'!I18 -> 0.05 | J9: ='Operating Metrics'!J18 -> 0.02 | ... L9: ='Operating Metrics'!L18 -> 0
A10: 全球销量同比（绝对量计算） | C10: ="n.a." -> n.a. | D10: ='Operating Metrics'!D15 -> -0.0034129693 | E10: ='Operating Metrics'!E15 -> 0.01369863 | F10: ='Operating Metrics'!F15 -> 0.023648649 | G10: ='Operating Metrics'!G15 -> -0.04290429 | H10: ='Operating Metrics'!H15 -> 0.079310345 | I10: ='Operating Metrics'!I15 -> 0.044728435 | J10: ='Operating Metrics'!J15 -> 0.018348624 | K10: ='Operating Metrics'!K15 -> 0.012012012 | L10: ='Operating Metrics'!L15 -> 0.0029673591
A12: 碳酸软饮占全球销量 | C12: 0.69 | D12: 0.69 | E12: 0.69 | F12: 0.69 | G12: 0.69 | H12: 0.69 | I12: 0.69 | J12: 0.69 | K12: 0.69 | L12: 0.69
A13: 可口可乐商标系列占全球销量 | C13: 0.45 | D13: 0.45 | E13: 0.45 | F13: 0.45 | G13: 0.47 | H13: 0.47 | I13: 0.46 | J13: 0.47 | K13: 0.47 | L13: 0.47
A14: 美国占全球销量 | C14: 0.19 | D14: 0.19 | E14: 0.18 | F14: 0.18 | G14: 0.18 | H14: 0.17 | I14: 0.17 | J14: 0.16 | K14: 0.16 | L14: 0.16
A15: 国际占全球销量 | C15: =1-C14 -> 0.81 | D15: =1-D14 -> 0.81 | E15: =1-E14 -> 0.82 | F15: =1-F14 -> 0.82 | G15: =1-G14 -> 0.82 | H15: =1-H14 -> 0.83 | I15: =1-I14 -> 0.83 | J15: =1-J14 -> 0.84 | ... L15: =1-L14 -> 0.84
A16: 品类结构来源 | C16: S003 | D16: S003 | E16: S003 | F16: S004 | G16: S005 | H16: S006 | I16: S007 | J16: S008 | K16: S009 | L16: S010
A17: 美国占比来源 | C17: S001 | D17: S002 | E17: S003 | F17: S004 | G17: S005 | H17: S006 | I17: S007 | J17: S008 | K17: S009 | L17: S010
A19: 2. 根据销量占比推算绝对量（亿单位箱）
A20: 碳酸软饮（估算） | C20: =C8*C12 -> 202.17 | D20: =D8*D12 -> 201.48 | E20: =E8*E12 -> 204.24 | F20: =F8*F12 -> 209.07 | G20: =G8*G12 -> 200.1 | H20: =H8*H12 -> 215.97 | I20: =I8*I12 -> 225.63 | J20: =J8*J12 -> 229.77 | ... L20: =L8*L12 -> 233.22
A21: 可口可乐商标系列（估算） | C21: =C8*C13 -> 131.85 | D21: =D8*D13 -> 131.4 | E21: =E8*E13 -> 133.2 | F21: =F8*F13 -> 136.35 | G21: =G8*G13 -> 136.3 | H21: =H8*H13 -> 147.11 | I21: =I8*I13 -> 150.42 | J21: =J8*J13 -> 156.51 | ... L21: =L8*L13 -> 158.86
A22: 其他品类（估算） | C22: =C8-C20 -> 90.83 | D22: =D8-D20 -> 90.52 | E22: =E8-E20 -> 91.76 | F22: =F8-F20 -> 93.93 | G22: =G8-G20 -> 89.9 | H22: =H8-H20 -> 97.03 | I22: =I8-I20 -> 101.37 | J22: =J8-J20 -> 103.23 | ... L22: =L8-L20 -> 104.78
A23: 碳酸软饮中其他商标（估算） | C23: =C20-C21 -> 70.32 | D23: =D20-D21 -> 70.08 | E23: =E20-E21 -> 71.04 | F23: =F20-F21 -> 72.72 | G23: =G20-G21 -> 63.8 | H23: =H20-H21 -> 68.86 | I23: =I20-I21 -> 75.21 | J23: =J20-J21 -> 73.26 | ... L23: =L20-L21 -> 74.36
A24: 美国体系销量（估算） | C24: =C8*C14 -> 55.67 | D24: =D8*D14 -> 55.48 | E24: =E8*E14 -> 53.28 | F24: =F8*F14 -> 54.54 | G24: =G8*G14 -> 52.2 | H24: =H8*H14 -> 53.21 | I24: =I8*I14 -> 55.59 | J24: =J8*J14 -> 53.28 | ... L24: =L8*L14 -> 54.08
A25: 国际体系销量（估算） | C25: =C8-C24 -> 237.33 | D25: =D8-D24 -> 236.52 | E25: =E8-E24 -> 242.72 | F25: =F8-F24 -> 248.46 | G25: =G8-G24 -> 237.8 | H25: =H8-H24 -> 259.79 | I25: =I8-I24 -> 271.41 | J25: =J8-J24 -> 279.72 | ... L25: =L8-L24 -> 283.92
A26: 商标系列包含在碳酸软饮中，两行不能相加。上述绝对量为估算，不能替代公司披露的可比同比。
A28: 3. 全年品类增长（FY2017—FY2020原分类）
A29: 碳酸软饮 | D29: -0.01 | E29: 0.02 | F29: 0.02 | G29: -0.04
A30: 果汁、乳制品和植物基饮料 | D30: 0 | E30: -0.01 | F30: 0 | G30: -0.09
A31: 水、增值水和运动饮料 | D31: 0.01 | E31: 0.03 | F31: 0.03 | G31: -0.11
A32: 茶和咖啡 | D32: 0.02 | E32: 0.01 | F32: 0.01 | G32: -0.17
A33: 可口可乐商标系列 | D33: 未披露 | E33: 未披露 | F33: 未披露 | G33: -0.01
A34: Coca-Cola Zero Sugar | D34: 未披露 | E34: 双位数 | F34: 双位数 | G34: 0.04
A35: 全年增长来源 | D35: VOL-FY2017 | E35: VOL-FY2018 | F35: VOL-FY2019 | G35: VOL-FY2020
A36: FY2016公告使用Sparkling beverages等旧分类，未填入同名新口径。2021年起分类调整，旧表与新表分开。
A38: 4. 全年品类及品牌增长（FY2021—FY2025）
A39: 碳酸软饮 | H39: 0.07 | I39: 0.04 | J39: 0.02 | K39: 0.02 | L39: 0
A40: 可口可乐商标系列 | H40: 0.07 | I40: 0.04 | J40: 0.02 | K40: 0.02 | L40: 0
A41: Coca-Cola Zero Sugar | H41: 双位数 | I41: 0.11 | J41: 0.05 | K41: 0.09 | L41: 0.14
A42: Diet Coke / Coca-Cola Light | H42: 未披露 | I42: 未披露 | J42: 未披露 | K42: 未披露 | L42: 0
A43: 风味碳酸饮料 | H43: 0.09 | I43: 0.05 | J43: 0.01 | K43: 0.01 | L43: -0.01
A44: 果汁、增值乳制品和植物基饮料 | H44: 0.12 | I44: 0.03 | J44: 0.02 | K44: 0 | L44: -0.03
A45: 水、运动饮料、咖啡和茶 | H45: 0.07 | I45: 0.06 | J45: 0.01 | K45: -0.01 | L45: 0.02
...

Sheet Derived Metrics
A1: The Coca-Cola Company — Derived Metrics
A2: $ in millions except per-share data | USD | as of 2026-10-14
C3: FY2016 | D3: FY2017 | E3: FY2018 | F3: FY2019 | G3: FY2020 | H3: FY2021 | I3: FY2022 | J3: FY2023 | K3: FY2024 | L3: FY2025 | M3: · | N3: · | O3: · | P3: 3Q2024 | Q3: 1Q2025 | R3: 2Q2025 | S3: 3Q2025 | T3: 1Q2026 | U3: 2Q2026
C4: 2016-12-31 | D4: 2017-12-31 | E4: 2018-12-31 | F4: 2019-12-31 | G4: 2020-12-31 | H4: 2021-12-31 | I4: 2022-12-31 | J4: 2023-12-31 | K4: 2024-12-31 | L4: 2025-12-31 | P4: 2024-09-27 | Q4: 2025-03-28 | R4: 2025-06-27 | S4: 2025-09-26 | T4: 2026-04-03 | U4: 2026-07-03
A6: CONTENTS
A7: =HYPERLINK("#'Derived Metrics'!A19","1. PROFITABILITY") -> 1. PROFITABILITY
A8: =HYPERLINK("#'Derived Metrics'!A29","2. RETURNS (average of opening and closing balances)") -> 2. RETURNS (average of opening and closing balances)
A9: =HYPERLINK("#'Derived Metrics'!A35","3. LEVERAGE") -> 3. LEVERAGE
A10: =HYPERLINK("#'Derived Metrics'!A42","4. SOLVENCY") -> 4. SOLVENCY
A11: =HYPERLINK("#'Derived Metrics'!A46","5. LIQUIDITY") -> 5. LIQUIDITY
A12: =HYPERLINK("#'Derived Metrics'!A51","6. COVERAGE") -> 6. COVERAGE
A13: =HYPERLINK("#'Derived Metrics'!A55","7. CASH CONVERSION") -> 7. CASH CONVERSION
A14: =HYPERLINK("#'Derived Metrics'!A64","8. EARNINGS QUALITY") -> 8. EARNINGS QUALITY
A15: =HYPERLINK("#'Derived Metrics'!A68","9. GROWTH") -> 9. GROWTH
A16: =HYPERLINK("#'Derived Metrics'!A76","10. SHAREOWNER RETURNS") -> 10. SHAREOWNER RETURNS
A17: =HYPERLINK("#'Derived Metrics'!A84","11. WORKING CAPITAL") -> 11. WORKING CAPITAL
A19: 1. PROFITABILITY
A20: Gross Margin | C20: ='Income Statement'!C14/'Income Statement'!C11 -> 0.60669326 | D20: ='Income Statement'!D14/'Income Statement'!D11 -> 0.62109246 | E20: ='Income Statement'!E14/'Income Statement'!E11 -> 0.6190379 | F20: ='Income Statement'!F14/'Income Statement'!F11 -> 0.60771212 | G20: ='Income Statement'!G14/'Income Statement'!G11 -> 0.59311201 | H20: ='Income Statement'!H14/'Income Statement'!H11 -> 0.60271634 | I20: ='Income Statement'!I14/'Income Statement'!I11 -> 0.58143429 | J20: ='Income Statement'!J14/'Income Statement'!J11 -> 0.59522665 | ... L20: ='Income Statement'!L14/'Income Statement'!L11 -> 0.61625748 | P20: =IFERROR('Income Statement'!P14/'Income Statement'!P11,"") -> 0.60654631 | Q20: =IFERROR('Income Statement'!Q14/'Income Statement'!Q11,"") -> 0.62593225 | R20: =IFERROR('Income Statement'!R14/'Income Statement'!R11,"") -> 0.62393299 | S20: =IFERROR('Income Statement'!S14/'Income Statement'!S11,"") -> 0.61485347 | T20: =IFERROR('Income Statement'!T14/'Income Statement'!T11,"") -> 0.62957024 | U20: =IFERROR('Income Statement'!U14/'Income Statement'!U11,"") -> 0.62892377
A21: SG&A % of Revenue | C21: ='Income Statement'!C16/'Income Statement'!C11 -> 0.36714999 | D21: ='Income Statement'!D16/'Income Statement'!D11 -> 0.3544129 | E21: ='Income Statement'!E16/'Income Statement'!E11 -> 0.32075802 | F21: ='Income Statement'!F16/'Income Statement'!F11 -> 0.32477325 | G21: ='Income Statement'!G16/'Income Statement'!G11 -> 0.29475374 | H21: ='Income Statement'!H16/'Income Statement'!H11 -> 0.31416376 | I21: ='Income Statement'!I16/'Income Statement'!I11 -> 0.29950702 | J21: ='Income Statement'!J16/'Income Statement'!J11 -> 0.30537221 | ... L21: ='Income Statement'!L16/'Income Statement'!L11 -> 0.30289314 | P21: =IFERROR('Income Statement'!P16/'Income Statement'!P11,"") -> 0.3067319 | Q21: =IFERROR('Income Statement'!Q16/'Income Statement'!Q11,"") -> 0.29059215 | R21: =IFERROR('Income Statement'!R16/'Income Statement'!R11,"") -> 0.27682489 | S21: =IFERROR('Income Statement'!S16/'Income Statement'!S11,"") -> 0.29048575 | T21: =IFERROR('Income Statement'!T16/'Income Statement'!T11,"") -> 0.27838358 | U21: =IFERROR('Income Statement'!U16/'Income Statement'!U11,"") -> 0.27802691
A22: Operating Margin | C22: ='Income Statement'!C18/'Income Statement'!C11 -> 0.20679359 | D22: ='Income Statement'!D18/'Income Statement'!D11 -> 0.21415553 | E22: ='Income Statement'!E18/'Income Statement'!E11 -> 0.26682216 | F22: ='Income Statement'!F18/'Income Statement'!F11 -> 0.27064885 | G22: ='Income Statement'!G18/'Income Statement'!G11 -> 0.27252075 | H22: ='Income Statement'!H18/'Income Statement'!H11 -> 0.26666667 | I22: ='Income Statement'!I18/'Income Statement'!I11 -> 0.25367408 | J22: ='Income Statement'!J18/'Income Statement'!J11 -> 0.24721336 | ... L22: ='Income Statement'!L18/'Income Statement'!L11 -> 0.28706118 | P22: =IFERROR('Income Statement'!P18/'Income Statement'!P11,"") -> 0.21174287 | Q22: =IFERROR('Income Statement'!Q18/'Income Statement'!Q11,"") -> 0.32878066 | R22: =IFERROR('Income Statement'!R18/'Income Statement'!R11,"") -> 0.34144396 | S22: =IFERROR('Income Statement'!S18/'Income Statement'!S11,"") -> 0.31971096 | T22: =IFERROR('Income Statement'!T18/'Income Statement'!T11,"") -> 0.34950289 | U22: =IFERROR('Income Statement'!U18/'Income Statement'!U11,"") -> 0.34917788
A23: EBITDA (operating income + D&A; analyst calculation) | C23: =('Income Statement'!C18+'Cash Flow'!C17) -> 10444 | D23: =('Income Statement'!D18+'Cash Flow'!D17) -> 9015 | E23: =('Income Statement'!E18+'Cash Flow'!E17) -> 10238 | F23: =('Income Statement'!F18+'Cash Flow'!F17) -> 11451 | G23: =('Income Statement'!G18+'Cash Flow'!G17) -> 10533 | H23: =('Income Statement'!H18+'Cash Flow'!H17) -> 11760 | I23: =('Income Statement'!I18+'Cash Flow'!I17) -> 12169 | J23: =('Income Statement'!J18+'Cash Flow'!J17) -> 12439 | ... L23: =('Income Statement'!L18+'Cash Flow'!L17) -> 14812 | Q23: ='Income Statement'!Q18+Segments!Q61 -> 3926 | R23: ='Income Statement'!R18+Segments!R61 -> 4559 | S23: ='Income Statement'!S18+Segments!S61 -> 4250 | T23: ='Income Statement'!T18+Segments!T61 -> 4623 | U23: ='Income Statement'!U18+Segments!U61 -> 4938
A24: EBITDA Margin | C24: =('Income Statement'!C18+'Cash Flow'!C17)/'Income Statement'!C11 -> 0.24948045 | D24: =('Income Statement'!D18+'Cash Flow'!D17)/'Income Statement'!D11 -> 0.24895062 | E24: =('Income Statement'!E18+'Cash Flow'!E17)/'Income Statement'!E11 -> 0.29848397 | F24: =('Income Statement'!F18+'Cash Flow'!F17)/'Income Statement'!F11 -> 0.30727741 | G24: =('Income Statement'!G18+'Cash Flow'!G17)/'Income Statement'!G11 -> 0.31904647 | H24: =('Income Statement'!H18+'Cash Flow'!H17)/'Income Statement'!H11 -> 0.30422972 | I24: =('Income Statement'!I18+'Cash Flow'!I17)/'Income Statement'!I11 -> 0.28297368 | J24: =('Income Statement'!J18+'Cash Flow'!J17)/'Income Statement'!J11 -> 0.27186694 | ... L24: =('Income Statement'!L18+'Cash Flow'!L17)/'Income Statement'!L11 -> 0.3089631 | Q24: =IFERROR(Q23/'Income Statement'!Q11,"") -> 0.35277204 | R24: =IFERROR(R23/'Income Statement'!R11,"") -> 0.36370164 | S24: =IFERROR(S23/'Income Statement'!S11,"") -> 0.34122842 | T24: =IFERROR(T23/'Income Statement'!T11,"") -> 0.3706703 | U24: =IFERROR(U23/'Income Statement'!U11,"") -> 0.3690583
A25: Net Margin (attributable) | C25: ='Income Statement'!C32/'Income Statement'!C11 -> 0.15591334 | D25: ='Income Statement'!D32/'Income Statement'!D11 -> 0.034463714 | E25: ='Income Statement'!E32/'Income Statement'!E11 -> 0.18758017 | F25: ='Income Statement'!F32/'Income Statement'!F11 -> 0.23936027 | G25: ='Income Statement'!G32/'Income Statement'!G11 -> 0.23465802 | H25: ='Income Statement'!H32/'Income Statement'!H11 -> 0.25277454 | I25: ='Income Statement'!I32/'Income Statement'!I11 -> 0.22188634 | J25: ='Income Statement'!J32/'Income Statement'!J11 -> 0.23416532 | ... L25: ='Income Statement'!L32/'Income Statement'!L11 -> 0.27339855 | P25: =IFERROR('Income Statement'!P32/'Income Statement'!P11,"") -> 0.24025645 | Q25: =IFERROR('Income Statement'!Q32/'Income Statement'!Q11,"") -> 0.29921826 | R25: =IFERROR('Income Statement'!R32/'Income Statement'!R11,"") -> 0.30394894 | S25: =IFERROR('Income Statement'!S32/'Income Statement'!S11,"") -> 0.29674829 | T25: =IFERROR('Income Statement'!T32/'Income Statement'!T11,"") -> 0.31462476 | U25: =IFERROR('Income Statement'!U32/'Income Statement'!U11,"") -> 0.33071749
